Workbook
Name ActuaryCredentialsGASB: #REF!
Name ActuaryNameGASB: #REF!
Name ActuaryTitleGASB: #REF!
Name AdjCNSDate: #REF!
Name AdjCNSDate1: #REF!
Name AdjCNSDateTempEnable: #REF!
Name AgencyCode: #REF!
Name AgencyCode: #REF!
Name AgencyCode: #REF!
Name AgencyCode: #REF!
Name AgencyCode1: #REF!
Name AgencyCode1: #REF!
Name AgencyCode1: #REF!
Name AgencyCode1: #REF!
Name AnalystGASB: #REF!
Name Annuity: #REF!
Name Annuity: #REF!
Name Annuity: #REF!
Name Annuity: #REF!
Name Annuity1: #REF!
Name Annuity1: #REF!
Name Annuity1: #REF!
Name Annuity1: #REF!
Name AnnuityLY: #REF!
Name AnnuityLY: #REF!
Name AnnuityLY: #REF!
Name AnnuityLY: #REF!
Name ASTABPF: #REF!
Name ASTABPF1: #REF!
Name ASTEBPF: #REF!
Name ClientShortGASB: #REF!
Name CLPOWERDisc: #REF!
Name CLPOWERDiscMinus1: #REF!
Name CLPOWERDiscPlus1: #REF!
Name CLPOWERExp: #REF!
Name CNSDateDisc: #REF!
Name CNSDateDisc1: #REF!
Name ColaRate: #REF!
Name ConsultantNameGASB: #REF!
Name ConsultantTitleGASB: #REF!
Name Disc1DELTACENSUS: #REF!
Name Disc1INTNDIV12: #REF!
Name Disc1SINTADJBOM: #REF!
Name Disc1SINTNDIV12: #REF!
Name DiscDELTACENSUS: #REF!
Name DiscINTADJBOM: #REF!
Name DiscINTNDIV12: #REF!
Name DiscMinusOneINTADJBOM: #REF!
Name DiscMinusOneINTNDIV12: #REF!
Name DiscPlusOneINTADJBOM: #REF!
Name DiscPlusOneINTNDIV12: #REF!
Name EmployerRates: #REF!
Name EmployerRates: #REF!
Name EmployerRates: #REF!
Name EmployerRates: #REF!
Name EmployerRates1: #REF!
Name EmployerRates1: #REF!
Name EmployerRates1: #REF!
Name EmployerRates1: #REF!
Name EmployerRatesLEO: #REF!

Sheet 0001 Journal
A1: GASB 96 - SBITA Contracts Fund-by-Fund Journal Entries Form (to be submitted to the SCO annually—one form per fund)
A2: Manually complete every yellow field in this worksheet—there are no automatically calculated data-entry cells in this worksheet.
A3: Fiscal year: | F3: 2022–2023
A4: Organization Name: | F4: Department of Justice
A5: Organization Code (Business Unit): | F5: 0820
A6: Fund Number: | F6: 1
A7: Fund Type: | F7: Governmental Fund
A8: Fund Classification: | F8: =IF(OR($F$7='Drop Down Menus'!B2,$F$7='Drop Down Menus'!$B$3),'Drop Down Menus'!$D$9,IFERROR(VLOOKUP($F$5,GAAP02Aindex!$A$2:$D$900,4,FALSE),"Unidentified")) -> GENERAL GOVERNMENT
A12: =IF($F$3="2022–2023","Establish Beginning Balances (SBITAs commenced on or before 07/01/2022)","Establish Beginning Balances (existing SBITAs only)") -> Establish Beginning Balances (SBITAs commenced on or before 07/01/2022)
A13: Entry #
A14: 0 | B14: =IF($F$3="2022–2023","To establish the beginning balance of SBITAs as of 07/01/2022.","Roll forward prior year right-to-use SBITAs to record opening balances.") -> To establish the beginning balance of SBITAs as of 07/01/2022.
B15: Dr: Acct 0480 - RIGHT-TO-USE SBITA - AMORTIZABLE | J15: 3402299
B16: Dr: Acct 0950 - BEGINNING FUND BALANCE
B17: Dr: Acct 0952 - BEG FB ADJ/PRIOR PERIOD ADJUSTMENT
C18: Cr. Acct 0475 - ACCUMULATED AMORTIZATION - RIGHT-TO-USE SBITA
C19: Cr: Acct 0674 - RIGHT-TO-USE SBITA LIABILITY | K19: 3402299
C20: Cr: Acct 0950 - BEGINNING FUND BALANCE
C21: Cr: Acct 0952 - BEG FB ADJ/PRIOR PERIOD ADJUSTMENT
J22: =ROUND(SUM(J15:J17),2) -> 3402299 | K22: =ROUND(SUM(K18:K21),2) -> 3402299 | L22: =IF(J22=K22,"<- Debits and Credits equal each other.","<- Debits and Credits do not equal each other.") -> <- Debits and Credits equal each other.
B24: SBITA ASSET (Acct 0480) AMOUNT SHOULD BE REPORTED AS BEGINNING BALANCE ON REPORT 18.
A26: =IF($F$3="2022–2023","Record SBITAs Commenced on or after 07/02/2022","Record New SBITAs (new SBITAs only)") -> Record SBITAs Commenced on or after 07/02/2022
A27: 1 | B27: Record at inception of SBITA in accordance with Fund-Based accounting (Governmental Funds Only).
B28: Dr: Acct 0842 - CAPITAL OUTLAY | J28: 253151
C29: Cr: Acct 0789 - LEASE AND OTHER FINANCING PROCEEDS | K29: =J28 -> 253151
C30: =VLOOKUP($F$8,'Drop Down Menus'!$D$2:$G$10,4,FALSE) -> Cr: Acct 0808 - GENERAL GOV. (GAAP ADJ)
J31: =ROUND(SUM(J28:J30),2) -> 253151 | K31: =ROUND(SUM(K28:K30),2) -> 253151 | L31: =IF(J31=K31,"<- Debits and Credits equal each other.","<- Debits and Credits do not equal each other.") -> <- Debits and Credits equal each other.
A33: 2 | B33: Reverse the fund-based entry in #1 above, if any, and record an inception of SBITA in accordance with GAAP Govt Wide.
B34: Dr: Acct 0480 - RIGHT-TO-USE SBITA - AMORTIZABLE | J34: =K36 -> 253151
B35: Dr: Acct 0789 - LEASE AND OTHER FINANCING PROCEEDS | J35: =K29 -> 253151
C36: Cr: Acct 0842 - CAPITAL OUTLAY | K36: =J28 -> 253151
C37: Cr: Acct 0674 - RIGHT-TO-USE SBITA LIABILITY | K37: =J35 -> 253151
C38: =VLOOKUP($F$8,'Drop Down Menus'!$D$2:$G$10,4,FALSE) -> Cr: Acct 0808 - GENERAL GOV. (GAAP ADJ)
J39: =ROUND(SUM(J34:J35),2) -> 506302 | K39: =ROUND(SUM(K36:K38),2) -> 506302 | L39: =IF(J39=K39,"<- Debits and Credits equal each other.","<- Debits and Credits do not equal each other.") -> <- Debits and Credits equal each other.
B41: SBITA ASSET (Acct 0480) AMOUNT SHOULD BE INCLUDED AS "ADDITIONS" ON REPORT 18.
A43: Record Annual Activity (all SBITAs)
A44: 3 | B44: Record amortization of the SBITA asset for the year.
B45: Dr: Acct 0875 - DEPRECIATION/AMORTIZATION | J45: 2247186
C46: Cr. Acct 0475 - ACCUMULATED AMORTIZATION - RIGHT-TO-USE SBITA | K46: =J45 -> 2247186
J47: =ROUND(SUM(J45:J45),2) -> 2247186 | K47: =ROUND(SUM(K46),2) -> 2247186 | L47: =IF(J47=K47,"<- Debits and Credits equal each other.","<- Debits and Credits do not equal each other.") -> <- Debits and Credits equal each other.
A49: 4 | B49: Reclassify information technology subscription exp. to debt service principal and interest exp.
...

Sheet 0012 Journal
A1: GASB 96 - SBITA Contracts Fund-by-Fund Journal Entries Form (to be submitted to the SCO annually—one form per fund)
A2: Manually complete every yellow field in this worksheet—there are no automatically calculated data-entry cells in this worksheet.
A3: Fiscal year: | F3: 2022–2023
A4: Organization Name: | F4: Department of Justice
A5: Organization Code (Business Unit): | F5: 0820
A6: Fund Number: | F6: 12
A7: Fund Type: | F7: Governmental Fund
A8: Fund Classification: | F8: =IF(OR($F$7='Drop Down Menus'!B2,$F$7='Drop Down Menus'!$B$3),'Drop Down Menus'!$D$9,IFERROR(VLOOKUP($F$5,GAAP02Aindex!$A$2:$D$900,4,FALSE),"Unidentified")) -> GENERAL GOVERNMENT
A12: =IF($F$3="2022–2023","Establish Beginning Balances (SBITAs commenced on or before 07/01/2022)","Establish Beginning Balances (existing SBITAs only)") -> Establish Beginning Balances (SBITAs commenced on or before 07/01/2022)
A13: Entry #
A14: 0 | B14: =IF($F$3="2022–2023","To establish the beginning balance of SBITAs as of 07/01/2022.","Roll forward prior year right-to-use SBITAs to record opening balances.") -> To establish the beginning balance of SBITAs as of 07/01/2022.
B15: Dr: Acct 0480 - RIGHT-TO-USE SBITA - AMORTIZABLE | J15: 639
B16: Dr: Acct 0950 - BEGINNING FUND BALANCE
B17: Dr: Acct 0952 - BEG FB ADJ/PRIOR PERIOD ADJUSTMENT
C18: Cr. Acct 0475 - ACCUMULATED AMORTIZATION - RIGHT-TO-USE SBITA
C19: Cr: Acct 0674 - RIGHT-TO-USE SBITA LIABILITY | K19: 639
C20: Cr: Acct 0950 - BEGINNING FUND BALANCE
C21: Cr: Acct 0952 - BEG FB ADJ/PRIOR PERIOD ADJUSTMENT
J22: =ROUND(SUM(J15:J17),2) -> 639 | K22: =ROUND(SUM(K18:K21),2) -> 639 | L22: =IF(J22=K22,"<- Debits and Credits equal each other.","<- Debits and Credits do not equal each other.") -> <- Debits and Credits equal each other.
B24: SBITA ASSET (Acct 0480) AMOUNT SHOULD BE REPORTED AS BEGINNING BALANCE ON REPORT 18.
A26: =IF($F$3="2022–2023","Record SBITAs Commenced on or after 07/02/2022","Record New SBITAs (new SBITAs only)") -> Record SBITAs Commenced on or after 07/02/2022
A27: 1 | B27: Record at inception of SBITA in accordance with Fund-Based accounting (Governmental Funds Only).
B28: Dr: Acct 0842 - CAPITAL OUTLAY | J28: 78
C29: Cr: Acct 0789 - LEASE AND OTHER FINANCING PROCEEDS | K29: =J28 -> 78
C30: =VLOOKUP($F$8,'Drop Down Menus'!$D$2:$G$10,4,FALSE) -> Cr: Acct 0808 - GENERAL GOV. (GAAP ADJ)
J31: =ROUND(SUM(J28:J30),2) -> 78 | K31: =ROUND(SUM(K28:K30),2) -> 78 | L31: =IF(J31=K31,"<- Debits and Credits equal each other.","<- Debits and Credits do not equal each other.") -> <- Debits and Credits equal each other.
A33: 2 | B33: Reverse the fund-based entry in #1 above, if any, and record an inception of SBITA in accordance with GAAP Govt Wide.
B34: Dr: Acct 0480 - RIGHT-TO-USE SBITA - AMORTIZABLE | J34: =K29 -> 78
B35: Dr: Acct 0789 - LEASE AND OTHER FINANCING PROCEEDS | J35: =K29 -> 78
C36: Cr: Acct 0842 - CAPITAL OUTLAY | K36: =J28 -> 78
C37: Cr: Acct 0674 - RIGHT-TO-USE SBITA LIABILITY | K37: =J35 -> 78
C38: =VLOOKUP($F$8,'Drop Down Menus'!$D$2:$G$10,4,FALSE) -> Cr: Acct 0808 - GENERAL GOV. (GAAP ADJ)
J39: =ROUND(SUM(J34:J35),2) -> 156 | K39: =ROUND(SUM(K36:K38),2) -> 156 | L39: =IF(J39=K39,"<- Debits and Credits equal each other.","<- Debits and Credits do not equal each other.") -> <- Debits and Credits equal each other.
B41: SBITA ASSET (Acct 0480) AMOUNT SHOULD BE INCLUDED AS "ADDITIONS" ON REPORT 18.
A43: Record Annual Activity (all SBITAs)
A44: 3 | B44: Record amortization of the SBITA asset for the year.
B45: Dr: Acct 0875 - DEPRECIATION/AMORTIZATION | J45: 295
C46: Cr. Acct 0475 - ACCUMULATED AMORTIZATION - RIGHT-TO-USE SBITA | K46: =J45 -> 295
J47: =ROUND(SUM(J45:J45),2) -> 295 | K47: =ROUND(SUM(K46),2) -> 295 | L47: =IF(J47=K47,"<- Debits and Credits equal each other.","<- Debits and Credits do not equal each other.") -> <- Debits and Credits equal each other.
A49: 4 | B49: Reclassify information technology subscription exp. to debt service principal and interest exp.
...

Sheet 0017 Journal
A1: GASB 96 - SBITA Contracts Fund-by-Fund Journal Entries Form (to be submitted to the SCO annually—one form per fund)
A2: Manually complete every yellow field in this worksheet—there are no automatically calculated data-entry cells in this worksheet.
A3: Fiscal year: | F3: 2022–2023
A4: Organization Name: | F4: Department of Justice
A5: Organization Code (Business Unit): | F5: 0820
A6: Fund Number: | F6: 17
A7: Fund Type: | F7: Governmental Fund
A8: Fund Classification: | F8: =IF(OR($F$7='Drop Down Menus'!B2,$F$7='Drop Down Menus'!$B$3),'Drop Down Menus'!$D$9,IFERROR(VLOOKUP($F$5,GAAP02Aindex!$A$2:$D$900,4,FALSE),"Unidentified")) -> GENERAL GOVERNMENT
A12: =IF($F$3="2022–2023","Establish Beginning Balances (SBITAs commenced on or before 07/01/2022)","Establish Beginning Balances (existing SBITAs only)") -> Establish Beginning Balances (SBITAs commenced on or before 07/01/2022)
A13: Entry #
A14: 0 | B14: =IF($F$3="2022–2023","To establish the beginning balance of SBITAs as of 07/01/2022.","Roll forward prior year right-to-use SBITAs to record opening balances.") -> To establish the beginning balance of SBITAs as of 07/01/2022.
B15: Dr: Acct 0480 - RIGHT-TO-USE SBITA - AMORTIZABLE | J15: 219388
B16: Dr: Acct 0950 - BEGINNING FUND BALANCE
B17: Dr: Acct 0952 - BEG FB ADJ/PRIOR PERIOD ADJUSTMENT
C18: Cr. Acct 0475 - ACCUMULATED AMORTIZATION - RIGHT-TO-USE SBITA
C19: Cr: Acct 0674 - RIGHT-TO-USE SBITA LIABILITY | K19: =J15 -> 219388
C20: Cr: Acct 0950 - BEGINNING FUND BALANCE
C21: Cr: Acct 0952 - BEG FB ADJ/PRIOR PERIOD ADJUSTMENT
J22: =ROUND(SUM(J15:J17),2) -> 219388 | K22: =ROUND(SUM(K18:K21),2) -> 219388 | L22: =IF(J22=K22,"<- Debits and Credits equal each other.","<- Debits and Credits do not equal each other.") -> <- Debits and Credits equal each other.
B24: SBITA ASSET (Acct 0480) AMOUNT SHOULD BE REPORTED AS BEGINNING BALANCE ON REPORT 18.
A26: =IF($F$3="2022–2023","Record SBITAs Commenced on or after 07/02/2022","Record New SBITAs (new SBITAs only)") -> Record SBITAs Commenced on or after 07/02/2022
A27: 1 | B27: Record at inception of SBITA in accordance with Fund-Based accounting (Governmental Funds Only).
B28: Dr: Acct 0842 - CAPITAL OUTLAY | J28: 113480
C29: Cr: Acct 0789 - LEASE AND OTHER FINANCING PROCEEDS | K29: =J28 -> 113480
C30: =VLOOKUP($F$8,'Drop Down Menus'!$D$2:$G$10,4,FALSE) -> Cr: Acct 0808 - GENERAL GOV. (GAAP ADJ)
J31: =ROUND(SUM(J28:J30),2) -> 113480 | K31: =ROUND(SUM(K28:K30),2) -> 113480 | L31: =IF(J31=K31,"<- Debits and Credits equal each other.","<- Debits and Credits do not equal each other.") -> <- Debits and Credits equal each other.
A33: 2 | B33: Reverse the fund-based entry in #1 above, if any, and record an inception of SBITA in accordance with GAAP Govt Wide.
B34: Dr: Acct 0480 - RIGHT-TO-USE SBITA - AMORTIZABLE | J34: 113480
B35: Dr: Acct 0789 - LEASE AND OTHER FINANCING PROCEEDS | J35: 113480
C36: Cr: Acct 0842 - CAPITAL OUTLAY | K36: 113480
C37: Cr: Acct 0674 - RIGHT-TO-USE SBITA LIABILITY | K37: 113480
C38: =VLOOKUP($F$8,'Drop Down Menus'!$D$2:$G$10,4,FALSE) -> Cr: Acct 0808 - GENERAL GOV. (GAAP ADJ)
J39: =ROUND(SUM(J34:J35),2) -> 226960 | K39: =ROUND(SUM(K36:K38),2) -> 226960 | L39: =IF(J39=K39,"<- Debits and Credits equal each other.","<- Debits and Credits do not equal each other.") -> <- Debits and Credits equal each other.
B41: SBITA ASSET (Acct 0480) AMOUNT SHOULD BE INCLUDED AS "ADDITIONS" ON REPORT 18.
A43: Record Annual Activity (all SBITAs)
A44: 3 | B44: Record amortization of the SBITA asset for the year.
B45: Dr: Acct 0875 - DEPRECIATION/AMORTIZATION | J45: 186858
C46: Cr. Acct 0475 - ACCUMULATED AMORTIZATION - RIGHT-TO-USE SBITA | K46: =J45 -> 186858
J47: =ROUND(SUM(J45:J45),2) -> 186858 | K47: =ROUND(SUM(K46),2) -> 186858 | L47: =IF(J47=K47,"<- Debits and Credits equal each other.","<- Debits and Credits do not equal each other.") -> <- Debits and Credits equal each other.
A49: 4 | B49: Reclassify information technology subscription exp. to debt service principal and interest exp.
...

Sheet 0044 Journal
A1: GASB 96 - SBITA Contracts Fund-by-Fund Journal Entries Form (to be submitted to the SCO annually—one form per fund)
A2: Manually complete every yellow field in this worksheet—there are no automatically calculated data-entry cells in this worksheet.
A3: Fiscal year: | F3: 2022–2023
A4: Organization Name: | F4: Department of Justice
A5: Organization Code (Business Unit): | F5: 0820
A6: Fund Number: | F6: 44
A7: Fund Type: | F7: Governmental Fund
A8: Fund Classification: | F8: =IF(OR($F$7='Drop Down Menus'!B2,$F$7='Drop Down Menus'!$B$3),'Drop Down Menus'!$D$9,IFERROR(VLOOKUP($F$5,GAAP02Aindex!$A$2:$D$900,4,FALSE),"Unidentified")) -> GENERAL GOVERNMENT
A12: =IF($F$3="2022–2023","Establish Beginning Balances (SBITAs commenced on or before 07/01/2022)","Establish Beginning Balances (existing SBITAs only)") -> Establish Beginning Balances (SBITAs commenced on or before 07/01/2022)
A13: Entry #
A14: 0 | B14: =IF($F$3="2022–2023","To establish the beginning balance of SBITAs as of 07/01/2022.","Roll forward prior year right-to-use SBITAs to record opening balances.") -> To establish the beginning balance of SBITAs as of 07/01/2022.
B15: Dr: Acct 0480 - RIGHT-TO-USE SBITA - AMORTIZABLE | J15: 287390
B16: Dr: Acct 0950 - BEGINNING FUND BALANCE
B17: Dr: Acct 0952 - BEG FB ADJ/PRIOR PERIOD ADJUSTMENT
C18: Cr. Acct 0475 - ACCUMULATED AMORTIZATION - RIGHT-TO-USE SBITA
C19: Cr: Acct 0674 - RIGHT-TO-USE SBITA LIABILITY | K19: 287390
C20: Cr: Acct 0950 - BEGINNING FUND BALANCE
C21: Cr: Acct 0952 - BEG FB ADJ/PRIOR PERIOD ADJUSTMENT
J22: =ROUND(SUM(J15:J17),2) -> 287390 | K22: =ROUND(SUM(K18:K21),2) -> 287390 | L22: =IF(J22=K22,"<- Debits and Credits equal each other.","<- Debits and Credits do not equal each other.") -> <- Debits and Credits equal each other.
B24: SBITA ASSET (Acct 0480) AMOUNT SHOULD BE REPORTED AS BEGINNING BALANCE ON REPORT 18.
A26: =IF($F$3="2022–2023","Record SBITAs Commenced on or after 07/02/2022","Record New SBITAs (new SBITAs only)") -> Record SBITAs Commenced on or after 07/02/2022
A27: 1 | B27: Record at inception of SBITA in accordance with Fund-Based accounting (Governmental Funds Only).
B28: Dr: Acct 0842 - CAPITAL OUTLAY | J28: 148655
C29: Cr: Acct 0789 - LEASE AND OTHER FINANCING PROCEEDS | K29: 148655
C30: =VLOOKUP($F$8,'Drop Down Menus'!$D$2:$G$10,4,FALSE) -> Cr: Acct 0808 - GENERAL GOV. (GAAP ADJ)
J31: =ROUND(SUM(J28:J30),2) -> 148655 | K31: =ROUND(SUM(K28:K30),2) -> 148655 | L31: =IF(J31=K31,"<- Debits and Credits equal each other.","<- Debits and Credits do not equal each other.") -> <- Debits and Credits equal each other.
A33: 2 | B33: Reverse the fund-based entry in #1 above, if any, and record an inception of SBITA in accordance with GAAP Govt Wide.
B34: Dr: Acct 0480 - RIGHT-TO-USE SBITA - AMORTIZABLE | J34: 148655
B35: Dr: Acct 0789 - LEASE AND OTHER FINANCING PROCEEDS | J35: 148655
C36: Cr: Acct 0842 - CAPITAL OUTLAY | K36: 148655
C37: Cr: Acct 0674 - RIGHT-TO-USE SBITA LIABILITY | K37: 148655
C38: =VLOOKUP($F$8,'Drop Down Menus'!$D$2:$G$10,4,FALSE) -> Cr: Acct 0808 - GENERAL GOV. (GAAP ADJ)
J39: =ROUND(SUM(J34:J35),2) -> 297310 | K39: =ROUND(SUM(K36:K38),2) -> 297310 | L39: =IF(J39=K39,"<- Debits and Credits equal each other.","<- Debits and Credits do not equal each other.") -> <- Debits and Credits equal each other.
B41: SBITA ASSET (Acct 0480) AMOUNT SHOULD BE INCLUDED AS "ADDITIONS" ON REPORT 18.
A43: Record Annual Activity (all SBITAs)
A44: 3 | B44: Record amortization of the SBITA asset for the year.
B45: Dr: Acct 0875 - DEPRECIATION/AMORTIZATION | J45: 244778
C46: Cr. Acct 0475 - ACCUMULATED AMORTIZATION - RIGHT-TO-USE SBITA | K46: =J45 -> 244778
J47: =ROUND(SUM(J45:J45),2) -> 244778 | K47: =ROUND(SUM(K46),2) -> 244778 | L47: =IF(J47=K47,"<- Debits and Credits equal each other.","<- Debits and Credits do not equal each other.") -> <- Debits and Credits equal each other.
A49: 4 | B49: Reclassify information technology subscription exp. to debt service principal and interest exp.
...

Sheet 0158 Journal
A1: GASB 96 - SBITA Contracts Fund-by-Fund Journal Entries Form (to be submitted to the SCO annually—one form per fund)
A2: Manually complete every yellow field in this worksheet—there are no automatically calculated data-entry cells in this worksheet.
A3: Fiscal year: | F3: 2022–2023
A4: Organization Name: | F4: Department of Justice
A5: Organization Code (Business Unit): | F5: 0820
A6: Fund Number: | F6: 158
A7: Fund Type: | F7: Governmental Fund
A8: Fund Classification: | F8: =IF(OR($F$7='Drop Down Menus'!B2,$F$7='Drop Down Menus'!$B$3),'Drop Down Menus'!$D$9,IFERROR(VLOOKUP($F$5,GAAP02Aindex!$A$2:$D$900,4,FALSE),"Unidentified")) -> GENERAL GOVERNMENT
A12: =IF($F$3="2022–2023","Establish Beginning Balances (SBITAs commenced on or before 07/01/2022)","Establish Beginning Balances (existing SBITAs only)") -> Establish Beginning Balances (SBITAs commenced on or before 07/01/2022)
A13: Entry #
A14: 0 | B14: =IF($F$3="2022–2023","To establish the beginning balance of SBITAs as of 07/01/2022.","Roll forward prior year right-to-use SBITAs to record opening balances.") -> To establish the beginning balance of SBITAs as of 07/01/2022.
B15: Dr: Acct 0480 - RIGHT-TO-USE SBITA - AMORTIZABLE | J15: 139
B16: Dr: Acct 0950 - BEGINNING FUND BALANCE
B17: Dr: Acct 0952 - BEG FB ADJ/PRIOR PERIOD ADJUSTMENT
C18: Cr. Acct 0475 - ACCUMULATED AMORTIZATION - RIGHT-TO-USE SBITA
C19: Cr: Acct 0674 - RIGHT-TO-USE SBITA LIABILITY | K19: 139
C20: Cr: Acct 0950 - BEGINNING FUND BALANCE
C21: Cr: Acct 0952 - BEG FB ADJ/PRIOR PERIOD ADJUSTMENT
J22: =ROUND(SUM(J15:J17),2) -> 139 | K22: =ROUND(SUM(K18:K21),2) -> 139 | L22: =IF(J22=K22,"<- Debits and Credits equal each other.","<- Debits and Credits do not equal each other.") -> <- Debits and Credits equal each other.
B24: SBITA ASSET (Acct 0480) AMOUNT SHOULD BE REPORTED AS BEGINNING BALANCE ON REPORT 18.
A26: =IF($F$3="2022–2023","Record SBITAs Commenced on or after 07/02/2022","Record New SBITAs (new SBITAs only)") -> Record SBITAs Commenced on or after 07/02/2022
A27: 1 | B27: Record at inception of SBITA in accordance with Fund-Based accounting (Governmental Funds Only).
B28: Dr: Acct 0842 - CAPITAL OUTLAY | J28: 72
C29: Cr: Acct 0789 - LEASE AND OTHER FINANCING PROCEEDS | K29: 72
C30: =VLOOKUP($F$8,'Drop Down Menus'!$D$2:$G$10,4,FALSE) -> Cr: Acct 0808 - GENERAL GOV. (GAAP ADJ)
J31: =ROUND(SUM(J28:J30),2) -> 72 | K31: =ROUND(SUM(K28:K30),2) -> 72 | L31: =IF(J31=K31,"<- Debits and Credits equal each other.","<- Debits and Credits do not equal each other.") -> <- Debits and Credits equal each other.
A33: 2 | B33: Reverse the fund-based entry in #1 above, if any, and record an inception of SBITA in accordance with GAAP Govt Wide.
B34: Dr: Acct 0480 - RIGHT-TO-USE SBITA - AMORTIZABLE | J34: 72
B35: Dr: Acct 0789 - LEASE AND OTHER FINANCING PROCEEDS | J35: 72
C36: Cr: Acct 0842 - CAPITAL OUTLAY | K36: 72
C37: Cr: Acct 0674 - RIGHT-TO-USE SBITA LIABILITY | K37: 72
C38: =VLOOKUP($F$8,'Drop Down Menus'!$D$2:$G$10,4,FALSE) -> Cr: Acct 0808 - GENERAL GOV. (GAAP ADJ)
J39: =ROUND(SUM(J34:J35),2) -> 144 | K39: =ROUND(SUM(K36:K38),2) -> 144 | L39: =IF(J39=K39,"<- Debits and Credits equal each other.","<- Debits and Credits do not equal each other.") -> <- Debits and Credits equal each other.
B41: SBITA ASSET (Acct 0480) AMOUNT SHOULD BE INCLUDED AS "ADDITIONS" ON REPORT 18.
A43: Record Annual Activity (all SBITAs)
A44: 3 | B44: Record amortization of the SBITA asset for the year.
B45: Dr: Acct 0875 - DEPRECIATION/AMORTIZATION | J45: 119
C46: Cr. Acct 0475 - ACCUMULATED AMORTIZATION - RIGHT-TO-USE SBITA | K46: =J45 -> 119
J47: =ROUND(SUM(J45:J45),2) -> 119 | K47: =ROUND(SUM(K46),2) -> 119 | L47: =IF(J47=K47,"<- Debits and Credits equal each other.","<- Debits and Credits do not equal each other.") -> <- Debits and Credits equal each other.
A49: 4 | B49: Reclassify information technology subscription exp. to debt service principal and interest exp.
...

Sheet 0367 Journal
A1: GASB 96 - SBITA Contracts Fund-by-Fund Journal Entries Form (to be submitted to the SCO annually—one form per fund)
A2: Manually complete every yellow field in this worksheet—there are no automatically calculated data-entry cells in this worksheet.
A3: Fiscal year: | F3: 2022–2023
A4: Organization Name: | F4: Department of Justice
A5: Organization Code (Business Unit): | F5: 0820
A6: Fund Number: | F6: 367
A7: Fund Type: | F7: Governmental Fund
A8: Fund Classification: | F8: =IF(OR($F$7='Drop Down Menus'!B2,$F$7='Drop Down Menus'!$B$3),'Drop Down Menus'!$D$9,IFERROR(VLOOKUP($F$5,GAAP02Aindex!$A$2:$D$900,4,FALSE),"Unidentified")) -> GENERAL GOVERNMENT
A12: =IF($F$3="2022–2023","Establish Beginning Balances (SBITAs commenced on or before 07/01/2022)","Establish Beginning Balances (existing SBITAs only)") -> Establish Beginning Balances (SBITAs commenced on or before 07/01/2022)
A13: Entry #
A14: 0 | B14: =IF($F$3="2022–2023","To establish the beginning balance of SBITAs as of 07/01/2022.","Roll forward prior year right-to-use SBITAs to record opening balances.") -> To establish the beginning balance of SBITAs as of 07/01/2022.
B15: Dr: Acct 0480 - RIGHT-TO-USE SBITA - AMORTIZABLE | J15: 285435
B16: Dr: Acct 0950 - BEGINNING FUND BALANCE
B17: Dr: Acct 0952 - BEG FB ADJ/PRIOR PERIOD ADJUSTMENT
C18: Cr. Acct 0475 - ACCUMULATED AMORTIZATION - RIGHT-TO-USE SBITA
C19: Cr: Acct 0674 - RIGHT-TO-USE SBITA LIABILITY | K19: 285435
C20: Cr: Acct 0950 - BEGINNING FUND BALANCE
C21: Cr: Acct 0952 - BEG FB ADJ/PRIOR PERIOD ADJUSTMENT
J22: =ROUND(SUM(J15:J17),2) -> 285435 | K22: =ROUND(SUM(K18:K21),2) -> 285435 | L22: =IF(J22=K22,"<- Debits and Credits equal each other.","<- Debits and Credits do not equal each other.") -> <- Debits and Credits equal each other.
B24: SBITA ASSET (Acct 0480) AMOUNT SHOULD BE REPORTED AS BEGINNING BALANCE ON REPORT 18.
A26: =IF($F$3="2022–2023","Record SBITAs Commenced on or after 07/02/2022","Record New SBITAs (new SBITAs only)") -> Record SBITAs Commenced on or after 07/02/2022
A27: 1 | B27: Record at inception of SBITA in accordance with Fund-Based accounting (Governmental Funds Only).
B28: Dr: Acct 0842 - CAPITAL OUTLAY | J28: 2315
C29: Cr: Acct 0789 - LEASE AND OTHER FINANCING PROCEEDS | K29: 2315
C30: =VLOOKUP($F$8,'Drop Down Menus'!$D$2:$G$10,4,FALSE) -> Cr: Acct 0808 - GENERAL GOV. (GAAP ADJ)
J31: =ROUND(SUM(J28:J30),2) -> 2315 | K31: =ROUND(SUM(K28:K30),2) -> 2315 | L31: =IF(J31=K31,"<- Debits and Credits equal each other.","<- Debits and Credits do not equal each other.") -> <- Debits and Credits equal each other.
A33: 2 | B33: Reverse the fund-based entry in #1 above, if any, and record an inception of SBITA in accordance with GAAP Govt Wide.
B34: Dr: Acct 0480 - RIGHT-TO-USE SBITA - AMORTIZABLE | J34: 2315
B35: Dr: Acct 0789 - LEASE AND OTHER FINANCING PROCEEDS | J35: 2315
C36: Cr: Acct 0842 - CAPITAL OUTLAY | K36: 2315
C37: Cr: Acct 0674 - RIGHT-TO-USE SBITA LIABILITY | K37: 2315
C38: =VLOOKUP($F$8,'Drop Down Menus'!$D$2:$G$10,4,FALSE) -> Cr: Acct 0808 - GENERAL GOV. (GAAP ADJ)
J39: =ROUND(SUM(J34:J35),2) -> 4630 | K39: =ROUND(SUM(K36:K38),2) -> 4630 | L39: =IF(J39=K39,"<- Debits and Credits equal each other.","<- Debits and Credits do not equal each other.") -> <- Debits and Credits equal each other.
B41: SBITA ASSET (Acct 0480) AMOUNT SHOULD BE INCLUDED AS "ADDITIONS" ON REPORT 18.
A43: Record Annual Activity (all SBITAs)
A44: 3 | B44: Record amortization of the SBITA asset for the year.
B45: Dr: Acct 0875 - DEPRECIATION/AMORTIZATION | J45: 99336
C46: Cr. Acct 0475 - ACCUMULATED AMORTIZATION - RIGHT-TO-USE SBITA | K46: =J45 -> 99336
J47: =ROUND(SUM(J45:J45),2) -> 99336 | K47: =ROUND(SUM(K46),2) -> 99336 | L47: =IF(J47=K47,"<- Debits and Credits equal each other.","<- Debits and Credits do not equal each other.") -> <- Debits and Credits equal each other.
A49: 4 | B49: Reclassify information technology subscription exp. to debt service principal and interest exp.
...

Sheet 0378 Journal
A1: GASB 96 - SBITA Contracts Fund-by-Fund Journal Entries Form (to be submitted to the SCO annually—one form per fund)
A2: Manually complete every yellow field in this worksheet—there are no automatically calculated data-entry cells in this worksheet.
A3: Fiscal year: | F3: 2022–2023
A4: Organization Name: | F4: Department of Justice
A5: Organization Code (Business Unit): | F5: 0820
A6: Fund Number: | F6: 378
A7: Fund Type: | F7: Governmental Fund
A8: Fund Classification: | F8: =IF(OR($F$7='Drop Down Menus'!B2,$F$7='Drop Down Menus'!$B$3),'Drop Down Menus'!$D$9,IFERROR(VLOOKUP($F$5,GAAP02Aindex!$A$2:$D$900,4,FALSE),"Unidentified")) -> GENERAL GOVERNMENT
A12: =IF($F$3="2022–2023","Establish Beginning Balances (SBITAs commenced on or before 07/01/2022)","Establish Beginning Balances (existing SBITAs only)") -> Establish Beginning Balances (SBITAs commenced on or before 07/01/2022)
A13: Entry #
A14: 0 | B14: =IF($F$3="2022–2023","To establish the beginning balance of SBITAs as of 07/01/2022.","Roll forward prior year right-to-use SBITAs to record opening balances.") -> To establish the beginning balance of SBITAs as of 07/01/2022.
B15: Dr: Acct 0480 - RIGHT-TO-USE SBITA - AMORTIZABLE | J15: 10908
B16: Dr: Acct 0950 - BEGINNING FUND BALANCE
B17: Dr: Acct 0952 - BEG FB ADJ/PRIOR PERIOD ADJUSTMENT
C18: Cr. Acct 0475 - ACCUMULATED AMORTIZATION - RIGHT-TO-USE SBITA
C19: Cr: Acct 0674 - RIGHT-TO-USE SBITA LIABILITY | K19: 10908
C20: Cr: Acct 0950 - BEGINNING FUND BALANCE
C21: Cr: Acct 0952 - BEG FB ADJ/PRIOR PERIOD ADJUSTMENT
J22: =ROUND(SUM(J15:J17),2) -> 10908 | K22: =ROUND(SUM(K18:K21),2) -> 10908 | L22: =IF(J22=K22,"<- Debits and Credits equal each other.","<- Debits and Credits do not equal each other.") -> <- Debits and Credits equal each other.
B24: SBITA ASSET (Acct 0480) AMOUNT SHOULD BE REPORTED AS BEGINNING BALANCE ON REPORT 18.
A26: =IF($F$3="2022–2023","Record SBITAs Commenced on or after 07/02/2022","Record New SBITAs (new SBITAs only)") -> Record SBITAs Commenced on or after 07/02/2022
A27: 1 | B27: Record at inception of SBITA in accordance with Fund-Based accounting (Governmental Funds Only).
B28: Dr: Acct 0842 - CAPITAL OUTLAY | J28: 3547
C29: Cr: Acct 0789 - LEASE AND OTHER FINANCING PROCEEDS | K29: 3547
C30: =VLOOKUP($F$8,'Drop Down Menus'!$D$2:$G$10,4,FALSE) -> Cr: Acct 0808 - GENERAL GOV. (GAAP ADJ)
J31: =ROUND(SUM(J28:J30),2) -> 3547 | K31: =ROUND(SUM(K28:K30),2) -> 3547 | L31: =IF(J31=K31,"<- Debits and Credits equal each other.","<- Debits and Credits do not equal each other.") -> <- Debits and Credits equal each other.
A33: 2 | B33: Reverse the fund-based entry in #1 above, if any, and record an inception of SBITA in accordance with GAAP Govt Wide.
B34: Dr: Acct 0480 - RIGHT-TO-USE SBITA - AMORTIZABLE | J34: 3547
B35: Dr: Acct 0789 - LEASE AND OTHER FINANCING PROCEEDS | J35: 3547
C36: Cr: Acct 0842 - CAPITAL OUTLAY | K36: 3547
C37: Cr: Acct 0674 - RIGHT-TO-USE SBITA LIABILITY | K37: 3547
C38: =VLOOKUP($F$8,'Drop Down Menus'!$D$2:$G$10,4,FALSE) -> Cr: Acct 0808 - GENERAL GOV. (GAAP ADJ)
J39: =ROUND(SUM(J34:J35),2) -> 7094 | K39: =ROUND(SUM(K36:K38),2) -> 7094 | L39: =IF(J39=K39,"<- Debits and Credits equal each other.","<- Debits and Credits do not equal each other.") -> <- Debits and Credits equal each other.
B41: SBITA ASSET (Acct 0480) AMOUNT SHOULD BE INCLUDED AS "ADDITIONS" ON REPORT 18.
A43: Record Annual Activity (all SBITAs)
A44: 3 | B44: Record amortization of the SBITA asset for the year.
B45: Dr: Acct 0875 - DEPRECIATION/AMORTIZATION | J45: 7866
C46: Cr. Acct 0475 - ACCUMULATED AMORTIZATION - RIGHT-TO-USE SBITA | K46: =J45 -> 7866
J47: =ROUND(SUM(J45:J45),2) -> 7866 | K47: =ROUND(SUM(K46),2) -> 7866 | L47: =IF(J47=K47,"<- Debits and Credits equal each other.","<- Debits and Credits do not equal each other.") -> <- Debits and Credits equal each other.
A49: 4 | B49: Reclassify information technology subscription exp. to debt service principal and interest exp.
...

Sheet 0460 Journal
A1: GASB 96 - SBITA Contracts Fund-by-Fund Journal Entries Form (to be submitted to the SCO annually—one form per fund)
A2: Manually complete every yellow field in this worksheet—there are no automatically calculated data-entry cells in this worksheet.
A3: Fiscal year: | F3: 2022–2023
A4: Organization Name: | F4: Department of Justice
A5: Organization Code (Business Unit): | F5: 0820
A6: Fund Number: | F6: 460
A7: Fund Type: | F7: Governmental Fund
A8: Fund Classification: | F8: =IF(OR($F$7='Drop Down Menus'!B2,$F$7='Drop Down Menus'!$B$3),'Drop Down Menus'!$D$9,IFERROR(VLOOKUP($F$5,GAAP02Aindex!$A$2:$D$900,4,FALSE),"Unidentified")) -> GENERAL GOVERNMENT
A12: =IF($F$3="2022–2023","Establish Beginning Balances (SBITAs commenced on or before 07/01/2022)","Establish Beginning Balances (existing SBITAs only)") -> Establish Beginning Balances (SBITAs commenced on or before 07/01/2022)
A13: Entry #
A14: 0 | B14: =IF($F$3="2022–2023","To establish the beginning balance of SBITAs as of 07/01/2022.","Roll forward prior year right-to-use SBITAs to record opening balances.") -> To establish the beginning balance of SBITAs as of 07/01/2022.
B15: Dr: Acct 0480 - RIGHT-TO-USE SBITA - AMORTIZABLE | J15: 121760
B16: Dr: Acct 0950 - BEGINNING FUND BALANCE
B17: Dr: Acct 0952 - BEG FB ADJ/PRIOR PERIOD ADJUSTMENT
C18: Cr. Acct 0475 - ACCUMULATED AMORTIZATION - RIGHT-TO-USE SBITA
C19: Cr: Acct 0674 - RIGHT-TO-USE SBITA LIABILITY | K19: 121760
C20: Cr: Acct 0950 - BEGINNING FUND BALANCE
C21: Cr: Acct 0952 - BEG FB ADJ/PRIOR PERIOD ADJUSTMENT
J22: =ROUND(SUM(J15:J17),2) -> 121760 | K22: =ROUND(SUM(K18:K21),2) -> 121760 | L22: =IF(J22=K22,"<- Debits and Credits equal each other.","<- Debits and Credits do not equal each other.") -> <- Debits and Credits equal each other.
B24: SBITA ASSET (Acct 0480) AMOUNT SHOULD BE REPORTED AS BEGINNING BALANCE ON REPORT 18.
A26: =IF($F$3="2022–2023","Record SBITAs Commenced on or after 07/02/2022","Record New SBITAs (new SBITAs only)") -> Record SBITAs Commenced on or after 07/02/2022
A27: 1 | B27: Record at inception of SBITA in accordance with Fund-Based accounting (Governmental Funds Only).
B28: Dr: Acct 0842 - CAPITAL OUTLAY | J28: 62716
C29: Cr: Acct 0789 - LEASE AND OTHER FINANCING PROCEEDS | K29: 62716
C30: =VLOOKUP($F$8,'Drop Down Menus'!$D$2:$G$10,4,FALSE) -> Cr: Acct 0808 - GENERAL GOV. (GAAP ADJ)
J31: =ROUND(SUM(J28:J30),2) -> 62716 | K31: =ROUND(SUM(K28:K30),2) -> 62716 | L31: =IF(J31=K31,"<- Debits and Credits equal each other.","<- Debits and Credits do not equal each other.") -> <- Debits and Credits equal each other.
A33: 2 | B33: Reverse the fund-based entry in #1 above, if any, and record an inception of SBITA in accordance with GAAP Govt Wide.
B34: Dr: Acct 0480 - RIGHT-TO-USE SBITA - AMORTIZABLE | J34: 62716
B35: Dr: Acct 0789 - LEASE AND OTHER FINANCING PROCEEDS | J35: 62716
C36: Cr: Acct 0842 - CAPITAL OUTLAY | K36: 62716
C37: Cr: Acct 0674 - RIGHT-TO-USE SBITA LIABILITY | K37: 62716
C38: =VLOOKUP($F$8,'Drop Down Menus'!$D$2:$G$10,4,FALSE) -> Cr: Acct 0808 - GENERAL GOV. (GAAP ADJ)
J39: =ROUND(SUM(J34:J35),2) -> 125432 | K39: =ROUND(SUM(K36:K38),2) -> 125432 | L39: =IF(J39=K39,"<- Debits and Credits equal each other.","<- Debits and Credits do not equal each other.") -> <- Debits and Credits equal each other.
B41: SBITA ASSET (Acct 0480) AMOUNT SHOULD BE INCLUDED AS "ADDITIONS" ON REPORT 18.
A43: Record Annual Activity (all SBITAs)
A44: 3 | B44: Record amortization of the SBITA asset for the year.
B45: Dr: Acct 0875 - DEPRECIATION/AMORTIZATION | J45: 103526
C46: Cr. Acct 0475 - ACCUMULATED AMORTIZATION - RIGHT-TO-USE SBITA | K46: =J45 -> 103526
J47: =ROUND(SUM(J45:J45),2) -> 103526 | K47: =ROUND(SUM(K46),2) -> 103526 | L47: =IF(J47=K47,"<- Debits and Credits equal each other.","<- Debits and Credits do not equal each other.") -> <- Debits and Credits equal each other.
A49: 4 | B49: Reclassify information technology subscription exp. to debt service principal and interest exp.
...

Sheet 0567 Journal
A1: GASB 96 - SBITA Contracts Fund-by-Fund Journal Entries Form (to be submitted to the SCO annually—one form per fund)
A2: Manually complete every yellow field in this worksheet—there are no automatically calculated data-entry cells in this worksheet.
A3: Fiscal year: | F3: 2022–2023
A4: Organization Name: | F4: Department of Justice
A5: Organization Code (Business Unit): | F5: 0820
A6: Fund Number: | F6: 567
A7: Fund Type: | F7: Governmental Fund
A8: Fund Classification: | F8: =IF(OR($F$7='Drop Down Menus'!B2,$F$7='Drop Down Menus'!$B$3),'Drop Down Menus'!$D$9,IFERROR(VLOOKUP($F$5,GAAP02Aindex!$A$2:$D$900,4,FALSE),"Unidentified")) -> GENERAL GOVERNMENT
A12: =IF($F$3="2022–2023","Establish Beginning Balances (SBITAs commenced on or before 07/01/2022)","Establish Beginning Balances (existing SBITAs only)") -> Establish Beginning Balances (SBITAs commenced on or before 07/01/2022)
A13: Entry #
A14: 0 | B14: =IF($F$3="2022–2023","To establish the beginning balance of SBITAs as of 07/01/2022.","Roll forward prior year right-to-use SBITAs to record opening balances.") -> To establish the beginning balance of SBITAs as of 07/01/2022.
B15: Dr: Acct 0480 - RIGHT-TO-USE SBITA - AMORTIZABLE | J15: 145210
B16: Dr: Acct 0950 - BEGINNING FUND BALANCE
B17: Dr: Acct 0952 - BEG FB ADJ/PRIOR PERIOD ADJUSTMENT
C18: Cr. Acct 0475 - ACCUMULATED AMORTIZATION - RIGHT-TO-USE SBITA
C19: Cr: Acct 0674 - RIGHT-TO-USE SBITA LIABILITY | K19: 145210
C20: Cr: Acct 0950 - BEGINNING FUND BALANCE
C21: Cr: Acct 0952 - BEG FB ADJ/PRIOR PERIOD ADJUSTMENT
J22: =ROUND(SUM(J15:J17),2) -> 145210 | K22: =ROUND(SUM(K18:K21),2) -> 145210 | L22: =IF(J22=K22,"<- Debits and Credits equal each other.","<- Debits and Credits do not equal each other.") -> <- Debits and Credits equal each other.
B24: SBITA ASSET (Acct 0480) AMOUNT SHOULD BE REPORTED AS BEGINNING BALANCE ON REPORT 18.
A26: =IF($F$3="2022–2023","Record SBITAs Commenced on or after 07/02/2022","Record New SBITAs (new SBITAs only)") -> Record SBITAs Commenced on or after 07/02/2022
A27: 1 | B27: Record at inception of SBITA in accordance with Fund-Based accounting (Governmental Funds Only).
B28: Dr: Acct 0842 - CAPITAL OUTLAY
C29: Cr: Acct 0789 - LEASE AND OTHER FINANCING PROCEEDS
C30: =VLOOKUP($F$8,'Drop Down Menus'!$D$2:$G$10,4,FALSE) -> Cr: Acct 0808 - GENERAL GOV. (GAAP ADJ)
J31: =ROUND(SUM(J28:J30),2) -> 0 | K31: =ROUND(SUM(K28:K30),2) -> 0 | L31: =IF(J31=K31,"<- Debits and Credits equal each other.","<- Debits and Credits do not equal each other.") -> <- Debits and Credits equal each other.
A33: 2 | B33: Reverse the fund-based entry in #1 above, if any, and record an inception of SBITA in accordance with GAAP Govt Wide.
B34: Dr: Acct 0480 - RIGHT-TO-USE SBITA - AMORTIZABLE
B35: Dr: Acct 0789 - LEASE AND OTHER FINANCING PROCEEDS
C36: Cr: Acct 0842 - CAPITAL OUTLAY
C37: Cr: Acct 0674 - RIGHT-TO-USE SBITA LIABILITY
C38: =VLOOKUP($F$8,'Drop Down Menus'!$D$2:$G$10,4,FALSE) -> Cr: Acct 0808 - GENERAL GOV. (GAAP ADJ)
J39: =ROUND(SUM(J34:J35),2) -> 0 | K39: =ROUND(SUM(K36:K38),2) -> 0 | L39: =IF(J39=K39,"<- Debits and Credits equal each other.","<- Debits and Credits do not equal each other.") -> <- Debits and Credits equal each other.
B41: SBITA ASSET (Acct 0480) AMOUNT SHOULD BE INCLUDED AS "ADDITIONS" ON REPORT 18.
A43: Record Annual Activity (all SBITAs)
A44: 3 | B44: Record amortization of the SBITA asset for the year.
B45: Dr: Acct 0875 - DEPRECIATION/AMORTIZATION | J45: 50401
C46: Cr. Acct 0475 - ACCUMULATED AMORTIZATION - RIGHT-TO-USE SBITA | K46: =J45 -> 50401
J47: =ROUND(SUM(J45:J45),2) -> 50401 | K47: =ROUND(SUM(K46),2) -> 50401 | L47: =IF(J47=K47,"<- Debits and Credits equal each other.","<- Debits and Credits do not equal each other.") -> <- Debits and Credits equal each other.
A49: 4 | B49: Reclassify information technology subscription exp. to debt service principal and interest exp.
...

Sheet 0569 Journal
A1: GASB 96 - SBITA Contracts Fund-by-Fund Journal Entries Form (to be submitted to the SCO annually—one form per fund)
A2: Manually complete every yellow field in this worksheet—there are no automatically calculated data-entry cells in this worksheet.
A3: Fiscal year: | F3: 2022–2023
A4: Organization Name: | F4: Department of Justice
A5: Organization Code (Business Unit): | F5: 0820
A6: Fund Number: | F6: 569
A7: Fund Type: | F7: Governmental Fund
A8: Fund Classification: | F8: =IF(OR($F$7='Drop Down Menus'!B2,$F$7='Drop Down Menus'!$B$3),'Drop Down Menus'!$D$9,IFERROR(VLOOKUP($F$5,GAAP02Aindex!$A$2:$D$900,4,FALSE),"Unidentified")) -> GENERAL GOVERNMENT
A12: =IF($F$3="2022–2023","Establish Beginning Balances (SBITAs commenced on or before 07/01/2022)","Establish Beginning Balances (existing SBITAs only)") -> Establish Beginning Balances (SBITAs commenced on or before 07/01/2022)
A13: Entry #
A14: 0 | B14: =IF($F$3="2022–2023","To establish the beginning balance of SBITAs as of 07/01/2022.","Roll forward prior year right-to-use SBITAs to record opening balances.") -> To establish the beginning balance of SBITAs as of 07/01/2022.
B15: Dr: Acct 0480 - RIGHT-TO-USE SBITA - AMORTIZABLE | J15: 12931
B16: Dr: Acct 0950 - BEGINNING FUND BALANCE
B17: Dr: Acct 0952 - BEG FB ADJ/PRIOR PERIOD ADJUSTMENT
C18: Cr. Acct 0475 - ACCUMULATED AMORTIZATION - RIGHT-TO-USE SBITA
C19: Cr: Acct 0674 - RIGHT-TO-USE SBITA LIABILITY | K19: 12931
C20: Cr: Acct 0950 - BEGINNING FUND BALANCE
C21: Cr: Acct 0952 - BEG FB ADJ/PRIOR PERIOD ADJUSTMENT
J22: =ROUND(SUM(J15:J17),2) -> 12931 | K22: =ROUND(SUM(K18:K21),2) -> 12931 | L22: =IF(J22=K22,"<- Debits and Credits equal each other.","<- Debits and Credits do not equal each other.") -> <- Debits and Credits equal each other.
B24: SBITA ASSET (Acct 0480) AMOUNT SHOULD BE REPORTED AS BEGINNING BALANCE ON REPORT 18.
A26: =IF($F$3="2022–2023","Record SBITAs Commenced on or after 07/02/2022","Record New SBITAs (new SBITAs only)") -> Record SBITAs Commenced on or after 07/02/2022
A27: 1 | B27: Record at inception of SBITA in accordance with Fund-Based accounting (Governmental Funds Only).
B28: Dr: Acct 0842 - CAPITAL OUTLAY | J28: 5518
C29: Cr: Acct 0789 - LEASE AND OTHER FINANCING PROCEEDS | K29: 5518
C30: =VLOOKUP($F$8,'Drop Down Menus'!$D$2:$G$10,4,FALSE) -> Cr: Acct 0808 - GENERAL GOV. (GAAP ADJ)
J31: =ROUND(SUM(J28:J30),2) -> 5518 | K31: =ROUND(SUM(K28:K30),2) -> 5518 | L31: =IF(J31=K31,"<- Debits and Credits equal each other.","<- Debits and Credits do not equal each other.") -> <- Debits and Credits equal each other.
A33: 2 | B33: Reverse the fund-based entry in #1 above, if any, and record an inception of SBITA in accordance with GAAP Govt Wide.
B34: Dr: Acct 0480 - RIGHT-TO-USE SBITA - AMORTIZABLE | J34: 5518
B35: Dr: Acct 0789 - LEASE AND OTHER FINANCING PROCEEDS | J35: 5518
C36: Cr: Acct 0842 - CAPITAL OUTLAY | K36: 5518
C37: Cr: Acct 0674 - RIGHT-TO-USE SBITA LIABILITY | K37: 5518
C38: =VLOOKUP($F$8,'Drop Down Menus'!$D$2:$G$10,4,FALSE) -> Cr: Acct 0808 - GENERAL GOV. (GAAP ADJ)
J39: =ROUND(SUM(J34:J35),2) -> 11036 | K39: =ROUND(SUM(K36:K38),2) -> 11036 | L39: =IF(J39=K39,"<- Debits and Credits equal each other.","<- Debits and Credits do not equal each other.") -> <- Debits and Credits equal each other.
B41: SBITA ASSET (Acct 0480) AMOUNT SHOULD BE INCLUDED AS "ADDITIONS" ON REPORT 18.
A43: Record Annual Activity (all SBITAs)
A44: 3 | B44: Record amortization of the SBITA asset for the year.
B45: Dr: Acct 0875 - DEPRECIATION/AMORTIZATION | J45: 9871
C46: Cr. Acct 0475 - ACCUMULATED AMORTIZATION - RIGHT-TO-USE SBITA | K46: =J45 -> 9871
J47: =ROUND(SUM(J45:J45),2) -> 9871 | K47: =ROUND(SUM(K46),2) -> 9871 | L47: =IF(J47=K47,"<- Debits and Credits equal each other.","<- Debits and Credits do not equal each other.") -> <- Debits and Credits equal each other.
A49: 4 | B49: Reclassify information technology subscription exp. to debt service principal and interest exp.
...

Sheet 0890 Journal
A1: GASB 96 - SBITA Contracts Fund-by-Fund Journal Entries Form (to be submitted to the SCO annually—one form per fund)
A2: Manually complete every yellow field in this worksheet—there are no automatically calculated data-entry cells in this worksheet.
A3: Fiscal year: | F3: 2022–2023
A4: Organization Name: | F4: Department of Justice
A5: Organization Code (Business Unit): | F5: 0820
A6: Fund Number: | F6: 890
A7: Fund Type: | F7: Governmental Fund
A8: Fund Classification: | F8: =IF(OR($F$7='Drop Down Menus'!B2,$F$7='Drop Down Menus'!$B$3),'Drop Down Menus'!$D$9,IFERROR(VLOOKUP($F$5,GAAP02Aindex!$A$2:$D$900,4,FALSE),"Unidentified")) -> GENERAL GOVERNMENT
A12: =IF($F$3="2022–2023","Establish Beginning Balances (SBITAs commenced on or before 07/01/2022)","Establish Beginning Balances (existing SBITAs only)") -> Establish Beginning Balances (SBITAs commenced on or before 07/01/2022)
A13: Entry #
A14: 0 | B14: =IF($F$3="2022–2023","To establish the beginning balance of SBITAs as of 07/01/2022.","Roll forward prior year right-to-use SBITAs to record opening balances.") -> To establish the beginning balance of SBITAs as of 07/01/2022.
B15: Dr: Acct 0480 - RIGHT-TO-USE SBITA - AMORTIZABLE | J15: 17865
B16: Dr: Acct 0950 - BEGINNING FUND BALANCE
B17: Dr: Acct 0952 - BEG FB ADJ/PRIOR PERIOD ADJUSTMENT
C18: Cr. Acct 0475 - ACCUMULATED AMORTIZATION - RIGHT-TO-USE SBITA
C19: Cr: Acct 0674 - RIGHT-TO-USE SBITA LIABILITY | K19: 17865
C20: Cr: Acct 0950 - BEGINNING FUND BALANCE
C21: Cr: Acct 0952 - BEG FB ADJ/PRIOR PERIOD ADJUSTMENT
J22: =ROUND(SUM(J15:J17),2) -> 17865 | K22: =ROUND(SUM(K18:K21),2) -> 17865 | L22: =IF(J22=K22,"<- Debits and Credits equal each other.","<- Debits and Credits do not equal each other.") -> <- Debits and Credits equal each other.
B24: SBITA ASSET (Acct 0480) AMOUNT SHOULD BE REPORTED AS BEGINNING BALANCE ON REPORT 18.
A26: =IF($F$3="2022–2023","Record SBITAs Commenced on or after 07/02/2022","Record New SBITAs (new SBITAs only)") -> Record SBITAs Commenced on or after 07/02/2022
A27: 1 | B27: Record at inception of SBITA in accordance with Fund-Based accounting (Governmental Funds Only).
B28: Dr: Acct 0842 - CAPITAL OUTLAY
C29: Cr: Acct 0789 - LEASE AND OTHER FINANCING PROCEEDS
C30: =VLOOKUP($F$8,'Drop Down Menus'!$D$2:$G$10,4,FALSE) -> Cr: Acct 0808 - GENERAL GOV. (GAAP ADJ)
J31: =ROUND(SUM(J28:J30),2) -> 0 | K31: =ROUND(SUM(K28:K30),2) -> 0 | L31: =IF(J31=K31,"<- Debits and Credits equal each other.","<- Debits and Credits do not equal each other.") -> <- Debits and Credits equal each other.
A33: 2 | B33: Reverse the fund-based entry in #1 above, if any, and record an inception of SBITA in accordance with GAAP Govt Wide.
B34: Dr: Acct 0480 - RIGHT-TO-USE SBITA - AMORTIZABLE
B35: Dr: Acct 0789 - LEASE AND OTHER FINANCING PROCEEDS
C36: Cr: Acct 0842 - CAPITAL OUTLAY
C37: Cr: Acct 0674 - RIGHT-TO-USE SBITA LIABILITY
C38: =VLOOKUP($F$8,'Drop Down Menus'!$D$2:$G$10,4,FALSE) -> Cr: Acct 0808 - GENERAL GOV. (GAAP ADJ)
J39: =ROUND(SUM(J34:J35),2) -> 0 | K39: =ROUND(SUM(K36:K38),2) -> 0 | L39: =IF(J39=K39,"<- Debits and Credits equal each other.","<- Debits and Credits do not equal each other.") -> <- Debits and Credits equal each other.
B41: SBITA ASSET (Acct 0480) AMOUNT SHOULD BE INCLUDED AS "ADDITIONS" ON REPORT 18.
A43: Record Annual Activity (all SBITAs)
A44: 3 | B44: Record amortization of the SBITA asset for the year.
B45: Dr: Acct 0875 - DEPRECIATION/AMORTIZATION | J45: 8932
C46: Cr. Acct 0475 - ACCUMULATED AMORTIZATION - RIGHT-TO-USE SBITA | K46: =J45 -> 8932
J47: =ROUND(SUM(J45:J45),2) -> 8932 | K47: =ROUND(SUM(K46),2) -> 8932 | L47: =IF(J47=K47,"<- Debits and Credits equal each other.","<- Debits and Credits do not equal each other.") -> <- Debits and Credits equal each other.
A49: 4 | B49: Reclassify information technology subscription exp. to debt service principal and interest exp.
...

Sheet 1008 Journal
A1: GASB 96 - SBITA Contracts Fund-by-Fund Journal Entries Form (to be submitted to the SCO annually—one form per fund)
A2: Manually complete every yellow field in this worksheet—there are no automatically calculated data-entry cells in this worksheet.
A3: Fiscal year: | F3: 2022–2023
A4: Organization Name: | F4: Department of Justice
A5: Organization Code (Business Unit): | F5: 0820
A6: Fund Number: | F6: 1008
A7: Fund Type: | F7: Governmental Fund
A8: Fund Classification: | F8: =IF(OR($F$7='Drop Down Menus'!B2,$F$7='Drop Down Menus'!$B$3),'Drop Down Menus'!$D$9,IFERROR(VLOOKUP($F$5,GAAP02Aindex!$A$2:$D$900,4,FALSE),"Unidentified")) -> GENERAL GOVERNMENT
A12: =IF($F$3="2022–2023","Establish Beginning Balances (SBITAs commenced on or before 07/01/2022)","Establish Beginning Balances (existing SBITAs only)") -> Establish Beginning Balances (SBITAs commenced on or before 07/01/2022)
A13: Entry #
A14: 0 | B14: =IF($F$3="2022–2023","To establish the beginning balance of SBITAs as of 07/01/2022.","Roll forward prior year right-to-use SBITAs to record opening balances.") -> To establish the beginning balance of SBITAs as of 07/01/2022.
B15: Dr: Acct 0480 - RIGHT-TO-USE SBITA - AMORTIZABLE | J15: 30776
B16: Dr: Acct 0950 - BEGINNING FUND BALANCE
B17: Dr: Acct 0952 - BEG FB ADJ/PRIOR PERIOD ADJUSTMENT
C18: Cr. Acct 0475 - ACCUMULATED AMORTIZATION - RIGHT-TO-USE SBITA
C19: Cr: Acct 0674 - RIGHT-TO-USE SBITA LIABILITY | K19: 30776
C20: Cr: Acct 0950 - BEGINNING FUND BALANCE
C21: Cr: Acct 0952 - BEG FB ADJ/PRIOR PERIOD ADJUSTMENT
J22: =ROUND(SUM(J15:J17),2) -> 30776 | K22: =ROUND(SUM(K18:K21),2) -> 30776 | L22: =IF(J22=K22,"<- Debits and Credits equal each other.","<- Debits and Credits do not equal each other.") -> <- Debits and Credits equal each other.
B24: SBITA ASSET (Acct 0480) AMOUNT SHOULD BE REPORTED AS BEGINNING BALANCE ON REPORT 18.
A26: =IF($F$3="2022–2023","Record SBITAs Commenced on or after 07/02/2022","Record New SBITAs (new SBITAs only)") -> Record SBITAs Commenced on or after 07/02/2022
A27: 1 | B27: Record at inception of SBITA in accordance with Fund-Based accounting (Governmental Funds Only).
B28: Dr: Acct 0842 - CAPITAL OUTLAY
C29: Cr: Acct 0789 - LEASE AND OTHER FINANCING PROCEEDS
C30: =VLOOKUP($F$8,'Drop Down Menus'!$D$2:$G$10,4,FALSE) -> Cr: Acct 0808 - GENERAL GOV. (GAAP ADJ)
J31: =ROUND(SUM(J28:J30),2) -> 0 | K31: =ROUND(SUM(K28:K30),2) -> 0 | L31: =IF(J31=K31,"<- Debits and Credits equal each other.","<- Debits and Credits do not equal each other.") -> <- Debits and Credits equal each other.
A33: 2 | B33: Reverse the fund-based entry in #1 above, if any, and record an inception of SBITA in accordance with GAAP Govt Wide.
B34: Dr: Acct 0480 - RIGHT-TO-USE SBITA - AMORTIZABLE
B35: Dr: Acct 0789 - LEASE AND OTHER FINANCING PROCEEDS
C36: Cr: Acct 0842 - CAPITAL OUTLAY
C37: Cr: Acct 0674 - RIGHT-TO-USE SBITA LIABILITY
C38: =VLOOKUP($F$8,'Drop Down Menus'!$D$2:$G$10,4,FALSE) -> Cr: Acct 0808 - GENERAL GOV. (GAAP ADJ)
J39: =ROUND(SUM(J34:J35),2) -> 0 | K39: =ROUND(SUM(K36:K38),2) -> 0 | L39: =IF(J39=K39,"<- Debits and Credits equal each other.","<- Debits and Credits do not equal each other.") -> <- Debits and Credits equal each other.
B41: SBITA ASSET (Acct 0480) AMOUNT SHOULD BE INCLUDED AS "ADDITIONS" ON REPORT 18.
A43: Record Annual Activity (all SBITAs)
A44: 3 | B44: Record amortization of the SBITA asset for the year.
B45: Dr: Acct 0875 - DEPRECIATION/AMORTIZATION | J45: 15388
C46: Cr. Acct 0475 - ACCUMULATED AMORTIZATION - RIGHT-TO-USE SBITA | K46: =J45 -> 15388
J47: =ROUND(SUM(J45:J45),2) -> 15388 | K47: =ROUND(SUM(K46),2) -> 15388 | L47: =IF(J47=K47,"<- Debits and Credits equal each other.","<- Debits and Credits do not equal each other.") -> <- Debits and Credits equal each other.
A49: 4 | B49: Reclassify information technology subscription exp. to debt service principal and interest exp.
...

Sheet 3053 Journal
A1: GASB 96 - SBITA Contracts Fund-by-Fund Journal Entries Form (to be submitted to the SCO annually—one form per fund)
A2: Manually complete every yellow field in this worksheet—there are no automatically calculated data-entry cells in this worksheet.
A3: Fiscal year: | F3: 2022–2023
A4: Organization Name: | F4: Department of Justice
A5: Organization Code (Business Unit): | F5: 0820
A6: Fund Number: | F6: 3053
A7: Fund Type: | F7: Governmental Fund
A8: Fund Classification: | F8: =IF(OR($F$7='Drop Down Menus'!B2,$F$7='Drop Down Menus'!$B$3),'Drop Down Menus'!$D$9,IFERROR(VLOOKUP($F$5,GAAP02Aindex!$A$2:$D$900,4,FALSE),"Unidentified")) -> GENERAL GOVERNMENT
A12: =IF($F$3="2022–2023","Establish Beginning Balances (SBITAs commenced on or before 07/01/2022)","Establish Beginning Balances (existing SBITAs only)") -> Establish Beginning Balances (SBITAs commenced on or before 07/01/2022)
A13: Entry #
A14: 0 | B14: =IF($F$3="2022–2023","To establish the beginning balance of SBITAs as of 07/01/2022.","Roll forward prior year right-to-use SBITAs to record opening balances.") -> To establish the beginning balance of SBITAs as of 07/01/2022.
B15: Dr: Acct 0480 - RIGHT-TO-USE SBITA - AMORTIZABLE | J15: 1671
B16: Dr: Acct 0950 - BEGINNING FUND BALANCE
B17: Dr: Acct 0952 - BEG FB ADJ/PRIOR PERIOD ADJUSTMENT
C18: Cr. Acct 0475 - ACCUMULATED AMORTIZATION - RIGHT-TO-USE SBITA
C19: Cr: Acct 0674 - RIGHT-TO-USE SBITA LIABILITY | K19: 1671
C20: Cr: Acct 0950 - BEGINNING FUND BALANCE
C21: Cr: Acct 0952 - BEG FB ADJ/PRIOR PERIOD ADJUSTMENT
J22: =ROUND(SUM(J15:J17),2) -> 1671 | K22: =ROUND(SUM(K18:K21),2) -> 1671 | L22: =IF(J22=K22,"<- Debits and Credits equal each other.","<- Debits and Credits do not equal each other.") -> <- Debits and Credits equal each other.
B24: SBITA ASSET (Acct 0480) AMOUNT SHOULD BE REPORTED AS BEGINNING BALANCE ON REPORT 18.
A26: =IF($F$3="2022–2023","Record SBITAs Commenced on or after 07/02/2022","Record New SBITAs (new SBITAs only)") -> Record SBITAs Commenced on or after 07/02/2022
A27: 1 | B27: Record at inception of SBITA in accordance with Fund-Based accounting (Governmental Funds Only).
B28: Dr: Acct 0842 - CAPITAL OUTLAY
C29: Cr: Acct 0789 - LEASE AND OTHER FINANCING PROCEEDS
C30: =VLOOKUP($F$8,'Drop Down Menus'!$D$2:$G$10,4,FALSE) -> Cr: Acct 0808 - GENERAL GOV. (GAAP ADJ)
J31: =ROUND(SUM(J28:J30),2) -> 0 | K31: =ROUND(SUM(K28:K30),2) -> 0 | L31: =IF(J31=K31,"<- Debits and Credits equal each other.","<- Debits and Credits do not equal each other.") -> <- Debits and Credits equal each other.
A33: 2 | B33: Reverse the fund-based entry in #1 above, if any, and record an inception of SBITA in accordance with GAAP Govt Wide.
B34: Dr: Acct 0480 - RIGHT-TO-USE SBITA - AMORTIZABLE
B35: Dr: Acct 0789 - LEASE AND OTHER FINANCING PROCEEDS
C36: Cr: Acct 0842 - CAPITAL OUTLAY
C37: Cr: Acct 0674 - RIGHT-TO-USE SBITA LIABILITY
C38: =VLOOKUP($F$8,'Drop Down Menus'!$D$2:$G$10,4,FALSE) -> Cr: Acct 0808 - GENERAL GOV. (GAAP ADJ)
J39: =ROUND(SUM(J34:J35),2) -> 0 | K39: =ROUND(SUM(K36:K38),2) -> 0 | L39: =IF(J39=K39,"<- Debits and Credits equal each other.","<- Debits and Credits do not equal each other.") -> <- Debits and Credits equal each other.
B41: SBITA ASSET (Acct 0480) AMOUNT SHOULD BE INCLUDED AS "ADDITIONS" ON REPORT 18.
A43: Record Annual Activity (all SBITAs)
A44: 3 | B44: Record amortization of the SBITA asset for the year.
B45: Dr: Acct 0875 - DEPRECIATION/AMORTIZATION | J45: 835
C46: Cr. Acct 0475 - ACCUMULATED AMORTIZATION - RIGHT-TO-USE SBITA | K46: =J45 -> 835
J47: =ROUND(SUM(J45:J45),2) -> 835 | K47: =ROUND(SUM(K46),2) -> 835 | L47: =IF(J47=K47,"<- Debits and Credits equal each other.","<- Debits and Credits do not equal each other.") -> <- Debits and Credits equal each other.
A49: 4 | B49: Reclassify information technology subscription exp. to debt service principal and interest exp.
...

Sheet 3086 Journal
A1: GASB 96 - SBITA Contracts Fund-by-Fund Journal Entries Form (to be submitted to the SCO annually—one form per fund)
A2: Manually complete every yellow field in this worksheet—there are no automatically calculated data-entry cells in this worksheet.
A3: Fiscal year: | F3: 2022–2023
A4: Organization Name: | F4: Department of Justice
A5: Organization Code (Business Unit): | F5: 0820
A6: Fund Number: | F6: 3086
A7: Fund Type: | F7: Governmental Fund
A8: Fund Classification: | F8: =IF(OR($F$7='Drop Down Menus'!B2,$F$7='Drop Down Menus'!$B$3),'Drop Down Menus'!$D$9,IFERROR(VLOOKUP($F$5,GAAP02Aindex!$A$2:$D$900,4,FALSE),"Unidentified")) -> GENERAL GOVERNMENT
A12: =IF($F$3="2022–2023","Establish Beginning Balances (SBITAs commenced on or before 07/01/2022)","Establish Beginning Balances (existing SBITAs only)") -> Establish Beginning Balances (SBITAs commenced on or before 07/01/2022)
A13: Entry #
A14: 0 | B14: =IF($F$3="2022–2023","To establish the beginning balance of SBITAs as of 07/01/2022.","Roll forward prior year right-to-use SBITAs to record opening balances.") -> To establish the beginning balance of SBITAs as of 07/01/2022.
B15: Dr: Acct 0480 - RIGHT-TO-USE SBITA - AMORTIZABLE | J15: 54222
B16: Dr: Acct 0950 - BEGINNING FUND BALANCE
B17: Dr: Acct 0952 - BEG FB ADJ/PRIOR PERIOD ADJUSTMENT
C18: Cr. Acct 0475 - ACCUMULATED AMORTIZATION - RIGHT-TO-USE SBITA
C19: Cr: Acct 0674 - RIGHT-TO-USE SBITA LIABILITY | K19: 54222
C20: Cr: Acct 0950 - BEGINNING FUND BALANCE
C21: Cr: Acct 0952 - BEG FB ADJ/PRIOR PERIOD ADJUSTMENT
J22: =ROUND(SUM(J15:J17),2) -> 54222 | K22: =ROUND(SUM(K18:K21),2) -> 54222 | L22: =IF(J22=K22,"<- Debits and Credits equal each other.","<- Debits and Credits do not equal each other.") -> <- Debits and Credits equal each other.
B24: SBITA ASSET (Acct 0480) AMOUNT SHOULD BE REPORTED AS BEGINNING BALANCE ON REPORT 18.
A26: =IF($F$3="2022–2023","Record SBITAs Commenced on or after 07/02/2022","Record New SBITAs (new SBITAs only)") -> Record SBITAs Commenced on or after 07/02/2022
A27: 1 | B27: Record at inception of SBITA in accordance with Fund-Based accounting (Governmental Funds Only).
B28: Dr: Acct 0842 - CAPITAL OUTLAY
C29: Cr: Acct 0789 - LEASE AND OTHER FINANCING PROCEEDS
C30: =VLOOKUP($F$8,'Drop Down Menus'!$D$2:$G$10,4,FALSE) -> Cr: Acct 0808 - GENERAL GOV. (GAAP ADJ)
J31: =ROUND(SUM(J28:J30),2) -> 0 | K31: =ROUND(SUM(K28:K30),2) -> 0 | L31: =IF(J31=K31,"<- Debits and Credits equal each other.","<- Debits and Credits do not equal each other.") -> <- Debits and Credits equal each other.
A33: 2 | B33: Reverse the fund-based entry in #1 above, if any, and record an inception of SBITA in accordance with GAAP Govt Wide.
B34: Dr: Acct 0480 - RIGHT-TO-USE SBITA - AMORTIZABLE
B35: Dr: Acct 0789 - LEASE AND OTHER FINANCING PROCEEDS
C36: Cr: Acct 0842 - CAPITAL OUTLAY
C37: Cr: Acct 0674 - RIGHT-TO-USE SBITA LIABILITY
C38: =VLOOKUP($F$8,'Drop Down Menus'!$D$2:$G$10,4,FALSE) -> Cr: Acct 0808 - GENERAL GOV. (GAAP ADJ)
J39: =ROUND(SUM(J34:J35),2) -> 0 | K39: =ROUND(SUM(K36:K38),2) -> 0 | L39: =IF(J39=K39,"<- Debits and Credits equal each other.","<- Debits and Credits do not equal each other.") -> <- Debits and Credits equal each other.
B41: SBITA ASSET (Acct 0480) AMOUNT SHOULD BE INCLUDED AS "ADDITIONS" ON REPORT 18.
A43: Record Annual Activity (all SBITAs)
A44: 3 | B44: Record amortization of the SBITA asset for the year.
B45: Dr: Acct 0875 - DEPRECIATION/AMORTIZATION | J45: 32913
C46: Cr. Acct 0475 - ACCUMULATED AMORTIZATION - RIGHT-TO-USE SBITA | K46: =J45 -> 32913
J47: =ROUND(SUM(J45:J45),2) -> 32913 | K47: =ROUND(SUM(K46),2) -> 32913 | L47: =IF(J47=K47,"<- Debits and Credits equal each other.","<- Debits and Credits do not equal each other.") -> <- Debits and Credits equal each other.
A49: 4 | B49: Reclassify information technology subscription exp. to debt service principal and interest exp.
...

Sheet 3088 Journal
A1: GASB 96 - SBITA Contracts Fund-by-Fund Journal Entries Form (to be submitted to the SCO annually—one form per fund)
A2: Manually complete every yellow field in this worksheet—there are no automatically calculated data-entry cells in this worksheet.
A3: Fiscal year: | F3: 2022–2023
A4: Organization Name: | F4: Department of Justice
A5: Organization Code (Business Unit): | F5: 0820
A6: Fund Number: | F6: 3088
A7: Fund Type: | F7: Governmental Fund
A8: Fund Classification: | F8: =IF(OR($F$7='Drop Down Menus'!B2,$F$7='Drop Down Menus'!$B$3),'Drop Down Menus'!$D$9,IFERROR(VLOOKUP($F$5,GAAP02Aindex!$A$2:$D$900,4,FALSE),"Unidentified")) -> GENERAL GOVERNMENT
A12: =IF($F$3="2022–2023","Establish Beginning Balances (SBITAs commenced on or before 07/01/2022)","Establish Beginning Balances (existing SBITAs only)") -> Establish Beginning Balances (SBITAs commenced on or before 07/01/2022)
A13: Entry #
A14: 0 | B14: =IF($F$3="2022–2023","To establish the beginning balance of SBITAs as of 07/01/2022.","Roll forward prior year right-to-use SBITAs to record opening balances.") -> To establish the beginning balance of SBITAs as of 07/01/2022.
B15: Dr: Acct 0480 - RIGHT-TO-USE SBITA - AMORTIZABLE | J15: 4057
B16: Dr: Acct 0950 - BEGINNING FUND BALANCE
B17: Dr: Acct 0952 - BEG FB ADJ/PRIOR PERIOD ADJUSTMENT
C18: Cr. Acct 0475 - ACCUMULATED AMORTIZATION - RIGHT-TO-USE SBITA
C19: Cr: Acct 0674 - RIGHT-TO-USE SBITA LIABILITY | K19: 4057
C20: Cr: Acct 0950 - BEGINNING FUND BALANCE
C21: Cr: Acct 0952 - BEG FB ADJ/PRIOR PERIOD ADJUSTMENT
J22: =ROUND(SUM(J15:J17),2) -> 4057 | K22: =ROUND(SUM(K18:K21),2) -> 4057 | L22: =IF(J22=K22,"<- Debits and Credits equal each other.","<- Debits and Credits do not equal each other.") -> <- Debits and Credits equal each other.
B24: SBITA ASSET (Acct 0480) AMOUNT SHOULD BE REPORTED AS BEGINNING BALANCE ON REPORT 18.
A26: =IF($F$3="2022–2023","Record SBITAs Commenced on or after 07/02/2022","Record New SBITAs (new SBITAs only)") -> Record SBITAs Commenced on or after 07/02/2022
A27: 1 | B27: Record at inception of SBITA in accordance with Fund-Based accounting (Governmental Funds Only).
B28: Dr: Acct 0842 - CAPITAL OUTLAY | J28: 2099
C29: Cr: Acct 0789 - LEASE AND OTHER FINANCING PROCEEDS | K29: 2099
C30: =VLOOKUP($F$8,'Drop Down Menus'!$D$2:$G$10,4,FALSE) -> Cr: Acct 0808 - GENERAL GOV. (GAAP ADJ)
J31: =ROUND(SUM(J28:J30),2) -> 2099 | K31: =ROUND(SUM(K28:K30),2) -> 2099 | L31: =IF(J31=K31,"<- Debits and Credits equal each other.","<- Debits and Credits do not equal each other.") -> <- Debits and Credits equal each other.
A33: 2 | B33: Reverse the fund-based entry in #1 above, if any, and record an inception of SBITA in accordance with GAAP Govt Wide.
B34: Dr: Acct 0480 - RIGHT-TO-USE SBITA - AMORTIZABLE | J34: 2099
B35: Dr: Acct 0789 - LEASE AND OTHER FINANCING PROCEEDS | J35: 2099
C36: Cr: Acct 0842 - CAPITAL OUTLAY | K36: 2099
