Workbook
Name ActuaryCredentialsGASB: #REF!
Name ActuaryNameGASB: #REF!
Name ActuaryTitleGASB: #REF!
Name AdjCNSDate: #REF!
Name AdjCNSDate1: #REF!
Name AdjCNSDateTempEnable: #REF!
Name AgencyCode: #REF!
Name AgencyCode1: #REF!
Name AnalystGASB: #REF!
Name Annuity: #REF!
Name Annuity1: #REF!
Name AnnuityLY: #REF!
Name ASTABPF: #REF!
Name ASTABPF1: #REF!
Name ASTEBPF: #REF!
Name ClientShortGASB: #REF!
Name CLPOWERDisc: #REF!
Name CLPOWERDiscMinus1: #REF!
Name CLPOWERDiscPlus1: #REF!
Name CLPOWERExp: #REF!
Name CNSDateDisc: #REF!
Name CNSDateDisc1: #REF!
Name ColaRate: #REF!
Name ConsultantNameGASB: #REF!
Name ConsultantTitleGASB: #REF!
Name Disc1DELTACENSUS: #REF!
Name Disc1INTNDIV12: #REF!
Name Disc1SINTADJBOM: #REF!
Name Disc1SINTNDIV12: #REF!
Name DiscDELTACENSUS: #REF!
Name DiscINTADJBOM: #REF!
Name DiscINTNDIV12: #REF!
Name DiscMinusOneINTADJBOM: #REF!
Name DiscMinusOneINTNDIV12: #REF!
Name DiscPlusOneINTADJBOM: #REF!
Name DiscPlusOneINTNDIV12: #REF!
Name EmployerRates: #REF!
Name EmployerRates1: #REF!
Name EmployerRatesLEO: #REF!
Name EmployerRatesLEO1: #REF!
Name ERData: #REF!
Name ERID: #REF!
Name ERInfo: #REF!
Name Exp1INTADJBOM: #REF!
Name Exp1INTNDIV12: #REF!
Name FracYearProj: #REF!
Name FundOfficeContactGASB: #REF!
Name FYrsGASB: #REF!
Name GainLoss: #REF!
Name GASBDiscMinusOneINTADJBOM: #REF!
Name GASBDiscMinusOneINTNDIV12: #REF!
Name InflRate: #REF!
Name InflRate1: #REF!
Name IntDisc: #REF!
Name IntDisc1: #REF!
Name IntDisc1S: #REF!
Name INTDiscMinusOne: #REF!
Name INTDiscPlusOne: #REF!
Name IntExp1: #REF!
Name MeasureDate: #REF!

Sheet Fund 0108 Journal Entries
A1: GASB 96 - SBITA Contracts Fund-by-Fund Journal Entries Form (to be submitted to the SCO annually—one form per fund)
A2: Manually complete every yellow field in this worksheet—there are no automatically calculated data-entry cells in this worksheet.
A3: Fiscal year: | F3: 2022–2023
A4: Organization Name: | F4: Department of Consumer Affairs
A5: Organization Code (Business Unit): | F5: 1111
A6: Fund Number: | F6: 108
A7: Fund Type: | F7: Governmental Fund
A8: Fund Classification: | F8: =IF(OR($F$7='Drop Down Menus'!B2,$F$7='Drop Down Menus'!$B$3),'Drop Down Menus'!$D$9,IFERROR(VLOOKUP($F$5,GAAP02Aindex!$A$2:$D$900,4,FALSE),"Unidentified")) -> BUS, CONSUMER SERV, HOUSING
A12: =IF($F$3="2022–2023","Establish Beginning Balances (SBITAs commenced on or before 07/01/2022)","Establish Beginning Balances (existing SBITAs only)") -> Establish Beginning Balances (SBITAs commenced on or before 07/01/2022)
A13: Entry #
A14: 0 | B14: =IF($F$3="2022–2023","To establish the beginning balance of SBITAs as of 07/01/2022.","Roll forward prior year right-to-use SBITAs to record opening balances.") -> To establish the beginning balance of SBITAs as of 07/01/2022.
B15: Dr: Acct 0480 - RIGHT-TO-USE SBITA - AMORTIZABLE | J15: 9321
B16: Dr: Acct 0950 - BEGINNING FUND BALANCE
B17: Dr: Acct 0952 - BEG FB ADJ/PRIOR PERIOD ADJUSTMENT
C18: Cr. Acct 0475 - ACCUMULATED AMORTIZATION - RIGHT-TO-USE SBITA
C19: Cr: Acct 0674 - RIGHT-TO-USE SBITA LIABILITY | K19: 8349
C20: Cr: Acct 0950 - BEGINNING FUND BALANCE
C21: Cr: Acct 0952 - BEG FB ADJ/PRIOR PERIOD ADJUSTMENT | K21: 972
J22: =ROUND(SUM(J15:J17),2) -> 9321 | K22: =ROUND(SUM(K18:K21),2) -> 9321 | L22: =IF(J22=K22,"<- Debits and Credits equal each other.","<- Debits and Credits do not equal each other.") -> <- Debits and Credits equal each other.
B24: SBITA ASSET (Acct 0480) AMOUNT SHOULD BE REPORTED AS BEGINNING BALANCE ON REPORT 18.
A26: =IF($F$3="2022–2023","Record SBITAs Commenced on or after 07/02/2022","Record New SBITAs (new SBITAs only)") -> Record SBITAs Commenced on or after 07/02/2022
A27: 1 | B27: Record at inception of SBITA in accordance with Fund-Based accounting (Governmental Funds Only).
B28: Dr: Acct 0842 - CAPITAL OUTLAY
C29: Cr: Acct 0789 - LEASE AND OTHER FINANCING PROCEEDS
C30: =VLOOKUP($F$8,'Drop Down Menus'!$D$2:$G$10,4,FALSE) -> Cr: Acct 0825 - BUS, CONSUMER SERV, HOUSING
J31: =ROUND(SUM(J28:J30),2) -> 0 | K31: =ROUND(SUM(K28:K30),2) -> 0 | L31: =IF(J31=K31,"<- Debits and Credits equal each other.","<- Debits and Credits do not equal each other.") -> <- Debits and Credits equal each other.
A33: 2 | B33: Reverse the fund-based entry in #1 above, if any, and record an inception of SBITA in accordance with GAAP Govt Wide.
B34: Dr: Acct 0480 - RIGHT-TO-USE SBITA - AMORTIZABLE
B35: Dr: Acct 0789 - LEASE AND OTHER FINANCING PROCEEDS
C36: Cr: Acct 0842 - CAPITAL OUTLAY
C37: Cr: Acct 0674 - RIGHT-TO-USE SBITA LIABILITY
C38: =VLOOKUP($F$8,'Drop Down Menus'!$D$2:$G$10,4,FALSE) -> Cr: Acct 0825 - BUS, CONSUMER SERV, HOUSING
J39: =ROUND(SUM(J34:J35),2) -> 0 | K39: =ROUND(SUM(K36:K38),2) -> 0 | L39: =IF(J39=K39,"<- Debits and Credits equal each other.","<- Debits and Credits do not equal each other.") -> <- Debits and Credits equal each other.
B41: SBITA ASSET (Acct 0480) AMOUNT SHOULD BE INCLUDED AS "ADDITIONS" ON REPORT 18.
A43: Record Annual Activity (all SBITAs)
A44: 3 | B44: Record amortization of the SBITA asset for the year.
B45: Dr: Acct 0875 - DEPRECIATION/AMORTIZATION | J45: 2796
C46: Cr. Acct 0475 - ACCUMULATED AMORTIZATION - RIGHT-TO-USE SBITA | K46: =J45 -> 2796
J47: =ROUND(SUM(J45:J45),2) -> 2796 | K47: =ROUND(SUM(K46),2) -> 2796 | L47: =IF(J47=K47,"<- Debits and Credits equal each other.","<- Debits and Credits do not equal each other.") -> <- Debits and Credits equal each other.
A49: 4 | B49: Reclassify information technology subscription exp. to debt service principal and interest exp.
...

Sheet Fund 0152 Journal Entries
A1: GASB 96 - SBITA Contracts Fund-by-Fund Journal Entries Form (to be submitted to the SCO annually—one form per fund)
A2: Manually complete every yellow field in this worksheet—there are no automatically calculated data-entry cells in this worksheet.
A3: Fiscal year: | F3: 2022–2023
A4: Organization Name: | F4: Department of Consumer Affairs
A5: Organization Code (Business Unit): | F5: 1111
A6: Fund Number: | F6: 152
A7: Fund Type: | F7: Governmental Fund
A8: Fund Classification: | F8: =IF(OR($F$7='Drop Down Menus'!B2,$F$7='Drop Down Menus'!$B$3),'Drop Down Menus'!$D$9,IFERROR(VLOOKUP($F$5,GAAP02Aindex!$A$2:$D$900,4,FALSE),"Unidentified")) -> BUS, CONSUMER SERV, HOUSING
A12: =IF($F$3="2022–2023","Establish Beginning Balances (SBITAs commenced on or before 07/01/2022)","Establish Beginning Balances (existing SBITAs only)") -> Establish Beginning Balances (SBITAs commenced on or before 07/01/2022)
A13: Entry #
A14: 0 | B14: =IF($F$3="2022–2023","To establish the beginning balance of SBITAs as of 07/01/2022.","Roll forward prior year right-to-use SBITAs to record opening balances.") -> To establish the beginning balance of SBITAs as of 07/01/2022.
B15: Dr: Acct 0480 - RIGHT-TO-USE SBITA - AMORTIZABLE | J15: 18642
B16: Dr: Acct 0950 - BEGINNING FUND BALANCE
B17: Dr: Acct 0952 - BEG FB ADJ/PRIOR PERIOD ADJUSTMENT
C18: Cr. Acct 0475 - ACCUMULATED AMORTIZATION - RIGHT-TO-USE SBITA
C19: Cr: Acct 0674 - RIGHT-TO-USE SBITA LIABILITY | K19: 16697
C20: Cr: Acct 0950 - BEGINNING FUND BALANCE
C21: Cr: Acct 0952 - BEG FB ADJ/PRIOR PERIOD ADJUSTMENT | K21: 1945
J22: =ROUND(SUM(J15:J17),2) -> 18642 | K22: =ROUND(SUM(K18:K21),2) -> 18642 | L22: =IF(J22=K22,"<- Debits and Credits equal each other.","<- Debits and Credits do not equal each other.") -> <- Debits and Credits equal each other.
B24: SBITA ASSET (Acct 0480) AMOUNT SHOULD BE REPORTED AS BEGINNING BALANCE ON REPORT 18.
A26: =IF($F$3="2022–2023","Record SBITAs Commenced on or after 07/02/2022","Record New SBITAs (new SBITAs only)") -> Record SBITAs Commenced on or after 07/02/2022
A27: 1 | B27: Record at inception of SBITA in accordance with Fund-Based accounting (Governmental Funds Only).
B28: Dr: Acct 0842 - CAPITAL OUTLAY
C29: Cr: Acct 0789 - LEASE AND OTHER FINANCING PROCEEDS
C30: =VLOOKUP($F$8,'Drop Down Menus'!$D$2:$G$10,4,FALSE) -> Cr: Acct 0825 - BUS, CONSUMER SERV, HOUSING
J31: =ROUND(SUM(J28:J30),2) -> 0 | K31: =ROUND(SUM(K28:K30),2) -> 0 | L31: =IF(J31=K31,"<- Debits and Credits equal each other.","<- Debits and Credits do not equal each other.") -> <- Debits and Credits equal each other.
A33: 2 | B33: Reverse the fund-based entry in #1 above, if any, and record an inception of SBITA in accordance with GAAP Govt Wide.
B34: Dr: Acct 0480 - RIGHT-TO-USE SBITA - AMORTIZABLE
B35: Dr: Acct 0789 - LEASE AND OTHER FINANCING PROCEEDS
C36: Cr: Acct 0842 - CAPITAL OUTLAY
C37: Cr: Acct 0674 - RIGHT-TO-USE SBITA LIABILITY
C38: =VLOOKUP($F$8,'Drop Down Menus'!$D$2:$G$10,4,FALSE) -> Cr: Acct 0825 - BUS, CONSUMER SERV, HOUSING
J39: =ROUND(SUM(J34:J35),2) -> 0 | K39: =ROUND(SUM(K36:K38),2) -> 0 | L39: =IF(J39=K39,"<- Debits and Credits equal each other.","<- Debits and Credits do not equal each other.") -> <- Debits and Credits equal each other.
B41: SBITA ASSET (Acct 0480) AMOUNT SHOULD BE INCLUDED AS "ADDITIONS" ON REPORT 18.
A43: Record Annual Activity (all SBITAs)
A44: 3 | B44: Record amortization of the SBITA asset for the year.
B45: Dr: Acct 0875 - DEPRECIATION/AMORTIZATION | J45: 5593
C46: Cr. Acct 0475 - ACCUMULATED AMORTIZATION - RIGHT-TO-USE SBITA | K46: =J45 -> 5593
J47: =ROUND(SUM(J45:J45),2) -> 5593 | K47: =ROUND(SUM(K46),2) -> 5593 | L47: =IF(J47=K47,"<- Debits and Credits equal each other.","<- Debits and Credits do not equal each other.") -> <- Debits and Credits equal each other.
A49: 4 | B49: Reclassify information technology subscription exp. to debt service principal and interest exp.
...

Sheet Fund 0305 Journal Entries
A1: GASB 96 - SBITA Contracts Fund-by-Fund Journal Entries Form (to be submitted to the SCO annually—one form per fund)
A2: Manually complete every yellow field in this worksheet—there are no automatically calculated data-entry cells in this worksheet.
A3: Fiscal year: | F3: 2022–2023
A4: Organization Name: | F4: Department of Consumer Affairs
A5: Organization Code (Business Unit): | F5: 1111
A6: Fund Number: | F6: 305
A7: Fund Type: | F7: Governmental Fund
A8: Fund Classification: | F8: =IF(OR($F$7='Drop Down Menus'!B2,$F$7='Drop Down Menus'!$B$3),'Drop Down Menus'!$D$9,IFERROR(VLOOKUP($F$5,GAAP02Aindex!$A$2:$D$900,4,FALSE),"Unidentified")) -> BUS, CONSUMER SERV, HOUSING
A12: =IF($F$3="2022–2023","Establish Beginning Balances (SBITAs commenced on or before 07/01/2022)","Establish Beginning Balances (existing SBITAs only)") -> Establish Beginning Balances (SBITAs commenced on or before 07/01/2022)
A13: Entry #
A14: 0 | B14: =IF($F$3="2022–2023","To establish the beginning balance of SBITAs as of 07/01/2022.","Roll forward prior year right-to-use SBITAs to record opening balances.") -> To establish the beginning balance of SBITAs as of 07/01/2022.
B15: Dr: Acct 0480 - RIGHT-TO-USE SBITA - AMORTIZABLE | J15: 736072
B16: Dr: Acct 0950 - BEGINNING FUND BALANCE
B17: Dr: Acct 0952 - BEG FB ADJ/PRIOR PERIOD ADJUSTMENT
C18: Cr. Acct 0475 - ACCUMULATED AMORTIZATION - RIGHT-TO-USE SBITA
C19: Cr: Acct 0674 - RIGHT-TO-USE SBITA LIABILITY | K19: 583778
C20: Cr: Acct 0950 - BEGINNING FUND BALANCE
C21: Cr: Acct 0952 - BEG FB ADJ/PRIOR PERIOD ADJUSTMENT | K21: 152294
J22: =ROUND(SUM(J15:J17),2) -> 736072 | K22: =ROUND(SUM(K18:K21),2) -> 736072 | L22: =IF(J22=K22,"<- Debits and Credits equal each other.","<- Debits and Credits do not equal each other.") -> <- Debits and Credits equal each other.
B24: SBITA ASSET (Acct 0480) AMOUNT SHOULD BE REPORTED AS BEGINNING BALANCE ON REPORT 18.
A26: =IF($F$3="2022–2023","Record SBITAs Commenced on or after 07/02/2022","Record New SBITAs (new SBITAs only)") -> Record SBITAs Commenced on or after 07/02/2022
A27: 1 | B27: Record at inception of SBITA in accordance with Fund-Based accounting (Governmental Funds Only).
B28: Dr: Acct 0842 - CAPITAL OUTLAY
C29: Cr: Acct 0789 - LEASE AND OTHER FINANCING PROCEEDS
C30: =VLOOKUP($F$8,'Drop Down Menus'!$D$2:$G$10,4,FALSE) -> Cr: Acct 0825 - BUS, CONSUMER SERV, HOUSING
J31: =ROUND(SUM(J28:J30),2) -> 0 | K31: =ROUND(SUM(K28:K30),2) -> 0 | L31: =IF(J31=K31,"<- Debits and Credits equal each other.","<- Debits and Credits do not equal each other.") -> <- Debits and Credits equal each other.
A33: 2 | B33: Reverse the fund-based entry in #1 above, if any, and record an inception of SBITA in accordance with GAAP Govt Wide.
B34: Dr: Acct 0480 - RIGHT-TO-USE SBITA - AMORTIZABLE
B35: Dr: Acct 0789 - LEASE AND OTHER FINANCING PROCEEDS
C36: Cr: Acct 0842 - CAPITAL OUTLAY
C37: Cr: Acct 0674 - RIGHT-TO-USE SBITA LIABILITY
C38: =VLOOKUP($F$8,'Drop Down Menus'!$D$2:$G$10,4,FALSE) -> Cr: Acct 0825 - BUS, CONSUMER SERV, HOUSING
J39: =ROUND(SUM(J34:J35),2) -> 0 | K39: =ROUND(SUM(K36:K38),2) -> 0 | L39: =IF(J39=K39,"<- Debits and Credits equal each other.","<- Debits and Credits do not equal each other.") -> <- Debits and Credits equal each other.
B41: SBITA ASSET (Acct 0480) AMOUNT SHOULD BE INCLUDED AS "ADDITIONS" ON REPORT 18.
A43: Record Annual Activity (all SBITAs)
A44: 3 | B44: Record amortization of the SBITA asset for the year.
B45: Dr: Acct 0875 - DEPRECIATION/AMORTIZATION | J45: 230678
C46: Cr. Acct 0475 - ACCUMULATED AMORTIZATION - RIGHT-TO-USE SBITA | K46: =J45 -> 230678
J47: =ROUND(SUM(J45:J45),2) -> 230678 | K47: =ROUND(SUM(K46),2) -> 230678 | L47: =IF(J47=K47,"<- Debits and Credits equal each other.","<- Debits and Credits do not equal each other.") -> <- Debits and Credits equal each other.
A49: 4 | B49: Reclassify information technology subscription exp. to debt service principal and interest exp.
...

Sheet Fund 0325 Journal Entries
A1: GASB 96 - SBITA Contracts Fund-by-Fund Journal Entries Form (to be submitted to the SCO annually—one form per fund)
A2: Manually complete every yellow field in this worksheet—there are no automatically calculated data-entry cells in this worksheet.
A3: Fiscal year: | F3: 2022–2023
A4: Organization Name: | F4: Department of Consumer Affairs
A5: Organization Code (Business Unit): | F5: 1111
A6: Fund Number: | F6: 325
A7: Fund Type: | F7: Governmental Fund
A8: Fund Classification: | F8: =IF(OR($F$7='Drop Down Menus'!B2,$F$7='Drop Down Menus'!$B$3),'Drop Down Menus'!$D$9,IFERROR(VLOOKUP($F$5,GAAP02Aindex!$A$2:$D$900,4,FALSE),"Unidentified")) -> BUS, CONSUMER SERV, HOUSING
A12: =IF($F$3="2022–2023","Establish Beginning Balances (SBITAs commenced on or before 07/01/2022)","Establish Beginning Balances (existing SBITAs only)") -> Establish Beginning Balances (SBITAs commenced on or before 07/01/2022)
A13: Entry #
A14: 0 | B14: =IF($F$3="2022–2023","To establish the beginning balance of SBITAs as of 07/01/2022.","Roll forward prior year right-to-use SBITAs to record opening balances.") -> To establish the beginning balance of SBITAs as of 07/01/2022.
B15: Dr: Acct 0480 - RIGHT-TO-USE SBITA - AMORTIZABLE | J15: 48585
B16: Dr: Acct 0950 - BEGINNING FUND BALANCE
B17: Dr: Acct 0952 - BEG FB ADJ/PRIOR PERIOD ADJUSTMENT
C18: Cr. Acct 0475 - ACCUMULATED AMORTIZATION - RIGHT-TO-USE SBITA
C19: Cr: Acct 0674 - RIGHT-TO-USE SBITA LIABILITY | K19: 27853
C20: Cr: Acct 0950 - BEGINNING FUND BALANCE
C21: Cr: Acct 0952 - BEG FB ADJ/PRIOR PERIOD ADJUSTMENT | K21: 20732
J22: =ROUND(SUM(J15:J17),2) -> 48585 | K22: =ROUND(SUM(K18:K21),2) -> 48585 | L22: =IF(J22=K22,"<- Debits and Credits equal each other.","<- Debits and Credits do not equal each other.") -> <- Debits and Credits equal each other.
B24: SBITA ASSET (Acct 0480) AMOUNT SHOULD BE REPORTED AS BEGINNING BALANCE ON REPORT 18.
A26: =IF($F$3="2022–2023","Record SBITAs Commenced on or after 07/02/2022","Record New SBITAs (new SBITAs only)") -> Record SBITAs Commenced on or after 07/02/2022
A27: 1 | B27: Record at inception of SBITA in accordance with Fund-Based accounting (Governmental Funds Only).
B28: Dr: Acct 0842 - CAPITAL OUTLAY
C29: Cr: Acct 0789 - LEASE AND OTHER FINANCING PROCEEDS
C30: =VLOOKUP($F$8,'Drop Down Menus'!$D$2:$G$10,4,FALSE) -> Cr: Acct 0825 - BUS, CONSUMER SERV, HOUSING
J31: =ROUND(SUM(J28:J30),2) -> 0 | K31: =ROUND(SUM(K28:K30),2) -> 0 | L31: =IF(J31=K31,"<- Debits and Credits equal each other.","<- Debits and Credits do not equal each other.") -> <- Debits and Credits equal each other.
A33: 2 | B33: Reverse the fund-based entry in #1 above, if any, and record an inception of SBITA in accordance with GAAP Govt Wide.
B34: Dr: Acct 0480 - RIGHT-TO-USE SBITA - AMORTIZABLE
B35: Dr: Acct 0789 - LEASE AND OTHER FINANCING PROCEEDS
C36: Cr: Acct 0842 - CAPITAL OUTLAY
C37: Cr: Acct 0674 - RIGHT-TO-USE SBITA LIABILITY
C38: =VLOOKUP($F$8,'Drop Down Menus'!$D$2:$G$10,4,FALSE) -> Cr: Acct 0825 - BUS, CONSUMER SERV, HOUSING
J39: =ROUND(SUM(J34:J35),2) -> 0 | K39: =ROUND(SUM(K36:K38),2) -> 0 | L39: =IF(J39=K39,"<- Debits and Credits equal each other.","<- Debits and Credits do not equal each other.") -> <- Debits and Credits equal each other.
B41: SBITA ASSET (Acct 0480) AMOUNT SHOULD BE INCLUDED AS "ADDITIONS" ON REPORT 18.
A43: Record Annual Activity (all SBITAs)
A44: 3 | B44: Record amortization of the SBITA asset for the year.
B45: Dr: Acct 0875 - DEPRECIATION/AMORTIZATION | J45: 10052
C46: Cr. Acct 0475 - ACCUMULATED AMORTIZATION - RIGHT-TO-USE SBITA | K46: =J45 -> 10052
J47: =ROUND(SUM(J45:J45),2) -> 10052 | K47: =ROUND(SUM(K46),2) -> 10052 | L47: =IF(J47=K47,"<- Debits and Credits equal each other.","<- Debits and Credits do not equal each other.") -> <- Debits and Credits equal each other.
A49: 4 | B49: Reclassify information technology subscription exp. to debt service principal and interest exp.
...

Sheet Fund 0492 Journal Entries
A1: GASB 96 - SBITA Contracts Fund-by-Fund Journal Entries Form (to be submitted to the SCO annually—one form per fund)
A2: Manually complete every yellow field in this worksheet—there are no automatically calculated data-entry cells in this worksheet.
A3: Fiscal year: | F3: 2022–2023
A4: Organization Name: | F4: Department of Consumer Affairs
A5: Organization Code (Business Unit): | F5: 1111
A6: Fund Number: | F6: 492
A7: Fund Type: | F7: Governmental Fund
A8: Fund Classification: | F8: =IF(OR($F$7='Drop Down Menus'!B2,$F$7='Drop Down Menus'!$B$3),'Drop Down Menus'!$D$9,IFERROR(VLOOKUP($F$5,GAAP02Aindex!$A$2:$D$900,4,FALSE),"Unidentified")) -> BUS, CONSUMER SERV, HOUSING
A12: =IF($F$3="2022–2023","Establish Beginning Balances (SBITAs commenced on or before 07/01/2022)","Establish Beginning Balances (existing SBITAs only)") -> Establish Beginning Balances (SBITAs commenced on or before 07/01/2022)
A13: Entry #
A14: 0 | B14: =IF($F$3="2022–2023","To establish the beginning balance of SBITAs as of 07/01/2022.","Roll forward prior year right-to-use SBITAs to record opening balances.") -> To establish the beginning balance of SBITAs as of 07/01/2022.
B15: Dr: Acct 0480 - RIGHT-TO-USE SBITA - AMORTIZABLE | J15: 51496
B16: Dr: Acct 0950 - BEGINNING FUND BALANCE
B17: Dr: Acct 0952 - BEG FB ADJ/PRIOR PERIOD ADJUSTMENT
C18: Cr. Acct 0475 - ACCUMULATED AMORTIZATION - RIGHT-TO-USE SBITA
C19: Cr: Acct 0674 - RIGHT-TO-USE SBITA LIABILITY | K19: 43913
C20: Cr: Acct 0950 - BEGINNING FUND BALANCE
C21: Cr: Acct 0952 - BEG FB ADJ/PRIOR PERIOD ADJUSTMENT | K21: 7583
J22: =ROUND(SUM(J15:J17),2) -> 51496 | K22: =ROUND(SUM(K18:K21),2) -> 51496 | L22: =IF(J22=K22,"<- Debits and Credits equal each other.","<- Debits and Credits do not equal each other.") -> <- Debits and Credits equal each other.
B24: SBITA ASSET (Acct 0480) AMOUNT SHOULD BE REPORTED AS BEGINNING BALANCE ON REPORT 18.
A26: =IF($F$3="2022–2023","Record SBITAs Commenced on or after 07/02/2022","Record New SBITAs (new SBITAs only)") -> Record SBITAs Commenced on or after 07/02/2022
A27: 1 | B27: Record at inception of SBITA in accordance with Fund-Based accounting (Governmental Funds Only).
B28: Dr: Acct 0842 - CAPITAL OUTLAY
C29: Cr: Acct 0789 - LEASE AND OTHER FINANCING PROCEEDS
C30: =VLOOKUP($F$8,'Drop Down Menus'!$D$2:$G$10,4,FALSE) -> Cr: Acct 0825 - BUS, CONSUMER SERV, HOUSING
J31: =ROUND(SUM(J28:J30),2) -> 0 | K31: =ROUND(SUM(K28:K30),2) -> 0 | L31: =IF(J31=K31,"<- Debits and Credits equal each other.","<- Debits and Credits do not equal each other.") -> <- Debits and Credits equal each other.
A33: 2 | B33: Reverse the fund-based entry in #1 above, if any, and record an inception of SBITA in accordance with GAAP Govt Wide.
B34: Dr: Acct 0480 - RIGHT-TO-USE SBITA - AMORTIZABLE
B35: Dr: Acct 0789 - LEASE AND OTHER FINANCING PROCEEDS
C36: Cr: Acct 0842 - CAPITAL OUTLAY
C37: Cr: Acct 0674 - RIGHT-TO-USE SBITA LIABILITY
C38: =VLOOKUP($F$8,'Drop Down Menus'!$D$2:$G$10,4,FALSE) -> Cr: Acct 0825 - BUS, CONSUMER SERV, HOUSING
J39: =ROUND(SUM(J34:J35),2) -> 0 | K39: =ROUND(SUM(K36:K38),2) -> 0 | L39: =IF(J39=K39,"<- Debits and Credits equal each other.","<- Debits and Credits do not equal each other.") -> <- Debits and Credits equal each other.
B41: SBITA ASSET (Acct 0480) AMOUNT SHOULD BE INCLUDED AS "ADDITIONS" ON REPORT 18.
A43: Record Annual Activity (all SBITAs)
A44: 3 | B44: Record amortization of the SBITA asset for the year.
B45: Dr: Acct 0875 - DEPRECIATION/AMORTIZATION | J45: 25748
C46: Cr. Acct 0475 - ACCUMULATED AMORTIZATION - RIGHT-TO-USE SBITA | K46: =J45 -> 25748
J47: =ROUND(SUM(J45:J45),2) -> 25748 | K47: =ROUND(SUM(K46),2) -> 25748 | L47: =IF(J47=K47,"<- Debits and Credits equal each other.","<- Debits and Credits do not equal each other.") -> <- Debits and Credits equal each other.
A49: 4 | B49: Reclassify information technology subscription exp. to debt service principal and interest exp.
...

Sheet Fund 0702 Journal Entries
A1: GASB 96 - SBITA Contracts Fund-by-Fund Journal Entries Form (to be submitted to the SCO annually—one form per fund)
A2: Manually complete every yellow field in this worksheet—there are no automatically calculated data-entry cells in this worksheet.
A3: Fiscal year: | F3: 2022–2023
A4: Organization Name: | F4: Department of Consumer Affairs
A5: Organization Code (Business Unit): | F5: 1111
A6: Fund Number: | F6: 702
A7: Fund Type: | F7: Governmental Fund
A8: Fund Classification: | F8: =IF(OR($F$7='Drop Down Menus'!B2,$F$7='Drop Down Menus'!$B$3),'Drop Down Menus'!$D$9,IFERROR(VLOOKUP($F$5,GAAP02Aindex!$A$2:$D$900,4,FALSE),"Unidentified")) -> BUS, CONSUMER SERV, HOUSING
A12: =IF($F$3="2022–2023","Establish Beginning Balances (SBITAs commenced on or before 07/01/2022)","Establish Beginning Balances (existing SBITAs only)") -> Establish Beginning Balances (SBITAs commenced on or before 07/01/2022)
A13: Entry #
A14: 0 | B14: =IF($F$3="2022–2023","To establish the beginning balance of SBITAs as of 07/01/2022.","Roll forward prior year right-to-use SBITAs to record opening balances.") -> To establish the beginning balance of SBITAs as of 07/01/2022.
B15: Dr: Acct 0480 - RIGHT-TO-USE SBITA - AMORTIZABLE | J15: 69182
B16: Dr: Acct 0950 - BEGINNING FUND BALANCE
B17: Dr: Acct 0952 - BEG FB ADJ/PRIOR PERIOD ADJUSTMENT
C18: Cr. Acct 0475 - ACCUMULATED AMORTIZATION - RIGHT-TO-USE SBITA
C19: Cr: Acct 0674 - RIGHT-TO-USE SBITA LIABILITY | K19: 58893
C20: Cr: Acct 0950 - BEGINNING FUND BALANCE
C21: Cr: Acct 0952 - BEG FB ADJ/PRIOR PERIOD ADJUSTMENT | K21: 10289
J22: =ROUND(SUM(J15:J17),2) -> 69182 | K22: =ROUND(SUM(K18:K21),2) -> 69182 | L22: =IF(J22=K22,"<- Debits and Credits equal each other.","<- Debits and Credits do not equal each other.") -> <- Debits and Credits equal each other.
B24: SBITA ASSET (Acct 0480) AMOUNT SHOULD BE REPORTED AS BEGINNING BALANCE ON REPORT 18.
A26: =IF($F$3="2022–2023","Record SBITAs Commenced on or after 07/02/2022","Record New SBITAs (new SBITAs only)") -> Record SBITAs Commenced on or after 07/02/2022
A27: 1 | B27: Record at inception of SBITA in accordance with Fund-Based accounting (Governmental Funds Only).
B28: Dr: Acct 0842 - CAPITAL OUTLAY
C29: Cr: Acct 0789 - LEASE AND OTHER FINANCING PROCEEDS
C30: =VLOOKUP($F$8,'Drop Down Menus'!$D$2:$G$10,4,FALSE) -> Cr: Acct 0825 - BUS, CONSUMER SERV, HOUSING
J31: =ROUND(SUM(J28:J30),2) -> 0 | K31: =ROUND(SUM(K28:K30),2) -> 0 | L31: =IF(J31=K31,"<- Debits and Credits equal each other.","<- Debits and Credits do not equal each other.") -> <- Debits and Credits equal each other.
A33: 2 | B33: Reverse the fund-based entry in #1 above, if any, and record an inception of SBITA in accordance with GAAP Govt Wide.
B34: Dr: Acct 0480 - RIGHT-TO-USE SBITA - AMORTIZABLE
B35: Dr: Acct 0789 - LEASE AND OTHER FINANCING PROCEEDS
C36: Cr: Acct 0842 - CAPITAL OUTLAY
C37: Cr: Acct 0674 - RIGHT-TO-USE SBITA LIABILITY
C38: =VLOOKUP($F$8,'Drop Down Menus'!$D$2:$G$10,4,FALSE) -> Cr: Acct 0825 - BUS, CONSUMER SERV, HOUSING
J39: =ROUND(SUM(J34:J35),2) -> 0 | K39: =ROUND(SUM(K36:K38),2) -> 0 | L39: =IF(J39=K39,"<- Debits and Credits equal each other.","<- Debits and Credits do not equal each other.") -> <- Debits and Credits equal each other.
B41: SBITA ASSET (Acct 0480) AMOUNT SHOULD BE INCLUDED AS "ADDITIONS" ON REPORT 18.
A43: Record Annual Activity (all SBITAs)
A44: 3 | B44: Record amortization of the SBITA asset for the year.
B45: Dr: Acct 0875 - DEPRECIATION/AMORTIZATION | J45: 31930
C46: Cr. Acct 0475 - ACCUMULATED AMORTIZATION - RIGHT-TO-USE SBITA | K46: =J45 -> 31930
J47: =ROUND(SUM(J45:J45),2) -> 31930 | K47: =ROUND(SUM(K46),2) -> 31930 | L47: =IF(J47=K47,"<- Debits and Credits equal each other.","<- Debits and Credits do not equal each other.") -> <- Debits and Credits equal each other.
A49: 4 | B49: Reclassify information technology subscription exp. to debt service principal and interest exp.
...

Sheet Fund 0706 Journal Entries
A1: GASB 96 - SBITA Contracts Fund-by-Fund Journal Entries Form (to be submitted to the SCO annually—one form per fund)
A2: Manually complete every yellow field in this worksheet—there are no automatically calculated data-entry cells in this worksheet.
A3: Fiscal year: | F3: 2022–2023
A4: Organization Name: | F4: Department of Consumer Affairs
A5: Organization Code (Business Unit): | F5: 1111
A6: Fund Number: | F6: 706
A7: Fund Type: | F7: Governmental Fund
A8: Fund Classification: | F8: =IF(OR($F$7='Drop Down Menus'!B2,$F$7='Drop Down Menus'!$B$3),'Drop Down Menus'!$D$9,IFERROR(VLOOKUP($F$5,GAAP02Aindex!$A$2:$D$900,4,FALSE),"Unidentified")) -> BUS, CONSUMER SERV, HOUSING
A12: =IF($F$3="2022–2023","Establish Beginning Balances (SBITAs commenced on or before 07/01/2022)","Establish Beginning Balances (existing SBITAs only)") -> Establish Beginning Balances (SBITAs commenced on or before 07/01/2022)
A13: Entry #
A14: 0 | B14: =IF($F$3="2022–2023","To establish the beginning balance of SBITAs as of 07/01/2022.","Roll forward prior year right-to-use SBITAs to record opening balances.") -> To establish the beginning balance of SBITAs as of 07/01/2022.
B15: Dr: Acct 0480 - RIGHT-TO-USE SBITA - AMORTIZABLE | J15: 121462
B16: Dr: Acct 0950 - BEGINNING FUND BALANCE
B17: Dr: Acct 0952 - BEG FB ADJ/PRIOR PERIOD ADJUSTMENT
C18: Cr. Acct 0475 - ACCUMULATED AMORTIZATION - RIGHT-TO-USE SBITA
C19: Cr: Acct 0674 - RIGHT-TO-USE SBITA LIABILITY | K19: 69633
C20: Cr: Acct 0950 - BEGINNING FUND BALANCE
C21: Cr: Acct 0952 - BEG FB ADJ/PRIOR PERIOD ADJUSTMENT | K21: 51829
J22: =ROUND(SUM(J15:J17),2) -> 121462 | K22: =ROUND(SUM(K18:K21),2) -> 121462 | L22: =IF(J22=K22,"<- Debits and Credits equal each other.","<- Debits and Credits do not equal each other.") -> <- Debits and Credits equal each other.
B24: SBITA ASSET (Acct 0480) AMOUNT SHOULD BE REPORTED AS BEGINNING BALANCE ON REPORT 18.
A26: =IF($F$3="2022–2023","Record SBITAs Commenced on or after 07/02/2022","Record New SBITAs (new SBITAs only)") -> Record SBITAs Commenced on or after 07/02/2022
A27: 1 | B27: Record at inception of SBITA in accordance with Fund-Based accounting (Governmental Funds Only).
B28: Dr: Acct 0842 - CAPITAL OUTLAY
C29: Cr: Acct 0789 - LEASE AND OTHER FINANCING PROCEEDS
C30: =VLOOKUP($F$8,'Drop Down Menus'!$D$2:$G$10,4,FALSE) -> Cr: Acct 0825 - BUS, CONSUMER SERV, HOUSING
J31: =ROUND(SUM(J28:J30),2) -> 0 | K31: =ROUND(SUM(K28:K30),2) -> 0 | L31: =IF(J31=K31,"<- Debits and Credits equal each other.","<- Debits and Credits do not equal each other.") -> <- Debits and Credits equal each other.
A33: 2 | B33: Reverse the fund-based entry in #1 above, if any, and record an inception of SBITA in accordance with GAAP Govt Wide.
B34: Dr: Acct 0480 - RIGHT-TO-USE SBITA - AMORTIZABLE
B35: Dr: Acct 0789 - LEASE AND OTHER FINANCING PROCEEDS
C36: Cr: Acct 0842 - CAPITAL OUTLAY
C37: Cr: Acct 0674 - RIGHT-TO-USE SBITA LIABILITY
C38: =VLOOKUP($F$8,'Drop Down Menus'!$D$2:$G$10,4,FALSE) -> Cr: Acct 0825 - BUS, CONSUMER SERV, HOUSING
J39: =ROUND(SUM(J34:J35),2) -> 0 | K39: =ROUND(SUM(K36:K38),2) -> 0 | L39: =IF(J39=K39,"<- Debits and Credits equal each other.","<- Debits and Credits do not equal each other.") -> <- Debits and Credits equal each other.
B41: SBITA ASSET (Acct 0480) AMOUNT SHOULD BE INCLUDED AS "ADDITIONS" ON REPORT 18.
A43: Record Annual Activity (all SBITAs)
A44: 3 | B44: Record amortization of the SBITA asset for the year.
B45: Dr: Acct 0875 - DEPRECIATION/AMORTIZATION | J45: 25130
C46: Cr. Acct 0475 - ACCUMULATED AMORTIZATION - RIGHT-TO-USE SBITA | K46: =J45 -> 25130
J47: =ROUND(SUM(J45:J45),2) -> 25130 | K47: =ROUND(SUM(K46),2) -> 25130 | L47: =IF(J47=K47,"<- Debits and Credits equal each other.","<- Debits and Credits do not equal each other.") -> <- Debits and Credits equal each other.
A49: 4 | B49: Reclassify information technology subscription exp. to debt service principal and interest exp.
...

Sheet Fund 0717 Journal Entries
A1: GASB 96 - SBITA Contracts Fund-by-Fund Journal Entries Form (to be submitted to the SCO annually—one form per fund)
A2: Manually complete every yellow field in this worksheet—there are no automatically calculated data-entry cells in this worksheet.
A3: Fiscal year: | F3: 2022–2023
A4: Organization Name: | F4: Department of Consumer Affairs
A5: Organization Code (Business Unit): | F5: 1111
A6: Fund Number: | F6: 717
A7: Fund Type: | F7: Governmental Fund
A8: Fund Classification: | F8: =IF(OR($F$7='Drop Down Menus'!B2,$F$7='Drop Down Menus'!$B$3),'Drop Down Menus'!$D$9,IFERROR(VLOOKUP($F$5,GAAP02Aindex!$A$2:$D$900,4,FALSE),"Unidentified")) -> BUS, CONSUMER SERV, HOUSING
A12: =IF($F$3="2022–2023","Establish Beginning Balances (SBITAs commenced on or before 07/01/2022)","Establish Beginning Balances (existing SBITAs only)") -> Establish Beginning Balances (SBITAs commenced on or before 07/01/2022)
A13: Entry #
A14: 0 | B14: =IF($F$3="2022–2023","To establish the beginning balance of SBITAs as of 07/01/2022.","Roll forward prior year right-to-use SBITAs to record opening balances.") -> To establish the beginning balance of SBITAs as of 07/01/2022.
B15: Dr: Acct 0480 - RIGHT-TO-USE SBITA - AMORTIZABLE | J15: 151827
B16: Dr: Acct 0950 - BEGINNING FUND BALANCE
B17: Dr: Acct 0952 - BEG FB ADJ/PRIOR PERIOD ADJUSTMENT
C18: Cr. Acct 0475 - ACCUMULATED AMORTIZATION - RIGHT-TO-USE SBITA
C19: Cr: Acct 0674 - RIGHT-TO-USE SBITA LIABILITY | K19: 87041
C20: Cr: Acct 0950 - BEGINNING FUND BALANCE
C21: Cr: Acct 0952 - BEG FB ADJ/PRIOR PERIOD ADJUSTMENT | K21: 64786
J22: =ROUND(SUM(J15:J17),2) -> 151827 | K22: =ROUND(SUM(K18:K21),2) -> 151827 | L22: =IF(J22=K22,"<- Debits and Credits equal each other.","<- Debits and Credits do not equal each other.") -> <- Debits and Credits equal each other.
B24: SBITA ASSET (Acct 0480) AMOUNT SHOULD BE REPORTED AS BEGINNING BALANCE ON REPORT 18.
A26: =IF($F$3="2022–2023","Record SBITAs Commenced on or after 07/02/2022","Record New SBITAs (new SBITAs only)") -> Record SBITAs Commenced on or after 07/02/2022
A27: 1 | B27: Record at inception of SBITA in accordance with Fund-Based accounting (Governmental Funds Only).
B28: Dr: Acct 0842 - CAPITAL OUTLAY
C29: Cr: Acct 0789 - LEASE AND OTHER FINANCING PROCEEDS
C30: =VLOOKUP($F$8,'Drop Down Menus'!$D$2:$G$10,4,FALSE) -> Cr: Acct 0825 - BUS, CONSUMER SERV, HOUSING
J31: =ROUND(SUM(J28:J30),2) -> 0 | K31: =ROUND(SUM(K28:K30),2) -> 0 | L31: =IF(J31=K31,"<- Debits and Credits equal each other.","<- Debits and Credits do not equal each other.") -> <- Debits and Credits equal each other.
A33: 2 | B33: Reverse the fund-based entry in #1 above, if any, and record an inception of SBITA in accordance with GAAP Govt Wide.
B34: Dr: Acct 0480 - RIGHT-TO-USE SBITA - AMORTIZABLE
B35: Dr: Acct 0789 - LEASE AND OTHER FINANCING PROCEEDS
C36: Cr: Acct 0842 - CAPITAL OUTLAY
C37: Cr: Acct 0674 - RIGHT-TO-USE SBITA LIABILITY
C38: =VLOOKUP($F$8,'Drop Down Menus'!$D$2:$G$10,4,FALSE) -> Cr: Acct 0825 - BUS, CONSUMER SERV, HOUSING
J39: =ROUND(SUM(J34:J35),2) -> 0 | K39: =ROUND(SUM(K36:K38),2) -> 0 | L39: =IF(J39=K39,"<- Debits and Credits equal each other.","<- Debits and Credits do not equal each other.") -> <- Debits and Credits equal each other.
B41: SBITA ASSET (Acct 0480) AMOUNT SHOULD BE INCLUDED AS "ADDITIONS" ON REPORT 18.
A43: Record Annual Activity (all SBITAs)
A44: 3 | B44: Record amortization of the SBITA asset for the year.
B45: Dr: Acct 0875 - DEPRECIATION/AMORTIZATION | J45: 31412
C46: Cr. Acct 0475 - ACCUMULATED AMORTIZATION - RIGHT-TO-USE SBITA | K46: =J45 -> 31412
J47: =ROUND(SUM(J45:J45),2) -> 31412 | K47: =ROUND(SUM(K46),2) -> 31412 | L47: =IF(J47=K47,"<- Debits and Credits equal each other.","<- Debits and Credits do not equal each other.") -> <- Debits and Credits equal each other.
A49: 4 | B49: Reclassify information technology subscription exp. to debt service principal and interest exp.
...

Sheet Fund 0752 Journal Entries
A1: GASB 96 - SBITA Contracts Fund-by-Fund Journal Entries Form (to be submitted to the SCO annually—one form per fund)
A2: Manually complete every yellow field in this worksheet—there are no automatically calculated data-entry cells in this worksheet.
A3: Fiscal year: | F3: 2022–2023
A4: Organization Name: | F4: Department of Consumer Affairs
A5: Organization Code (Business Unit): | F5: 1111
A6: Fund Number: | F6: 752
A7: Fund Type: | F7: Governmental Fund
A8: Fund Classification: | F8: =IF(OR($F$7='Drop Down Menus'!B2,$F$7='Drop Down Menus'!$B$3),'Drop Down Menus'!$D$9,IFERROR(VLOOKUP($F$5,GAAP02Aindex!$A$2:$D$900,4,FALSE),"Unidentified")) -> BUS, CONSUMER SERV, HOUSING
A12: =IF($F$3="2022–2023","Establish Beginning Balances (SBITAs commenced on or before 07/01/2022)","Establish Beginning Balances (existing SBITAs only)") -> Establish Beginning Balances (SBITAs commenced on or before 07/01/2022)
A13: Entry #
A14: 0 | B14: =IF($F$3="2022–2023","To establish the beginning balance of SBITAs as of 07/01/2022.","Roll forward prior year right-to-use SBITAs to record opening balances.") -> To establish the beginning balance of SBITAs as of 07/01/2022.
B15: Dr: Acct 0480 - RIGHT-TO-USE SBITA - AMORTIZABLE | J15: 12146
B16: Dr: Acct 0950 - BEGINNING FUND BALANCE
B17: Dr: Acct 0952 - BEG FB ADJ/PRIOR PERIOD ADJUSTMENT
C18: Cr. Acct 0475 - ACCUMULATED AMORTIZATION - RIGHT-TO-USE SBITA
C19: Cr: Acct 0674 - RIGHT-TO-USE SBITA LIABILITY | K19: 6963
C20: Cr: Acct 0950 - BEGINNING FUND BALANCE
C21: Cr: Acct 0952 - BEG FB ADJ/PRIOR PERIOD ADJUSTMENT | K21: 5183
J22: =ROUND(SUM(J15:J17),2) -> 12146 | K22: =ROUND(SUM(K18:K21),2) -> 12146 | L22: =IF(J22=K22,"<- Debits and Credits equal each other.","<- Debits and Credits do not equal each other.") -> <- Debits and Credits equal each other.
B24: SBITA ASSET (Acct 0480) AMOUNT SHOULD BE REPORTED AS BEGINNING BALANCE ON REPORT 18.
A26: =IF($F$3="2022–2023","Record SBITAs Commenced on or after 07/02/2022","Record New SBITAs (new SBITAs only)") -> Record SBITAs Commenced on or after 07/02/2022
A27: 1 | B27: Record at inception of SBITA in accordance with Fund-Based accounting (Governmental Funds Only).
B28: Dr: Acct 0842 - CAPITAL OUTLAY
C29: Cr: Acct 0789 - LEASE AND OTHER FINANCING PROCEEDS
C30: =VLOOKUP($F$8,'Drop Down Menus'!$D$2:$G$10,4,FALSE) -> Cr: Acct 0825 - BUS, CONSUMER SERV, HOUSING
J31: =ROUND(SUM(J28:J30),2) -> 0 | K31: =ROUND(SUM(K28:K30),2) -> 0 | L31: =IF(J31=K31,"<- Debits and Credits equal each other.","<- Debits and Credits do not equal each other.") -> <- Debits and Credits equal each other.
A33: 2 | B33: Reverse the fund-based entry in #1 above, if any, and record an inception of SBITA in accordance with GAAP Govt Wide.
B34: Dr: Acct 0480 - RIGHT-TO-USE SBITA - AMORTIZABLE
B35: Dr: Acct 0789 - LEASE AND OTHER FINANCING PROCEEDS
C36: Cr: Acct 0842 - CAPITAL OUTLAY
C37: Cr: Acct 0674 - RIGHT-TO-USE SBITA LIABILITY
C38: =VLOOKUP($F$8,'Drop Down Menus'!$D$2:$G$10,4,FALSE) -> Cr: Acct 0825 - BUS, CONSUMER SERV, HOUSING
J39: =ROUND(SUM(J34:J35),2) -> 0 | K39: =ROUND(SUM(K36:K38),2) -> 0 | L39: =IF(J39=K39,"<- Debits and Credits equal each other.","<- Debits and Credits do not equal each other.") -> <- Debits and Credits equal each other.
B41: SBITA ASSET (Acct 0480) AMOUNT SHOULD BE INCLUDED AS "ADDITIONS" ON REPORT 18.
A43: Record Annual Activity (all SBITAs)
A44: 3 | B44: Record amortization of the SBITA asset for the year.
B45: Dr: Acct 0875 - DEPRECIATION/AMORTIZATION | J45: 2513
C46: Cr. Acct 0475 - ACCUMULATED AMORTIZATION - RIGHT-TO-USE SBITA | K46: =J45 -> 2513
J47: =ROUND(SUM(J45:J45),2) -> 2513 | K47: =ROUND(SUM(K46),2) -> 2513 | L47: =IF(J47=K47,"<- Debits and Credits equal each other.","<- Debits and Credits do not equal each other.") -> <- Debits and Credits equal each other.
A49: 4 | B49: Reclassify information technology subscription exp. to debt service principal and interest exp.
...

Sheet Fund 0757 Journal Entries
A1: GASB 96 - SBITA Contracts Fund-by-Fund Journal Entries Form (to be submitted to the SCO annually—one form per fund)
A2: Manually complete every yellow field in this worksheet—there are no automatically calculated data-entry cells in this worksheet.
A3: Fiscal year: | F3: 2022–2023
A4: Organization Name: | F4: Department of Consumer Affairs
A5: Organization Code (Business Unit): | F5: 1111
A6: Fund Number: | F6: 757
A7: Fund Type: | F7: Governmental Fund
A8: Fund Classification: | F8: =IF(OR($F$7='Drop Down Menus'!B2,$F$7='Drop Down Menus'!$B$3),'Drop Down Menus'!$D$9,IFERROR(VLOOKUP($F$5,GAAP02Aindex!$A$2:$D$900,4,FALSE),"Unidentified")) -> BUS, CONSUMER SERV, HOUSING
A12: =IF($F$3="2022–2023","Establish Beginning Balances (SBITAs commenced on or before 07/01/2022)","Establish Beginning Balances (existing SBITAs only)") -> Establish Beginning Balances (SBITAs commenced on or before 07/01/2022)
A13: Entry #
A14: 0 | B14: =IF($F$3="2022–2023","To establish the beginning balance of SBITAs as of 07/01/2022.","Roll forward prior year right-to-use SBITAs to record opening balances.") -> To establish the beginning balance of SBITAs as of 07/01/2022.
B15: Dr: Acct 0480 - RIGHT-TO-USE SBITA - AMORTIZABLE | J15: 30365
B16: Dr: Acct 0950 - BEGINNING FUND BALANCE
B17: Dr: Acct 0952 - BEG FB ADJ/PRIOR PERIOD ADJUSTMENT
C18: Cr. Acct 0475 - ACCUMULATED AMORTIZATION - RIGHT-TO-USE SBITA
C19: Cr: Acct 0674 - RIGHT-TO-USE SBITA LIABILITY | K19: 17408
C20: Cr: Acct 0950 - BEGINNING FUND BALANCE
C21: Cr: Acct 0952 - BEG FB ADJ/PRIOR PERIOD ADJUSTMENT | K21: 12957
J22: =ROUND(SUM(J15:J17),2) -> 30365 | K22: =ROUND(SUM(K18:K21),2) -> 30365 | L22: =IF(J22=K22,"<- Debits and Credits equal each other.","<- Debits and Credits do not equal each other.") -> <- Debits and Credits equal each other.
B24: SBITA ASSET (Acct 0480) AMOUNT SHOULD BE REPORTED AS BEGINNING BALANCE ON REPORT 18.
A26: =IF($F$3="2022–2023","Record SBITAs Commenced on or after 07/02/2022","Record New SBITAs (new SBITAs only)") -> Record SBITAs Commenced on or after 07/02/2022
A27: 1 | B27: Record at inception of SBITA in accordance with Fund-Based accounting (Governmental Funds Only).
B28: Dr: Acct 0842 - CAPITAL OUTLAY
C29: Cr: Acct 0789 - LEASE AND OTHER FINANCING PROCEEDS
C30: =VLOOKUP($F$8,'Drop Down Menus'!$D$2:$G$10,4,FALSE) -> Cr: Acct 0825 - BUS, CONSUMER SERV, HOUSING
J31: =ROUND(SUM(J28:J30),2) -> 0 | K31: =ROUND(SUM(K28:K30),2) -> 0 | L31: =IF(J31=K31,"<- Debits and Credits equal each other.","<- Debits and Credits do not equal each other.") -> <- Debits and Credits equal each other.
A33: 2 | B33: Reverse the fund-based entry in #1 above, if any, and record an inception of SBITA in accordance with GAAP Govt Wide.
B34: Dr: Acct 0480 - RIGHT-TO-USE SBITA - AMORTIZABLE
B35: Dr: Acct 0789 - LEASE AND OTHER FINANCING PROCEEDS
C36: Cr: Acct 0842 - CAPITAL OUTLAY
C37: Cr: Acct 0674 - RIGHT-TO-USE SBITA LIABILITY
C38: =VLOOKUP($F$8,'Drop Down Menus'!$D$2:$G$10,4,FALSE) -> Cr: Acct 0825 - BUS, CONSUMER SERV, HOUSING
J39: =ROUND(SUM(J34:J35),2) -> 0 | K39: =ROUND(SUM(K36:K38),2) -> 0 | L39: =IF(J39=K39,"<- Debits and Credits equal each other.","<- Debits and Credits do not equal each other.") -> <- Debits and Credits equal each other.
B41: SBITA ASSET (Acct 0480) AMOUNT SHOULD BE INCLUDED AS "ADDITIONS" ON REPORT 18.
A43: Record Annual Activity (all SBITAs)
A44: 3 | B44: Record amortization of the SBITA asset for the year.
B45: Dr: Acct 0875 - DEPRECIATION/AMORTIZATION | J45: 6282
C46: Cr. Acct 0475 - ACCUMULATED AMORTIZATION - RIGHT-TO-USE SBITA | K46: =J45 -> 6282
J47: =ROUND(SUM(J45:J45),2) -> 6282 | K47: =ROUND(SUM(K46),2) -> 6282 | L47: =IF(J47=K47,"<- Debits and Credits equal each other.","<- Debits and Credits do not equal each other.") -> <- Debits and Credits equal each other.
A49: 4 | B49: Reclassify information technology subscription exp. to debt service principal and interest exp.
...

Sheet Fund 0770 Journal Entries
A1: GASB 96 - SBITA Contracts Fund-by-Fund Journal Entries Form (to be submitted to the SCO annually—one form per fund)
A2: Manually complete every yellow field in this worksheet—there are no automatically calculated data-entry cells in this worksheet.
A3: Fiscal year: | F3: 2022–2023
A4: Organization Name: | F4: Department of Consumer Affairs
A5: Organization Code (Business Unit): | F5: 1111
A6: Fund Number: | F6: 770
A7: Fund Type: | F7: Governmental Fund
A8: Fund Classification: | F8: =IF(OR($F$7='Drop Down Menus'!B2,$F$7='Drop Down Menus'!$B$3),'Drop Down Menus'!$D$9,IFERROR(VLOOKUP($F$5,GAAP02Aindex!$A$2:$D$900,4,FALSE),"Unidentified")) -> BUS, CONSUMER SERV, HOUSING
A12: =IF($F$3="2022–2023","Establish Beginning Balances (SBITAs commenced on or before 07/01/2022)","Establish Beginning Balances (existing SBITAs only)") -> Establish Beginning Balances (SBITAs commenced on or before 07/01/2022)
A13: Entry #
A14: 0 | B14: =IF($F$3="2022–2023","To establish the beginning balance of SBITAs as of 07/01/2022.","Roll forward prior year right-to-use SBITAs to record opening balances.") -> To establish the beginning balance of SBITAs as of 07/01/2022.
B15: Dr: Acct 0480 - RIGHT-TO-USE SBITA - AMORTIZABLE | J15: 46606
B16: Dr: Acct 0950 - BEGINNING FUND BALANCE
B17: Dr: Acct 0952 - BEG FB ADJ/PRIOR PERIOD ADJUSTMENT
C18: Cr. Acct 0475 - ACCUMULATED AMORTIZATION - RIGHT-TO-USE SBITA
C19: Cr: Acct 0674 - RIGHT-TO-USE SBITA LIABILITY | K19: 41743
C20: Cr: Acct 0950 - BEGINNING FUND BALANCE
C21: Cr: Acct 0952 - BEG FB ADJ/PRIOR PERIOD ADJUSTMENT | K21: 4863
J22: =ROUND(SUM(J15:J17),2) -> 46606 | K22: =ROUND(SUM(K18:K21),2) -> 46606 | L22: =IF(J22=K22,"<- Debits and Credits equal each other.","<- Debits and Credits do not equal each other.") -> <- Debits and Credits equal each other.
B24: SBITA ASSET (Acct 0480) AMOUNT SHOULD BE REPORTED AS BEGINNING BALANCE ON REPORT 18.
A26: =IF($F$3="2022–2023","Record SBITAs Commenced on or after 07/02/2022","Record New SBITAs (new SBITAs only)") -> Record SBITAs Commenced on or after 07/02/2022
A27: 1 | B27: Record at inception of SBITA in accordance with Fund-Based accounting (Governmental Funds Only).
B28: Dr: Acct 0842 - CAPITAL OUTLAY
C29: Cr: Acct 0789 - LEASE AND OTHER FINANCING PROCEEDS
C30: =VLOOKUP($F$8,'Drop Down Menus'!$D$2:$G$10,4,FALSE) -> Cr: Acct 0825 - BUS, CONSUMER SERV, HOUSING
J31: =ROUND(SUM(J28:J30),2) -> 0 | K31: =ROUND(SUM(K28:K30),2) -> 0 | L31: =IF(J31=K31,"<- Debits and Credits equal each other.","<- Debits and Credits do not equal each other.") -> <- Debits and Credits equal each other.
A33: 2 | B33: Reverse the fund-based entry in #1 above, if any, and record an inception of SBITA in accordance with GAAP Govt Wide.
B34: Dr: Acct 0480 - RIGHT-TO-USE SBITA - AMORTIZABLE
B35: Dr: Acct 0789 - LEASE AND OTHER FINANCING PROCEEDS
C36: Cr: Acct 0842 - CAPITAL OUTLAY
C37: Cr: Acct 0674 - RIGHT-TO-USE SBITA LIABILITY
C38: =VLOOKUP($F$8,'Drop Down Menus'!$D$2:$G$10,4,FALSE) -> Cr: Acct 0825 - BUS, CONSUMER SERV, HOUSING
J39: =ROUND(SUM(J34:J35),2) -> 0 | K39: =ROUND(SUM(K36:K38),2) -> 0 | L39: =IF(J39=K39,"<- Debits and Credits equal each other.","<- Debits and Credits do not equal each other.") -> <- Debits and Credits equal each other.
B41: SBITA ASSET (Acct 0480) AMOUNT SHOULD BE INCLUDED AS "ADDITIONS" ON REPORT 18.
A43: Record Annual Activity (all SBITAs)
A44: 3 | B44: Record amortization of the SBITA asset for the year.
B45: Dr: Acct 0875 - DEPRECIATION/AMORTIZATION | J45: 13982
C46: Cr. Acct 0475 - ACCUMULATED AMORTIZATION - RIGHT-TO-USE SBITA | K46: =J45 -> 13982
J47: =ROUND(SUM(J45:J45),2) -> 13982 | K47: =ROUND(SUM(K46),2) -> 13982 | L47: =IF(J47=K47,"<- Debits and Credits equal each other.","<- Debits and Credits do not equal each other.") -> <- Debits and Credits equal each other.
A49: 4 | B49: Reclassify information technology subscription exp. to debt service principal and interest exp.
...

Sheet Fund 0775 Journal Entries
A1: GASB 96 - SBITA Contracts Fund-by-Fund Journal Entries Form (to be submitted to the SCO annually—one form per fund)
A2: Manually complete every yellow field in this worksheet—there are no automatically calculated data-entry cells in this worksheet.
A3: Fiscal year: | F3: 2022–2023
A4: Organization Name: | F4: Department of Consumer Affairs
A5: Organization Code (Business Unit): | F5: 1111
A6: Fund Number: | F6: 775
A7: Fund Type: | F7: Governmental Fund
A8: Fund Classification: | F8: =IF(OR($F$7='Drop Down Menus'!B2,$F$7='Drop Down Menus'!$B$3),'Drop Down Menus'!$D$9,IFERROR(VLOOKUP($F$5,GAAP02Aindex!$A$2:$D$900,4,FALSE),"Unidentified")) -> BUS, CONSUMER SERV, HOUSING
A12: =IF($F$3="2022–2023","Establish Beginning Balances (SBITAs commenced on or before 07/01/2022)","Establish Beginning Balances (existing SBITAs only)") -> Establish Beginning Balances (SBITAs commenced on or before 07/01/2022)
A13: Entry #
A14: 0 | B14: =IF($F$3="2022–2023","To establish the beginning balance of SBITAs as of 07/01/2022.","Roll forward prior year right-to-use SBITAs to record opening balances.") -> To establish the beginning balance of SBITAs as of 07/01/2022.
B15: Dr: Acct 0480 - RIGHT-TO-USE SBITA - AMORTIZABLE | J15: 151827
B16: Dr: Acct 0950 - BEGINNING FUND BALANCE
B17: Dr: Acct 0952 - BEG FB ADJ/PRIOR PERIOD ADJUSTMENT
C18: Cr. Acct 0475 - ACCUMULATED AMORTIZATION - RIGHT-TO-USE SBITA
C19: Cr: Acct 0674 - RIGHT-TO-USE SBITA LIABILITY | K19: 87041
C20: Cr: Acct 0950 - BEGINNING FUND BALANCE
C21: Cr: Acct 0952 - BEG FB ADJ/PRIOR PERIOD ADJUSTMENT | K21: 64786
J22: =ROUND(SUM(J15:J17),2) -> 151827 | K22: =ROUND(SUM(K18:K21),2) -> 151827 | L22: =IF(J22=K22,"<- Debits and Credits equal each other.","<- Debits and Credits do not equal each other.") -> <- Debits and Credits equal each other.
B24: SBITA ASSET (Acct 0480) AMOUNT SHOULD BE REPORTED AS BEGINNING BALANCE ON REPORT 18.
A26: =IF($F$3="2022–2023","Record SBITAs Commenced on or after 07/02/2022","Record New SBITAs (new SBITAs only)") -> Record SBITAs Commenced on or after 07/02/2022
A27: 1 | B27: Record at inception of SBITA in accordance with Fund-Based accounting (Governmental Funds Only).
B28: Dr: Acct 0842 - CAPITAL OUTLAY
C29: Cr: Acct 0789 - LEASE AND OTHER FINANCING PROCEEDS
C30: =VLOOKUP($F$8,'Drop Down Menus'!$D$2:$G$10,4,FALSE) -> Cr: Acct 0825 - BUS, CONSUMER SERV, HOUSING
J31: =ROUND(SUM(J28:J30),2) -> 0 | K31: =ROUND(SUM(K28:K30),2) -> 0 | L31: =IF(J31=K31,"<- Debits and Credits equal each other.","<- Debits and Credits do not equal each other.") -> <- Debits and Credits equal each other.
A33: 2 | B33: Reverse the fund-based entry in #1 above, if any, and record an inception of SBITA in accordance with GAAP Govt Wide.
B34: Dr: Acct 0480 - RIGHT-TO-USE SBITA - AMORTIZABLE
B35: Dr: Acct 0789 - LEASE AND OTHER FINANCING PROCEEDS
C36: Cr: Acct 0842 - CAPITAL OUTLAY
C37: Cr: Acct 0674 - RIGHT-TO-USE SBITA LIABILITY
C38: =VLOOKUP($F$8,'Drop Down Menus'!$D$2:$G$10,4,FALSE) -> Cr: Acct 0825 - BUS, CONSUMER SERV, HOUSING
J39: =ROUND(SUM(J34:J35),2) -> 0 | K39: =ROUND(SUM(K36:K38),2) -> 0 | L39: =IF(J39=K39,"<- Debits and Credits equal each other.","<- Debits and Credits do not equal each other.") -> <- Debits and Credits equal each other.
B41: SBITA ASSET (Acct 0480) AMOUNT SHOULD BE INCLUDED AS "ADDITIONS" ON REPORT 18.
A43: Record Annual Activity (all SBITAs)
A44: 3 | B44: Record amortization of the SBITA asset for the year.
B45: Dr: Acct 0875 - DEPRECIATION/AMORTIZATION | J45: 31412
C46: Cr. Acct 0475 - ACCUMULATED AMORTIZATION - RIGHT-TO-USE SBITA | K46: =J45 -> 31412
J47: =ROUND(SUM(J45:J45),2) -> 31412 | K47: =ROUND(SUM(K46),2) -> 31412 | L47: =IF(J47=K47,"<- Debits and Credits equal each other.","<- Debits and Credits do not equal each other.") -> <- Debits and Credits equal each other.
A49: 4 | B49: Reclassify information technology subscription exp. to debt service principal and interest exp.
...

Sheet Fund 3315 Journal Entries
A1: GASB 96 - SBITA Contracts Fund-by-Fund Journal Entries Form (to be submitted to the SCO annually—one form per fund)
A2: Manually complete every yellow field in this worksheet—there are no automatically calculated data-entry cells in this worksheet.
A3: Fiscal year: | F3: 2022–2023
A4: Organization Name: | F4: Department of Consumer Affairs
A5: Organization Code (Business Unit): | F5: 1111
A6: Fund Number: | F6: 3315
A7: Fund Type: | F7: Governmental Fund
A8: Fund Classification: | F8: =IF(OR($F$7='Drop Down Menus'!B2,$F$7='Drop Down Menus'!$B$3),'Drop Down Menus'!$D$9,IFERROR(VLOOKUP($F$5,GAAP02Aindex!$A$2:$D$900,4,FALSE),"Unidentified")) -> BUS, CONSUMER SERV, HOUSING
A12: =IF($F$3="2022–2023","Establish Beginning Balances (SBITAs commenced on or before 07/01/2022)","Establish Beginning Balances (existing SBITAs only)") -> Establish Beginning Balances (SBITAs commenced on or before 07/01/2022)
A13: Entry #
A14: 0 | B14: =IF($F$3="2022–2023","To establish the beginning balance of SBITAs as of 07/01/2022.","Roll forward prior year right-to-use SBITAs to record opening balances.") -> To establish the beginning balance of SBITAs as of 07/01/2022.
B15: Dr: Acct 0480 - RIGHT-TO-USE SBITA - AMORTIZABLE | J15: 91096
B16: Dr: Acct 0950 - BEGINNING FUND BALANCE
B17: Dr: Acct 0952 - BEG FB ADJ/PRIOR PERIOD ADJUSTMENT
C18: Cr. Acct 0475 - ACCUMULATED AMORTIZATION - RIGHT-TO-USE SBITA
C19: Cr: Acct 0674 - RIGHT-TO-USE SBITA LIABILITY | K19: 52224
C20: Cr: Acct 0950 - BEGINNING FUND BALANCE
C21: Cr: Acct 0952 - BEG FB ADJ/PRIOR PERIOD ADJUSTMENT | K21: 38872
J22: =ROUND(SUM(J15:J17),2) -> 91096 | K22: =ROUND(SUM(K18:K21),2) -> 91096 | L22: =IF(J22=K22,"<- Debits and Credits equal each other.","<- Debits and Credits do not equal each other.") -> <- Debits and Credits equal each other.
B24: SBITA ASSET (Acct 0480) AMOUNT SHOULD BE REPORTED AS BEGINNING BALANCE ON REPORT 18.
A26: =IF($F$3="2022–2023","Record SBITAs Commenced on or after 07/02/2022","Record New SBITAs (new SBITAs only)") -> Record SBITAs Commenced on or after 07/02/2022
A27: 1 | B27: Record at inception of SBITA in accordance with Fund-Based accounting (Governmental Funds Only).
B28: Dr: Acct 0842 - CAPITAL OUTLAY
C29: Cr: Acct 0789 - LEASE AND OTHER FINANCING PROCEEDS
C30: =VLOOKUP($F$8,'Drop Down Menus'!$D$2:$G$10,4,FALSE) -> Cr: Acct 0825 - BUS, CONSUMER SERV, HOUSING
J31: =ROUND(SUM(J28:J30),2) -> 0 | K31: =ROUND(SUM(K28:K30),2) -> 0 | L31: =IF(J31=K31,"<- Debits and Credits equal each other.","<- Debits and Credits do not equal each other.") -> <- Debits and Credits equal each other.
A33: 2 | B33: Reverse the fund-based entry in #1 above, if any, and record an inception of SBITA in accordance with GAAP Govt Wide.
B34: Dr: Acct 0480 - RIGHT-TO-USE SBITA - AMORTIZABLE
B35: Dr: Acct 0789 - LEASE AND OTHER FINANCING PROCEEDS
C36: Cr: Acct 0842 - CAPITAL OUTLAY
C37: Cr: Acct 0674 - RIGHT-TO-USE SBITA LIABILITY
C38: =VLOOKUP($F$8,'Drop Down Menus'!$D$2:$G$10,4,FALSE) -> Cr: Acct 0825 - BUS, CONSUMER SERV, HOUSING
J39: =ROUND(SUM(J34:J35),2) -> 0 | K39: =ROUND(SUM(K36:K38),2) -> 0 | L39: =IF(J39=K39,"<- Debits and Credits equal each other.","<- Debits and Credits do not equal each other.") -> <- Debits and Credits equal each other.
B41: SBITA ASSET (Acct 0480) AMOUNT SHOULD BE INCLUDED AS "ADDITIONS" ON REPORT 18.
A43: Record Annual Activity (all SBITAs)
A44: 3 | B44: Record amortization of the SBITA asset for the year.
B45: Dr: Acct 0875 - DEPRECIATION/AMORTIZATION | J45: 18847
C46: Cr. Acct 0475 - ACCUMULATED AMORTIZATION - RIGHT-TO-USE SBITA | K46: =J45 -> 18847
J47: =ROUND(SUM(J45:J45),2) -> 18847 | K47: =ROUND(SUM(K46),2) -> 18847 | L47: =IF(J47=K47,"<- Debits and Credits equal each other.","<- Debits and Credits do not equal each other.") -> <- Debits and Credits equal each other.
A49: 4 | B49: Reclassify information technology subscription exp. to debt service principal and interest exp.
...

Sheet Department Note Disclosure
A1: GASB 96 - SBITA Note Disclosure Form ( Submit one form for the department to the SCO annually)
A3: Note: There are three tables of note disclosures on this form —1) governmental funds, 2) proprietary - internal service funds, and 3) proprietary - enterprise funds. Complete all applicable tables before submitting to the SCO.
A4: Manually complete every yellow field in this worksheet—there are no automatically calculated cells in this worksheet.
A5: Complete the fields below using aggregated and summarized information from all of your department's completed contract template forms.
A7: The fields in this worksheet should contain the sums of the department's contracts' corresponding information in their note disclosure worksheets.
A10: I. Governmental Funds
A11: Fiscal Year: | B11: 2022–2023
A12: Org Code/Business Unit: | B12: 1111
A13: Reporting Department Name: | B13: Department of Consumer Affairs
A14: The below information must be entered manually.
B15: Principal Payments | C15: Interest Payments | D15: ="All of the below questions are for Fiscal Year "&$B$11&":" -> All of the below questions are for Fiscal Year 2022–2023:
A16: =RIGHT(B11,4)&"–"&RIGHT(B11,4)+1 -> 2023–2024 | B16: 394571 | C16: 9605 | D16: 1. Did your SBITAs have any variable payments which ARE NOT included in the measurement of the subscription liability?
A17: =LEFT(A16,4)+1&"–"&RIGHT(A16,4)+1 -> 2024–2025 | B17: 317508 | C17: 2164
A18: =LEFT(A17,4)+1&"–"&RIGHT(A17,4)+1 -> 2025–2026 | B18: 92326 | C18: 0 | D18: No
A19: =LEFT(A18,4)+1&"–"&RIGHT(A18,4)+1 -> 2026–2027 | D19: ="If yes, record the dollar amount of variable payments below for fiscal year "&$B$11&":" -> If yes, record the dollar amount of variable payments below for fiscal year 2022–2023:
A20: =LEFT(A19,4)+1&"–"&RIGHT(A19,4)+1 -> 2027–2028 | D20: 0
A21: =LEFT(A20,4)+1&"–"&RIGHT(A20,4)+5 -> 2028–2033 | D21: ="2. Record the dollar amount of any other payments for your SBITAs, such as termination penalties, not previously recorded in the payment schedule for fiscal year "&$B$11&":" -> 2. Record the dollar amount of any other payments for your SBITAs, such as termination penalties, not previously recorded in the payment schedule for fiscal year 2022–2023:
A22: =LEFT(A21,4)+5&"–"&RIGHT(A21,4)+5 -> 2033–2038
A23: =LEFT(A22,4)+5&"–"&RIGHT(A22,4)+5 -> 2038–2043 | D23: N/A
A24: =LEFT(A23,4)+5&"–"&RIGHT(A23,4)+5 -> 2043–2048 | D24: ="3. Did you receive any SBITA incentives from the SBITA vendor (not already included in the SBITA measurement) during fiscal year "&$B$11&"? If so, record the amount below:" -> 3. Did you receive any SBITA incentives from the SBITA vendor (not already included in the SBITA measurement) during fiscal year 2022–2023? If so, record the amount below:
A25: =LEFT(A24,4)+5&"–"&RIGHT(A24,4)+5 -> 2048–2053
A26: =LEFT(A25,4)+5&"–"&RIGHT(A25,4)+5 -> 2053–2058 | D26: No
A27: =LEFT(A26,4)+5&"–"&RIGHT(A26,4)+5 -> 2058–2063 | D27: ="4. Are there any SBITA commitments known that have yet to commence as of June 30, "&RIGHT($B$11,4)&"?" -> 4. Are there any SBITA commitments known that have yet to commence as of June 30, 2023?
A28: =LEFT(A27,4)+5&"–"&RIGHT(A27,4)+5 -> 2063–2068
A29: =LEFT(A28,4)+5&"–"&RIGHT(A28,4)+5 -> 2068–2073 | D29: No
A30: =LEFT(A29,4)+5&"–"&RIGHT(A29,4)+5 -> 2073–2078 | D30: ="If yes, record the dollar amount of any SBITA commitments not commenced below for fiscal year "&$A$16&":" -> If yes, record the dollar amount of any SBITA commitments not commenced below for fiscal year 2023–2024:
A31: =LEFT(A30,4)+5&"–"&RIGHT(A30,4)+5 -> 2078–2083
A32: =LEFT(A31,4)+5&"–"&RIGHT(A31,4)+5 -> 2083–2088 | D32: 0
A33: =LEFT(A32,4)+5&"–"&RIGHT(A32,4)+5 -> 2088–2093
A34: =LEFT(A33,4)+5&"–"&RIGHT(A33,4)+5 -> 2093–2098
A35: =LEFT(A34,4)+5&"–"&RIGHT(A34,4)+5 -> 2098–2103
A36: =LEFT(A35,4)+5&"–"&RIGHT(A35,4)+5 -> 2103–2108
A37: =LEFT(A36,4)+5&"–"&RIGHT(A36,4)+5 -> 2108–2113
A38: =LEFT(A37,4)+5&"–"&RIGHT(A37,4)+5 -> 2113–2118
A39: =LEFT(A38,4)+5&"–"&RIGHT(A38,4)+5 -> 2118–2123
A41: II. Proprietary - Internal Service Funds
A42: Fiscal Year: | B42: =B11 -> 2022–2023
A43: Org Code/Business Unit: | B43: =B12 -> 1111
A44: Reporting Department Name: | B44: =B13 -> Department of Consumer Affairs
A45: The below information must be entered manually.
...

Sheet SBITA Liabilities
G3: Schedule of Changes in SBITA Liabilities
G4: ="FY "&'Department Note Disclosure'!$B$11 -> FY 2022–2023
G5: ="Business Unit " &'Fund 0717 Journal Entries'!$F$5&" "&'Fund 0717 Journal Entries'!$F$4 -> Business Unit 1111 Department of Consumer Affairs
C7: Source: Tab "Fund #### Journal Entries" | F7: ENTRY #0 | H7: ENTRY #2 | J7: ENTRY #5 | N7: ENTRY #6
F8: ="Balance July 1, "&LEFT('Fund 0717 Journal Entries'!$F$3,4) -> Balance July 1, 2022 | H8: Additions | J8: Deductions | L8: ="Balance June 30, "&RIGHT('Fund 0717 Journal Entries'!$F$3,4) -> Balance June 30, 2023 | N8: Due Within One Year | P8: Noncurrent Liabilities
C9: Governmental Funds
D10: SBITA Liability | F10: =+'Fund 0108 Journal Entries'!K19+'Fund 0152 Journal Entries'!K19+'Fund 0305 Journal Entries'!K19+'Fund 0325 Journal Entries'!K19+'Fund 0492 Journal Entries'!K19+'Fund 0702 Journal Entries'!K19+'Fund 0706 Journal Entries'!K19+'Fund 0717 Journal Entries'!K19+'Fund 0752 Journal Entries'!K19+'Fund 0757 Journal Entries'!K19+'Fund 0770 Journal Entries'!K19+'Fund 0775 Journal Entries'!K19+'Fund 3315 Journal Entries'!K19 -> 1101536 | H10: =+'Fund 0108 Journal Entries'!K37+'Fund 0152 Journal Entries'!K37+'Fund 0305 Journal Entries'!K37+'Fund 0325 Journal Entries'!K37+'Fund 0492 Journal Entries'!K37+'Fund 0702 Journal Entries'!K37+'Fund 0706 Journal Entries'!K37+'Fund 0717 Journal Entries'!K37+'Fund 0752 Journal Entries'!K37+'Fund 0757 Journal Entries'!K37+'Fund 0770 Journal Entries'!K37+'Fund 0775 Journal Entries'!K37+'Fund 3315 Journal Entries'!K37-'Fund 0702 Journal Entries'!J56 -> 2861 | J10: =+'Fund 0108 Journal Entries'!J56+'Fund 0152 Journal Entries'!J56+'Fund 0305 Journal Entries'!J56+'Fund 0325 Journal Entries'!J56+'Fund 0492 Journal Entries'!J56+'Fund 0706 Journal Entries'!J56+'Fund 0717 Journal Entries'!J56+'Fund 0752 Journal Entries'!J56+'Fund 0757 Journal Entries'!J56+'Fund 0770 Journal Entries'!J56+'Fund 0775 Journal Entries'!J56+'Fund 3315 Journal Entries'!J56 -> 299992 | L10: =SUM(F10+H10-J10) -> 804405 | N10: =+'Fund 0108 Journal Entries'!J61+'Fund 0152 Journal Entries'!J61+'Fund 0305 Journal Entries'!J61+'Fund 0325 Journal Entries'!J61+'Fund 0492 Journal Entries'!J61+'Fund 0702 Journal Entries'!J61+'Fund 0706 Journal Entries'!J61+'Fund 0717 Journal Entries'!J61+'Fund 0752 Journal Entries'!J61+'Fund 0757 Journal Entries'!J61+'Fund 0770 Journal Entries'!J61+'Fund 0775 Journal Entries'!J61+'Fund 3315 Journal Entries'!J61 -> 394571 | P10: =L10-N10 -> 409834
C11: Total Governmental Funds | F11: =SUM(F10:F10) -> 1101536 | H11: =SUM(H10:H10) -> 2861 | J11: =SUM(J10:J10) -> 299992 | L11: =SUM(L10:L10) -> 804405 | N11: =SUM(N10:N10) -> 394571 | P11: =SUM(P10:P10) -> 409834
