Workbook
Name ActuaryCredentialsGASB: #REF!
Name ActuaryNameGASB: #REF!
Name ActuaryTitleGASB: #REF!
Name AdjCNSDate: #REF!
Name AdjCNSDate1: #REF!
Name AdjCNSDateTempEnable: #REF!
Name AgencyCode: #REF!
Name AgencyCode1: #REF!
Name AnalystGASB: #REF!
Name Annuity: #REF!
Name Annuity1: #REF!
Name AnnuityLY: #REF!
Name ASTABPF: #REF!
Name ASTABPF1: #REF!
Name ASTEBPF: #REF!
Name ClientShortGASB: #REF!
Name CLPOWERDisc: #REF!
Name CLPOWERDiscMinus1: #REF!
Name CLPOWERDiscPlus1: #REF!
Name CLPOWERExp: #REF!
Name CNSDateDisc: #REF!
Name CNSDateDisc1: #REF!
Name ColaRate: #REF!
Name ConsultantNameGASB: #REF!
Name ConsultantTitleGASB: #REF!
Name Disc1DELTACENSUS: #REF!
Name Disc1INTNDIV12: #REF!
Name Disc1SINTADJBOM: #REF!
Name Disc1SINTNDIV12: #REF!
Name DiscDELTACENSUS: #REF!
Name DiscINTADJBOM: #REF!
Name DiscINTNDIV12: #REF!
Name DiscMinusOneINTADJBOM: #REF!
Name DiscMinusOneINTNDIV12: #REF!
Name DiscPlusOneINTADJBOM: #REF!
Name DiscPlusOneINTNDIV12: #REF!
Name EmployerRates: #REF!
Name EmployerRates1: #REF!
Name EmployerRatesLEO: #REF!
Name EmployerRatesLEO1: #REF!
Name ERData: #REF!
Name ERID: #REF!
Name ERInfo: #REF!
Name Exp1INTADJBOM: #REF!
Name Exp1INTNDIV12: #REF!
Name FracYearProj: #REF!
Name FundOfficeContactGASB: #REF!
Name FYrsGASB: #REF!
Name GainLoss: #REF!
Name GASBDiscMinusOneINTADJBOM: #REF!
Name GASBDiscMinusOneINTNDIV12: #REF!
Name InflRate: #REF!
Name InflRate1: #REF!
Name IntDisc: #REF!
Name IntDisc1: #REF!
Name IntDisc1S: #REF!
Name INTDiscMinusOne: #REF!
Name INTDiscPlusOne: #REF!
Name IntExp1: #REF!
Name MeasureDate: #REF!

Sheet Fund 0041 Journal Entries
A1: GASB 96 - SBITA Contracts Fund-by-Fund Journal Entries Form (to be submitted to the SCO annually—one form per fund)
A2: Manually complete every yellow field in this worksheet—there are no automatically calculated data-entry cells in this worksheet.
A3: Fiscal year: | F3: 2022–2023
A4: Organization Name: | F4: Department of Transportation
A5: Organization Code (Business Unit): | F5: 2660
A6: Fund Number: | F6: 41
A7: Fund Type: | F7: Governmental Fund
A8: Fund Classification: | F8: =IF(OR($F$7='Drop Down Menus'!B2,$F$7='Drop Down Menus'!$B$3),'Drop Down Menus'!$D$9,IFERROR(VLOOKUP($F$5,GAAP02Aindex!$A$2:$D$900,4,FALSE),"Unidentified")) -> TRANSPORTATION
A12: =IF($F$3="2022–2023","Establish Beginning Balances (SBITAs commenced on or before 07/01/2022)","Establish Beginning Balances (existing SBITAs only)") -> Establish Beginning Balances (SBITAs commenced on or before 07/01/2022)
A13: Entry #
A14: 0 | B14: =IF($F$3="2022–2023","To establish the beginning balance of SBITAs as of 07/01/2022.","Roll forward prior year right-to-use SBITAs to record opening balances.") -> To establish the beginning balance of SBITAs as of 07/01/2022.
B15: Dr: Acct 0480 - RIGHT-TO-USE SBITA - AMORTIZABLE | J15: 1031
B16: Dr: Acct 0950 - BEGINNING FUND BALANCE
B17: Dr: Acct 0952 - BEG FB ADJ/PRIOR PERIOD ADJUSTMENT | J17: 0
C18: Cr. Acct 0475 - ACCUMULATED AMORTIZATION - RIGHT-TO-USE SBITA
C19: Cr: Acct 0674 - RIGHT-TO-USE SBITA LIABILITY | K19: 805
C20: Cr: Acct 0950 - BEGINNING FUND BALANCE
C21: Cr: Acct 0952 - BEG FB ADJ/PRIOR PERIOD ADJUSTMENT | K21: 226
J22: =ROUND(SUM(J15:J17),2) -> 1031 | K22: =ROUND(SUM(K18:K21),2) -> 1031 | L22: =IF(J22=K22,"<- Debits and Credits equal each other.","<- Debits and Credits do not equal each other.") -> <- Debits and Credits equal each other.
B24: SBITA ASSET (Acct 0480) AMOUNT SHOULD BE REPORTED AS BEGINNING BALANCE ON REPORT 18.
A26: =IF($F$3="2022–2023","Record SBITAs Commenced on or after 07/02/2022","Record New SBITAs (new SBITAs only)") -> Record SBITAs Commenced on or after 07/02/2022
A27: 1 | B27: Record at inception of SBITA in accordance with Fund-Based accounting (Governmental Funds Only).
B28: Dr: Acct 0842 - CAPITAL OUTLAY | J28: 1886
C29: Cr: Acct 0789 - LEASE AND OTHER FINANCING PROCEEDS | K29: 1886
C30: =VLOOKUP($F$8,'Drop Down Menus'!$D$2:$G$10,4,FALSE) -> Cr: Acct 0830 - TRANSPORTATION (GAAP ADJ) | K30: 0
J31: =ROUND(SUM(J28:J30),2) -> 1886 | K31: =ROUND(SUM(K28:K30),2) -> 1886 | L31: =IF(J31=K31,"<- Debits and Credits equal each other.","<- Debits and Credits do not equal each other.") -> <- Debits and Credits equal each other.
A33: 2 | B33: Reverse the fund-based entry in #1 above, if any, and record an inception of SBITA in accordance with GAAP Govt Wide.
B34: Dr: Acct 0480 - RIGHT-TO-USE SBITA - AMORTIZABLE | J34: 1886
B35: Dr: Acct 0789 - LEASE AND OTHER FINANCING PROCEEDS | J35: 1886
C36: Cr: Acct 0842 - CAPITAL OUTLAY | K36: 1886
C37: Cr: Acct 0674 - RIGHT-TO-USE SBITA LIABILITY | K37: 1886
C38: =VLOOKUP($F$8,'Drop Down Menus'!$D$2:$G$10,4,FALSE) -> Cr: Acct 0830 - TRANSPORTATION (GAAP ADJ) | K38: 0
J39: =ROUND(SUM(J34:J35),2) -> 3772 | K39: =ROUND(SUM(K36:K38),2) -> 3772 | L39: =IF(J39=K39,"<- Debits and Credits equal each other.","<- Debits and Credits do not equal each other.") -> <- Debits and Credits equal each other.
B41: SBITA ASSET (Acct 0480) AMOUNT SHOULD BE INCLUDED AS "ADDITIONS" ON REPORT 18.
A43: Record Annual Activity (all SBITAs)
A44: 3 | B44: Record amortization of the SBITA asset for the year.
B45: Dr: Acct 0875 - DEPRECIATION/AMORTIZATION | J45: 1216
C46: Cr. Acct 0475 - ACCUMULATED AMORTIZATION - RIGHT-TO-USE SBITA | K46: =J45 -> 1216
J47: =ROUND(SUM(J45:J45),2) -> 1216 | K47: =ROUND(SUM(K46),2) -> 1216 | L47: =IF(J47=K47,"<- Debits and Credits equal each other.","<- Debits and Credits do not equal each other.") -> <- Debits and Credits equal each other.
A49: 4 | B49: Reclassify information technology subscription exp. to debt service principal and interest exp.
...

Sheet Fund 0042 Journal Entries
A1: GASB 96 - SBITA Contracts Fund-by-Fund Journal Entries Form (to be submitted to the SCO annually—one form per fund)
A2: Manually complete every yellow field in this worksheet—there are no automatically calculated data-entry cells in this worksheet.
A3: Fiscal year: | F3: 2022–2023
A4: Organization Name: | F4: Department of Transportation
A5: Organization Code (Business Unit): | F5: 2660
A6: Fund Number: | F6: 42
A7: Fund Type: | F7: Governmental Fund
A8: Fund Classification: | F8: =IF(OR($F$7='Drop Down Menus'!B2,$F$7='Drop Down Menus'!$B$3),'Drop Down Menus'!$D$9,IFERROR(VLOOKUP($F$5,GAAP02Aindex!$A$2:$D$900,4,FALSE),"Unidentified")) -> TRANSPORTATION
A12: =IF($F$3="2022–2023","Establish Beginning Balances (SBITAs commenced on or before 07/01/2022)","Establish Beginning Balances (existing SBITAs only)") -> Establish Beginning Balances (SBITAs commenced on or before 07/01/2022)
A13: Entry #
A14: 0 | B14: =IF($F$3="2022–2023","To establish the beginning balance of SBITAs as of 07/01/2022.","Roll forward prior year right-to-use SBITAs to record opening balances.") -> To establish the beginning balance of SBITAs as of 07/01/2022.
B15: Dr: Acct 0480 - RIGHT-TO-USE SBITA - AMORTIZABLE | J15: 3929037
B16: Dr: Acct 0950 - BEGINNING FUND BALANCE
B17: Dr: Acct 0952 - BEG FB ADJ/PRIOR PERIOD ADJUSTMENT
C18: Cr. Acct 0475 - ACCUMULATED AMORTIZATION - RIGHT-TO-USE SBITA
C19: Cr: Acct 0674 - RIGHT-TO-USE SBITA LIABILITY | K19: 2804063
C20: Cr: Acct 0950 - BEGINNING FUND BALANCE
C21: Cr: Acct 0952 - BEG FB ADJ/PRIOR PERIOD ADJUSTMENT | K21: 1124974
J22: =ROUND(SUM(J15:J17),2) -> 3929037 | K22: =ROUND(SUM(K18:K21),2) -> 3929037 | L22: =IF(J22=K22,"<- Debits and Credits equal each other.","<- Debits and Credits do not equal each other.") -> <- Debits and Credits equal each other.
B24: SBITA ASSET (Acct 0480) AMOUNT SHOULD BE REPORTED AS BEGINNING BALANCE ON REPORT 18.
A26: =IF($F$3="2022–2023","Record SBITAs Commenced on or after 07/02/2022","Record New SBITAs (new SBITAs only)") -> Record SBITAs Commenced on or after 07/02/2022
A27: 1 | B27: Record at inception of SBITA in accordance with Fund-Based accounting (Governmental Funds Only).
B28: Dr: Acct 0842 - CAPITAL OUTLAY | J28: 4550490
C29: Cr: Acct 0789 - LEASE AND OTHER FINANCING PROCEEDS | K29: 4550490
C30: =VLOOKUP($F$8,'Drop Down Menus'!$D$2:$G$10,4,FALSE) -> Cr: Acct 0830 - TRANSPORTATION (GAAP ADJ) | K30: 0
J31: =ROUND(SUM(J28:J30),2) -> 4550490 | K31: =ROUND(SUM(K28:K30),2) -> 4550490 | L31: =IF(J31=K31,"<- Debits and Credits equal each other.","<- Debits and Credits do not equal each other.") -> <- Debits and Credits equal each other.
A33: 2 | B33: Reverse the fund-based entry in #1 above, if any, and record an inception of SBITA in accordance with GAAP Govt Wide.
B34: Dr: Acct 0480 - RIGHT-TO-USE SBITA - AMORTIZABLE | J34: 4550490
B35: Dr: Acct 0789 - LEASE AND OTHER FINANCING PROCEEDS | J35: 4550490
C36: Cr: Acct 0842 - CAPITAL OUTLAY | K36: 4550490
C37: Cr: Acct 0674 - RIGHT-TO-USE SBITA LIABILITY | K37: 4550490
C38: =VLOOKUP($F$8,'Drop Down Menus'!$D$2:$G$10,4,FALSE) -> Cr: Acct 0830 - TRANSPORTATION (GAAP ADJ) | K38: 0
J39: =ROUND(SUM(J34:J35),2) -> 9100980 | K39: =ROUND(SUM(K36:K38),2) -> 9100980 | L39: =IF(J39=K39,"<- Debits and Credits equal each other.","<- Debits and Credits do not equal each other.") -> <- Debits and Credits equal each other.
B41: SBITA ASSET (Acct 0480) AMOUNT SHOULD BE INCLUDED AS "ADDITIONS" ON REPORT 18.
A43: Record Annual Activity (all SBITAs)
A44: 3 | B44: Record amortization of the SBITA asset for the year.
B45: Dr: Acct 0875 - DEPRECIATION/AMORTIZATION | J45: 2706008
C46: Cr. Acct 0475 - ACCUMULATED AMORTIZATION - RIGHT-TO-USE SBITA | K46: =J45 -> 2706008
J47: =ROUND(SUM(J45:J45),2) -> 2706008 | K47: =ROUND(SUM(K46),2) -> 2706008 | L47: =IF(J47=K47,"<- Debits and Credits equal each other.","<- Debits and Credits do not equal each other.") -> <- Debits and Credits equal each other.
A49: 4 | B49: Reclassify information technology subscription exp. to debt service principal and interest exp.
...

Sheet Fund 0046 Journal Entries
A1: GASB 96 - SBITA Contracts Fund-by-Fund Journal Entries Form (to be submitted to the SCO annually—one form per fund)
A2: Manually complete every yellow field in this worksheet—there are no automatically calculated data-entry cells in this worksheet.
A3: Fiscal year: | F3: 2022–2023
A4: Organization Name: | F4: Department of Transportation
A5: Organization Code (Business Unit): | F5: 2660
A6: Fund Number: | F6: 46
A7: Fund Type: | F7: Governmental Fund
A8: Fund Classification: | F8: =IF(OR($F$7='Drop Down Menus'!B2,$F$7='Drop Down Menus'!$B$3),'Drop Down Menus'!$D$9,IFERROR(VLOOKUP($F$5,GAAP02Aindex!$A$2:$D$900,4,FALSE),"Unidentified")) -> TRANSPORTATION
A12: =IF($F$3="2022–2023","Establish Beginning Balances (SBITAs commenced on or before 07/01/2022)","Establish Beginning Balances (existing SBITAs only)") -> Establish Beginning Balances (SBITAs commenced on or before 07/01/2022)
A13: Entry #
A14: 0 | B14: =IF($F$3="2022–2023","To establish the beginning balance of SBITAs as of 07/01/2022.","Roll forward prior year right-to-use SBITAs to record opening balances.") -> To establish the beginning balance of SBITAs as of 07/01/2022.
B15: Dr: Acct 0480 - RIGHT-TO-USE SBITA - AMORTIZABLE | J15: 45733
B16: Dr: Acct 0950 - BEGINNING FUND BALANCE
B17: Dr: Acct 0952 - BEG FB ADJ/PRIOR PERIOD ADJUSTMENT | J17: 0
C18: Cr. Acct 0475 - ACCUMULATED AMORTIZATION - RIGHT-TO-USE SBITA
C19: Cr: Acct 0674 - RIGHT-TO-USE SBITA LIABILITY | K19: 36091
C20: Cr: Acct 0950 - BEGINNING FUND BALANCE
C21: Cr: Acct 0952 - BEG FB ADJ/PRIOR PERIOD ADJUSTMENT | K21: 9642
J22: =ROUND(SUM(J15:J17),2) -> 45733 | K22: =ROUND(SUM(K18:K21),2) -> 45733 | L22: =IF(J22=K22,"<- Debits and Credits equal each other.","<- Debits and Credits do not equal each other.") -> <- Debits and Credits equal each other.
B24: SBITA ASSET (Acct 0480) AMOUNT SHOULD BE REPORTED AS BEGINNING BALANCE ON REPORT 18.
A26: =IF($F$3="2022–2023","Record SBITAs Commenced on or after 07/02/2022","Record New SBITAs (new SBITAs only)") -> Record SBITAs Commenced on or after 07/02/2022
A27: 1 | B27: Record at inception of SBITA in accordance with Fund-Based accounting (Governmental Funds Only).
B28: Dr: Acct 0842 - CAPITAL OUTLAY | J28: 89658
C29: Cr: Acct 0789 - LEASE AND OTHER FINANCING PROCEEDS | K29: 89658
C30: =VLOOKUP($F$8,'Drop Down Menus'!$D$2:$G$10,4,FALSE) -> Cr: Acct 0830 - TRANSPORTATION (GAAP ADJ) | K30: 0
J31: =ROUND(SUM(J28:J30),2) -> 89658 | K31: =ROUND(SUM(K28:K30),2) -> 89658 | L31: =IF(J31=K31,"<- Debits and Credits equal each other.","<- Debits and Credits do not equal each other.") -> <- Debits and Credits equal each other.
A33: 2 | B33: Reverse the fund-based entry in #1 above, if any, and record an inception of SBITA in accordance with GAAP Govt Wide.
B34: Dr: Acct 0480 - RIGHT-TO-USE SBITA - AMORTIZABLE | J34: 89658
B35: Dr: Acct 0789 - LEASE AND OTHER FINANCING PROCEEDS | J35: 89658
C36: Cr: Acct 0842 - CAPITAL OUTLAY | K36: 89658
C37: Cr: Acct 0674 - RIGHT-TO-USE SBITA LIABILITY | K37: 89658
C38: =VLOOKUP($F$8,'Drop Down Menus'!$D$2:$G$10,4,FALSE) -> Cr: Acct 0830 - TRANSPORTATION (GAAP ADJ) | K38: 0
J39: =ROUND(SUM(J34:J35),2) -> 179316 | K39: =ROUND(SUM(K36:K38),2) -> 179316 | L39: =IF(J39=K39,"<- Debits and Credits equal each other.","<- Debits and Credits do not equal each other.") -> <- Debits and Credits equal each other.
B41: SBITA ASSET (Acct 0480) AMOUNT SHOULD BE INCLUDED AS "ADDITIONS" ON REPORT 18.
A43: Record Annual Activity (all SBITAs)
A44: 3 | B44: Record amortization of the SBITA asset for the year.
B45: Dr: Acct 0875 - DEPRECIATION/AMORTIZATION | J45: 55597
C46: Cr. Acct 0475 - ACCUMULATED AMORTIZATION - RIGHT-TO-USE SBITA | K46: =J45 -> 55597
J47: =ROUND(SUM(J45:J45),2) -> 55597 | K47: =ROUND(SUM(K46),2) -> 55597 | L47: =IF(J47=K47,"<- Debits and Credits equal each other.","<- Debits and Credits do not equal each other.") -> <- Debits and Credits equal each other.
A49: 4 | B49: Reclassify information technology subscription exp. to debt service principal and interest exp.
...

Sheet Fund 3290 Journal Entries
A1: GASB 96 - SBITA Contracts Fund-by-Fund Journal Entries Form (to be submitted to the SCO annually—one form per fund)
A2: Manually complete every yellow field in this worksheet—there are no automatically calculated data-entry cells in this worksheet.
A3: Fiscal year: | F3: 2022–2023
A4: Organization Name: | F4: Department of Transportation
A5: Organization Code (Business Unit): | F5: 2660
A6: Fund Number: | F6: 3290
A7: Fund Type: | F7: Governmental Fund
A8: Fund Classification: | F8: =IF(OR($F$7='Drop Down Menus'!B2,$F$7='Drop Down Menus'!$B$3),'Drop Down Menus'!$D$9,IFERROR(VLOOKUP($F$5,GAAP02Aindex!$A$2:$D$900,4,FALSE),"Unidentified")) -> TRANSPORTATION
A12: =IF($F$3="2022–2023","Establish Beginning Balances (SBITAs commenced on or before 07/01/2022)","Establish Beginning Balances (existing SBITAs only)") -> Establish Beginning Balances (SBITAs commenced on or before 07/01/2022)
A13: Entry #
A14: 0 | B14: =IF($F$3="2022–2023","To establish the beginning balance of SBITAs as of 07/01/2022.","Roll forward prior year right-to-use SBITAs to record opening balances.") -> To establish the beginning balance of SBITAs as of 07/01/2022.
B15: Dr: Acct 0480 - RIGHT-TO-USE SBITA - AMORTIZABLE | J15: 14113
B16: Dr: Acct 0950 - BEGINNING FUND BALANCE
B17: Dr: Acct 0952 - BEG FB ADJ/PRIOR PERIOD ADJUSTMENT | J17: 0
C18: Cr. Acct 0475 - ACCUMULATED AMORTIZATION - RIGHT-TO-USE SBITA
C19: Cr: Acct 0674 - RIGHT-TO-USE SBITA LIABILITY | K19: 11129
C20: Cr: Acct 0950 - BEGINNING FUND BALANCE
C21: Cr: Acct 0952 - BEG FB ADJ/PRIOR PERIOD ADJUSTMENT | K21: 2984
J22: =ROUND(SUM(J15:J17),2) -> 14113 | K22: =ROUND(SUM(K18:K21),2) -> 14113 | L22: =IF(J22=K22,"<- Debits and Credits equal each other.","<- Debits and Credits do not equal each other.") -> <- Debits and Credits equal each other.
B24: SBITA ASSET (Acct 0480) AMOUNT SHOULD BE REPORTED AS BEGINNING BALANCE ON REPORT 18.
A26: =IF($F$3="2022–2023","Record SBITAs Commenced on or after 07/02/2022","Record New SBITAs (new SBITAs only)") -> Record SBITAs Commenced on or after 07/02/2022
A27: 1 | B27: Record at inception of SBITA in accordance with Fund-Based accounting (Governmental Funds Only).
B28: Dr: Acct 0842 - CAPITAL OUTLAY | J28: 27600
C29: Cr: Acct 0789 - LEASE AND OTHER FINANCING PROCEEDS | K29: 27600
C30: =VLOOKUP($F$8,'Drop Down Menus'!$D$2:$G$10,4,FALSE) -> Cr: Acct 0830 - TRANSPORTATION (GAAP ADJ) | K30: 0
J31: =ROUND(SUM(J28:J30),2) -> 27600 | K31: =ROUND(SUM(K28:K30),2) -> 27600 | L31: =IF(J31=K31,"<- Debits and Credits equal each other.","<- Debits and Credits do not equal each other.") -> <- Debits and Credits equal each other.
A33: 2 | B33: Reverse the fund-based entry in #1 above, if any, and record an inception of SBITA in accordance with GAAP Govt Wide.
B34: Dr: Acct 0480 - RIGHT-TO-USE SBITA - AMORTIZABLE | J34: 27600
B35: Dr: Acct 0789 - LEASE AND OTHER FINANCING PROCEEDS | J35: 27600
C36: Cr: Acct 0842 - CAPITAL OUTLAY | K36: 27600
C37: Cr: Acct 0674 - RIGHT-TO-USE SBITA LIABILITY | K37: 27600
C38: =VLOOKUP($F$8,'Drop Down Menus'!$D$2:$G$10,4,FALSE) -> Cr: Acct 0830 - TRANSPORTATION (GAAP ADJ) | K38: 0
J39: =ROUND(SUM(J34:J35),2) -> 55200 | K39: =ROUND(SUM(K36:K38),2) -> 55200 | L39: =IF(J39=K39,"<- Debits and Credits equal each other.","<- Debits and Credits do not equal each other.") -> <- Debits and Credits equal each other.
B41: SBITA ASSET (Acct 0480) AMOUNT SHOULD BE INCLUDED AS "ADDITIONS" ON REPORT 18.
A43: Record Annual Activity (all SBITAs)
A44: 3 | B44: Record amortization of the SBITA asset for the year.
B45: Dr: Acct 0875 - DEPRECIATION/AMORTIZATION | J45: 17134
C46: Cr. Acct 0475 - ACCUMULATED AMORTIZATION - RIGHT-TO-USE SBITA | K46: =J45 -> 17134
J47: =ROUND(SUM(J45:J45),2) -> 17134 | K47: =ROUND(SUM(K46),2) -> 17134 | L47: =IF(J47=K47,"<- Debits and Credits equal each other.","<- Debits and Credits do not equal each other.") -> <- Debits and Credits equal each other.
A49: 4 | B49: Reclassify information technology subscription exp. to debt service principal and interest exp.
...

Sheet Department Note Disclosure
A1: GASB 96 - SBITA Note Disclosure Form ( Submit one form for the department to the SCO annually)
A3: Note: There are three tables of note disclosures on this form —1) governmental funds, 2) proprietary - internal service funds, and 3) proprietary - enterprise funds. Complete all applicable tables before submitting to the SCO.
A4: Manually complete every yellow field in this worksheet—there are no automatically calculated cells in this worksheet.
A5: Complete the fields below using aggregated and summarized information from all of your department's completed contract template forms.
A7: The fields in this worksheet should contain the sums of the department's contracts' corresponding information in their note disclosure worksheets.
A10: I. Governmental Funds
A11: Fiscal Year: | B11: 2022–2023
A12: Org Code/Business Unit: | B12: 2660
A13: Reporting Department Name: | B13: Transportation
A14: The below information must be entered manually.
B15: Principal Payments | C15: Interest Payments | D15: ="All of the below questions are for Fiscal Year "&$B$11&":" -> All of the below questions are for Fiscal Year 2022–2023:
A16: =RIGHT(B11,4)&"–"&RIGHT(B11,4)+1 -> 2023–2024 | B16: 1393331 | C16: 60655 | D16: 1. Did your SBITAs have any variable payments which ARE NOT included in the measurement of the subscription liability?
A17: =LEFT(A16,4)+1&"–"&RIGHT(A16,4)+1 -> 2024–2025 | B17: 1293552 | C17: 26985
A18: =LEFT(A17,4)+1&"–"&RIGHT(A17,4)+1 -> 2025–2026 | B18: 168264 | C18: 8136 | D18: Yes
A19: =LEFT(A18,4)+1&"–"&RIGHT(A18,4)+1 -> 2026–2027 | B19: 181556 | C19: 3664 | D19: ="If yes, record the dollar amount of variable payments below for fiscal year "&$B$11&":" -> If yes, record the dollar amount of variable payments below for fiscal year 2022–2023:
A20: =LEFT(A19,4)+1&"–"&RIGHT(A19,4)+1 -> 2027–2028 | D20: 1067080
A21: =LEFT(A20,4)+1&"–"&RIGHT(A20,4)+5 -> 2028–2033 | D21: ="2. Record the dollar amount of any other payments for your SBITAs, such as termination penalties, not previously recorded in the payment schedule for fiscal year "&$B$11&":" -> 2. Record the dollar amount of any other payments for your SBITAs, such as termination penalties, not previously recorded in the payment schedule for fiscal year 2022–2023:
A22: =LEFT(A21,4)+5&"–"&RIGHT(A21,4)+5 -> 2033–2038
A23: =LEFT(A22,4)+5&"–"&RIGHT(A22,4)+5 -> 2038–2043 | D23: 0
A24: =LEFT(A23,4)+5&"–"&RIGHT(A23,4)+5 -> 2043–2048 | D24: ="3. Did you receive any SBITA incentives from the SBITA vendor (not already included in the SBITA measurement) during fiscal year "&$B$11&"? If so, record the amount below:" -> 3. Did you receive any SBITA incentives from the SBITA vendor (not already included in the SBITA measurement) during fiscal year 2022–2023? If so, record the amount below:
A25: =LEFT(A24,4)+5&"–"&RIGHT(A24,4)+5 -> 2048–2053
A26: =LEFT(A25,4)+5&"–"&RIGHT(A25,4)+5 -> 2053–2058 | D26: No
A27: =LEFT(A26,4)+5&"–"&RIGHT(A26,4)+5 -> 2058–2063 | D27: ="4. Are there any SBITA commitments known that have yet to commence as of June 30, "&RIGHT($B$11,4)&"?" -> 4. Are there any SBITA commitments known that have yet to commence as of June 30, 2023?
A28: =LEFT(A27,4)+5&"–"&RIGHT(A27,4)+5 -> 2063–2068
A29: =LEFT(A28,4)+5&"–"&RIGHT(A28,4)+5 -> 2068–2073 | D29: Yes
A30: =LEFT(A29,4)+5&"–"&RIGHT(A29,4)+5 -> 2073–2078 | D30: ="If yes, record the dollar amount of any SBITA commitments not commenced below for fiscal year "&$A$16&":" -> If yes, record the dollar amount of any SBITA commitments not commenced below for fiscal year 2023–2024:
A31: =LEFT(A30,4)+5&"–"&RIGHT(A30,4)+5 -> 2078–2083
A32: =LEFT(A31,4)+5&"–"&RIGHT(A31,4)+5 -> 2083–2088 | D32: 5364449.4
A33: =LEFT(A32,4)+5&"–"&RIGHT(A32,4)+5 -> 2088–2093
A34: =LEFT(A33,4)+5&"–"&RIGHT(A33,4)+5 -> 2093–2098
A35: =LEFT(A34,4)+5&"–"&RIGHT(A34,4)+5 -> 2098–2103
A36: =LEFT(A35,4)+5&"–"&RIGHT(A35,4)+5 -> 2103–2108
A37: =LEFT(A36,4)+5&"–"&RIGHT(A36,4)+5 -> 2108–2113
A38: =LEFT(A37,4)+5&"–"&RIGHT(A37,4)+5 -> 2113–2118
A39: =LEFT(A38,4)+5&"–"&RIGHT(A38,4)+5 -> 2118–2123
A41: II. Proprietary - Internal Service Funds
A42: Fiscal Year: | B42: =B11 -> 2022–2023
A43: Org Code/Business Unit: | B43: =B12 -> 2660
A44: Reporting Department Name: | B44: =B13 -> Transportation
A45: The below information must be entered manually.
...

Sheet SBITA Liabilities
G3: Schedule of Changes in SBITA Liabilities
G4: ="FY "&'Department Note Disclosure'!$B$11 -> FY 2022–2023
G5: ="Business Unit " &'Fund 0041 Journal Entries'!$F$5&" "&'Fund 0041 Journal Entries'!$F$4 -> Business Unit 2660 Department of Transportation
C7: Source: Tab "Fund #### Journal Entries" | F7: ENTRY #0 | H7: ENTRY #2 | J7: ENTRY #5 | N7: ENTRY #6
F8: ="Balance July 1, "&LEFT('Fund 0041 Journal Entries'!$F$3,4) -> Balance July 1, 2022 | H8: Additions | J8: Deductions | L8: ="Balance June 30, "&RIGHT('Fund 0041 Journal Entries'!$F$3,4) -> Balance June 30, 2023 | N8: Due Within One Year | P8: Noncurrent Liabilities
C9: Governmental Funds
D10: SBITA Liability | F10: =+'Fund 0041 Journal Entries'!K19+'Fund 0042 Journal Entries'!K19+'Fund 0046 Journal Entries'!K19+'Fund 3290 Journal Entries'!K19 -> 2852088 | H10: =+'Fund 0041 Journal Entries'!K37+'Fund 0042 Journal Entries'!K37+'Fund 0046 Journal Entries'!K37+'Fund 3290 Journal Entries'!K37 -> 4669634 | J10: =+'Fund 0041 Journal Entries'!J56+'Fund 0042 Journal Entries'!J56+'Fund 0046 Journal Entries'!J56+'Fund 3290 Journal Entries'!J56 -> 4485019 | L10: =SUM(F10+H10-J10) -> 3036703 | N10: =+'Fund 0041 Journal Entries'!J61+'Fund 0042 Journal Entries'!J61+'Fund 0046 Journal Entries'!J61+'Fund 3290 Journal Entries'!J61 -> 1393331 | P10: =L10-N10 -> 1643372
C11: Total Governmental Funds | F11: =SUM(F10:F10) -> 2852088 | H11: =SUM(H10:H10) -> 4669634 | J11: =SUM(J10:J10) -> 4485019 | L11: =SUM(L10:L10) -> 3036703 | N11: =SUM(N10:N10) -> 1393331 | P11: =SUM(P10:P10) -> 1643372
C13: Proprietary - Internal Service Funds
D14: SBITA Liability | F14: =IF('Fund 0041 Journal Entries'!$F$7="Proprietary - Internal Service Fund",'Fund 0041 Journal Entries'!$K$19,0) -> 0 | H14: =IF('Fund 0041 Journal Entries'!$F$7="Proprietary - Internal Service Fund",'Fund 0041 Journal Entries'!$K$37,0) -> 0 | J14: =IF('Fund 0041 Journal Entries'!$F$7="Proprietary - Internal Service Fund",'Fund 0041 Journal Entries'!$J$56,0) -> 0 | L14: =SUM(F14+H14-J14) -> 0 | N14: =IF('Fund 0041 Journal Entries'!$F$7="Proprietary - Internal Service Fund",'Fund 0041 Journal Entries'!$J$61,0) -> 0 | P14: =L14-N14 -> 0
C15: Total Proprietary - Internal Service Funds | F15: =SUM(F14:F14) -> 0 | H15: =SUM(H14:H14) -> 0 | J15: =SUM(J14:J14) -> 0 | L15: =SUM(L14:L14) -> 0 | N15: =SUM(N14:N14) -> 0 | P15: =SUM(P14:P14) -> 0
C17: Proprietary - Enterprise Funds
D18: SBITA Liability | F18: =IF('Fund 0041 Journal Entries'!$F$7="Proprietary - Enterprise Fund",'Fund 0041 Journal Entries'!$K$19,0) -> 0 | H18: =IF('Fund 0041 Journal Entries'!$F$7="Proprietary - Enterprise Fund",'Fund 0041 Journal Entries'!$K$37,0) -> 0 | J18: =IF('Fund 0041 Journal Entries'!$F$7="Proprietary - Enterprise Fund",'Fund 0041 Journal Entries'!$J$56,0) -> 0 | L18: =SUM(F18+H18-J18) -> 0 | N18: =IF('Fund 0041 Journal Entries'!$F$7="Proprietary - Enterprise Fund",'Fund 0041 Journal Entries'!$J$61,0) -> 0 | P18: =L18-N18 -> 0
C19: Total Proprietary - Enterprise Funds | F19: =SUM(F18:F18) -> 0 | H19: =SUM(H18:H18) -> 0 | J19: =SUM(J18:J18) -> 0 | L19: =SUM(L18:L18) -> 0 | N19: =SUM(N18:N18) -> 0 | P19: =SUM(P18:P18) -> 0
A25: NOTE: The yellow highlighted fields have formulas embedded to generate the amounts automatically based on inputs (Acct 0674 - RIGHT-TO-USE SBITA LIABILITY) in the journal entries tab. If multiple funds are included in this Workbook, overwrite the yellow highlighted fields to update the amounts.

Sheet Check Figures 
A1: GASB Statement No. 96 Subscription-Based Information Technology Arrangements
A2: Check Figures
A4: Purpose:
A5: The purpose of this workbook is to check the figures entered in the journal entries reconcile to the future principal payments disclosed and the changes in the schedule of the SBITA liabilities.
A8: NOTE: The yellow highlighted fields have formulas embedded to generate the amounts automatically based on inputs in the journal entries tab. If multiple funds are included in this Workbook, manually complete every yellow field by consolidating the entries by fund type (Governmental Fund, Proprietary - Internal Service Fund, and Proprietary - Enterprise Fund).
A11: 1. To reconcile the journal entries of RTU SBITA Liability with the principal payments in Note Disclosure.
B12: a) Governmental Funds
B14: Journal Entries (Acct 0674 - RIGHT-TO-USE SBITA LIABILITY) | J14: Department Note Disclosure
B15: Entry #0 | C15: + | D15: Entry #2 | E15: - | F15: Entry #5 | J15: Sum Principal Payments | L15: Variance
B16: =+'Fund 0041 Journal Entries'!K19+'Fund 0042 Journal Entries'!K19+'Fund 0046 Journal Entries'!K19+'Fund 3290 Journal Entries'!K19 -> 2852088 | C16: + | D16: =+'Fund 0041 Journal Entries'!K37+'Fund 0042 Journal Entries'!K37+'Fund 0046 Journal Entries'!K37+'Fund 3290 Journal Entries'!K37 -> 4669634 | E16: - | F16: =+'Fund 0041 Journal Entries'!J56+'Fund 0042 Journal Entries'!J56+'Fund 0046 Journal Entries'!J56+'Fund 3290 Journal Entries'!J56 -> 4485019 | G16: = | H16: =+B16+D16-F16 -> 3036703 | J16: =ROUND(SUM('Department Note Disclosure'!$B$16:$B$39),0) -> 3036703 | L16: =H16-J16 -> 0
D17: =IF(OR(L16>0, (L16<0)), "Please review and correct the variance.","")
B19: b) Proprietary - Internal Service Funds
B21: Journal Entries (Acct 0674 - RIGHT-TO-USE SBITA LIABILITY) | J21: Department Note Disclosure
B22: Entry #0 | C22: + | D22: Entry #2 | E22: - | F22: Entry #5 | J22: Sum Principal Payments | L22: Variance
B23: =IF('Fund 0041 Journal Entries'!$F$7="Proprietary - Internal Service Fund",ROUND('Fund 0041 Journal Entries'!$K$19,0),0) -> 0 | C23: + | D23: =IF('Fund 0041 Journal Entries'!$F$7="Proprietary - Internal Service Fund",ROUND('Fund 0041 Journal Entries'!$K$37,0),0) -> 0 | E23: - | F23: =IF('Fund 0041 Journal Entries'!$F$7="Proprietary - Internal Service Fund",ROUND('Fund 0041 Journal Entries'!$J$56,0),0) -> 0 | G23: = | H23: =+B23+D23-F23 -> 0 | J23: =ROUND(SUM('Department Note Disclosure'!$B$47:$B$70),0) -> 0 | L23: =H23-J23 -> 0
D25: =IF(OR(L23>0, (L23<0)), "Please review and correct the variance.","")
B27: c) Proprietary - Enterprise Funds
B29: Journal Entries (Acct 0674 - RIGHT-TO-USE SBITA LIABILITY) | J29: Department Note Disclosure
B30: Entry #0 | C30: + | D30: Entry #2 | E30: - | F30: Entry #5 | J30: Sum Principal Payments | L30: Variance
B31: =IF('Fund 0041 Journal Entries'!$F$7="Proprietary - Enterprise Fund",ROUND('Fund 0041 Journal Entries'!$K$19,0),0) -> 0 | C31: + | D31: =IF('Fund 0041 Journal Entries'!$F$7="Proprietary - Enterprise Fund",ROUND('Fund 0041 Journal Entries'!$K$37,0),0) -> 0 | E31: - | F31: =IF('Fund 0041 Journal Entries'!$F$7="Proprietary - Enterprise Fund",ROUND('Fund 0041 Journal Entries'!$J$56,0),0) -> 0 | G31: = | H31: =+B31+D31-F31 -> 0 | J31: =ROUND(SUM('Department Note Disclosure'!$B$78:$B$101),0) -> 0 | L31: =H31-J31 -> 0
D32: =IF(OR(L31>0, (L31<0)), "Please review and correct the variance.","")
A34: 2. To match the journal entry to the principal amount due in the next fiscal year in Note Disclosure.
B35: a) Governmental Funds
B37: Journal Entries (Acct 0674 - RIGHT-TO-USE SBITA LIABILITY) | J37: Department Note Disclosure
F38: Entry #6 | J38: ='Department Note Disclosure'!$A$16&" Principal Payments" -> 2023–2024 Principal Payments | L38: Variance
F39: =+'Fund 0041 Journal Entries'!J61+'Fund 0042 Journal Entries'!J61+'Fund 0046 Journal Entries'!J61+'Fund 3290 Journal Entries'!J61 -> 1393331 | J39: =ROUND('Department Note Disclosure'!$B$16,0) -> 1393331 | L39: =F39-J39 -> 0
D40: =IF(OR(L39>0, (L39<0)), "Please review and correct the variance.","")
B42: b) Proprietary - Internal Service Funds
B44: Journal Entries (Acct 0674 - RIGHT-TO-USE SBITA LIABILITY) | J44: Department Note Disclosure
F45: Entry #6 | J45: ='Department Note Disclosure'!$A$47&" Principal Payments" -> 2023–2024 Principal Payments | L45: Variance
F46: =IF('Fund 0041 Journal Entries'!$F$7="Proprietary - Internal Service Fund",ROUND('Fund 0041 Journal Entries'!$K$62,0),0) -> 0 | J46: =ROUND('Department Note Disclosure'!$B$47,0) -> 0 | L46: =F46-J46 -> 0
D47: =IF(OR(L46>0, (L46<0)), "Please review and correct the variance.","")
B49: c) Proprietary - Enterprise Funds
B51: Journal Entries (Acct 0674 - RIGHT-TO-USE SBITA LIABILITY) | J51: Department Note Disclosure
F52: Entry #6 | J52: ='Department Note Disclosure'!$A$47&" Principal Payments" -> 2023–2024 Principal Payments | L52: Variance
F53: =IF('Fund 0041 Journal Entries'!$F$7="Proprietary - Enterprise Fund",ROUND('Fund 0041 Journal Entries'!$K$62,0),0) -> 0 | J53: =ROUND('Department Note Disclosure'!$B$78,0) -> 0 | L53: =F53-J53 -> 0
D54: =IF(OR(L53>0, (L53<0)), "Please review and correct the variance.","")
A56: 3. To reconcile the journal entries of RTU SBITA Liability with the schedule of changes in SBITA Liabilities.
B57: a) Governmental Funds
B59: Journal Entries (Acct 0674 - RIGHT-TO-USE SBITA LIABILITY) | H59: Schedule of Changes in SBITA Liabilities
...

Sheet Drop Down Menus
A1: 2022–2023 | B1: Governmental Fund | C1: Yes | E1: Please select fund type above. | F1: Please select fund type above. | G1: Please select fund type above.
A2: 2023–2024 | B2: Proprietary - Internal Service Fund | C2: No | D2: GENERAL GOVERNMENT | E2: Dr: Acct 5808 - GENERAL GOV. (REV & EXP) | F2: Dr: Acct 0808 - GENERAL GOV. (GAAP ADJ) | G2: Cr: Acct 0808 - GENERAL GOV. (GAAP ADJ)
A3: 2024–2025 | B3: Proprietary - Enterprise Fund | D3: EDUCATION | E3: Dr: Acct 5810 - EDUCATION EXP (REV-EXP) | F3: Dr: Acct 0810 - EDUCATION EXP (GAAP ADJ) | G3: Cr: Acct 0810 - EDUCATION EXP (GAAP ADJ)
A4: 2025–2026 | D4: HEALTH AND HUMAN SERVICES | E4: Dr: Acct 5815 - HEALTH HM SRV & LAB (REV-EXP) | F4: Dr: Acct 0815 - HLTH&HUM SV SV.LAB(GAAP ADJ) | G4: Cr: Acct 0815 - HLTH&HUM SV SV.LAB(GAAP ADJ)
A5: 2026–2027 | D5: RESOURCES | E5: Dr: Acct 5820 - NATURL RSRCS & ENVIR (REV-EXP) | F5: Dr: Acct 0820 - NAT RES & ENVIRON (GAAP ADJ) | G5: Cr: Acct 0820 - NAT RES & ENVIRON (GAAP ADJ)
A6: 2027–2028 | D6: BUS, CONSUMER SERV, HOUSING | E6: Dr: Acct 5825 - BUS, CONS SERV, HS (REV-EXP) | F6: Dr: Acct 0825 - BUS, CONSUMER SERV, HOUSING | G6: Cr: Acct 0825 - BUS, CONSUMER SERV, HOUSING
A7: 2028–2029 | D7: TRANSPORTATION | E7: Dr: Acct 5830 - TRANSPORTATION (REV-EXP) | F7: Dr: Acct 0830 - TRANSPORTATION (GAAP ADJ) | G7: Cr: Acct 0830 - TRANSPORTATION (GAAP ADJ)
A8: 2029–2030 | D8: CORRECTIONS AND REHABILITATION | E8: Dr: Acct 5835 - CORRECTIONAL PROG. (REV-EXP) | F8: Dr: Acct 0835 - CORRECTIONS AND REHABILITATION | G8: Cr: Acct 0835 - CORRECTIONS AND REHABILITATION
A9: 2030–2031 | D9: PROPRIETARY FUND | E9: Dr: Acct 0870 - SERVICES & CHARGES (MG ADJ) | F9: Dr: Acct 0875 - DEPRECIATION/AMORTIZATION (MG ADJ) | G9: Cr: Acct 0870 - SERVICES & CHARGES (MG ADJ)
A10: 2031–2032 | D10: UNIDENTIFIED | E10: Dr: Acct 0XXX - FUNCTIONAL EXPENSE | F10: Dr: Acct 0XXX - FUNCTIONAL EXPENSE | G10: Cr: Acct 0XXX - FUNCTIONAL EXPENSE
A11: 2032–2033
A12: 2033–2034
A13: 2034–2035
A14: 2035–2036
A15: 2036–2037
A16: 2037–2038
A17: 2038–2039
A18: 2039–2040
A19: 2040–2041
A20: 2041–2042
A21: 2042–2043
A22: 2043–2044
... A101: 2022–2023

Sheet GAAP02Aindex
A1: Agency | B1: Title | C1: Hier1 | D1: Desc1 | E1: Desc2 | F1: Hier2 | G1: Hier3 | H1: Hier4 | I1: Hier5 | J1: EffectiveDate | K1: CancelDate
A2: 0000 | B2: BOND INTEREST AND REDEMPTION | C2: 9000 | D2: BOND INTEREST AND REDEMPTION | F2: 9030 | G2: 9600 | H2: 0000 | I2: 0000 | J2: 04/04/1984 | K2: 00/00/0000
A3: 0010 | B3: LEGISLATIVE, JUDICIAL AND EXEC | C3: 0808 | D3: GENERAL GOVERNMENT | F3: 0000 | G3: 0000 | H3: 0000 | I3: 0000 | J3: 07/11/2006 | K3: 00/00/0000
A4: 0015 | B4: ADD AGENCY TEST | C4: 0808 | D4: GENERAL GOVERNMENT | F4: 0000 | G4: 0000 | H4: 0000 | I4: 0000 | J4: 99/99/9999 | K4: 00/00/0000
A5: 0020 | B5: LEGISLATIVE | C5: 0808 | D5: GENERAL GOVERNMENT | F5: 0000 | G5: 0000 | H5: 0000 | I5: 0000 | J5: 99/99/9999 | K5: 00/00/0000
A6: 0100 | B6: LEGISLATURE | C6: 0808 | D6: GENERAL GOVERNMENT | F6: 0000 | G6: 0000 | H6: 0000 | I6: 0000 | J6: 99/99/9999 | K6: 00/00/0000
A7: 0110 | B7: SENATE | C7: 0808 | D7: GENERAL GOVERNMENT | F7: 0000 | G7: 0000 | H7: 0000 | I7: 0000 | J7: 06/26/1985 | K7: 00/00/0000
A8: 0120 | B8: ASSEMBLY | C8: 0808 | D8: GENERAL GOVERNMENT | F8: 0000 | G8: 0000 | H8: 0000 | I8: 0000 | J8: 06/26/1985 | K8: 00/00/0000
A9: 0130 | B9: LEGISLATIVE JOINT EXPENSES | C9: 0808 | D9: GENERAL GOVERNMENT | F9: 0000 | G9: 0000 | H9: 0000 | I9: 0000 | J9: 06/26/1985 | K9: 00/00/0000
A10: 0150 | B10: CONTRIB TO LEGIS RETIRE FUND | C10: 0808 | D10: GENERAL GOVERNMENT | F10: 0000 | G10: 0000 | H10: 0000 | I10: 0000 | J10: 07/11/2006 | K10: 00/00/0000
A11: 0155 | B11: AUDITOR GENERAL OFFICE | C11: 0808 | D11: GENERAL GOVERNMENT | F11: 0000 | G11: 0000 | H11: 0000 | I11: 0000 | J11: 99/99/9999 | K11: 00/00/0000
A12: 0160 | B12: LEGISLATIVE COUNSEL BUREAU | C12: 0808 | D12: GENERAL GOVERNMENT | F12: 0000 | G12: 0000 | H12: 0000 | I12: 0000 | J12: 04/04/1984 | K12: 00/00/0000
A13: 0170 | B13: CA LAW REVISION COMMISSION | C13: 0808 | D13: GENERAL GOVERNMENT | F13: 0000 | G13: 0000 | H13: 0000 | I13: 0000 | J13: 99/99/9999 | K13: 07/01/1985
... A190: 2140 | B190: STATE BANKING DEPARTMENT | C190: 0825 | D190: BUS, CONSUMER SERV, HOUSING | F190: 0000 | G190: 0000 | H190: 0000 | I190: 0000 | J190: 12/21/2016 | K190: 00/00/0000
A191: 2150 | B191: FINANCIAL INSTITUTIONS | C191: 0825 | D191: ADD BACK TO POST PY REVERSAL | E191: DELETE 16/17 | F191: 0000 | G191: 0000 | H191: 0000 | I191: 0000 | J191: 08/18/2016 | K191: 00/00/0000
A192: 2180 | B192: DEPART OF CORPORATIONS | C192: 0825 | D192: ADD BACK TO POST PY REVERSAL | E192: DELETE 16/17 | F192: 0000 | G192: 0000 | H192: 0000 | I192: 0000 | J192: 08/24/2016 | K192: 00/00/0000
A193: 2190 | B193: MAJOR MEDICAL INSURANCE BOARD | C193: 0825 | D193: BUS, CONSUMER SERV, HOUSING | F193: 0000 | G193: 0000 | H193: 0000 | I193: 0000 | J193: 12/21/2016 | K193: 00/00/0000
A194: 2200 | B194: DEPARTMENT OF COMMERCE | C194: 0825 | D194: BUS, CONSUMER SERV, HOUSING | F194: 0000 | G194: 0000 | H194: 0000 | I194: 0000 | J194: 12/21/2016 | K194: 00/00/0000
A195: 2220 | B195: OFFICE OF SMALL BUSINESS DEVEL | C195: 0825 | D195: BUS, CONSUMER SERV, HOUSING | F195: 0000 | G195: 0000 | H195: 0000 | I195: 0000 | J195: 12/21/2016 | K195: 00/00/0000
A196: 2222 | B196: ST ASST FD FOR ENTERPRISE | C196: 0825 | D196: BUS, CONSUMER SERV, HOUSING | F196: 0000 | G196: 0000 | H196: 0000 | I196: 0000 | J196: 12/21/2016 | K196: 00/00/0000
A197: 2225 | B197: UNITARY FUND PROGRAMS | C197: 0825 | D197: BUS, CONSUMER SERV, HOUSING | F197: 0000 | G197: 0000 | H197: 0000 | I197: 0000 | J197: 12/21/2016 | K197: 00/00/0000
A198: 2230 | B198: CA INDTRL DEV FINCL ADVRY COMM | C198: 0825 | D198: BUS, CONSUMER SERV, HOUSING | F198: 0000 | G198: 0000 | H198: 0000 | I198: 0000 | J198: 12/21/2016 | K198: 07/01/1985
A199: 2235 | B199: CA HOME LOAN MORTGAGE ASSN | C199: 0825 | D199: BUS, CONSUMER SERV, HOUSING | F199: 0000 | G199: 0000 | H199: 0000 | I199: 0000 | J199: 12/21/2016 | K199: 00/00/0000
A200: 2240 | B200: DEPT-HOUSING/COMMUNITY DEVEL | C200: 0825 | D200: BUS, CONSUMER SERV, HOUSING | F200: 0000 | G200: 0000 | H200: 0000 | I200: 0000 | J200: 12/12/2016 | K200: 00/00/1999
A201: 2245 | B201: CALIFORNIA HOUSING FINANCE AGY | C201: 0825 | D201: BUS, CONSUMER SERV, HOUSING | F201: 0000 | G201: 0000 | H201: 0000 | I201: 0000 | J201: 08/19/2016 | K201: 00/00/0000
A202: 2265 | B202: CALIFORNIA HOUSING INSURANCE | C202: 0825 | D202: BUS, CONSUMER SERV, HOUSING | F202: 0000 | G202: 0000 | H202: 0000 | I202: 0000 | J202: 12/21/2016 | K202: 00/00/0000
A203: 2270 | B203: MORTGAGE BOND ALLOC COMMITTEE | C203: 0825 | D203: BUS, CONSUMER SERV, HOUSING | F203: 0000 | G203: 0000 | H203: 0000 | I203: 0000 | J203: 12/21/2016 | K203: 07/01/1985
A204: 2290 | B204: DEPARTMENT OF INSURANCE | C204: 0825 | D204: BUS, CONSUMER SERV, HOUSING | F204: 0000 | G204: 0000 | H204: 0000 | I204: 0000 | J204: 12/21/2016 | K204: 00/00/1999
... A214: 2670 | B214: BD OF PILOT COMMISSIONERS-SF | C214: 0830 | D214: TRANSPORTATION | F214: 0000 | G214: 0000 | H214: 0000 | I214: 0000 | J214: 08/03/2017 | K214: 00/00/0000
A215: 2700 | B215: OFFICE OF TRAFFIC SAFETY | C215: 0830 | D215: TRANSPORTATION | E215: MERGED W/0521-ADD 4 PY ACCR RV | F215: 0000 | G215: 0000 | H215: 0000 | I215: 0000 | J215: 09/28/2016 | K215: 00/00/0000
A216: 2720 | B216: DEPT OF CAL HIGHWAY PATROL | C216: 0830 | D216: TRANSPORTATION | F216: 0000 | G216: 0000 | H216: 0000 | I216: 0000 | J216: 10/28/2016 | K216: 00/00/1999
A217: 2740 | B217: DEPARTMENT OF MOTOR VEHICLES | C217: 0830 | D217: TRANSPORTATION | F217: 0000 | G217: 0000 | H217: 0000 | I217: 0000 | J217: 10/28/2016 | K217: 00/00/0000
A218: 2780 | B218: STEPHEN P TEALE DATA CENTER | C218: 0825 | D218: BUS, CONSUMER SERV, HOUSING | F218: 0000 | G218: 0000 | H218: 0000 | I218: 0000 | J218: 12/21/2016 | K218: 00/00/0000
A219: 2900 | B219: TRADE AND COMMERCE | C219: 0825 | D219: BUS, CONSUMER SERV, HOUSING | F219: 0000 | G219: 0000 | H219: 0000 | I219: 0000 | J219: 12/21/2016 | K219: 00/00/0000
A220: 2920 | B220: TECHNOLOGY TRADE & COMMERCE AG | C220: 0825 | D220: BUS, CONSUMER SERV, HOUSING | F220: 0000 | G220: 0000 | H220: 0000 | I220: 0000 | J220: 12/21/2016 | K220: 00/00/0000
A221: 3000 | B221: NATURAL RESOURCES | C221: 0820 | D221: RESOURCES | F221: 0000 | G221: 0000 | H221: 0000 | I221: 0000 | J221: 08/25/2010 | K221: 00/00/0000
A222: 3100 | B222: EXPOSITION PARK | C222: 0820 | D222: RESOURCES | F222: 0000 | G222: 0000 | H222: 0000 | I222: 0000 | J222: 10/17/2018 | K222: 00/00/0000
A223: 3105 | B223: CALIFORNIA AFRO-AMERICAN MUSEU | C223: 0820 | D223: RESOURCES | F223: 0000 | G223: 0000 | H223: 0000 | I223: 0000 | J223: 09/05/2014 | K223: 00/00/0000
A224: 3110 | B224: SPECIAL RESOURCES PROGRAMS | C224: 0820 | D224: RESOURCES | F224: 0000 | G224: 0000 | H224: 0000 | I224: 0000 | J224: 07/11/2006 | K224: 00/00/1999
A225: 3125 | B225: CALIF TAHOE CONSERVANCY | C225: 0820 | D225: RESOURCES | F225: 0000 | G225: 0000 | H225: 0000 | I225: 0000 | J225: 04/18/1988 | K225: 00/00/1999
...
