Workbook

Sheet Outstanding BUs
A1: EMAILED | C1: Last Day of Correspondence with department | D1: Days since last Correspondence
A2: 3790 | B2: EMAILED | C2: 45119 | D2: =TODAY()-C2 -> 579
A4: =COUNTIFS(B2:B3,"EMAILED") -> 1 | B4: EMAILED | K4: =I36 -> 2.4777798e+09 | M4: ='1. Rpt 18s (non-CSU)'!AF556 -> 1.6944546e+08
K5: % of Outstanding total | M5: % of Non-CSU total
A6: # of funds outstanding | D6: BU | E6: Fund | F6: Department Name | G6: Fund Name | H6: Ending Balance
A7: 1 | B7: EMAILED | C7: F | D7: 3790 | E7: 0001 | F7: DEPT OF PARKS AND RECREATION | G7: GENERAL FUND | H7: 8.8640915e+08
A8: =A7+1 -> 2 | B8: EMAILED | C8: F | D8: 3790 | E8: 0005 | F8: DEPT OF PARKS AND RECREATION | G8: SAFE NEIGHBRHD PARK, CLEAN WAT | H8: 4.6337999e+08
A9: =A8+1 -> 3 | B9: EMAILED | C9: F | D9: 3790 | E9: 0013 | F9: DEPT OF PARKS AND RECREATION | G9: Park & Rec Revolving Account | H9: 6145690
A10: =A9+1 -> 4 | B10: EMAILED | C10: F | D10: 3790 | E10: 0018 | F10: DEPT OF PARKS AND RECREATION | G10: SITE REMEDIATION ACCOUNT | H10: 550000
A11: =A10+1 -> 5 | B11: EMAILED | C11: F | D11: 3790 | E11: 0036 | F11: DEPT OF PARKS AND RECREATION | G11: SPECIAL ACCOUNT FOR CAP OUTLAY | H11: 5746101.5
A12: =A11+1 -> 6 | B12: EMAILED | C12: F | D12: 3790 | E12: 0132 | F12: DEPT OF PARKS AND RECREATION | G12: WORKERS COMP MANAGED CARE FUND | H12: 1.05552e+08
A13: =A12+1 -> 7 | B13: EMAILED | C13: F | D13: 3790 | E13: 0140 | F13: DEPT OF PARKS AND RECREATION | G13: ENVIRONMENTL LICENSE PLATE FD | H13: 422064.25
A14: =A13+1 -> 8 | B14: EMAILED | C14: F | D14: 3790 | E14: 0156 | F14: DEPT OF PARKS AND RECREATION | G14: CALIFORNIA HERITAGE FUND | H14: 15488246
A15: =A14+1 -> 9 | B15: EMAILED | C15: F | D15: 3790 | E15: 0188 | F15: DEPT OF PARKS AND RECREATION | G15: ENERGY AND RESOURCES FUND | H15: 67000
A16: =A15+1 -> 10 | B16: EMAILED | C16: F | D16: 3790 | E16: 0190 | F16: DEPT OF PARKS AND RECREATION | G16: ENERGY AND RESOURCES FUND | H16: 6922668.9
A17: =A16+1 -> 11 | B17: EMAILED | C17: F | D17: 3790 | E17: 0235 | F17: DEPT OF PARKS AND RECREATION | G17: CIGARETTE&TOBACCO FD, PUB RES | H17: 745065.03
A18: =A17+1 -> 12 | B18: EMAILED | C18: F | D18: 3790 | E18: 0262 | F18: DEPT OF PARKS AND RECREATION | G18: HABITAT CONSERVATION FUND | H18: 69333048
A19: =A18+1 -> 13 | B19: EMAILED | C19: F | D19: 3790 | E19: 0263 | F19: DEPT OF PARKS AND RECREATION | G19: OFF-HIGHWAY VEHICLE TRUST FUND | H19: 1.1142941e+08
... A34: =A33+1 -> 28 | B34: EMAILED | C34: F | D34: 3790 | E34: 6029 | F34: DEPT OF PARKS AND RECREATION | G34: CA CLEAN WATER AIR ETC | H34: 1.2884846e+08
A35: =A34+1 -> 29 | B35: EMAILED | C35: F | D35: 3790 | E35: 6051 | F35: DEPT OF PARKS AND RECREATION | G35: SAFE DRINKING WATER OF 2006 | H35: 11995281 | I35: =SUM(H7:H35) -> 2.4777798e+09 | K35: =I35/$K$4 -> 1 | M35: =I35/$M$4 -> 14.622875
H36: =SUM(H7:H35) -> 2.4777798e+09 | I36: =SUM(I7:I35) -> 2.4777798e+09 | K36: =SUM(K7:K35) -> 1 | M36: =SUM(M7:M35) -> 14.6229
A37: =A35/515 -> 0.06
A38: % outstanding

Sheet 1. Rpt 18s (non-CSU)
A1: Capital Assets - Governmental and Proprietary Funds (Non-CSU) | G1: Source: | H1: Prior year's Non-CSU Workbook and Report 18s submitted with the GAAP Agency Requests.
G2: Purpose: | H2: To record capital asset balances (Right-to-Use Leases, SBITAs and APAs) and activity by BU and fund.
A3: as of June 30, 2024 | G3: Procedures: | H3: Record data reflected on the Report 18s for unaudited governmental and proprietary funds. | N3: Highlight yellow if restatement
N5: Beginning | O5: Beginning | P5: Beginning | Q5: Beginning | R5: Beginning | S5: Beginning | T5: Beginning | U5: Additions | V5: Additions | W5: Additions | X5: Additions | Y5: Additions | Z5: Deductions | AA5: Deductions | AB5: Deductions | AC5: Deductions | AD5: Deductions | AE5: Ending | AF5: Ending | AG5: Ending | AH5: Ending | AI5: Ending | AJ5: Ending | AK5: Ending
N6: Right-to-Use Leased Land | O6: Right-to-Use Leased Buildings | P6: Right-to-Use Leased Equipment | Q6: Right-to-Use SBITAs | R6: APA Land | S6: APA Buildings | T6: Total | U6: Right-to-Use Leased Land | V6: Right-to-Use Leased Buildings | W6: Right-to-Use Leased Equipment | X6: Right-to-Use SBITAs | Y6: Total | Z6: Right-to-Use Leased Land | AA6: Right-to-Use Leased Buildings | AB6: Right-to-Use Leased Equipment | AC6: Right-to-Use SBITAs | AD6: Total | AE6: Right-to-Use Leased Land | AF6: Right-to-Use Leased Buildings | AG6: Right-to-Use Leased Equipment | AH6: Right-to-Use SBITAs | AI6: APA Land | AJ6: APA Buildings | AK6: Total
A7: See bottom for legend | D7: GASB 87 | E7: GASB 96 | N7: Amortizable | O7: Amortizable | P7: Amortizable | Q7: Amortizable | S7: Depreciable | U7: Amortizable | V7: Amortizable | W7: Amortizable | X7: Amortizable | Z7: Amortizable | AA7: Amortizable | AB7: Amortizable | AC7: Amortizable | AE7: Amortizable | AF7: Amortizable | AG7: Amortizable | AH7: Amortizable | AI7: Depreciable
B8: Input | C8: FI$Cal Status | D8: GASB 87 Review | E8: GASB 96 Review | F8: Agency | G8: Fund | H8: Concatenate | I8: Fd Hier | J8: Agy Function | K8: Function | L8: Agency Name | M8: Fund Name | N8: (0476 GABX) | O8: (0477 GABX) | P8: (0478 GABX) | Q8: (0480 GABX) | R8: (0446 GABR) | S8: (0448 GABS) | U8: (0476 GABX) | V8: (0477 GABX) | W8: (0478 GABX) | X8: (0480 GABX) | Z8: (0476 GABX) | AA8: (0477 GABX) | AB8: (0478 GABX) | AC8: (0480 GABX) | AE8: (0476 GABX) | AF8: (0477 GABX) | AG8: (0478 GABX) | AH8: (0480 GABX) | AI8: (0446 GABR) | AJ8: (0448 GABS)
A9: 19 | C9: E | F9: 0160 | G9: 0001 | H9: =F9&G9 -> 01600001 | I9: =IF(ISNA(VLOOKUP(G9,GAAP02F[[#All],[Column1]:[FundHier1]],5,FALSE)),"Leases",(VLOOKUP(G9,GAAP02F[[#All],[Column1]:[FundHier1]],5,FALSE))) -> 100 | J9: =IF(ISNA(VLOOKUP(F9,Table_GAAP02A[[#All],[Agency]:[Hier1]],4,FALSE)),"Abolished Agency",(VLOOKUP(F9,Table_GAAP02A[[#All],[Agency]:[Hier1]],4,FALSE))) -> 0808 | K9: =IF(ISNA(VLOOKUP(F9,Table_GAAP02A[[#All],[Agency]:[Hier1]],2,FALSE)),"Abolished Agency",(VLOOKUP(F9,Table_GAAP02A[[#All],[Agency]:[Hier1]],2,FALSE))) -> GENERAL GOVERNMENT | L9: =IF(ISNA(VLOOKUP(F9,Table_GAAP02A[[#All],[Agency]:[Hier1]],3,FALSE)),"Abolished Agency",(VLOOKUP(F9,Table_GAAP02A[[#All],[Agency]:[Hier1]],3,FALSE))) -> LEGISLATIVE COUNSEL BUREAU | M9: =IF(ISNA(VLOOKUP(G9,GAAP02F[[#All],[Column1]:[FundName]],2,FALSE)),"Leases",(VLOOKUP(G9,GAAP02F[[#All],[Column1]:[FundName]],2,FALSE))) -> GENERAL FUND | N9: 0 | O9: 0 | P9: 0 | Q9: 0 | R9: 0 | S9: 0 | T9: =SUM(N9:S9) -> 0 | U9: 0 | V9: 0 | W9: 0 | X9: 0 | Y9: =SUM(U9:X9) -> 0 | Z9: 0 | AA9: 0 | AB9: 0 | AC9: 0 | AD9: =SUM(Z9:AC9) -> 0 | AE9: =N9 +U9-Z9 -> 0 | AF9: =O9 +V9-AA9 -> 0 | AG9: =P9 +W9-AB9 -> 0 | AH9: =Q9 +X9-AC9 -> 0 | AI9: =R9 -> 0 | AJ9: =S9 -> 0 | AK9: =SUM(AE9:AJ9) -> 0
A10: 19 | C10: F | F10: 0250 | G10: 0001 | H10: =F10&G10 -> 02500001 | I10: =IF(ISNA(VLOOKUP(G10,GAAP02F[[#All],[Column1]:[FundHier1]],5,FALSE)),"Leases",(VLOOKUP(G10,GAAP02F[[#All],[Column1]:[FundHier1]],5,FALSE))) -> 100 | J10: =IF(ISNA(VLOOKUP(F10,Table_GAAP02A[[#All],[Agency]:[Hier1]],4,FALSE)),"Abolished Agency",(VLOOKUP(F10,Table_GAAP02A[[#All],[Agency]:[Hier1]],4,FALSE))) -> 0808 | K10: =IF(ISNA(VLOOKUP(F10,Table_GAAP02A[[#All],[Agency]:[Hier1]],2,FALSE)),"Abolished Agency",(VLOOKUP(F10,Table_GAAP02A[[#All],[Agency]:[Hier1]],2,FALSE))) -> GENERAL GOVERNMENT | L10: =IF(ISNA(VLOOKUP(F10,Table_GAAP02A[[#All],[Agency]:[Hier1]],3,FALSE)),"Abolished Agency",(VLOOKUP(F10,Table_GAAP02A[[#All],[Agency]:[Hier1]],3,FALSE))) -> JUDICIARY | M10: =IF(ISNA(VLOOKUP(G10,GAAP02F[[#All],[Column1]:[FundName]],2,FALSE)),"Leases",(VLOOKUP(G10,GAAP02F[[#All],[Column1]:[FundName]],2,FALSE))) -> GENERAL FUND | N10: 0 | O10: 0 | P10: 0 | Q10: 0 | R10: 0 | S10: 0 | T10: =SUM(N10:S10) -> 0 | U10: 0 | V10: 0 | W10: 0 | X10: 0 | Y10: =SUM(U10:X10) -> 0 | Z10: 0 | AA10: 0 | AB10: 0 | AC10: 0 | AD10: =SUM(Z10:AC10) -> 0 | AE10: =N10 +U10-Z10 -> 0 | AF10: =O10 +V10-AA10 -> 0 | AG10: =P10 +W10-AB10 -> 0 | AH10: =Q10 +X10-AC10 -> 0 | AI10: =R10 -> 0 | AJ10: =S10 -> 0 | AK10: =SUM(AE10:AJ10) -> 0
A11: 19 | C11: F | F11: 0250 | G11: 0159 | H11: =F11&G11 -> 02500159 | I11: =IF(ISNA(VLOOKUP(G11,GAAP02F[[#All],[Column1]:[FundHier1]],5,FALSE)),"Leases",(VLOOKUP(G11,GAAP02F[[#All],[Column1]:[FundHier1]],5,FALSE))) -> 200 | J11: =IF(ISNA(VLOOKUP(F11,Table_GAAP02A[[#All],[Agency]:[Hier1]],4,FALSE)),"Abolished Agency",(VLOOKUP(F11,Table_GAAP02A[[#All],[Agency]:[Hier1]],4,FALSE))) -> 0808 | K11: =IF(ISNA(VLOOKUP(F11,Table_GAAP02A[[#All],[Agency]:[Hier1]],2,FALSE)),"Abolished Agency",(VLOOKUP(F11,Table_GAAP02A[[#All],[Agency]:[Hier1]],2,FALSE))) -> GENERAL GOVERNMENT | L11: =IF(ISNA(VLOOKUP(F11,Table_GAAP02A[[#All],[Agency]:[Hier1]],3,FALSE)),"Abolished Agency",(VLOOKUP(F11,Table_GAAP02A[[#All],[Agency]:[Hier1]],3,FALSE))) -> JUDICIARY | M11: =IF(ISNA(VLOOKUP(G11,GAAP02F[[#All],[Column1]:[FundName]],2,FALSE)),"Leases",(VLOOKUP(G11,GAAP02F[[#All],[Column1]:[FundName]],2,FALSE))) -> TRIAL COURT IMPROVEMENT FUND | N11: 0 | O11: 0 | P11: 0 | Q11: 0 | R11: 0 | S11: 0 | T11: =SUM(N11:S11) -> 0 | U11: 0 | V11: 0 | W11: 0 | X11: 0 | Y11: =SUM(U11:X11) -> 0 | Z11: 0 | AA11: 0 | AB11: 0 | AC11: 0 | AD11: =SUM(Z11:AC11) -> 0 | AE11: =N11 +U11-Z11 -> 0 | AF11: =O11 +V11-AA11 -> 0 | AG11: =P11 +W11-AB11 -> 0 | AH11: =Q11 +X11-AC11 -> 0 | AI11: =R11 -> 0 | AJ11: =S11 -> 0 | AK11: =SUM(AE11:AJ11) -> 0
A12: 19 | C12: F | F12: 0250 | G12: 0587 | H12: =F12&G12 -> 02500587 | I12: =IF(ISNA(VLOOKUP(G12,GAAP02F[[#All],[Column1]:[FundHier1]],5,FALSE)),"Leases",(VLOOKUP(G12,GAAP02F[[#All],[Column1]:[FundHier1]],5,FALSE))) -> 200 | J12: =IF(ISNA(VLOOKUP(F12,Table_GAAP02A[[#All],[Agency]:[Hier1]],4,FALSE)),"Abolished Agency",(VLOOKUP(F12,Table_GAAP02A[[#All],[Agency]:[Hier1]],4,FALSE))) -> 0808 | K12: =IF(ISNA(VLOOKUP(F12,Table_GAAP02A[[#All],[Agency]:[Hier1]],2,FALSE)),"Abolished Agency",(VLOOKUP(F12,Table_GAAP02A[[#All],[Agency]:[Hier1]],2,FALSE))) -> GENERAL GOVERNMENT | L12: =IF(ISNA(VLOOKUP(F12,Table_GAAP02A[[#All],[Agency]:[Hier1]],3,FALSE)),"Abolished Agency",(VLOOKUP(F12,Table_GAAP02A[[#All],[Agency]:[Hier1]],3,FALSE))) -> JUDICIARY | M12: =IF(ISNA(VLOOKUP(G12,GAAP02F[[#All],[Column1]:[FundName]],2,FALSE)),"Leases",(VLOOKUP(G12,GAAP02F[[#All],[Column1]:[FundName]],2,FALSE))) -> FAMILY LAW TRUST FUND | N12: 0 | O12: 0 | P12: 0 | Q12: 0 | R12: 0 | S12: 0 | T12: =SUM(N12:S12) -> 0 | U12: 0 | V12: 0 | W12: 0 | X12: 0 | Y12: =SUM(U12:X12) -> 0 | Z12: 0 | AA12: 0 | AB12: 0 | AC12: 0 | AD12: =SUM(Z12:AC12) -> 0 | AE12: =N12 +U12-Z12 -> 0 | AF12: =O12 +V12-AA12 -> 0 | AG12: =P12 +W12-AB12 -> 0 | AH12: =Q12 +X12-AC12 -> 0 | AI12: =R12 -> 0 | AJ12: =S12 -> 0 | AK12: =SUM(AE12:AJ12) -> 0
A13: 19 | C13: F | F13: 0250 | G13: 0890 | H13: =F13&G13 -> 02500890 | I13: =IF(ISNA(VLOOKUP(G13,GAAP02F[[#All],[Column1]:[FundHier1]],5,FALSE)),"Leases",(VLOOKUP(G13,GAAP02F[[#All],[Column1]:[FundHier1]],5,FALSE))) -> 200 | J13: =IF(ISNA(VLOOKUP(F13,Table_GAAP02A[[#All],[Agency]:[Hier1]],4,FALSE)),"Abolished Agency",(VLOOKUP(F13,Table_GAAP02A[[#All],[Agency]:[Hier1]],4,FALSE))) -> 0808 | K13: =IF(ISNA(VLOOKUP(F13,Table_GAAP02A[[#All],[Agency]:[Hier1]],2,FALSE)),"Abolished Agency",(VLOOKUP(F13,Table_GAAP02A[[#All],[Agency]:[Hier1]],2,FALSE))) -> GENERAL GOVERNMENT | L13: =IF(ISNA(VLOOKUP(F13,Table_GAAP02A[[#All],[Agency]:[Hier1]],3,FALSE)),"Abolished Agency",(VLOOKUP(F13,Table_GAAP02A[[#All],[Agency]:[Hier1]],3,FALSE))) -> JUDICIARY | M13: =IF(ISNA(VLOOKUP(G13,GAAP02F[[#All],[Column1]:[FundName]],2,FALSE)),"Leases",(VLOOKUP(G13,GAAP02F[[#All],[Column1]:[FundName]],2,FALSE))) -> FEDERAL TRUST FUND | N13: 0 | O13: 0 | P13: 0 | Q13: 0 | R13: 0 | S13: 0 | T13: =SUM(N13:S13) -> 0 | U13: 0 | V13: 0 | W13: 0 | X13: 0 | Y13: =SUM(U13:X13) -> 0 | Z13: 0 | AA13: 0 | AB13: 0 | AC13: 0 | AD13: =SUM(Z13:AC13) -> 0 | AE13: =N13 +U13-Z13 -> 0 | AF13: =O13 +V13-AA13 -> 0 | AG13: =P13 +W13-AB13 -> 0 | AH13: =Q13 +X13-AC13 -> 0 | AI13: =R13 -> 0 | AJ13: =S13 -> 0 | AK13: =SUM(AE13:AJ13) -> 0
A14: 19 | C14: F | F14: 0250 | G14: 0932 | H14: =F14&G14 -> 02500932 | I14: =IF(ISNA(VLOOKUP(G14,GAAP02F[[#All],[Column1]:[FundHier1]],5,FALSE)),"Leases",(VLOOKUP(G14,GAAP02F[[#All],[Column1]:[FundHier1]],5,FALSE))) -> 200 | J14: =IF(ISNA(VLOOKUP(F14,Table_GAAP02A[[#All],[Agency]:[Hier1]],4,FALSE)),"Abolished Agency",(VLOOKUP(F14,Table_GAAP02A[[#All],[Agency]:[Hier1]],4,FALSE))) -> 0808 | K14: =IF(ISNA(VLOOKUP(F14,Table_GAAP02A[[#All],[Agency]:[Hier1]],2,FALSE)),"Abolished Agency",(VLOOKUP(F14,Table_GAAP02A[[#All],[Agency]:[Hier1]],2,FALSE))) -> GENERAL GOVERNMENT | L14: =IF(ISNA(VLOOKUP(F14,Table_GAAP02A[[#All],[Agency]:[Hier1]],3,FALSE)),"Abolished Agency",(VLOOKUP(F14,Table_GAAP02A[[#All],[Agency]:[Hier1]],3,FALSE))) -> JUDICIARY | M14: =IF(ISNA(VLOOKUP(G14,GAAP02F[[#All],[Column1]:[FundName]],2,FALSE)),"Leases",(VLOOKUP(G14,GAAP02F[[#All],[Column1]:[FundName]],2,FALSE))) -> TRIAL COURT TRUST FUND | N14: 0 | O14: 0 | P14: 0 | Q14: 0 | R14: 0 | S14: 0 | T14: =SUM(N14:S14) -> 0 | U14: 0 | V14: 0 | W14: 0 | X14: 0 | Y14: =SUM(U14:X14) -> 0 | Z14: 0 | AA14: 0 | AB14: 0 | AC14: 0 | AD14: =SUM(Z14:AC14) -> 0 | AE14: =N14 +U14-Z14 -> 0 | AF14: =O14 +V14-AA14 -> 0 | AG14: =P14 +W14-AB14 -> 0 | AH14: =Q14 +X14-AC14 -> 0 | AI14: =R14 -> 0 | AJ14: =S14 -> 0 | AK14: =SUM(AE14:AJ14) -> 0
A15: G | C15: F | F15: 0250 | G15: 0991 | H15: =F15&G15 -> 02500991 | I15: =IF(ISNA(VLOOKUP(G15,GAAP02F[[#All],[Column1]:[FundHier1]],5,FALSE)),"Leases",(VLOOKUP(G15,GAAP02F[[#All],[Column1]:[FundHier1]],5,FALSE))) -> 200 | J15: =IF(ISNA(VLOOKUP(F15,Table_GAAP02A[[#All],[Agency]:[Hier1]],4,FALSE)),"Abolished Agency",(VLOOKUP(F15,Table_GAAP02A[[#All],[Agency]:[Hier1]],4,FALSE))) -> 0808 | K15: =IF(ISNA(VLOOKUP(F15,Table_GAAP02A[[#All],[Agency]:[Hier1]],2,FALSE)),"Abolished Agency",(VLOOKUP(F15,Table_GAAP02A[[#All],[Agency]:[Hier1]],2,FALSE))) -> GENERAL GOVERNMENT | L15: =IF(ISNA(VLOOKUP(F15,Table_GAAP02A[[#All],[Agency]:[Hier1]],3,FALSE)),"Abolished Agency",(VLOOKUP(F15,Table_GAAP02A[[#All],[Agency]:[Hier1]],3,FALSE))) -> JUDICIARY | M15: =IF(ISNA(VLOOKUP(G15,GAAP02F[[#All],[Column1]:[FundName]],2,FALSE)),"Leases",(VLOOKUP(G15,GAAP02F[[#All],[Column1]:[FundName]],2,FALSE))) -> TRIAL COURTS FUND | N15: 0 | O15: 0 | P15: 0 | Q15: 0 | R15: 0 | S15: 0 | T15: =SUM(N15:S15) -> 0 | U15: 0 | V15: 0 | W15: 0 | X15: 0 | Y15: =SUM(U15:X15) -> 0 | Z15: 0 | AA15: 0 | AB15: 0 | AC15: 0 | AD15: =SUM(Z15:AC15) -> 0 | AE15: =N15 +U15-Z15 -> 0 | AF15: =O15 +V15-AA15 -> 0 | AG15: =P15 +W15-AB15 -> 0 | AH15: =Q15 +X15-AC15 -> 0 | AI15: =R15 -> 0 | AJ15: =S15 -> 0 | AK15: =SUM(AE15:AJ15) -> 0
A16: 19 | C16: F | F16: 0250 | G16: 3037 | H16: =F16&G16 -> 02503037 | I16: =IF(ISNA(VLOOKUP(G16,GAAP02F[[#All],[Column1]:[FundHier1]],5,FALSE)),"Leases",(VLOOKUP(G16,GAAP02F[[#All],[Column1]:[FundHier1]],5,FALSE))) -> 200 | J16: =IF(ISNA(VLOOKUP(F16,Table_GAAP02A[[#All],[Agency]:[Hier1]],4,FALSE)),"Abolished Agency",(VLOOKUP(F16,Table_GAAP02A[[#All],[Agency]:[Hier1]],4,FALSE))) -> 0808 | K16: =IF(ISNA(VLOOKUP(F16,Table_GAAP02A[[#All],[Agency]:[Hier1]],2,FALSE)),"Abolished Agency",(VLOOKUP(F16,Table_GAAP02A[[#All],[Agency]:[Hier1]],2,FALSE))) -> GENERAL GOVERNMENT | L16: =IF(ISNA(VLOOKUP(F16,Table_GAAP02A[[#All],[Agency]:[Hier1]],3,FALSE)),"Abolished Agency",(VLOOKUP(F16,Table_GAAP02A[[#All],[Agency]:[Hier1]],3,FALSE))) -> JUDICIARY | M16: =IF(ISNA(VLOOKUP(G16,GAAP02F[[#All],[Column1]:[FundName]],2,FALSE)),"Leases",(VLOOKUP(G16,GAAP02F[[#All],[Column1]:[FundName]],2,FALSE))) -> STATE COURT FACILITIES CONST F | N16: 0 | O16: 0 | P16: 0 | Q16: 0 | R16: 0 | S16: 0 | T16: =SUM(N16:S16) -> 0 | U16: 0 | V16: 0 | W16: 0 | X16: 0 | Y16: =SUM(U16:X16) -> 0 | Z16: 0 | AA16: 0 | AB16: 0 | AC16: 0 | AD16: =SUM(Z16:AC16) -> 0 | AE16: =N16 +U16-Z16 -> 0 | AF16: =O16 +V16-AA16 -> 0 | AG16: =P16 +W16-AB16 -> 0 | AH16: =Q16 +X16-AC16 -> 0 | AI16: =R16 -> 0 | AJ16: =S16 -> 0 | AK16: =SUM(AE16:AJ16) -> 0
A17: 19 | C17: F | F17: 0250 | G17: 3060 | H17: =F17&G17 -> 02503060 | I17: =IF(ISNA(VLOOKUP(G17,GAAP02F[[#All],[Column1]:[FundHier1]],5,FALSE)),"Leases",(VLOOKUP(G17,GAAP02F[[#All],[Column1]:[FundHier1]],5,FALSE))) -> 200 | J17: =IF(ISNA(VLOOKUP(F17,Table_GAAP02A[[#All],[Agency]:[Hier1]],4,FALSE)),"Abolished Agency",(VLOOKUP(F17,Table_GAAP02A[[#All],[Agency]:[Hier1]],4,FALSE))) -> 0808 | K17: =IF(ISNA(VLOOKUP(F17,Table_GAAP02A[[#All],[Agency]:[Hier1]],2,FALSE)),"Abolished Agency",(VLOOKUP(F17,Table_GAAP02A[[#All],[Agency]:[Hier1]],2,FALSE))) -> GENERAL GOVERNMENT | L17: =IF(ISNA(VLOOKUP(F17,Table_GAAP02A[[#All],[Agency]:[Hier1]],3,FALSE)),"Abolished Agency",(VLOOKUP(F17,Table_GAAP02A[[#All],[Agency]:[Hier1]],3,FALSE))) -> JUDICIARY | M17: =IF(ISNA(VLOOKUP(G17,GAAP02F[[#All],[Column1]:[FundName]],2,FALSE)),"Leases",(VLOOKUP(G17,GAAP02F[[#All],[Column1]:[FundName]],2,FALSE))) -> APPELLATE COURT TRUST FUND | N17: 0 | O17: 0 | P17: 0 | Q17: 0 | R17: 0 | S17: 0 | T17: =SUM(N17:S17) -> 0 | U17: 0 | V17: 0 | W17: 0 | X17: 0 | Y17: =SUM(U17:X17) -> 0 | Z17: 0 | AA17: 0 | AB17: 0 | AC17: 0 | AD17: =SUM(Z17:AC17) -> 0 | AE17: =N17 +U17-Z17 -> 0 | AF17: =O17 +V17-AA17 -> 0 | AG17: =P17 +W17-AB17 -> 0 | AH17: =Q17 +X17-AC17 -> 0 | AI17: =R17 -> 0 | AJ17: =S17 -> 0 | AK17: =SUM(AE17:AJ17) -> 0
A18: 19 | C18: F | F18: 0250 | G18: 3066 | H18: =F18&G18 -> 02503066 | I18: =IF(ISNA(VLOOKUP(G18,GAAP02F[[#All],[Column1]:[FundHier1]],5,FALSE)),"Leases",(VLOOKUP(G18,GAAP02F[[#All],[Column1]:[FundHier1]],5,FALSE))) -> 200 | J18: =IF(ISNA(VLOOKUP(F18,Table_GAAP02A[[#All],[Agency]:[Hier1]],4,FALSE)),"Abolished Agency",(VLOOKUP(F18,Table_GAAP02A[[#All],[Agency]:[Hier1]],4,FALSE))) -> 0808 | K18: =IF(ISNA(VLOOKUP(F18,Table_GAAP02A[[#All],[Agency]:[Hier1]],2,FALSE)),"Abolished Agency",(VLOOKUP(F18,Table_GAAP02A[[#All],[Agency]:[Hier1]],2,FALSE))) -> GENERAL GOVERNMENT | L18: =IF(ISNA(VLOOKUP(F18,Table_GAAP02A[[#All],[Agency]:[Hier1]],3,FALSE)),"Abolished Agency",(VLOOKUP(F18,Table_GAAP02A[[#All],[Agency]:[Hier1]],3,FALSE))) -> JUDICIARY | M18: =IF(ISNA(VLOOKUP(G18,GAAP02F[[#All],[Column1]:[FundName]],2,FALSE)),"Leases",(VLOOKUP(G18,GAAP02F[[#All],[Column1]:[FundName]],2,FALSE))) -> COURT FACILITIES TRUST FUND | N18: 0 | O18: 0 | P18: 0 | Q18: 0 | R18: 0 | S18: 0 | T18: =SUM(N18:S18) -> 0 | U18: 0 | V18: 0 | W18: 0 | X18: 0 | Y18: =SUM(U18:X18) -> 0 | Z18: 0 | AA18: 0 | AB18: 0 | AC18: 0 | AD18: =SUM(Z18:AC18) -> 0 | AE18: =N18 +U18-Z18 -> 0 | AF18: =O18 +V18-AA18 -> 0 | AG18: =P18 +W18-AB18 -> 0 | AH18: =Q18 +X18-AC18 -> 0 | AI18: =R18 -> 0 | AJ18: =S18 -> 0 | AK18: =SUM(AE18:AJ18) -> 0
A19: 19 | C19: F | F19: 0250 | G19: 3085 | H19: =F19&G19 -> 02503085 | I19: =IF(ISNA(VLOOKUP(G19,GAAP02F[[#All],[Column1]:[FundHier1]],5,FALSE)),"Leases",(VLOOKUP(G19,GAAP02F[[#All],[Column1]:[FundHier1]],5,FALSE))) -> 200 | J19: =IF(ISNA(VLOOKUP(F19,Table_GAAP02A[[#All],[Agency]:[Hier1]],4,FALSE)),"Abolished Agency",(VLOOKUP(F19,Table_GAAP02A[[#All],[Agency]:[Hier1]],4,FALSE))) -> 0808 | K19: =IF(ISNA(VLOOKUP(F19,Table_GAAP02A[[#All],[Agency]:[Hier1]],2,FALSE)),"Abolished Agency",(VLOOKUP(F19,Table_GAAP02A[[#All],[Agency]:[Hier1]],2,FALSE))) -> GENERAL GOVERNMENT | L19: =IF(ISNA(VLOOKUP(F19,Table_GAAP02A[[#All],[Agency]:[Hier1]],3,FALSE)),"Abolished Agency",(VLOOKUP(F19,Table_GAAP02A[[#All],[Agency]:[Hier1]],3,FALSE))) -> JUDICIARY | M19: =IF(ISNA(VLOOKUP(G19,GAAP02F[[#All],[Column1]:[FundName]],2,FALSE)),"Leases",(VLOOKUP(G19,GAAP02F[[#All],[Column1]:[FundName]],2,FALSE))) -> MENTAL HEALTH SERVICE FUND | N19: 0 | O19: 0 | P19: 0 | Q19: 0 | R19: 0 | S19: 0 | T19: =SUM(N19:S19) -> 0 | U19: 0 | V19: 0 | W19: 0 | X19: 0 | Y19: =SUM(U19:X19) -> 0 | Z19: 0 | AA19: 0 | AB19: 0 | AC19: 0 | AD19: =SUM(Z19:AC19) -> 0 | AE19: =N19 +U19-Z19 -> 0 | AF19: =O19 +V19-AA19 -> 0 | AG19: =P19 +W19-AB19 -> 0 | AH19: =Q19 +X19-AC19 -> 0 | AI19: =R19 -> 0 | AJ19: =S19 -> 0 | AK19: =SUM(AE19:AJ19) -> 0
A20: 19 | C20: F | F20: 0250 | G20: 3138 | H20: =F20&G20 -> 02503138 | I20: =IF(ISNA(VLOOKUP(G20,GAAP02F[[#All],[Column1]:[FundHier1]],5,FALSE)),"Leases",(VLOOKUP(G20,GAAP02F[[#All],[Column1]:[FundHier1]],5,FALSE))) -> 200 | J20: =IF(ISNA(VLOOKUP(F20,Table_GAAP02A[[#All],[Agency]:[Hier1]],4,FALSE)),"Abolished Agency",(VLOOKUP(F20,Table_GAAP02A[[#All],[Agency]:[Hier1]],4,FALSE))) -> 0808 | K20: =IF(ISNA(VLOOKUP(F20,Table_GAAP02A[[#All],[Agency]:[Hier1]],2,FALSE)),"Abolished Agency",(VLOOKUP(F20,Table_GAAP02A[[#All],[Agency]:[Hier1]],2,FALSE))) -> GENERAL GOVERNMENT | L20: =IF(ISNA(VLOOKUP(F20,Table_GAAP02A[[#All],[Agency]:[Hier1]],3,FALSE)),"Abolished Agency",(VLOOKUP(F20,Table_GAAP02A[[#All],[Agency]:[Hier1]],3,FALSE))) -> JUDICIARY | M20: =IF(ISNA(VLOOKUP(G20,GAAP02F[[#All],[Column1]:[FundName]],2,FALSE)),"Leases",(VLOOKUP(G20,GAAP02F[[#All],[Column1]:[FundName]],2,FALSE))) -> IMMEDIATE & CRITICAL NEEDS | N20: 0 | O20: 0 | P20: 0 | Q20: 0 | R20: 0 | S20: 0 | T20: =SUM(N20:S20) -> 0 | U20: 0 | V20: 0 | W20: 0 | X20: 0 | Y20: =SUM(U20:X20) -> 0 | Z20: 0 | AA20: 0 | AB20: 0 | AC20: 0 | AD20: =SUM(Z20:AC20) -> 0 | AE20: =N20 +U20-Z20 -> 0 | AF20: =O20 +V20-AA20 -> 0 | AG20: =P20 +W20-AB20 -> 0 | AH20: =Q20 +X20-AC20 -> 0 | AI20: =R20 -> 0 | AJ20: =S20 -> 0 | AK20: =SUM(AE20:AJ20) -> 0
A21: 19 | C21: F | F21: 0280 | G21: 0001 | H21: =F21&G21 -> 02800001 | I21: =IF(ISNA(VLOOKUP(G21,GAAP02F[[#All],[Column1]:[FundHier1]],5,FALSE)),"Leases",(VLOOKUP(G21,GAAP02F[[#All],[Column1]:[FundHier1]],5,FALSE))) -> 100 | J21: =IF(ISNA(VLOOKUP(F21,Table_GAAP02A[[#All],[Agency]:[Hier1]],4,FALSE)),"Abolished Agency",(VLOOKUP(F21,Table_GAAP02A[[#All],[Agency]:[Hier1]],4,FALSE))) -> 0808 | K21: =IF(ISNA(VLOOKUP(F21,Table_GAAP02A[[#All],[Agency]:[Hier1]],2,FALSE)),"Abolished Agency",(VLOOKUP(F21,Table_GAAP02A[[#All],[Agency]:[Hier1]],2,FALSE))) -> GENERAL GOVERNMENT | L21: =IF(ISNA(VLOOKUP(F21,Table_GAAP02A[[#All],[Agency]:[Hier1]],3,FALSE)),"Abolished Agency",(VLOOKUP(F21,Table_GAAP02A[[#All],[Agency]:[Hier1]],3,FALSE))) -> COMM ON JUDICIAL PERFORMANCE | M21: =IF(ISNA(VLOOKUP(G21,GAAP02F[[#All],[Column1]:[FundName]],2,FALSE)),"Leases",(VLOOKUP(G21,GAAP02F[[#All],[Column1]:[FundName]],2,FALSE))) -> GENERAL FUND | N21: 0 | O21: 0 | P21: 0 | Q21: 0 | R21: 0 | S21: 0 | T21: =SUM(N21:S21) -> 0 | U21: 0 | V21: 0 | W21: 0 | X21: 0 | Y21: =SUM(U21:X21) -> 0 | Z21: 0 | AA21: 0 | AB21: 0 | AC21: 0 | AD21: =SUM(Z21:AC21) -> 0 | AE21: =N21 +U21-Z21 -> 0 | AF21: =O21 +V21-AA21 -> 0 | AG21: =P21 +W21-AB21 -> 0 | AH21: =Q21 +X21-AC21 -> 0 | AI21: =R21 -> 0 | AJ21: =S21 -> 0 | AK21: =SUM(AE21:AJ21) -> 0
F22: 0500 | G22: 9740 | H22: =F22&G22 -> 05009740 | I22: =IF(ISNA(VLOOKUP(G22,GAAP02F[[#All],[Column1]:[FundHier1]],5,FALSE)),"Leases",(VLOOKUP(G22,GAAP02F[[#All],[Column1]:[FundHier1]],5,FALSE))) -> 500 | J22: =IF(ISNA(VLOOKUP(F22,Table_GAAP02A[[#All],[Agency]:[Hier1]],4,FALSE)),"Abolished Agency",(VLOOKUP(F22,Table_GAAP02A[[#All],[Agency]:[Hier1]],4,FALSE))) -> 0808 | K22: =IF(ISNA(VLOOKUP(F22,Table_GAAP02A[[#All],[Agency]:[Hier1]],2,FALSE)),"Abolished Agency",(VLOOKUP(F22,Table_GAAP02A[[#All],[Agency]:[Hier1]],2,FALSE))) -> GENERAL GOVERNMENT | L22: =IF(ISNA(VLOOKUP(F22,Table_GAAP02A[[#All],[Agency]:[Hier1]],3,FALSE)),"Abolished Agency",(VLOOKUP(F22,Table_GAAP02A[[#All],[Agency]:[Hier1]],3,FALSE))) -> GOVERNORS OFFICE | M22: =IF(ISNA(VLOOKUP(G22,GAAP02F[[#All],[Column1]:[FundName]],2,FALSE)),"Leases",(VLOOKUP(G22,GAAP02F[[#All],[Column1]:[FundName]],2,FALSE))) -> CENTRAL SERVICE COST RECOVERY | N22: 0 | O22: 0 | P22: 0 | Q22: 0 | R22: 0 | S22: 0 | T22: =SUM(N22:S22) -> 0 | U22: 0 | V22: 0 | W22: 0 | X22: 0 | Y22: =SUM(U22:X22) -> 0 | Z22: 0 | AA22: 0 | AB22: 0 | AC22: 0 | AD22: =SUM(Z22:AC22) -> 0 | AE22: =N22 +U22-Z22 -> 0 | AF22: =O22 +V22-AA22 -> 0 | AG22: =P22 +W22-AB22 -> 0 | AH22: =Q22 +X22-AC22 -> 0 | AI22: =R22 -> 0 | AJ22: =S22 -> 0 | AK22: =SUM(AE22:AJ22) -> 0
A23: 19 | C23: F | F23: 0509 | G23: 0001 | H23: =F23&G23 -> 05090001 | I23: =IF(ISNA(VLOOKUP(G23,GAAP02F[[#All],[Column1]:[FundHier1]],5,FALSE)),"Leases",(VLOOKUP(G23,GAAP02F[[#All],[Column1]:[FundHier1]],5,FALSE))) -> 100 | J23: =IF(ISNA(VLOOKUP(F23,Table_GAAP02A[[#All],[Agency]:[Hier1]],4,FALSE)),"Abolished Agency",(VLOOKUP(F23,Table_GAAP02A[[#All],[Agency]:[Hier1]],4,FALSE))) -> 0808 | K23: =IF(ISNA(VLOOKUP(F23,Table_GAAP02A[[#All],[Agency]:[Hier1]],2,FALSE)),"Abolished Agency",(VLOOKUP(F23,Table_GAAP02A[[#All],[Agency]:[Hier1]],2,FALSE))) -> GENERAL GOVERNMENT | L23: =IF(ISNA(VLOOKUP(F23,Table_GAAP02A[[#All],[Agency]:[Hier1]],3,FALSE)),"Abolished Agency",(VLOOKUP(F23,Table_GAAP02A[[#All],[Agency]:[Hier1]],3,FALSE))) -> GOV OFC OF BUSINESS & ECONOMIC | M23: =IF(ISNA(VLOOKUP(G23,GAAP02F[[#All],[Column1]:[FundName]],2,FALSE)),"Leases",(VLOOKUP(G23,GAAP02F[[#All],[Column1]:[FundName]],2,FALSE))) -> GENERAL FUND | N23: 0 | O23: 0 | P23: 0 | Q23: 0 | R23: 0 | S23: 0 | T23: =SUM(N23:S23) -> 0 | U23: 0 | V23: 0 | W23: 0 | X23: 0 | Y23: =SUM(U23:X23) -> 0 | Z23: 0 | AA23: 0 | AB23: 0 | AC23: 0 | AD23: =SUM(Z23:AC23) -> 0 | AE23: =N23 +U23-Z23 -> 0 | AF23: =O23 +V23-AA23 -> 0 | AG23: =P23 +W23-AB23 -> 0 | AH23: =Q23 +X23-AC23 -> 0 | AI23: =R23 -> 0 | AJ23: =S23 -> 0 | AK23: =SUM(AE23:AJ23) -> 0
A24: 19 | C24: F | F24: 0511 | G24: 0001 | H24: =F24&G24 -> 05110001 | I24: =IF(ISNA(VLOOKUP(G24,GAAP02F[[#All],[Column1]:[FundHier1]],5,FALSE)),"Leases",(VLOOKUP(G24,GAAP02F[[#All],[Column1]:[FundHier1]],5,FALSE))) -> 100 | J24: =IF(ISNA(VLOOKUP(F24,Table_GAAP02A[[#All],[Agency]:[Hier1]],4,FALSE)),"Abolished Agency",(VLOOKUP(F24,Table_GAAP02A[[#All],[Agency]:[Hier1]],4,FALSE))) -> 0808 | K24: =IF(ISNA(VLOOKUP(F24,Table_GAAP02A[[#All],[Agency]:[Hier1]],2,FALSE)),"Abolished Agency",(VLOOKUP(F24,Table_GAAP02A[[#All],[Agency]:[Hier1]],2,FALSE))) -> GENERAL GOVERNMENT | L24: =IF(ISNA(VLOOKUP(F24,Table_GAAP02A[[#All],[Agency]:[Hier1]],3,FALSE)),"Abolished Agency",(VLOOKUP(F24,Table_GAAP02A[[#All],[Agency]:[Hier1]],3,FALSE))) -> SEC FOR GOVERNMENT OPERATIONS | M24: =IF(ISNA(VLOOKUP(G24,GAAP02F[[#All],[Column1]:[FundName]],2,FALSE)),"Leases",(VLOOKUP(G24,GAAP02F[[#All],[Column1]:[FundName]],2,FALSE))) -> GENERAL FUND | N24: 0 | O24: 0 | P24: 0 | Q24: 0 | R24: 0 | S24: 0 | T24: =SUM(N24:S24) -> 0 | U24: 0 | V24: 0 | W24: 0 | X24: 0 | Y24: =SUM(U24:X24) -> 0 | Z24: 0 | AA24: 0 | AB24: 0 | AC24: 0 | AD24: =SUM(Z24:AC24) -> 0 | AE24: =N24 +U24-Z24 -> 0 | AF24: =O24 +V24-AA24 -> 0 | AG24: =P24 +W24-AB24 -> 0 | AH24: =Q24 +X24-AC24 -> 0 | AI24: =R24 -> 0 | AJ24: =S24 -> 0 | AK24: =SUM(AE24:AJ24) -> 0
A25: 19 | C25: F | D25: JR 12/18 | E25: NO SBITA | F25: 0515 | G25: 0001 | H25: =F25&G25 -> 05150001 | I25: =IF(ISNA(VLOOKUP(G25,GAAP02F[[#All],[Column1]:[FundHier1]],5,FALSE)),"Leases",(VLOOKUP(G25,GAAP02F[[#All],[Column1]:[FundHier1]],5,FALSE))) -> 100 | J25: =IF(ISNA(VLOOKUP(F25,Table_GAAP02A[[#All],[Agency]:[Hier1]],4,FALSE)),"Abolished Agency",(VLOOKUP(F25,Table_GAAP02A[[#All],[Agency]:[Hier1]],4,FALSE))) -> 0825 | K25: =IF(ISNA(VLOOKUP(F25,Table_GAAP02A[[#All],[Agency]:[Hier1]],2,FALSE)),"Abolished Agency",(VLOOKUP(F25,Table_GAAP02A[[#All],[Agency]:[Hier1]],2,FALSE))) -> BUS, CONSUMER SERV, HOUSING | L25: =IF(ISNA(VLOOKUP(F25,Table_GAAP02A[[#All],[Agency]:[Hier1]],3,FALSE)),"Abolished Agency",(VLOOKUP(F25,Table_GAAP02A[[#All],[Agency]:[Hier1]],3,FALSE))) -> SEC FOR BUS-CONSUM-SERV & HOUS | M25: =IF(ISNA(VLOOKUP(G25,GAAP02F[[#All],[Column1]:[FundName]],2,FALSE)),"Leases",(VLOOKUP(G25,GAAP02F[[#All],[Column1]:[FundName]],2,FALSE))) -> GENERAL FUND | N25: 0 | O25: 2296229.7 | P25: 0 | Q25: 0 | R25: 0 | S25: 0 | T25: =SUM(N25:S25) -> 2296229.7 | U25: 0 | V25: 0 | W25: 0 | X25: 0 | Y25: =SUM(U25:X25) -> 0 | Z25: 0 | AA25: 0 | AB25: 0 | AC25: 0 | AD25: =SUM(Z25:AC25) -> 0 | AE25: =N25 +U25-Z25 -> 0 | AF25: =O25 +V25-AA25 -> 2296229.7 | AG25: =P25 +W25-AB25 -> 0 | AH25: =Q25 +X25-AC25 -> 0 | AI25: =R25 -> 0 | AJ25: =S25 -> 0 | AK25: =SUM(AE25:AJ25) -> 2296229.7
A26: 19 | C26: F | F26: 0521 | G26: 0042 | H26: =F26&G26 -> 05210042 | I26: =IF(ISNA(VLOOKUP(G26,GAAP02F[[#All],[Column1]:[FundHier1]],5,FALSE)),"Leases",(VLOOKUP(G26,GAAP02F[[#All],[Column1]:[FundHier1]],5,FALSE))) -> 200 | J26: =IF(ISNA(VLOOKUP(F26,Table_GAAP02A[[#All],[Agency]:[Hier1]],4,FALSE)),"Abolished Agency",(VLOOKUP(F26,Table_GAAP02A[[#All],[Agency]:[Hier1]],4,FALSE))) -> 0830 | K26: =IF(ISNA(VLOOKUP(F26,Table_GAAP02A[[#All],[Agency]:[Hier1]],2,FALSE)),"Abolished Agency",(VLOOKUP(F26,Table_GAAP02A[[#All],[Agency]:[Hier1]],2,FALSE))) -> TRANSPORTATION | L26: =IF(ISNA(VLOOKUP(F26,Table_GAAP02A[[#All],[Agency]:[Hier1]],3,FALSE)),"Abolished Agency",(VLOOKUP(F26,Table_GAAP02A[[#All],[Agency]:[Hier1]],3,FALSE))) -> SECRETARY OF TRANSPORTATION AG | M26: =IF(ISNA(VLOOKUP(G26,GAAP02F[[#All],[Column1]:[FundName]],2,FALSE)),"Leases",(VLOOKUP(G26,GAAP02F[[#All],[Column1]:[FundName]],2,FALSE))) -> STATE HIGHWAY ACCOUNT | N26: 0 | O26: 0 | P26: 0 | Q26: 0 | R26: 0 | S26: 0 | T26: =SUM(N26:S26) -> 0 | U26: 0 | V26: 0 | W26: 0 | X26: 0 | Y26: =SUM(U26:X26) -> 0 | Z26: 0 | AA26: 0 | AB26: 0 | AC26: 0 | AD26: =SUM(Z26:AC26) -> 0 | AE26: =N26 +U26-Z26 -> 0 | AF26: =O26 +V26-AA26 -> 0 | AG26: =P26 +W26-AB26 -> 0 | AH26: =Q26 +X26-AC26 -> 0 | AI26: =R26 -> 0 | AJ26: =S26 -> 0 | AK26: =SUM(AE26:AJ26) -> 0
A27: 19 | C27: F | F27: 0521 | G27: 0044 | H27: =F27&G27 -> 05210044 | I27: =IF(ISNA(VLOOKUP(G27,GAAP02F[[#All],[Column1]:[FundHier1]],5,FALSE)),"Leases",(VLOOKUP(G27,GAAP02F[[#All],[Column1]:[FundHier1]],5,FALSE))) -> 200 | J27: =IF(ISNA(VLOOKUP(F27,Table_GAAP02A[[#All],[Agency]:[Hier1]],4,FALSE)),"Abolished Agency",(VLOOKUP(F27,Table_GAAP02A[[#All],[Agency]:[Hier1]],4,FALSE))) -> 0830 | K27: =IF(ISNA(VLOOKUP(F27,Table_GAAP02A[[#All],[Agency]:[Hier1]],2,FALSE)),"Abolished Agency",(VLOOKUP(F27,Table_GAAP02A[[#All],[Agency]:[Hier1]],2,FALSE))) -> TRANSPORTATION | L27: =IF(ISNA(VLOOKUP(F27,Table_GAAP02A[[#All],[Agency]:[Hier1]],3,FALSE)),"Abolished Agency",(VLOOKUP(F27,Table_GAAP02A[[#All],[Agency]:[Hier1]],3,FALSE))) -> SECRETARY OF TRANSPORTATION AG | M27: =IF(ISNA(VLOOKUP(G27,GAAP02F[[#All],[Column1]:[FundName]],2,FALSE)),"Leases",(VLOOKUP(G27,GAAP02F[[#All],[Column1]:[FundName]],2,FALSE))) -> MOTOR VEHICLE ACCOUNT | N27: 0 | O27: 0 | P27: 0 | Q27: 0 | R27: 0 | S27: 0 | T27: =SUM(N27:S27) -> 0 | U27: 0 | V27: 0 | W27: 0 | X27: 0 | Y27: =SUM(U27:X27) -> 0 | Z27: 0 | AA27: 0 | AB27: 0 | AC27: 0 | AD27: =SUM(Z27:AC27) -> 0 | AE27: =N27 +U27-Z27 -> 0 | AF27: =O27 +V27-AA27 -> 0 | AG27: =P27 +W27-AB27 -> 0 | AH27: =Q27 +X27-AC27 -> 0 | AI27: =R27 -> 0 | AJ27: =S27 -> 0 | AK27: =SUM(AE27:AJ27) -> 0
A28: 19 | C28: F | F28: 0521 | G28: 0046 | H28: =F28&G28 -> 05210046 | I28: =IF(ISNA(VLOOKUP(G28,GAAP02F[[#All],[Column1]:[FundHier1]],5,FALSE)),"Leases",(VLOOKUP(G28,GAAP02F[[#All],[Column1]:[FundHier1]],5,FALSE))) -> 200 | J28: =IF(ISNA(VLOOKUP(F28,Table_GAAP02A[[#All],[Agency]:[Hier1]],4,FALSE)),"Abolished Agency",(VLOOKUP(F28,Table_GAAP02A[[#All],[Agency]:[Hier1]],4,FALSE))) -> 0830 | K28: =IF(ISNA(VLOOKUP(F28,Table_GAAP02A[[#All],[Agency]:[Hier1]],2,FALSE)),"Abolished Agency",(VLOOKUP(F28,Table_GAAP02A[[#All],[Agency]:[Hier1]],2,FALSE))) -> TRANSPORTATION | L28: =IF(ISNA(VLOOKUP(F28,Table_GAAP02A[[#All],[Agency]:[Hier1]],3,FALSE)),"Abolished Agency",(VLOOKUP(F28,Table_GAAP02A[[#All],[Agency]:[Hier1]],3,FALSE))) -> SECRETARY OF TRANSPORTATION AG | M28: =IF(ISNA(VLOOKUP(G28,GAAP02F[[#All],[Column1]:[FundName]],2,FALSE)),"Leases",(VLOOKUP(G28,GAAP02F[[#All],[Column1]:[FundName]],2,FALSE))) -> PUBLIC TRANSPORTATION ACCT STF | N28: 0 | O28: 0 | P28: 0 | Q28: 0 | R28: 0 | S28: 0 | T28: =SUM(N28:S28) -> 0 | U28: 0 | V28: 0 | W28: 0 | X28: 0 | Y28: =SUM(U28:X28) -> 0 | Z28: 0 | AA28: 0 | AB28: 0 | AC28: 0 | AD28: =SUM(Z28:AC28) -> 0 | AE28: =N28 +U28-Z28 -> 0 | AF28: =O28 +V28-AA28 -> 0 | AG28: =P28 +W28-AB28 -> 0 | AH28: =Q28 +X28-AC28 -> 0 | AI28: =R28 -> 0 | AJ28: =S28 -> 0 | AK28: =SUM(AE28:AJ28) -> 0
A29: 19 | C29: F | F29: 0521 | G29: 0917 | H29: =F29&G29 -> 05210917 | I29: =IF(ISNA(VLOOKUP(G29,GAAP02F[[#All],[Column1]:[FundHier1]],5,FALSE)),"Leases",(VLOOKUP(G29,GAAP02F[[#All],[Column1]:[FundHier1]],5,FALSE))) -> 400 | J29: =IF(ISNA(VLOOKUP(F29,Table_GAAP02A[[#All],[Agency]:[Hier1]],4,FALSE)),"Abolished Agency",(VLOOKUP(F29,Table_GAAP02A[[#All],[Agency]:[Hier1]],4,FALSE))) -> 0830 | K29: =IF(ISNA(VLOOKUP(F29,Table_GAAP02A[[#All],[Agency]:[Hier1]],2,FALSE)),"Abolished Agency",(VLOOKUP(F29,Table_GAAP02A[[#All],[Agency]:[Hier1]],2,FALSE))) -> TRANSPORTATION | L29: =IF(ISNA(VLOOKUP(F29,Table_GAAP02A[[#All],[Agency]:[Hier1]],3,FALSE)),"Abolished Agency",(VLOOKUP(F29,Table_GAAP02A[[#All],[Agency]:[Hier1]],3,FALSE))) -> SECRETARY OF TRANSPORTATION AG | M29: =IF(ISNA(VLOOKUP(G29,GAAP02F[[#All],[Column1]:[FundName]],2,FALSE)),"Leases",(VLOOKUP(G29,GAAP02F[[#All],[Column1]:[FundName]],2,FALSE))) -> INMATES' WELFARE FUND | N29: 0 | O29: 0 | P29: 0 | Q29: 585419 | R29: 0 | S29: 0 | T29: =SUM(N29:S29) -> 585419 | U29: 0 | V29: 0 | W29: 0 | X29: 0 | Y29: =SUM(U29:X29) -> 0 | Z29: 0 | AA29: 0 | AB29: 0 | AC29: 0 | AD29: =SUM(Z29:AC29) -> 0 | AE29: =N29 +U29-Z29 -> 0 | AF29: =O29 +V29-AA29 -> 0 | AG29: =P29 +W29-AB29 -> 0 | AH29: =Q29 +X29-AC29 -> 585419 | AI29: =R29 -> 0 | AJ29: =S29 -> 0 | AK29: =SUM(AE29:AJ29) -> 585419
A30: 19 | C30: F | F30: 0521 | G30: 6043 | H30: =F30&G30 -> 05216043 | I30: =IF(ISNA(VLOOKUP(G30,GAAP02F[[#All],[Column1]:[FundHier1]],5,FALSE)),"Leases",(VLOOKUP(G30,GAAP02F[[#All],[Column1]:[FundHier1]],5,FALSE))) -> 200 | J30: =IF(ISNA(VLOOKUP(F30,Table_GAAP02A[[#All],[Agency]:[Hier1]],4,FALSE)),"Abolished Agency",(VLOOKUP(F30,Table_GAAP02A[[#All],[Agency]:[Hier1]],4,FALSE))) -> 0830 | K30: =IF(ISNA(VLOOKUP(F30,Table_GAAP02A[[#All],[Agency]:[Hier1]],2,FALSE)),"Abolished Agency",(VLOOKUP(F30,Table_GAAP02A[[#All],[Agency]:[Hier1]],2,FALSE))) -> TRANSPORTATION | L30: =IF(ISNA(VLOOKUP(F30,Table_GAAP02A[[#All],[Agency]:[Hier1]],3,FALSE)),"Abolished Agency",(VLOOKUP(F30,Table_GAAP02A[[#All],[Agency]:[Hier1]],3,FALSE))) -> SECRETARY OF TRANSPORTATION AG | M30: =IF(ISNA(VLOOKUP(G30,GAAP02F[[#All],[Column1]:[FundName]],2,FALSE)),"Leases",(VLOOKUP(G30,GAAP02F[[#All],[Column1]:[FundName]],2,FALSE))) -> HIGH-SPEED PASSENGER TRAIN | N30: 0 | O30: 0 | P30: 0 | Q30: 585419 | R30: 0 | S30: 0 | T30: =SUM(N30:S30) -> 585419 | U30: 0 | V30: 0 | W30: 0 | X30: 0 | Y30: =SUM(U30:X30) -> 0 | Z30: 0 | AA30: 0 | AB30: 0 | AC30: 0 | AD30: =SUM(Z30:AC30) -> 0 | AE30: =N30 +U30-Z30 -> 0 | AF30: =O30 +V30-AA30 -> 0 | AG30: =P30 +W30-AB30 -> 0 | AH30: =Q30 +X30-AC30 -> 585419 | AI30: =R30 -> 0 | AJ30: =S30 -> 0 | AK30: =SUM(AE30:AJ30) -> 585419
A31: 19 | C31: F | F31: 0521 | G31: 9730 | H31: =F31&G31 -> 05219730 | I31: =IF(ISNA(VLOOKUP(G31,GAAP02F[[#All],[Column1]:[FundHier1]],5,FALSE)),"Leases",(VLOOKUP(G31,GAAP02F[[#All],[Column1]:[FundHier1]],5,FALSE))) -> 500 | J31: =IF(ISNA(VLOOKUP(F31,Table_GAAP02A[[#All],[Agency]:[Hier1]],4,FALSE)),"Abolished Agency",(VLOOKUP(F31,Table_GAAP02A[[#All],[Agency]:[Hier1]],4,FALSE))) -> 0830 | K31: =IF(ISNA(VLOOKUP(F31,Table_GAAP02A[[#All],[Agency]:[Hier1]],2,FALSE)),"Abolished Agency",(VLOOKUP(F31,Table_GAAP02A[[#All],[Agency]:[Hier1]],2,FALSE))) -> TRANSPORTATION | L31: =IF(ISNA(VLOOKUP(F31,Table_GAAP02A[[#All],[Agency]:[Hier1]],3,FALSE)),"Abolished Agency",(VLOOKUP(F31,Table_GAAP02A[[#All],[Agency]:[Hier1]],3,FALSE))) -> SECRETARY OF TRANSPORTATION AG | M31: =IF(ISNA(VLOOKUP(G31,GAAP02F[[#All],[Column1]:[FundName]],2,FALSE)),"Leases",(VLOOKUP(G31,GAAP02F[[#All],[Column1]:[FundName]],2,FALSE))) -> TECHNOLOGY SERVICES REVOLVING | N31: 0 | O31: 0 | P31: 0 | Q31: 25927171 | R31: 0 | S31: 0 | T31: =SUM(N31:S31) -> 25927171 | U31: 0 | V31: 0 | W31: 0 | X31: 3919547 | Y31: =SUM(U31:X31) -> 3919547 | Z31: 0 | AA31: 0 | AB31: 0 | AC31: 1486301 | AD31: =SUM(Z31:AC31) -> 1486301 | AE31: =N31 +U31-Z31 -> 0 | AF31: =O31 +V31-AA31 -> 0 | AG31: =P31 +W31-AB31 -> 0 | AH31: =Q31 +X31-AC31 -> 28360417 | AI31: =R31 -> 0 | AJ31: =S31 -> 0 | AK31: =SUM(AE31:AJ31) -> 28360417
A32: 19 | C32: F | D32: JR 12/18 | E32: JR 12/18 | F32: 0530 | G32: 0001 | H32: =F32&G32 -> 05300001 | I32: =IF(ISNA(VLOOKUP(G32,GAAP02F[[#All],[Column1]:[FundHier1]],5,FALSE)),"Leases",(VLOOKUP(G32,GAAP02F[[#All],[Column1]:[FundHier1]],5,FALSE))) -> 100 | J32: =IF(ISNA(VLOOKUP(F32,Table_GAAP02A[[#All],[Agency]:[Hier1]],4,FALSE)),"Abolished Agency",(VLOOKUP(F32,Table_GAAP02A[[#All],[Agency]:[Hier1]],4,FALSE))) -> 0815 | K32: =IF(ISNA(VLOOKUP(F32,Table_GAAP02A[[#All],[Agency]:[Hier1]],2,FALSE)),"Abolished Agency",(VLOOKUP(F32,Table_GAAP02A[[#All],[Agency]:[Hier1]],2,FALSE))) -> HEALTH AND HUMAN SERVICES | L32: =IF(ISNA(VLOOKUP(F32,Table_GAAP02A[[#All],[Agency]:[Hier1]],3,FALSE)),"Abolished Agency",(VLOOKUP(F32,Table_GAAP02A[[#All],[Agency]:[Hier1]],3,FALSE))) -> HEALTH AND WELFARE AGENCY | M32: =IF(ISNA(VLOOKUP(G32,GAAP02F[[#All],[Column1]:[FundName]],2,FALSE)),"Leases",(VLOOKUP(G32,GAAP02F[[#All],[Column1]:[FundName]],2,FALSE))) -> GENERAL FUND | N32: 0 | O32: 733592.64 | P32: 0 | Q32: 199130 | R32: 0 | S32: 0 | T32: =SUM(N32:S32) -> 932722.64 | U32: 0 | V32: 0 | W32: 0 | X32: 0 | Y32: =SUM(U32:X32) -> 0 | Z32: 0 | AA32: 0 | AB32: 0 | AC32: 0 | AD32: =SUM(Z32:AC32) -> 0 | AE32: =N32 +U32-Z32 -> 0 | AF32: =O32 +V32-AA32 -> 733592.64 | AG32: =P32 +W32-AB32 -> 0 | AH32: =Q32 +X32-AC32 -> 199130 | AI32: =R32 -> 0 | AJ32: =S32 -> 0 | AK32: =SUM(AE32:AJ32) -> 932722.64
A33: 19 | C33: F | F33: 0531 | G33: 9745 | H33: =F33&G33 -> 05319745 | I33: =IF(ISNA(VLOOKUP(G33,GAAP02F[[#All],[Column1]:[FundHier1]],5,FALSE)),"Leases",(VLOOKUP(G33,GAAP02F[[#All],[Column1]:[FundHier1]],5,FALSE))) -> 500 | J33: =IF(ISNA(VLOOKUP(F33,Table_GAAP02A[[#All],[Agency]:[Hier1]],4,FALSE)),"Abolished Agency",(VLOOKUP(F33,Table_GAAP02A[[#All],[Agency]:[Hier1]],4,FALSE))) -> 0815 | K33: =IF(ISNA(VLOOKUP(F33,Table_GAAP02A[[#All],[Agency]:[Hier1]],2,FALSE)),"Abolished Agency",(VLOOKUP(F33,Table_GAAP02A[[#All],[Agency]:[Hier1]],2,FALSE))) -> HEALTH AND HUMAN SERVICES | L33: =IF(ISNA(VLOOKUP(F33,Table_GAAP02A[[#All],[Agency]:[Hier1]],3,FALSE)),"Abolished Agency",(VLOOKUP(F33,Table_GAAP02A[[#All],[Agency]:[Hier1]],3,FALSE))) -> OFFICE OF SYSTEM INTEGRATION | M33: =IF(ISNA(VLOOKUP(G33,GAAP02F[[#All],[Column1]:[FundName]],2,FALSE)),"Leases",(VLOOKUP(G33,GAAP02F[[#All],[Column1]:[FundName]],2,FALSE))) -> HEALTH&HUMAN SVCS AUTOMATION | N33: 0 | O33: 0 | P33: 0 | Q33: 0 | R33: 0 | S33: 0 | T33: =SUM(N33:S33) -> 0 | U33: 0 | V33: 0 | W33: 0 | X33: 0 | Y33: =SUM(U33:X33) -> 0 | Z33: 0 | AA33: 0 | AB33: 0 | AC33: 0 | AD33: =SUM(Z33:AC33) -> 0 | AE33: =N33 +U33-Z33 -> 0 | AF33: =O33 +V33-AA33 -> 0 | AG33: =P33 +W33-AB33 -> 0 | AH33: =Q33 +X33-AC33 -> 0 | AI33: =R33 -> 0 | AJ33: =S33 -> 0 | AK33: =SUM(AE33:AJ33) -> 0
A34: 19 | C34: F | F34: 0540 | G34: 0001 | H34: =F34&G34 -> 05400001 | I34: =IF(ISNA(VLOOKUP(G34,GAAP02F[[#All],[Column1]:[FundHier1]],5,FALSE)),"Leases",(VLOOKUP(G34,GAAP02F[[#All],[Column1]:[FundHier1]],5,FALSE))) -> 100 | J34: =IF(ISNA(VLOOKUP(F34,Table_GAAP02A[[#All],[Agency]:[Hier1]],4,FALSE)),"Abolished Agency",(VLOOKUP(F34,Table_GAAP02A[[#All],[Agency]:[Hier1]],4,FALSE))) -> 0820 | K34: =IF(ISNA(VLOOKUP(F34,Table_GAAP02A[[#All],[Agency]:[Hier1]],2,FALSE)),"Abolished Agency",(VLOOKUP(F34,Table_GAAP02A[[#All],[Agency]:[Hier1]],2,FALSE))) -> RESOURCES | L34: =IF(ISNA(VLOOKUP(F34,Table_GAAP02A[[#All],[Agency]:[Hier1]],3,FALSE)),"Abolished Agency",(VLOOKUP(F34,Table_GAAP02A[[#All],[Agency]:[Hier1]],3,FALSE))) -> NATURAL RESOURCES AGENCY, SECY | M34: =IF(ISNA(VLOOKUP(G34,GAAP02F[[#All],[Column1]:[FundName]],2,FALSE)),"Leases",(VLOOKUP(G34,GAAP02F[[#All],[Column1]:[FundName]],2,FALSE))) -> GENERAL FUND | N34: 0 | O34: 0 | P34: 0 | Q34: 0 | R34: 0 | S34: 0 | T34: =SUM(N34:S34) -> 0 | U34: 0 | V34: 0 | W34: 0 | X34: 0 | Y34: =SUM(U34:X34) -> 0 | Z34: 0 | AA34: 0 | AB34: 0 | AC34: 0 | AD34: =SUM(Z34:AC34) -> 0 | AE34: =N34 +U34-Z34 -> 0 | AF34: =O34 +V34-AA34 -> 0 | AG34: =P34 +W34-AB34 -> 0 | AH34: =Q34 +X34-AC34 -> 0 | AI34: =R34 -> 0 | AJ34: =S34 -> 0 | AK34: =SUM(AE34:AJ34) -> 0
A35: 19 | C35: F | F35: 0540 | G35: 0140 | H35: =F35&G35 -> 05400140 | I35: =IF(ISNA(VLOOKUP(G35,GAAP02F[[#All],[Column1]:[FundHier1]],5,FALSE)),"Leases",(VLOOKUP(G35,GAAP02F[[#All],[Column1]:[FundHier1]],5,FALSE))) -> 200 | J35: =IF(ISNA(VLOOKUP(F35,Table_GAAP02A[[#All],[Agency]:[Hier1]],4,FALSE)),"Abolished Agency",(VLOOKUP(F35,Table_GAAP02A[[#All],[Agency]:[Hier1]],4,FALSE))) -> 0820 | K35: =IF(ISNA(VLOOKUP(F35,Table_GAAP02A[[#All],[Agency]:[Hier1]],2,FALSE)),"Abolished Agency",(VLOOKUP(F35,Table_GAAP02A[[#All],[Agency]:[Hier1]],2,FALSE))) -> RESOURCES | L35: =IF(ISNA(VLOOKUP(F35,Table_GAAP02A[[#All],[Agency]:[Hier1]],3,FALSE)),"Abolished Agency",(VLOOKUP(F35,Table_GAAP02A[[#All],[Agency]:[Hier1]],3,FALSE))) -> NATURAL RESOURCES AGENCY, SECY | M35: =IF(ISNA(VLOOKUP(G35,GAAP02F[[#All],[Column1]:[FundName]],2,FALSE)),"Leases",(VLOOKUP(G35,GAAP02F[[#All],[Column1]:[FundName]],2,FALSE))) -> ENVIRONMENTL LICENSE PLATE FD | N35: 0 | O35: 0 | P35: 0 | Q35: 0 | R35: 0 | S35: 0 | T35: =SUM(N35:S35) -> 0 | U35: 0 | V35: 0 | W35: 0 | X35: 0 | Y35: =SUM(U35:X35) -> 0 | Z35: 0 | AA35: 0 | AB35: 0 | AC35: 0 | AD35: =SUM(Z35:AC35) -> 0 | AE35: =N35 +U35-Z35 -> 0 | AF35: =O35 +V35-AA35 -> 0 | AG35: =P35 +W35-AB35 -> 0 | AH35: =Q35 +X35-AC35 -> 0 | AI35: =R35 -> 0 | AJ35: =S35 -> 0 | AK35: =SUM(AE35:AJ35) -> 0
A36: 19 | C36: F | E36: JR 12/20 | F36: 0552 | G36: 0001 | H36: =F36&G36 -> 05520001 | I36: =IF(ISNA(VLOOKUP(G36,GAAP02F[[#All],[Column1]:[FundHier1]],5,FALSE)),"Leases",(VLOOKUP(G36,GAAP02F[[#All],[Column1]:[FundHier1]],5,FALSE))) -> 100 | J36: =IF(ISNA(VLOOKUP(F36,Table_GAAP02A[[#All],[Agency]:[Hier1]],4,FALSE)),"Abolished Agency",(VLOOKUP(F36,Table_GAAP02A[[#All],[Agency]:[Hier1]],4,FALSE))) -> 0808 | K36: =IF(ISNA(VLOOKUP(F36,Table_GAAP02A[[#All],[Agency]:[Hier1]],2,FALSE)),"Abolished Agency",(VLOOKUP(F36,Table_GAAP02A[[#All],[Agency]:[Hier1]],2,FALSE))) -> GENERAL GOVERNMENT | L36: =IF(ISNA(VLOOKUP(F36,Table_GAAP02A[[#All],[Agency]:[Hier1]],3,FALSE)),"Abolished Agency",(VLOOKUP(F36,Table_GAAP02A[[#All],[Agency]:[Hier1]],3,FALSE))) -> OFFICE OF THE INSPECTOR GENERL | M36: =IF(ISNA(VLOOKUP(G36,GAAP02F[[#All],[Column1]:[FundName]],2,FALSE)),"Leases",(VLOOKUP(G36,GAAP02F[[#All],[Column1]:[FundName]],2,FALSE))) -> GENERAL FUND | N36: 0 | O36: 0 | P36: 0 | Q36: 431793.04 | R36: 0 | S36: 0 | T36: =SUM(N36:S36) -> 431793.04 | U36: 0 | V36: 0 | W36: 0 | X36: 0 | Y36: =SUM(U36:X36) -> 0 | Z36: 0 | AA36: 0 | AB36: 0 | AC36: 0 | AD36: =SUM(Z36:AC36) -> 0 | AE36: =N36 +U36-Z36 -> 0 | AF36: =O36 +V36-AA36 -> 0 | AG36: =P36 +W36-AB36 -> 0 | AH36: =Q36 +X36-AC36 -> 431793.04 | AI36: =R36 -> 0 | AJ36: =S36 -> 0 | AK36: =SUM(AE36:AJ36) -> 431793.04
A37: 19 | C37: F | F37: 0555 | G37: 0044 | H37: =F37&G37 -> 05550044 | I37: =IF(ISNA(VLOOKUP(G37,GAAP02F[[#All],[Column1]:[FundHier1]],5,FALSE)),"Leases",(VLOOKUP(G37,GAAP02F[[#All],[Column1]:[FundHier1]],5,FALSE))) -> 200 | J37: =IF(ISNA(VLOOKUP(F37,Table_GAAP02A[[#All],[Agency]:[Hier1]],4,FALSE)),"Abolished Agency",(VLOOKUP(F37,Table_GAAP02A[[#All],[Agency]:[Hier1]],4,FALSE))) -> 0820 | K37: =IF(ISNA(VLOOKUP(F37,Table_GAAP02A[[#All],[Agency]:[Hier1]],2,FALSE)),"Abolished Agency",(VLOOKUP(F37,Table_GAAP02A[[#All],[Agency]:[Hier1]],2,FALSE))) -> RESOURCES | L37: =IF(ISNA(VLOOKUP(F37,Table_GAAP02A[[#All],[Agency]:[Hier1]],3,FALSE)),"Abolished Agency",(VLOOKUP(F37,Table_GAAP02A[[#All],[Agency]:[Hier1]],3,FALSE))) -> ENVIRONMENTAL PROTECTION, SECY | M37: =IF(ISNA(VLOOKUP(G37,GAAP02F[[#All],[Column1]:[FundName]],2,FALSE)),"Leases",(VLOOKUP(G37,GAAP02F[[#All],[Column1]:[FundName]],2,FALSE))) -> MOTOR VEHICLE ACCOUNT | N37: 0 | O37: 0 | P37: 0 | Q37: 0 | R37: 0 | S37: 0 | T37: =SUM(N37:S37) -> 0 | U37: 0 | V37: 0 | W37: 0 | X37: 0 | Y37: =SUM(U37:X37) -> 0 | Z37: 0 | AA37: 0 | AB37: 0 | AC37: 0 | AD37: =SUM(Z37:AC37) -> 0 | AE37: =N37 +U37-Z37 -> 0 | AF37: =O37 +V37-AA37 -> 0 | AG37: =P37 +W37-AB37 -> 0 | AH37: =Q37 +X37-AC37 -> 0 | AI37: =R37 -> 0 | AJ37: =S37 -> 0 | AK37: =SUM(AE37:AJ37) -> 0
A38: 19 | C38: F | F38: 0559 | G38: 0001 | H38: =F38&G38 -> 05590001 | I38: =IF(ISNA(VLOOKUP(G38,GAAP02F[[#All],[Column1]:[FundHier1]],5,FALSE)),"Leases",(VLOOKUP(G38,GAAP02F[[#All],[Column1]:[FundHier1]],5,FALSE))) -> 100 | J38: =IF(ISNA(VLOOKUP(F38,Table_GAAP02A[[#All],[Agency]:[Hier1]],4,FALSE)),"Abolished Agency",(VLOOKUP(F38,Table_GAAP02A[[#All],[Agency]:[Hier1]],4,FALSE))) -> 0815 | K38: =IF(ISNA(VLOOKUP(F38,Table_GAAP02A[[#All],[Agency]:[Hier1]],2,FALSE)),"Abolished Agency",(VLOOKUP(F38,Table_GAAP02A[[#All],[Agency]:[Hier1]],2,FALSE))) -> HEALTH AND HUMAN SERVICES | L38: =IF(ISNA(VLOOKUP(F38,Table_GAAP02A[[#All],[Agency]:[Hier1]],3,FALSE)),"Abolished Agency",(VLOOKUP(F38,Table_GAAP02A[[#All],[Agency]:[Hier1]],3,FALSE))) -> SEC-LABOR-AND-WORKFORCE-DEVLMT | M38: =IF(ISNA(VLOOKUP(G38,GAAP02F[[#All],[Column1]:[FundName]],2,FALSE)),"Leases",(VLOOKUP(G38,GAAP02F[[#All],[Column1]:[FundName]],2,FALSE))) -> GENERAL FUND | N38: 0 | O38: 0 | P38: 0 | Q38: 0 | R38: 0 | S38: 0 | T38: =SUM(N38:S38) -> 0 | U38: 0 | V38: 0 | W38: 0 | X38: 0 | Y38: =SUM(U38:X38) -> 0 | Z38: 0 | AA38: 0 | AB38: 0 | AC38: 0 | AD38: =SUM(Z38:AC38) -> 0 | AE38: =N38 +U38-Z38 -> 0 | AF38: =O38 +V38-AA38 -> 0 | AG38: =P38 +W38-AB38 -> 0 | AH38: =Q38 +X38-AC38 -> 0 | AI38: =R38 -> 0 | AJ38: =S38 -> 0 | AK38: =SUM(AE38:AJ38) -> 0
A39: 19 | C39: F | F39: 0650 | G39: 0001 | H39: =F39&G39 -> 06500001 | I39: =IF(ISNA(VLOOKUP(G39,GAAP02F[[#All],[Column1]:[FundHier1]],5,FALSE)),"Leases",(VLOOKUP(G39,GAAP02F[[#All],[Column1]:[FundHier1]],5,FALSE))) -> 100 | J39: =IF(ISNA(VLOOKUP(F39,Table_GAAP02A[[#All],[Agency]:[Hier1]],4,FALSE)),"Abolished Agency",(VLOOKUP(F39,Table_GAAP02A[[#All],[Agency]:[Hier1]],4,FALSE))) -> 0808 | K39: =IF(ISNA(VLOOKUP(F39,Table_GAAP02A[[#All],[Agency]:[Hier1]],2,FALSE)),"Abolished Agency",(VLOOKUP(F39,Table_GAAP02A[[#All],[Agency]:[Hier1]],2,FALSE))) -> GENERAL GOVERNMENT | L39: =IF(ISNA(VLOOKUP(F39,Table_GAAP02A[[#All],[Agency]:[Hier1]],3,FALSE)),"Abolished Agency",(VLOOKUP(F39,Table_GAAP02A[[#All],[Agency]:[Hier1]],3,FALSE))) -> OFFICE OF PLANNING & RESEARCH | M39: =IF(ISNA(VLOOKUP(G39,GAAP02F[[#All],[Column1]:[FundName]],2,FALSE)),"Leases",(VLOOKUP(G39,GAAP02F[[#All],[Column1]:[FundName]],2,FALSE))) -> GENERAL FUND | N39: 0 | O39: 0 | P39: 0 | Q39: 0 | R39: 0 | S39: 0 | T39: =SUM(N39:S39) -> 0 | U39: 0 | V39: 0 | W39: 0 | X39: 0 | Y39: =SUM(U39:X39) -> 0 | Z39: 0 | AA39: 0 | AB39: 0 | AC39: 0 | AD39: =SUM(Z39:AC39) -> 0 | AE39: =N39 +U39-Z39 -> 0 | AF39: =O39 +V39-AA39 -> 0 | AG39: =P39 +W39-AB39 -> 0 | AH39: =Q39 +X39-AC39 -> 0 | AI39: =R39 -> 0 | AJ39: =S39 -> 0 | AK39: =SUM(AE39:AJ39) -> 0
A40: 19 | C40: F | F40: 0650 | G40: 0890 | H40: =F40&G40 -> 06500890 | I40: =IF(ISNA(VLOOKUP(G40,GAAP02F[[#All],[Column1]:[FundHier1]],5,FALSE)),"Leases",(VLOOKUP(G40,GAAP02F[[#All],[Column1]:[FundHier1]],5,FALSE))) -> 200 | J40: =IF(ISNA(VLOOKUP(F40,Table_GAAP02A[[#All],[Agency]:[Hier1]],4,FALSE)),"Abolished Agency",(VLOOKUP(F40,Table_GAAP02A[[#All],[Agency]:[Hier1]],4,FALSE))) -> 0808 | K40: =IF(ISNA(VLOOKUP(F40,Table_GAAP02A[[#All],[Agency]:[Hier1]],2,FALSE)),"Abolished Agency",(VLOOKUP(F40,Table_GAAP02A[[#All],[Agency]:[Hier1]],2,FALSE))) -> GENERAL GOVERNMENT | L40: =IF(ISNA(VLOOKUP(F40,Table_GAAP02A[[#All],[Agency]:[Hier1]],3,FALSE)),"Abolished Agency",(VLOOKUP(F40,Table_GAAP02A[[#All],[Agency]:[Hier1]],3,FALSE))) -> OFFICE OF PLANNING & RESEARCH | M40: =IF(ISNA(VLOOKUP(G40,GAAP02F[[#All],[Column1]:[FundName]],2,FALSE)),"Leases",(VLOOKUP(G40,GAAP02F[[#All],[Column1]:[FundName]],2,FALSE))) -> FEDERAL TRUST FUND | N40: 0 | O40: 0 | P40: 0 | Q40: 0 | R40: 0 | S40: 0 | T40: =SUM(N40:S40) -> 0 | U40: 0 | V40: 0 | W40: 0 | X40: 0 | Y40: =SUM(U40:X40) -> 0 | Z40: 0 | AA40: 0 | AB40: 0 | AC40: 0 | AD40: =SUM(Z40:AC40) -> 0 | AE40: =N40 +U40-Z40 -> 0 | AF40: =O40 +V40-AA40 -> 0 | AG40: =P40 +W40-AB40 -> 0 | AH40: =Q40 +X40-AC40 -> 0 | AI40: =R40 -> 0 | AJ40: =S40 -> 0 | AK40: =SUM(AE40:AJ40) -> 0
A41: 19 | C41: F | F41: 0650 | G41: 3228 | H41: =F41&G41 -> 06503228 | I41: =IF(ISNA(VLOOKUP(G41,GAAP02F[[#All],[Column1]:[FundHier1]],5,FALSE)),"Leases",(VLOOKUP(G41,GAAP02F[[#All],[Column1]:[FundHier1]],5,FALSE))) -> 200 | J41: =IF(ISNA(VLOOKUP(F41,Table_GAAP02A[[#All],[Agency]:[Hier1]],4,FALSE)),"Abolished Agency",(VLOOKUP(F41,Table_GAAP02A[[#All],[Agency]:[Hier1]],4,FALSE))) -> 0808 | K41: =IF(ISNA(VLOOKUP(F41,Table_GAAP02A[[#All],[Agency]:[Hier1]],2,FALSE)),"Abolished Agency",(VLOOKUP(F41,Table_GAAP02A[[#All],[Agency]:[Hier1]],2,FALSE))) -> GENERAL GOVERNMENT | L41: =IF(ISNA(VLOOKUP(F41,Table_GAAP02A[[#All],[Agency]:[Hier1]],3,FALSE)),"Abolished Agency",(VLOOKUP(F41,Table_GAAP02A[[#All],[Agency]:[Hier1]],3,FALSE))) -> OFFICE OF PLANNING & RESEARCH | M41: =IF(ISNA(VLOOKUP(G41,GAAP02F[[#All],[Column1]:[FundName]],2,FALSE)),"Leases",(VLOOKUP(G41,GAAP02F[[#All],[Column1]:[FundName]],2,FALSE))) -> GREENHOUSE GAS REDUCTION FD | N41: 0 | O41: 0 | P41: 0 | Q41: 0 | R41: 0 | S41: 0 | T41: =SUM(N41:S41) -> 0 | U41: 0 | V41: 0 | W41: 0 | X41: 0 | Y41: =SUM(U41:X41) -> 0 | Z41: 0 | AA41: 0 | AB41: 0 | AC41: 0 | AD41: =SUM(Z41:AC41) -> 0 | AE41: =N41 +U41-Z41 -> 0 | AF41: =O41 +V41-AA41 -> 0 | AG41: =P41 +W41-AB41 -> 0 | AH41: =Q41 +X41-AC41 -> 0 | AI41: =R41 -> 0 | AJ41: =S41 -> 0 | AK41: =SUM(AE41:AJ41) -> 0
...

Sheet 2. Totals by Asset & Exp Code
A1: Capital Assets - Governmental Funds (Non-CSU) | D1: Source: | E1: Tab 1
A2: Assets by Type and Function | D2: Purpose: | E2: Consolidate tab 1 by major capital asset catergory and by function
A3: ='1. Rpt 18s (non-CSU)'!$A$3 -> as of June 30, 2024 | D3: Procedures: | E3: N/A-Spreadsheet is formula driven
A5: Land-0446 | H5: For input in Governmental Activities Workbook only
C6: (Restated) | H6: Amounts in thousands
A7: Expense Code | B7: Function | C7: Beginning Balance | D7: Additions | E7: Deductions | F7: Ending Balance | H7: Beginning Balance | I7: Additions | J7: Deductions | K7: Ending Balance
A8: 808 | B8: General Government | C8: =SUM(SUMIFS('1. Rpt 18s (non-CSU)'!R$9:R$555,'1. Rpt 18s (non-CSU)'!$J$9:$J$555,A8,'1. Rpt 18s (non-CSU)'!$I$9:$I$555,100),SUMIFS('1. Rpt 18s (non-CSU)'!R$9:R$555,'1. Rpt 18s (non-CSU)'!$J$9:$J$555,A8,'1. Rpt 18s (non-CSU)'!$I$9:$I$555,200),SUMIFS('1. Rpt 18s (non-CSU)'!R$9:R$555,'1. Rpt 18s (non-CSU)'!$J$9:$J$555,A8,'1. Rpt 18s (non-CSU)'!$I$9:$I$555,300)) -> 0 | D8: 0 | E8: 0 | F8: =+C8 +D8-E8 -> 0
A9: 810 | B9: Education | C9: =SUM(SUMIFS('1. Rpt 18s (non-CSU)'!R$9:R$555,'1. Rpt 18s (non-CSU)'!$J$9:$J$555,A9,'1. Rpt 18s (non-CSU)'!$I$9:$I$555,100),SUMIFS('1. Rpt 18s (non-CSU)'!R$9:R$555,'1. Rpt 18s (non-CSU)'!$J$9:$J$555,A9,'1. Rpt 18s (non-CSU)'!$I$9:$I$555,200),SUMIFS('1. Rpt 18s (non-CSU)'!R$9:R$555,'1. Rpt 18s (non-CSU)'!$J$9:$J$555,A9,'1. Rpt 18s (non-CSU)'!$I$9:$I$555,300)) -> 0 | D9: 0 | E9: 0 | F9: =+C9 +D9-E9 -> 0
A10: 815 | B10: Health & Human Services | C10: =SUM(SUMIFS('1. Rpt 18s (non-CSU)'!R$9:R$555,'1. Rpt 18s (non-CSU)'!$J$9:$J$555,A10,'1. Rpt 18s (non-CSU)'!$I$9:$I$555,100),SUMIFS('1. Rpt 18s (non-CSU)'!R$9:R$555,'1. Rpt 18s (non-CSU)'!$J$9:$J$555,A10,'1. Rpt 18s (non-CSU)'!$I$9:$I$555,200),SUMIFS('1. Rpt 18s (non-CSU)'!R$9:R$555,'1. Rpt 18s (non-CSU)'!$J$9:$J$555,A10,'1. Rpt 18s (non-CSU)'!$I$9:$I$555,300)) -> 0 | D10: 0 | E10: 0 | F10: =+C10 +D10-E10 -> 0
A11: 820 | B11: Natural Resources & Environmental Protection | C11: =SUM(SUMIFS('1. Rpt 18s (non-CSU)'!R$9:R$555,'1. Rpt 18s (non-CSU)'!$J$9:$J$555,A11,'1. Rpt 18s (non-CSU)'!$I$9:$I$555,100),SUMIFS('1. Rpt 18s (non-CSU)'!R$9:R$555,'1. Rpt 18s (non-CSU)'!$J$9:$J$555,A11,'1. Rpt 18s (non-CSU)'!$I$9:$I$555,200),SUMIFS('1. Rpt 18s (non-CSU)'!R$9:R$555,'1. Rpt 18s (non-CSU)'!$J$9:$J$555,A11,'1. Rpt 18s (non-CSU)'!$I$9:$I$555,300)) -> 0 | D11: 0 | E11: 0 | F11: =+C11 +D11-E11 -> 0
A12: 825 | B12: Business, Consumer Services, & Housing | C12: =SUM(SUMIFS('1. Rpt 18s (non-CSU)'!R$9:R$555,'1. Rpt 18s (non-CSU)'!$J$9:$J$555,A12,'1. Rpt 18s (non-CSU)'!$I$9:$I$555,100),SUMIFS('1. Rpt 18s (non-CSU)'!R$9:R$555,'1. Rpt 18s (non-CSU)'!$J$9:$J$555,A12,'1. Rpt 18s (non-CSU)'!$I$9:$I$555,200),SUMIFS('1. Rpt 18s (non-CSU)'!R$9:R$555,'1. Rpt 18s (non-CSU)'!$J$9:$J$555,A12,'1. Rpt 18s (non-CSU)'!$I$9:$I$555,300)) -> 0 | D12: 0 | E12: 0 | F12: =+C12 +D12-E12 -> 0
A13: 830 | B13: Transportation | C13: =SUM(SUMIFS('1. Rpt 18s (non-CSU)'!R$9:R$555,'1. Rpt 18s (non-CSU)'!$J$9:$J$555,A13,'1. Rpt 18s (non-CSU)'!$I$9:$I$555,100),SUMIFS('1. Rpt 18s (non-CSU)'!R$9:R$555,'1. Rpt 18s (non-CSU)'!$J$9:$J$555,A13,'1. Rpt 18s (non-CSU)'!$I$9:$I$555,200),SUMIFS('1. Rpt 18s (non-CSU)'!R$9:R$555,'1. Rpt 18s (non-CSU)'!$J$9:$J$555,A13,'1. Rpt 18s (non-CSU)'!$I$9:$I$555,300)) -> 0 | D13: 0 | E13: 0 | F13: =+C13 +D13-E13 -> 0
A14: 835 | B14: Corrections and Rehabilitation | C14: =SUM(SUMIFS('1. Rpt 18s (non-CSU)'!R$9:R$555,'1. Rpt 18s (non-CSU)'!$J$9:$J$555,A14,'1. Rpt 18s (non-CSU)'!$I$9:$I$555,100),SUMIFS('1. Rpt 18s (non-CSU)'!R$9:R$555,'1. Rpt 18s (non-CSU)'!$J$9:$J$555,A14,'1. Rpt 18s (non-CSU)'!$I$9:$I$555,200),SUMIFS('1. Rpt 18s (non-CSU)'!R$9:R$555,'1. Rpt 18s (non-CSU)'!$J$9:$J$555,A14,'1. Rpt 18s (non-CSU)'!$I$9:$I$555,300)) -> 0 | D14: 0 | E14: 0 | F14: =+C14 +D14-E14 -> 0
B15: Total | C15: =SUM(C8:C14) -> 0 | D15: =SUM(D8:D14) -> 0 | E15: =SUM(E8:E14) -> 0 | F15: =SUM(F8:F14) -> 0 | H15: =ROUND(C15,0)/1000 -> 0 | I15: =ROUND(D15,0)/1000 -> 0 | J15: =ROUND(E15,0)/1000 -> 0 | K15: =ROUND(F15,0)/1000 -> 0
A18: Building & Building Improvements-0448
A19: (Reported as Structures) | C19: (Restated)
A20: Expense Code | B20: Function | C20: Beginning Balance | D20: Additions | E20: Deductions | F20: Ending Balance
A21: 808 | B21: General Government | C21: =SUM(SUMIFS('1. Rpt 18s (non-CSU)'!S$9:S$555,'1. Rpt 18s (non-CSU)'!$J$9:$J$555,A21,'1. Rpt 18s (non-CSU)'!$I$9:$I$555,100),SUMIFS('1. Rpt 18s (non-CSU)'!S$9:S$555,'1. Rpt 18s (non-CSU)'!$J$9:$J$555,A21,'1. Rpt 18s (non-CSU)'!$I$9:$I$555,200),SUMIFS('1. Rpt 18s (non-CSU)'!S$9:S$555,'1. Rpt 18s (non-CSU)'!$J$9:$J$555,A21,'1. Rpt 18s (non-CSU)'!$I$9:$I$555,300)) -> 0 | D21: 0 | E21: 0 | F21: =+C21+D21-E21 -> 0
A22: 810 | B22: Education | C22: =SUM(SUMIFS('1. Rpt 18s (non-CSU)'!S$9:S$555,'1. Rpt 18s (non-CSU)'!$J$9:$J$555,A22,'1. Rpt 18s (non-CSU)'!$I$9:$I$555,100),SUMIFS('1. Rpt 18s (non-CSU)'!S$9:S$555,'1. Rpt 18s (non-CSU)'!$J$9:$J$555,A22,'1. Rpt 18s (non-CSU)'!$I$9:$I$555,200),SUMIFS('1. Rpt 18s (non-CSU)'!S$9:S$555,'1. Rpt 18s (non-CSU)'!$J$9:$J$555,A22,'1. Rpt 18s (non-CSU)'!$I$9:$I$555,300)) -> 0 | D22: 0 | E22: 0 | F22: =+C22+D22-E22 -> 0
A23: 815 | B23: Health & Human Services | C23: =SUM(SUMIFS('1. Rpt 18s (non-CSU)'!S$9:S$555,'1. Rpt 18s (non-CSU)'!$J$9:$J$555,A23,'1. Rpt 18s (non-CSU)'!$I$9:$I$555,100),SUMIFS('1. Rpt 18s (non-CSU)'!S$9:S$555,'1. Rpt 18s (non-CSU)'!$J$9:$J$555,A23,'1. Rpt 18s (non-CSU)'!$I$9:$I$555,200),SUMIFS('1. Rpt 18s (non-CSU)'!S$9:S$555,'1. Rpt 18s (non-CSU)'!$J$9:$J$555,A23,'1. Rpt 18s (non-CSU)'!$I$9:$I$555,300)) -> 0 | D23: 0 | E23: 0 | F23: =+C23+D23-E23 -> 0
A24: 820 | B24: Natural Resources & Environmental Protection | C24: =SUM(SUMIFS('1. Rpt 18s (non-CSU)'!S$9:S$555,'1. Rpt 18s (non-CSU)'!$J$9:$J$555,A24,'1. Rpt 18s (non-CSU)'!$I$9:$I$555,100),SUMIFS('1. Rpt 18s (non-CSU)'!S$9:S$555,'1. Rpt 18s (non-CSU)'!$J$9:$J$555,A24,'1. Rpt 18s (non-CSU)'!$I$9:$I$555,200),SUMIFS('1. Rpt 18s (non-CSU)'!S$9:S$555,'1. Rpt 18s (non-CSU)'!$J$9:$J$555,A24,'1. Rpt 18s (non-CSU)'!$I$9:$I$555,300)) -> 0 | D24: 0 | E24: 0 | F24: =+C24+D24-E24 -> 0
A25: 825 | B25: Business, Consumer Services, & Housing | C25: =SUM(SUMIFS('1. Rpt 18s (non-CSU)'!S$9:S$555,'1. Rpt 18s (non-CSU)'!$J$9:$J$555,A25,'1. Rpt 18s (non-CSU)'!$I$9:$I$555,100),SUMIFS('1. Rpt 18s (non-CSU)'!S$9:S$555,'1. Rpt 18s (non-CSU)'!$J$9:$J$555,A25,'1. Rpt 18s (non-CSU)'!$I$9:$I$555,200),SUMIFS('1. Rpt 18s (non-CSU)'!S$9:S$555,'1. Rpt 18s (non-CSU)'!$J$9:$J$555,A25,'1. Rpt 18s (non-CSU)'!$I$9:$I$555,300)) -> 0 | D25: 0 | E25: 0 | F25: =+C25+D25-E25 -> 0
A26: 830 | B26: Transportation | C26: =SUM(SUMIFS('1. Rpt 18s (non-CSU)'!S$9:S$555,'1. Rpt 18s (non-CSU)'!$J$9:$J$555,A26,'1. Rpt 18s (non-CSU)'!$I$9:$I$555,100),SUMIFS('1. Rpt 18s (non-CSU)'!S$9:S$555,'1. Rpt 18s (non-CSU)'!$J$9:$J$555,A26,'1. Rpt 18s (non-CSU)'!$I$9:$I$555,200),SUMIFS('1. Rpt 18s (non-CSU)'!S$9:S$555,'1. Rpt 18s (non-CSU)'!$J$9:$J$555,A26,'1. Rpt 18s (non-CSU)'!$I$9:$I$555,300)) -> 0 | D26: 0 | E26: 0 | F26: =+C26+D26-E26 -> 0
A27: 835 | B27: Corrections and Rehabilitation | C27: =SUM(SUMIFS('1. Rpt 18s (non-CSU)'!S$9:S$555,'1. Rpt 18s (non-CSU)'!$J$9:$J$555,A27,'1. Rpt 18s (non-CSU)'!$I$9:$I$555,100),SUMIFS('1. Rpt 18s (non-CSU)'!S$9:S$555,'1. Rpt 18s (non-CSU)'!$J$9:$J$555,A27,'1. Rpt 18s (non-CSU)'!$I$9:$I$555,200),SUMIFS('1. Rpt 18s (non-CSU)'!S$9:S$555,'1. Rpt 18s (non-CSU)'!$J$9:$J$555,A27,'1. Rpt 18s (non-CSU)'!$I$9:$I$555,300)) -> 0 | D27: 0 | E27: 0 | F27: =+C27+D27-E27 -> 0
B28: Total | C28: =SUM(C21:C27) -> 0 | D28: =SUM(D21:D27) -> 0 | E28: =SUM(E21:E27) -> 0 | F28: =SUM(F21:F27) -> 0 | H28: =ROUND(C28,0)/1000 -> 0 | I28: =ROUND(D28,0)/1000 -> 0 | J28: =ROUND(E28,0)/1000 -> 0 | K28: =ROUND(F28,0)/1000 -> 0
A31: Other Tangible Assets(Non-amortizable)-0447
A33: Expense Code | B33: Function | C33: Beginning Balance | D33: Additions | E33: Deductions | F33: Ending Balance
A34: 808 | B34: General Government | C34: =SUMIF('1. Rpt 18s (non-CSU)'!$J$9:$J$555,A34,'1. Rpt 18s (non-CSU)'!#REF!) -> #REF! | D34: =SUMIF('1. Rpt 18s (non-CSU)'!$J$9:$J$555,A34,'1. Rpt 18s (non-CSU)'!#REF!) -> #REF! | E34: =SUMIF('1. Rpt 18s (non-CSU)'!$J$9:$J$555,A34,'1. Rpt 18s (non-CSU)'!#REF!) -> #REF! | F34: =+C34 +D34-E34 -> #REF!
A35: 810 | B35: Education | C35: =SUMIF('1. Rpt 18s (non-CSU)'!$J$9:$J$555,A35,'1. Rpt 18s (non-CSU)'!#REF!) -> #REF! | D35: =SUMIF('1. Rpt 18s (non-CSU)'!$J$9:$J$555,A35,'1. Rpt 18s (non-CSU)'!#REF!) -> #REF! | E35: =SUMIF('1. Rpt 18s (non-CSU)'!$J$9:$J$555,A35,'1. Rpt 18s (non-CSU)'!#REF!) -> #REF! | F35: =+C35 +D35-E35 -> #REF!
A36: 815 | B36: Health & Human Services | C36: =SUMIF('1. Rpt 18s (non-CSU)'!$J$9:$J$555,A36,'1. Rpt 18s (non-CSU)'!#REF!) -> #REF! | D36: =SUMIF('1. Rpt 18s (non-CSU)'!$J$9:$J$555,A36,'1. Rpt 18s (non-CSU)'!#REF!) -> #REF! | E36: =SUMIF('1. Rpt 18s (non-CSU)'!$J$9:$J$555,A36,'1. Rpt 18s (non-CSU)'!#REF!) -> #REF! | F36: =+C36 +D36-E36 -> #REF!
A37: 820 | B37: Natural Resources & Environmental Protection | C37: =SUMIF('1. Rpt 18s (non-CSU)'!$J$9:$J$555,A37,'1. Rpt 18s (non-CSU)'!#REF!) -> #REF! | D37: =SUMIF('1. Rpt 18s (non-CSU)'!$J$9:$J$555,A37,'1. Rpt 18s (non-CSU)'!#REF!) -> #REF! | E37: =SUMIF('1. Rpt 18s (non-CSU)'!$J$9:$J$555,A37,'1. Rpt 18s (non-CSU)'!#REF!) -> #REF! | F37: =+C37 +D37-E37 -> #REF!
A38: 825 | B38: Business, Consumer Services, & Housing | C38: =SUMIF('1. Rpt 18s (non-CSU)'!$J$9:$J$555,A38,'1. Rpt 18s (non-CSU)'!#REF!) -> #REF! | D38: =SUMIF('1. Rpt 18s (non-CSU)'!$J$9:$J$555,A38,'1. Rpt 18s (non-CSU)'!#REF!) -> #REF! | E38: =SUMIF('1. Rpt 18s (non-CSU)'!$J$9:$J$555,A38,'1. Rpt 18s (non-CSU)'!#REF!) -> #REF! | F38: =+C38 +D38-E38 -> #REF!
A39: 830 | B39: Transportation | C39: =SUMIF('1. Rpt 18s (non-CSU)'!$J$9:$J$555,A39,'1. Rpt 18s (non-CSU)'!#REF!) -> #REF! | D39: =SUMIF('1. Rpt 18s (non-CSU)'!$J$9:$J$555,A39,'1. Rpt 18s (non-CSU)'!#REF!) -> #REF! | E39: =SUMIF('1. Rpt 18s (non-CSU)'!$J$9:$J$555,A39,'1. Rpt 18s (non-CSU)'!#REF!) -> #REF! | F39: =+C39 +D39-E39 -> #REF!
A40: 835 | B40: Corrections and Rehabilitation | C40: =SUMIF('1. Rpt 18s (non-CSU)'!$J$9:$J$555,A40,'1. Rpt 18s (non-CSU)'!#REF!) -> #REF! | D40: =SUMIF('1. Rpt 18s (non-CSU)'!$J$9:$J$555,A40,'1. Rpt 18s (non-CSU)'!#REF!) -> #REF! | E40: =SUMIF('1. Rpt 18s (non-CSU)'!$J$9:$J$555,A40,'1. Rpt 18s (non-CSU)'!#REF!) -> #REF! | F40: =+C40 +D40-E40 -> #REF!
B41: Total | C41: =SUM(C34:C40) -> #REF! | D41: =SUM(D34:D40) -> #REF! | E41: =SUM(E34:E40) -> #REF! | F41: =SUM(F34:F40) -> #REF! | H41: =ROUND(C41,0)/1000 -> #REF! | I41: =ROUND(D41,0)/1000 -> #REF! | J41: =ROUND(E41,0)/1000 -> #REF! | K41: =ROUND(F41,0)/1000 -> #REF!
C42: =IF(C41='1. Rpt 18s (non-CSU)'!#REF!,"OK","Formula Error") -> #REF! | D42: =IF(D41='1. Rpt 18s (non-CSU)'!#REF!,"OK","Formula Error") -> #REF! | E42: =IF(E41='1. Rpt 18s (non-CSU)'!#REF!,"OK","Formula Error") -> #REF! | F42: =IF(F41='1. Rpt 18s (non-CSU)'!#REF!,"OK","Formula Error") -> #REF!
A44: Improvements Other Than Buildings-0449
A45: (Reported as Structures) | C45: (Restated)
