Workbook
Name ActuaryCredentialsGASB: [1]DeveloperInfo!$D$19
Name ActuaryNameGASB: [1]DeveloperInfo!$D$17
Name ActuaryTitleGASB: [1]DeveloperInfo!$D$18
Name AdjCNSDate: [1]DeveloperInfo!$D$33
Name AdjCNSDate1: [1]DeveloperInfo!$E$33
Name AdjCNSDateTempEnable: [1]DeveloperInfo!$F$34
Name AgencyCode: #REF!
Name AgencyCode: #REF!
Name AgencyCode1: #REF!
Name AgencyCode1: #REF!
Name AnalystGASB: [1]DeveloperInfo!$D$20
Name Annuity: #REF!
Name Annuity: #REF!
Name Annuity1: #REF!
Name Annuity1: #REF!
Name AnnuityLY: #REF!
Name AnnuityLY: #REF!
Name ASTABPF: [1]DeveloperInfo!$D$36
Name ASTABPF1: [1]DeveloperInfo!$D$37
Name ASTEBPF: [1]DeveloperInfo!$F$37
Name ClientShortGASB: [1]DeveloperInfo!$D$9
Name CLPOWERDisc: [1]Adjust!$H$199
Name CLPOWERDiscMinus1: [1]Adjust!$L$199
Name CLPOWERDiscPlus1: [1]Adjust!$K$199
Name CLPOWERExp: [1]Adjust!$G$199
Name CNSDateDisc: [1]DeveloperInfo!$D$32
Name CNSDateDisc1: [1]DeveloperInfo!$E$32
Name ColaRate: [1]DeveloperInfo!$D$40
Name ConsultantNameGASB: [1]DeveloperInfo!$D$22
Name ConsultantTitleGASB: [1]DeveloperInfo!$D$23
Name Disc1DELTACENSUS: [1]Adjust!$G$102
Name Disc1INTNDIV12: [1]Adjust!$H$195
Name Disc1SINTADJBOM: [1]Adjust!$I$197
Name Disc1SINTNDIV12: [1]Adjust!$I$195
Name DiscDELTACENSUS: [1]Adjust!$H$102
Name DiscINTADJBOM: [1]Adjust!$J$197
Name DiscINTNDIV12: [1]Adjust!$J$195
Name DiscMinusOneINTADJBOM: [1]Adjust!$L$197
Name DiscMinusOneINTNDIV12: [1]Adjust!$L$195
Name DiscPlusOneINTADJBOM: [1]Adjust!$K$197
Name DiscPlusOneINTNDIV12: [1]Adjust!$K$195
Name EmployerRates: #REF!
Name EmployerRates: #REF!
Name EmployerRates1: #REF!
Name EmployerRates1: #REF!
Name EmployerRatesLEO: #REF!
Name EmployerRatesLEO: #REF!
Name EmployerRatesLEO1: #REF!
Name EmployerRatesLEO1: #REF!
Name ERData: [1]ER_DATA!$B$16:$EN$318
Name ERID: [1]ER_NPLExpense!$L$8
Name ERInfo: [1]ER_Input!$B$16:$Y$318
Name Exp1INTADJBOM: [1]Adjust!$G$197
Name Exp1INTNDIV12: [1]Adjust!$G$195
Name FracYearProj: [1]TPL!$C$43
Name FundOfficeContactGASB: [1]DeveloperInfo!$D$10
Name FYrsGASB: [1]DeveloperInfo!$D$54
Name GainLoss: [1]ER_Allocation!$P$12
Name GASBDiscMinusOneINTADJBOM: [1]Adjust!$L$197
Name GASBDiscMinusOneINTNDIV12: [1]Adjust!$L$195

Sheet LS-Fund 0042 Journal Entries
A1: Lessee-Type Contracts Fund-by-Fund Journal Entries Form (to be submitted to the SCO annually—one form per fund)
A2: Manually complete every yellow field in this worksheet—there are no automatically calculated data-entry cells in this worksheet.
A3: Fiscal Year: | F3: 2022–2023
A4: Organization Name: | F4: Department of Transportation
A5: Organization Code (4-Digits): | F5: 2660
A6: Fund Number (4-Digits): | F6: 42
A7: Fund Classification: | F7: Governmental
A8: Fund Type: | F8: Governmental Fund
A9: Functional Expense: | F9: =IFERROR(IF(F7="Proprietary","Proprietary Fund",VLOOKUP(F5,[2]qryIndex02a!$A$2:$K$654,4,FALSE)),"Unidentified") -> TRANSPORTATION
A12: Establish Beginning Balances (existing leases only)
A13: Entry #
A14: 0 | B14: Roll forward prior year right-to-use leases to record opening balances. | M14: Combined Lessee Templates | P14: From SCO BB List | S14: Difference
A15: *Rpt 18 | B15: Dr: Acct 0476 - RIGHT-TO-USE LEASED LAND - AMORTIZABLE | J15: =M15 -> 0 | P15: 0 | S15: =P15-M15 -> 0
A16: *Rpt 18 | B16: Dr: Acct 0478 - RIGHT-TO-USE LEASED EQUIPMENT - AMORTIZABLE | J16: =M16 -> 0 | P16: 0 | S16: =P16-M16 -> 0
A17: *Rpt 18 | B17: Dr: Acct 0477 - RIGHT-TO-USE LEASED BUILDINGS - AMORTIZABLE | J17: =M17 -> 88282279 | M17: 88282279 | P17: 88282279 | S17: =P17-M17 -> 0.20515753
B18: Dr: Acct 0950 - BEGINNING FUND BALANCE | J18: =P18 -> 295241 | M18: 361780.37 | P18: =IF(SUM($Q$21:$Q$23)>SUM($P$15:$P$17),SUM($Q$21:$Q$23)-SUM($P$15:$P$17),0) -> 295241 | S18: =P18-M18 -> -66539.374
B19: Dr: Acct 0952 - BEGINNING FUND ADJUSTMENT/PRIOR PERIOD ADJUSTMENT | J19: =IF(SUM($K$21:$K$24)>SUM($J$15:$J$18),SUM($K$21:$K$24)-SUM($J$15:$J$18),0) -> 0 | S19: =P19-M19 -> 0
C20: Cr: Acct 0485 - ACCUMULATED AMORTIZATION - RIGHT-TO-USE LEASED LAND | K20: =N20 -> 0 | Q20: 0 | S20: =P20-M20 -> 0
C21: Cr: Acct 0479 - ACCUMULATED AMORTIZATION - RIGHT-TO-USE LEASED EQUIPMENT | K21: =N21 -> 0 | Q21: 0 | S21: =Q21-N21 -> 0
C22: Cr: Acct 0486 - ACCUMULATED AMORTIZATION - RIGHT-TO-USE LEASED BUILDINGS | K22: =N22 -> 18684623 | N22: 18684623 | Q22: 18684623 | S22: =Q22-N22 -> -0.10120259
A23: **LS LL/CF | C23: Cr: Acct 0691 - RIGHT-TO-USE LEASE LIABILITY | K23: =N23 -> 69892896 | N23: 69892896 | Q23: 69892897 | S23: =Q23-N23 -> 0.6374571
C24: Cr: Acct 0950 - BEGINNING FUND BALANCE | K24: =Q24 -> 0 | N24: -66539.705 | Q24: =IF(SUM($Q$39:$Q$41)<SUM($P$33:$P$35),-SUM($Q$39:$Q$41)+SUM($P$33:$P$35),0) -> 0 | S24: =Q24-N24 -> 66539.705
C25: Cr: Acct 0952 - BEGINNING FUND ADJUSTMENT/PRIOR PERIOD ADJUSTMENT | K25: =IF(SUM($K$21:$K$24)<SUM($J$15:$J$18),-SUM($K$21:$K$24)+SUM($J$15:$J$18),0) -> 0.33109698 | S25: =Q25-N25 -> 0
J26: =SUM(J15:J25) -> 88577520 | K26: =SUM(K15:K25) -> 88577520 | L26: =IF(J26=K26,"<- Debits and Credits equal each other.","<- Debits and Credits do not equal each other.") -> <- Debits and Credits equal each other.
B27: * THESE ASSET AMOUNTS SHOULD BE REPORTED AS BEGINNING BALANCES ON REPORT 18.
B28: ** This amount should be included in the beginning balance column on the LS-Lease Liability and LS-Check Figures Tabs.
A31: Record New Leases (new leases only)
A32: 1 | B32: Record lease contract commencement (fund-based entries only)
B33: Dr: Acct 0842 - CAPITAL OUTLAY | J33: 4233405.7
C34: Cr: Acct 0789 - LEASE AND OTHER FINANCING PROCEEDS | K34: 4233405.7
C35: =IF($F$7="Proprietary","Cr: Acct 0870 - SERVICES & CHARGES (MG ADJ)",VLOOKUP($F$9,'[2]Drop Down Menus'!$F$2:$G$10,2,FALSE)) -> Cr: Acct 0830 - TRANSPORTATION (GAAP ADJ)
J36: =SUM(J33:J35) -> 4233405.7 | K36: =SUM(K33:K35) -> 4233405.7 | L36: =IF(J36=K36,"<- Debits and Credits equal each other.","<- Debits and Credits do not equal each other.") -> <- Debits and Credits equal each other.
A38: 2 | B38: Record leased assets.
A39: *Rpt 18 | B39: Dr: Acct 0476 - RIGHT-TO-USE LEASED LAND - AMORTIZABLE
A40: *Rpt 18 | B40: Dr: Acct 0478 - RIGHT-TO-USE LEASED EQUIPMENT - AMORTIZABLE
A41: *Rpt 18 | B41: Dr: Acct 0477 - RIGHT-TO-USE LEASED BUILDINGS - AMORTIZABLE | J41: 4233405.7
C42: Cr: Acct 0842 - CAPITAL OUTLAY | K42: 4233405.7
B43: * THESE AMOUNTS SHOULD BE INCLUDED AS "ADDITIONS" ON REPORT 18. | J43: =SUM(J39:J42) -> 4233405.7 | K43: =SUM(K39:K42) -> 4233405.7 | L43: =IF(J43=K43,"<- Debits and Credits equal each other.","<- Debits and Credits do not equal each other.") -> <- Debits and Credits equal each other.
A46: 3 | B46: Replace proceeds from leases with right-to-use lease liability.
B47: Dr: Acct 0789 - LEASE AND OTHER FINANCING PROCEEDS | J47: 4233405.7
...

Sheet LS-Fund 0046 Journal Entrie
A1: Lessee-Type Contracts Fund-by-Fund Journal Entries Form (to be submitted to the SCO annually—one form per fund)
A2: Manually complete every yellow field in this worksheet—there are no automatically calculated data-entry cells in this worksheet.
A3: Fiscal Year: | F3: 2022–2023
A4: Organization Name: | F4: Department of Transportation
A5: Organization Code (4-Digits): | F5: 2660
A6: Fund Number (4-Digits): | F6: 46
A7: Fund Classification: | F7: Governmental
A8: Fund Type: | F8: Governmental Fund
A9: Functional Expense: | F9: =IFERROR(IF(F7="Proprietary","Proprietary Fund",VLOOKUP(F5,[2]qryIndex02a!$A$2:$K$654,4,FALSE)),"Unidentified") -> TRANSPORTATION
A12: Establish Beginning Balances (existing leases only)
A13: Entry #
A14: 0 | B14: Roll forward prior year right-to-use leases to record opening balances. | M14: Combined Lessee Templates | P14: From SCO BB List | S14: Difference
A15: *Rpt 18 | B15: Dr: Acct 0476 - RIGHT-TO-USE LEASED LAND - AMORTIZABLE | J15: =M15 -> 0 | P15: 0 | S15: =P15-M15 -> 0
A16: *Rpt 18 | B16: Dr: Acct 0478 - RIGHT-TO-USE LEASED EQUIPMENT - AMORTIZABLE | J16: =M16 -> 0 | M16: 0 | P16: 0 | S16: =P16-M16 -> 0
A17: *Rpt 18 | B17: Dr: Acct 0477 - RIGHT-TO-USE LEASED BUILDINGS - AMORTIZABLE | J17: =M17 -> 0 | P17: 0 | S17: =P17-M17 -> 0
B18: Dr: Acct 0950 - BEGINNING FUND BALANCE | J18: =P18 -> 0 | M18: 0 | P18: =IF(SUM($Q$21:$Q$23)>SUM($P$15:$P$17),SUM($Q$21:$Q$23)-SUM($P$15:$P$17),0) -> 0 | S18: =P18-M18 -> 0
B19: Dr: Acct 0952 - BEGINNING FUND ADJUSTMENT/PRIOR PERIOD ADJUSTMENT | J19: =IF(SUM($K$21:$K$24)>SUM($J$15:$J$18),SUM($K$21:$K$24)-SUM($J$15:$J$18),0) -> 0 | M19: 0 | S19: =P19-M19 -> 0
C20: Cr: Acct 0485 - ACCUMULATED AMORTIZATION - RIGHT-TO-USE LEASED LAND | K20: =N20 -> 0 | Q20: 0 | S20: =P20-M20 -> 0
C21: Cr: Acct 0479 - ACCUMULATED AMORTIZATION - RIGHT-TO-USE LEASED EQUIPMENT | K21: =N21 -> 0 | N21: 0 | Q21: 0 | S21: =Q21-N21 -> 0
C22: Cr: Acct 0486 - ACCUMULATED AMORTIZATION - RIGHT-TO-USE LEASED BUILDINGS | K22: =N22 -> 0 | Q22: 0 | S22: =Q22-N22 -> 0
A23: **LS LL/CF | C23: Cr: Acct 0691 - RIGHT-TO-USE LEASE LIABILITY | K23: =N23 -> 0 | N23: 0 | Q23: 0 | S23: =Q23-N23 -> 0
C24: Cr: Acct 0950 - BEGINNING FUND BALANCE | K24: =Q24 -> 0 | N24: 0 | Q24: =IF(SUM($Q$39:$Q$41)<SUM($P$33:$P$35),-SUM($Q$39:$Q$41)+SUM($P$33:$P$35),0) -> 0 | S24: =Q24-N24 -> 0
C25: Cr: Acct 0952 - BEGINNING FUND ADJUSTMENT/PRIOR PERIOD ADJUSTMENT | K25: =IF(SUM($K$21:$K$24)<SUM($J$15:$J$18),-SUM($K$21:$K$24)+SUM($J$15:$J$18),0) -> 0 | N25: 0 | S25: =Q25-N25 -> 0
J26: =SUM(J15:J25) -> 0 | K26: =SUM(K15:K25) -> 0 | L26: =IF(J26=K26,"<- Debits and Credits equal each other.","<- Debits and Credits do not equal each other.") -> <- Debits and Credits equal each other.
B27: * THESE ASSET AMOUNTS SHOULD BE REPORTED AS BEGINNING BALANCES ON REPORT 18.
B28: ** This amount should be included in the beginning balance column on the LS-Lease Liability and LS-Check Figures Tabs.
A31: Record New Leases (new leases only)
A32: 1 | B32: Record lease contract commencement (fund-based entries only)
B33: Dr: Acct 0842 - CAPITAL OUTLAY | J33: 17089708
C34: Cr: Acct 0789 - LEASE AND OTHER FINANCING PROCEEDS | K34: 17089708
C35: =IF($F$7="Proprietary","Cr: Acct 0870 - SERVICES & CHARGES (MG ADJ)",VLOOKUP($F$9,'[2]Drop Down Menus'!$F$2:$G$10,2,FALSE)) -> Cr: Acct 0830 - TRANSPORTATION (GAAP ADJ)
J36: =SUM(J33:J35) -> 17089708 | K36: =SUM(K33:K35) -> 17089708 | L36: =IF(J36=K36,"<- Debits and Credits equal each other.","<- Debits and Credits do not equal each other.") -> <- Debits and Credits equal each other.
A38: 2 | B38: Record leased assets.
A39: *Rpt 18 | B39: Dr: Acct 0476 - RIGHT-TO-USE LEASED LAND - AMORTIZABLE
A40: *Rpt 18 | B40: Dr: Acct 0478 - RIGHT-TO-USE LEASED EQUIPMENT - AMORTIZABLE | J40: 17089708
A41: *Rpt 18 | B41: Dr: Acct 0477 - RIGHT-TO-USE LEASED BUILDINGS - AMORTIZABLE
C42: Cr: Acct 0842 - CAPITAL OUTLAY | K42: 17089708
B43: * THESE AMOUNTS SHOULD BE INCLUDED AS "ADDITIONS" ON REPORT 18. | J43: =SUM(J39:J42) -> 17089708 | K43: =SUM(K39:K42) -> 17089708 | L43: =IF(J43=K43,"<- Debits and Credits equal each other.","<- Debits and Credits do not equal each other.") -> <- Debits and Credits equal each other.
A46: 3 | B46: Replace proceeds from leases with right-to-use lease liability.
B47: Dr: Acct 0789 - LEASE AND OTHER FINANCING PROCEEDS | J47: 17089708
...

Sheet LS-Fund 3290 Journal Entrie
A1: Lessee-Type Contracts Fund-by-Fund Journal Entries Form (to be submitted to the SCO annually—one form per fund)
A2: Manually complete every yellow field in this worksheet—there are no automatically calculated data-entry cells in this worksheet.
A3: Fiscal Year: | F3: 2022–2023
A4: Organization Name: | F4: Department of Transportation
A5: Organization Code (4-Digits): | F5: 2660
A6: Fund Number (4-Digits): | F6: 3290
A7: Fund Classification: | F7: Governmental
A8: Fund Type: | F8: Governmental Fund
A9: Functional Expense: | F9: =IFERROR(IF(F7="Proprietary","Proprietary Fund",VLOOKUP(F5,[2]qryIndex02a!$A$2:$K$654,4,FALSE)),"Unidentified") -> TRANSPORTATION
A12: Establish Beginning Balances (existing leases only)
A13: Entry #
A14: 0 | B14: Roll forward prior year right-to-use leases to record opening balances. | M14: Combined Lessee Templates | P14: From SCO BB List | S14: Difference
A15: *Rpt 18 | B15: Dr: Acct 0476 - RIGHT-TO-USE LEASED LAND - AMORTIZABLE | J15: =M15 -> 0 | S15: =P15-M15 -> 0
A16: *Rpt 18 | B16: Dr: Acct 0478 - RIGHT-TO-USE LEASED EQUIPMENT - AMORTIZABLE | J16: =M16 -> 0 | S16: =P16-M16 -> 0
A17: *Rpt 18 | B17: Dr: Acct 0477 - RIGHT-TO-USE LEASED BUILDINGS - AMORTIZABLE | J17: =M17 -> 4195765.1 | M17: 4195765.1 | P17: 3763842 | S17: =P17-M17 -> -431923.13
B18: Dr: Acct 0950 - BEGINNING FUND BALANCE | J18: =P18 -> 17601 | M18: 17601.515 | P18: =IF(SUM($Q$21:$Q$23)>SUM($P$15:$P$17),SUM($Q$21:$Q$23)-SUM($P$15:$P$17),0) -> 17601 | S18: =P18-M18 -> -0.51484835
B19: Dr: Acct 0952 - BEGINNING FUND ADJUSTMENT/PRIOR PERIOD ADJUSTMENT | J19: =IF(SUM($K$21:$K$24)>SUM($J$15:$J$18),SUM($K$21:$K$24)-SUM($J$15:$J$18),0) -> 295.90153 | M19: 295 | S19: =P19-M19 -> -295
C20: Cr: Acct 0485 - ACCUMULATED AMORTIZATION - RIGHT-TO-USE LEASED LAND | K20: =N20 -> 0 | S20: =P20-M20 -> 0
C21: Cr: Acct 0479 - ACCUMULATED AMORTIZATION - RIGHT-TO-USE LEASED EQUIPMENT | K21: =N21 -> 0 | S21: =Q21-N21 -> 0
C22: Cr: Acct 0486 - ACCUMULATED AMORTIZATION - RIGHT-TO-USE LEASED BUILDINGS | K22: =N22 -> 1187191.9 | N22: 1187191.9 | Q22: 1050795 | S22: =Q22-N22 -> -136396.9
A23: **LS LL/CF | C23: Cr: Acct 0691 - RIGHT-TO-USE LEASE LIABILITY | K23: =N23 -> 3026470.1 | N23: 3026470.1 | Q23: 2730648 | S23: =Q23-N23 -> -295822.14
C24: Cr: Acct 0950 - BEGINNING FUND BALANCE | K24: =Q24 -> 0 | Q24: =IF(SUM($Q$39:$Q$41)<SUM($P$33:$P$35),-SUM($Q$39:$Q$41)+SUM($P$33:$P$35),0) -> 0 | S24: =Q24-N24 -> 0
C25: Cr: Acct 0952 - BEGINNING FUND ADJUSTMENT/PRIOR PERIOD ADJUSTMENT | K25: =IF(SUM($K$21:$K$24)<SUM($J$15:$J$18),-SUM($K$21:$K$24)+SUM($J$15:$J$18),0) -> 0 | S25: =Q25-N25 -> 0
J26: =SUM(J15:J25) -> 4213662 | K26: =SUM(K15:K25) -> 4213662 | L26: =IF(J26=K26,"<- Debits and Credits equal each other.","<- Debits and Credits do not equal each other.") -> <- Debits and Credits equal each other.
B27: * THESE ASSET AMOUNTS SHOULD BE REPORTED AS BEGINNING BALANCES ON REPORT 18.
B28: ** This amount should be included in the beginning balance column on the LS-Lease Liability and LS-Check Figures Tabs.
A31: Record New Leases (new leases only)
A32: 1 | B32: Record lease contract commencement (fund-based entries only)
B33: Dr: Acct 0842 - CAPITAL OUTLAY | J33: 5740523.1
C34: Cr: Acct 0789 - LEASE AND OTHER FINANCING PROCEEDS | K34: 5740523.1
C35: =IF($F$7="Proprietary","Cr: Acct 0870 - SERVICES & CHARGES (MG ADJ)",VLOOKUP($F$9,'[2]Drop Down Menus'!$F$2:$G$10,2,FALSE)) -> Cr: Acct 0830 - TRANSPORTATION (GAAP ADJ)
J36: =SUM(J33:J35) -> 5740523.1 | K36: =SUM(K33:K35) -> 5740523.1 | L36: =IF(J36=K36,"<- Debits and Credits equal each other.","<- Debits and Credits do not equal each other.") -> <- Debits and Credits equal each other.
A38: 2 | B38: Record leased assets.
A39: *Rpt 18 | B39: Dr: Acct 0476 - RIGHT-TO-USE LEASED LAND - AMORTIZABLE
A40: *Rpt 18 | B40: Dr: Acct 0478 - RIGHT-TO-USE LEASED EQUIPMENT - AMORTIZABLE
A41: *Rpt 18 | B41: Dr: Acct 0477 - RIGHT-TO-USE LEASED BUILDINGS - AMORTIZABLE | J41: 5740523.1
C42: Cr: Acct 0842 - CAPITAL OUTLAY | K42: 5740523.1
B43: * THESE AMOUNTS SHOULD BE INCLUDED AS "ADDITIONS" ON REPORT 18. | J43: =SUM(J39:J42) -> 5740523.1 | K43: =SUM(K39:K42) -> 5740523.1 | L43: =IF(J43=K43,"<- Debits and Credits equal each other.","<- Debits and Credits do not equal each other.") -> <- Debits and Credits equal each other.
A46: 3 | B46: Replace proceeds from leases with right-to-use lease liability.
B47: Dr: Acct 0789 - LEASE AND OTHER FINANCING PROCEEDS | J47: 5740523.1
...

Sheet LS-Fund 3291 Journal Entrie
A1: Lessee-Type Contracts Fund-by-Fund Journal Entries Form (to be submitted to the SCO annually—one form per fund)
A2: Manually complete every yellow field in this worksheet—there are no automatically calculated data-entry cells in this worksheet.
A3: Fiscal Year: | F3: 2022–2023
A4: Organization Name: | F4: Department of Transportation
A5: Organization Code (4-Digits): | F5: 2660
A6: Fund Number (4-Digits): | F6: 3291
A7: Fund Classification: | F7: Governmental
A8: Fund Type: | F8: Governmental Fund
A9: Functional Expense: | F9: =IFERROR(IF(F7="Proprietary","Proprietary Fund",VLOOKUP(F5,[2]qryIndex02a!$A$2:$K$654,4,FALSE)),"Unidentified") -> TRANSPORTATION
A12: Establish Beginning Balances (existing leases only)
A13: Entry #
A14: 0 | B14: Roll forward prior year right-to-use leases to record opening balances. | M14: Combined Lessee Templates | P14: From SCO BB List | S14: Difference
A15: *Rpt 18 | B15: Dr: Acct 0476 - RIGHT-TO-USE LEASED LAND - AMORTIZABLE | J15: =M15 -> 0 | S15: =P15-M15 -> 0
A16: *Rpt 18 | B16: Dr: Acct 0478 - RIGHT-TO-USE LEASED EQUIPMENT - AMORTIZABLE | J16: =M16 -> 0 | S16: =P16-M16 -> 0
A17: *Rpt 18 | B17: Dr: Acct 0477 - RIGHT-TO-USE LEASED BUILDINGS - AMORTIZABLE | J17: =M17 -> 83839 | M17: 83839 | P17: 83839 | S17: =P17-M17 -> 0
B18: Dr: Acct 0950 - BEGINNING FUND BALANCE | J18: =P18 -> 151 | M18: 150 | P18: =IF(SUM($Q$21:$Q$23)>SUM($P$15:$P$17),SUM($Q$21:$Q$23)-SUM($P$15:$P$17),0) -> 151 | S18: =P18-M18 -> 1
B19: Dr: Acct 0952 - BEGINNING FUND ADJUSTMENT/PRIOR PERIOD ADJUSTMENT | J19: =IF(SUM($K$21:$K$24)>SUM($J$15:$J$18),SUM($K$21:$K$24)-SUM($J$15:$J$18),0) -> 0 | S19: =P19-M19 -> 0
C20: Cr: Acct 0485 - ACCUMULATED AMORTIZATION - RIGHT-TO-USE LEASED LAND | K20: =N20 -> 0 | S20: =P20-M20 -> 0
C21: Cr: Acct 0479 - ACCUMULATED AMORTIZATION - RIGHT-TO-USE LEASED EQUIPMENT | K21: =N21 -> 0 | S21: =Q21-N21 -> 0
C22: Cr: Acct 0486 - ACCUMULATED AMORTIZATION - RIGHT-TO-USE LEASED BUILDINGS | K22: =N22 -> 4658 | N22: 4658 | Q22: 4658 | S22: =Q22-N22 -> 0
A23: **LS LL/CF | C23: Cr: Acct 0691 - RIGHT-TO-USE LEASE LIABILITY | K23: =N23 -> 79332 | N23: 79332 | Q23: 79332 | S23: =Q23-N23 -> 0
C24: Cr: Acct 0950 - BEGINNING FUND BALANCE | K24: =Q24 -> 0 | Q24: =IF(SUM($Q$39:$Q$41)<SUM($P$33:$P$35),-SUM($Q$39:$Q$41)+SUM($P$33:$P$35),0) -> 0 | S24: =Q24-N24 -> 0
C25: Cr: Acct 0952 - BEGINNING FUND ADJUSTMENT/PRIOR PERIOD ADJUSTMENT | K25: =IF(SUM($K$21:$K$24)<SUM($J$15:$J$18),-SUM($K$21:$K$24)+SUM($J$15:$J$18),0) -> 0 | S25: =Q25-N25 -> 0
J26: =SUM(J15:J25) -> 83990 | K26: =SUM(K15:K25) -> 83990 | L26: =IF(J26=K26,"<- Debits and Credits equal each other.","<- Debits and Credits do not equal each other.") -> <- Debits and Credits equal each other.
B27: * THESE ASSET AMOUNTS SHOULD BE REPORTED AS BEGINNING BALANCES ON REPORT 18.
B28: ** This amount should be included in the beginning balance column on the LS-Lease Liability and LS-Check Figures Tabs.
A31: Record New Leases (new leases only)
A32: 1 | B32: Record lease contract commencement (fund-based entries only)
B33: Dr: Acct 0842 - CAPITAL OUTLAY | J33: 0
C34: Cr: Acct 0789 - LEASE AND OTHER FINANCING PROCEEDS | K34: 0
C35: =IF($F$7="Proprietary","Cr: Acct 0870 - SERVICES & CHARGES (MG ADJ)",VLOOKUP($F$9,'[2]Drop Down Menus'!$F$2:$G$10,2,FALSE)) -> Cr: Acct 0830 - TRANSPORTATION (GAAP ADJ) | K35: 0
J36: =SUM(J33:J35) -> 0 | K36: =SUM(K33:K35) -> 0 | L36: =IF(J36=K36,"<- Debits and Credits equal each other.","<- Debits and Credits do not equal each other.") -> <- Debits and Credits equal each other.
A38: 2 | B38: Record leased assets.
A39: *Rpt 18 | B39: Dr: Acct 0476 - RIGHT-TO-USE LEASED LAND - AMORTIZABLE | J39: 0
A40: *Rpt 18 | B40: Dr: Acct 0478 - RIGHT-TO-USE LEASED EQUIPMENT - AMORTIZABLE | J40: 0
A41: *Rpt 18 | B41: Dr: Acct 0477 - RIGHT-TO-USE LEASED BUILDINGS - AMORTIZABLE | J41: 0
C42: Cr: Acct 0842 - CAPITAL OUTLAY | K42: 0
B43: * THESE AMOUNTS SHOULD BE INCLUDED AS "ADDITIONS" ON REPORT 18. | J43: =SUM(J39:J42) -> 0 | K43: =SUM(K39:K42) -> 0 | L43: =IF(J43=K43,"<- Debits and Credits equal each other.","<- Debits and Credits do not equal each other.") -> <- Debits and Credits equal each other.
A46: 3 | B46: Replace proceeds from leases with right-to-use lease liability.
B47: Dr: Acct 0789 - LEASE AND OTHER FINANCING PROCEEDS | J47: 0
...

Sheet LS-Fund 6072 Journal Entrie 
A1: Lessee-Type Contracts Fund-by-Fund Journal Entries Form (to be submitted to the SCO annually—one form per fund)
A2: Manually complete every yellow field in this worksheet—there are no automatically calculated data-entry cells in this worksheet.
A3: Fiscal Year: | F3: 2022–2023
A4: Organization Name: | F4: Department of Transportation
A5: Organization Code (4-Digits): | F5: 2660
A6: Fund Number (4-Digits): | F6: 6072
A7: Fund Classification: | F7: Governmental
A8: Fund Type: | F8: Governmental Fund
A9: Functional Expense: | F9: =IFERROR(IF(F7="Proprietary","Proprietary Fund",VLOOKUP(F5,[2]qryIndex02a!$A$2:$K$654,4,FALSE)),"Unidentified") -> TRANSPORTATION
A12: Establish Beginning Balances (existing leases only)
A13: Entry #
A14: 0 | B14: Roll forward prior year right-to-use leases to record opening balances. | M14: Combined Lessee Templates | P14: From SCO BB List | S14: Difference
A15: *Rpt 18 | B15: Dr: Acct 0476 - RIGHT-TO-USE LEASED LAND - AMORTIZABLE | J15: =M15 -> 0 | P15: 0 | S15: =P15-M15 -> 0
A16: *Rpt 18 | B16: Dr: Acct 0478 - RIGHT-TO-USE LEASED EQUIPMENT - AMORTIZABLE | J16: =M16 -> 0 | P16: 0 | S16: =P16-M16 -> 0
A17: *Rpt 18 | B17: Dr: Acct 0477 - RIGHT-TO-USE LEASED BUILDINGS - AMORTIZABLE | J17: =M17 -> 127178 | M17: 127178 | P17: 127178 | S17: =P17-M17 -> 0
B18: Dr: Acct 0950 - BEGINNING FUND BALANCE | J18: =P18 -> 32 | M18: 32 | P18: =IF(SUM($Q$21:$Q$23)>SUM($P$15:$P$17),SUM($Q$21:$Q$23)-SUM($P$15:$P$17),0) -> 32 | S18: =P18-M18 -> 0
B19: Dr: Acct 0952 - BEGINNING FUND ADJUSTMENT/PRIOR PERIOD ADJUSTMENT | J19: =IF(SUM($K$21:$K$24)>SUM($J$15:$J$18),SUM($K$21:$K$24)-SUM($J$15:$J$18),0) -> 0 | S19: =P19-M19 -> 0
C20: Cr: Acct 0485 - ACCUMULATED AMORTIZATION - RIGHT-TO-USE LEASED LAND | K20: =N20 -> 0 | S20: =P20-M20 -> 0
C21: Cr: Acct 0479 - ACCUMULATED AMORTIZATION - RIGHT-TO-USE LEASED EQUIPMENT | K21: =N21 -> 0 | S21: =Q21-N21 -> 0
C22: Cr: Acct 0486 - ACCUMULATED AMORTIZATION - RIGHT-TO-USE LEASED BUILDINGS | K22: =N22 -> 95383 | N22: 95383 | Q22: 95383 | S22: =Q22-N22 -> 0
A23: **LS LL/CF | C23: Cr: Acct 0691 - RIGHT-TO-USE LEASE LIABILITY | K23: =N23 -> 31826 | N23: 31826 | Q23: 31827 | S23: =Q23-N23 -> 1
C24: Cr: Acct 0950 - BEGINNING FUND BALANCE | K24: =Q24 -> 0 | Q24: =IF(SUM($Q$39:$Q$41)<SUM($P$33:$P$35),-SUM($Q$39:$Q$41)+SUM($P$33:$P$35),0) -> 0 | S24: =Q24-N24 -> 0
C25: Cr: Acct 0952 - BEGINNING FUND ADJUSTMENT/PRIOR PERIOD ADJUSTMENT | K25: =IF(SUM($K$21:$K$24)<SUM($J$15:$J$18),-SUM($K$21:$K$24)+SUM($J$15:$J$18),0) -> 1 | S25: =Q25-N25 -> 0
J26: =SUM(J15:J25) -> 127210 | K26: =SUM(K15:K25) -> 127210 | L26: =IF(J26=K26,"<- Debits and Credits equal each other.","<- Debits and Credits do not equal each other.") -> <- Debits and Credits equal each other.
B27: * THESE ASSET AMOUNTS SHOULD BE REPORTED AS BEGINNING BALANCES ON REPORT 18.
B28: ** This amount should be included in the beginning balance column on the LS-Lease Liability and LS-Check Figures Tabs.
A31: Record New Leases (new leases only)
A32: 1 | B32: Record lease contract commencement (fund-based entries only)
B33: Dr: Acct 0842 - CAPITAL OUTLAY | J33: 0
C34: Cr: Acct 0789 - LEASE AND OTHER FINANCING PROCEEDS | K34: 0
C35: =IF($F$7="Proprietary","Cr: Acct 0870 - SERVICES & CHARGES (MG ADJ)",VLOOKUP($F$9,'[2]Drop Down Menus'!$F$2:$G$10,2,FALSE)) -> Cr: Acct 0830 - TRANSPORTATION (GAAP ADJ) | K35: 0
J36: =SUM(J33:J35) -> 0 | K36: =SUM(K33:K35) -> 0 | L36: =IF(J36=K36,"<- Debits and Credits equal each other.","<- Debits and Credits do not equal each other.") -> <- Debits and Credits equal each other.
A38: 2 | B38: Record leased assets.
A39: *Rpt 18 | B39: Dr: Acct 0476 - RIGHT-TO-USE LEASED LAND - AMORTIZABLE | J39: 0
A40: *Rpt 18 | B40: Dr: Acct 0478 - RIGHT-TO-USE LEASED EQUIPMENT - AMORTIZABLE | J40: 0
A41: *Rpt 18 | B41: Dr: Acct 0477 - RIGHT-TO-USE LEASED BUILDINGS - AMORTIZABLE | J41: 0
C42: Cr: Acct 0842 - CAPITAL OUTLAY | K42: 0
B43: * THESE AMOUNTS SHOULD BE INCLUDED AS "ADDITIONS" ON REPORT 18. | J43: =SUM(J39:J42) -> 0 | K43: =SUM(K39:K42) -> 0 | L43: =IF(J43=K43,"<- Debits and Credits equal each other.","<- Debits and Credits do not equal each other.") -> <- Debits and Credits equal each other.
A46: 3 | B46: Replace proceeds from leases with right-to-use lease liability.
B47: Dr: Acct 0789 - LEASE AND OTHER FINANCING PROCEEDS | J47: 0
...

Sheet LS-Department Note Disclosure
A1: Submit one form for the department to the SCO annually.
A2: Note: There are three tables of note disclosures on this form —1) governmental funds, 2) proprietary - internal service funds, and 3) proprietary - enterprise funds. Complete all applicable tables before submitting to the SCO.
A3: Manually complete every yellow field in this worksheet—there are no automatically calculated cells in this worksheet.
A4: Complete the fields below using aggregated and summarized information from all of your department's completed contract template forms.
A5: The fields in this worksheet should contain the sums of the department's contracts' corresponding information in their note disclosure worksheets.
A7: I. Governmental funds
A8: Fiscal Year: | B8: 2022–2023
A9: Organization Code: | B9: 2660
A10: Organization Name: | B10: Department of Transportation
A11: The below information must be entered manually.
B12: Principal Payments | C12: Interest Payments | D12: ="All of the below questions are for Fiscal Year "&$B$8&":" -> All of the below questions are for Fiscal Year 2022–2023:
A13: =RIGHT(B8,4)&"–"&RIGHT(B8,4)+1 -> 2023–2024 | B13: 33463895 | C13: 205805.74 | D13: 1. Did your leasing arrangements have any variable payments which ARE NOT included in the measurement of the lease liability?
A14: =LEFT(A13,4)+1&"–"&RIGHT(A13,4)+1 -> 2024–2025 | B14: 21928739 | C14: 117696.78
A15: =LEFT(A14,4)+1&"–"&RIGHT(A14,4)+1 -> 2025–2026 | B15: 15979935 | C15: 60153.574 | D15: No
A16: =LEFT(A15,4)+1&"–"&RIGHT(A15,4)+1 -> 2026–2027 | B16: 4063074 | C16: 19847.1 | D16: ="If yes, record the dollar amount of variable payments below for fiscal year "&$B$8&":" -> If yes, record the dollar amount of variable payments below for fiscal year 2022–2023:
A17: =LEFT(A16,4)+1&"–"&RIGHT(A16,4)+1 -> 2027–2028 | B17: 983007.94 | C17: 6986.9
A18: =LEFT(A17,4)+1&"–"&RIGHT(A17,4)+5 -> 2028–2033 | B18: 0 | C18: 0 | D18: 2. Do your leasing arrangements have any residual value guarantees provided by YOU which ARE NOT included in the measurement of the lease liability?
A19: =LEFT(A18,4)+5&"–"&RIGHT(A18,4)+5 -> 2033–2038 | B19: 0 | C19: 0
A20: =LEFT(A19,4)+5&"–"&RIGHT(A19,4)+5 -> 2038–2043 | B20: 0 | C20: 0 | D20: No
A21: =LEFT(A20,4)+5&"–"&RIGHT(A20,4)+5 -> 2043–2048 | D21: ="If yes, record the dollar amount of any payments made for residual value guarantees below for fiscal year "&$B$8&":" -> If yes, record the dollar amount of any payments made for residual value guarantees below for fiscal year 2022–2023:
A22: =LEFT(A21,4)+5&"–"&RIGHT(A21,4)+5 -> 2048–2053
A23: =LEFT(A22,4)+5&"–"&RIGHT(A22,4)+5 -> 2053–2058
A24: =LEFT(A23,4)+5&"–"&RIGHT(A23,4)+5 -> 2058–2063 | D24: ="3. Record the dollar amount of any other payments for this lease, such as termination penalties, not previously recorded in the payment schedule for fiscal year "&$B$8&":" -> 3. Record the dollar amount of any other payments for this lease, such as termination penalties, not previously recorded in the payment schedule for fiscal year 2022–2023:
A25: =LEFT(A24,4)+5&"–"&RIGHT(A24,4)+5 -> 2063–2068
A26: =LEFT(A25,4)+5&"–"&RIGHT(A25,4)+5 -> 2068–2073 | D26: 0
A27: =LEFT(A26,4)+5&"–"&RIGHT(A26,4)+5 -> 2073–2078 | D27: ="4. Did you receive any lease incentives from the lessor (not already included in the lease measurment) during fiscal year "&$B$8&"? If so, record the amount below:" -> 4. Did you receive any lease incentives from the lessor (not already included in the lease measurment) during fiscal year 2022–2023? If so, record the amount below:
A28: =LEFT(A27,4)+5&"–"&RIGHT(A27,4)+5 -> 2078–2083
A29: =LEFT(A28,4)+5&"–"&RIGHT(A28,4)+5 -> 2083–2088 | D29: No
A30: =LEFT(A29,4)+5&"–"&RIGHT(A29,4)+5 -> 2088–2093 | D30: =CONCATENATE("5. Are there any lease commitments known that have yet to commence as of June 30, ",RIGHT(B8,4),"?") -> 5. Are there any lease commitments known that have yet to commence as of June 30, 2023?
A31: =LEFT(A30,4)+5&"–"&RIGHT(A30,4)+5 -> 2093–2098 | D31: No
A32: =LEFT(A31,4)+5&"–"&RIGHT(A31,4)+5 -> 2098–2103 | D32: ="If yes, record the dollar amount of any lease commitments not commenced below for fiscal year "&A13&"." -> If yes, record the dollar amount of any lease commitments not commenced below for fiscal year 2023–2024.
A33: =LEFT(A32,4)+5&"–"&RIGHT(A32,4)+5 -> 2103–2108
A34: =LEFT(A33,4)+5&"–"&RIGHT(A33,4)+5 -> 2108–2113
A35: =LEFT(A34,4)+5&"–"&RIGHT(A34,4)+5 -> 2113–2118
A36: =LEFT(A35,4)+5&"–"&RIGHT(A35,4)+5 -> 2118–2123
A38: II. Proprietary - INTERNAL SERVICE FUNDS
A39: Fiscal Year: | B39: =B8 -> 2022–2023
A40: Organization Code: | B40: =B9 -> 2660
A41: Organization Name: | B41: =B10 -> Department of Transportation
A42: The below information must be entered manually.
...

Sheet LS-Lease Liabilities
J3: Schedule of Changes in Lease Liabilities
J4: =CONCATENATE("FY ",'LS-Fund 0042 Journal Entries'!F3) -> FY 2022–2023
J5: =CONCATENATE("Business Unit ",'LS-Department Note Disclosure'!B9," - ",'LS-Department Note Disclosure'!B10) -> Business Unit 2660 - Department of Transportation
F7: =CONCATENATE("Balance July 1, ",MID(J4,4,4)) -> Balance July 1, 2022 | H7: Additions | J7: Deductions | L7: =CONCATENATE("Balance June 30, ",RIGHT(J4,4)) -> Balance June 30, 2023 | N7: Due Within One Year | P7: Noncurrent Liabilities
F8: (Entry #0) | H8: (Entry #3 & 10) | J8: (Entry #6 & 9) | N8: (Entry #7)
C9: Governmental Funds
D10: Lease Liability | F10: 72734703 | H10: 27063636 | J10: 23379687 | L10: =SUM(F10+H10-J10) -> 76418652 | N10: 33463895 | P10: =L10-N10 -> 42954757
C11: Total Governmental Funds | F11: =SUM(F10:F10) -> 72734703 | H11: =SUM(H10:H10) -> 27063636 | J11: =SUM(J10:J10) -> 23379687 | L11: =SUM(L10:L10) -> 76418652 | N11: =SUM(N10:N10) -> 33463895 | P11: =SUM(P10:P10) -> 42954757
C13: Proprietary - Internal Service Funds
D14: Lease Liability | L14: =SUM(F14+H14-J14) -> 0 | P14: =L14-N14 -> 0
C15: Total Proprietary - Internal Service Funds | F15: =SUM(F14:F14) -> 0 | H15: =SUM(H14:H14) -> 0 | J15: =SUM(J14:J14) -> 0 | L15: =SUM(L14:L14) -> 0 | N15: =SUM(N14:N14) -> 0 | P15: =SUM(P14:P14) -> 0
C17: Proprietary - Enterprise Funds
D18: Lease Liability | L18: =SUM(F18+H18-J18) -> 0 | P18: =L18-N18 -> 0
C19: Total Proprietary - Enterprise Funds | F19: =SUM(F18:F18) -> 0 | H19: =SUM(H18:H18) -> 0 | J19: =SUM(J18:J18) -> 0 | L19: =SUM(L18:L18) -> 0 | N19: =SUM(N18:N18) -> 0 | P19: =SUM(P18:P18) -> 0

Sheet LS-Check Figures  
A1: GASB Statement No. 87 Leases
A2: Check Figures
A4: Purpose:
A5: The purpose of this workbook is to check the figures entered in the journal entries reconcile to the future principal payments disclosed and the changes in the schedule of the lease liabilities.
A8: NOTE: If multiple funds are included in this workbook, manually complete every yellow field by consolidating the entries by fund type (Governmental, Proprietary ISF, and Proprietary EF).
A10: 1. To reconcile the journal entries of RTU Lease Liability with the principal payments in Note Disclosure.
B11: a) Governmental Funds
B13: Journal Entries | N13: Department Note Disclosure
B14: Beginning Balance | D14: Additions | F14: Deductions | H14: Deductions (Mod) | J14: Additions (Mod)
B15: Entry #0 | C15: + | D15: Entry #3 | E15: - | F15: Entry #6 | G15: - | H15: Entry #9 | I15: + | J15: Entry #10 | N15: Sum Principal Payments | P15: Variance
B16: 72734703 | C16: + | D16: 27063636 | E16: - | F16: 23379687 | G16: - | H16: 0 | I16: + | J16: 0 | K16: = | L16: =+B16+D16-F16-H16+J16 -> 76418652 | N16: =SUM('LS-Department Note Disclosure'!B13:B36) -> 76418652 | P16: =L16-N16 -> 0.28839019
D18: =IF(OR(P16>0, (P16<0)), "Please review and correct the variance.","") -> Please review and correct the variance.
B19: b) Proprietary - Internal Service Funds
B21: Journal Entries | N21: Department Note Disclosure
B22: Beginning Balance | D22: Additions | F22: Deductions | H22: Deductions (Mod) | J22: Additions (Mod)
B23: Entry #0 | C23: + | D23: Entry #3 | E23: - | F23: Entry #6 | G23: - | H23: Entry #9 | I23: + | J23: Entry #10 | N23: Sum Principal Payments | P23: Variance
B24: =IF('LS-Fund 0042 Journal Entries'!$F$8="Proprietary - Internal Service Fund",'LS-Fund 0042 Journal Entries'!$K$23,0) -> 0 | C24: + | D24: =IF('LS-Fund 0042 Journal Entries'!$F$8="Proprietary - Internal Service Fund",'LS-Fund 0042 Journal Entries'!$K$48,0) -> 0 | E24: - | F24: =IF('LS-Fund 0042 Journal Entries'!$F$8="Proprietary - Internal Service Fund",'LS-Fund 0042 Journal Entries'!$J$68,0) -> 0 | G24: - | H24: =IF('LS-Fund 0042 Journal Entries'!$F$8="Proprietary - Internal Service Fund",'LS-Fund 0042 Journal Entries'!$J$96,0) -> 0 | I24: + | J24: =IF('LS-Fund 0042 Journal Entries'!$F$8="Proprietary - Internal Service Fund",'LS-Fund 0042 Journal Entries'!$K$113,0) -> 0 | K24: = | L24: =+B24+D24-F24-H24+J24 -> 0 | N24: =SUM('LS-Department Note Disclosure'!B44:B67) -> 0 | P24: =L24-N24 -> 0
D26: =IF(OR(P24>0, (P24<0)), "Please review and correct the variance.","")
B28: c) Proprietary - Enterprise Funds
B30: Journal Entries | N30: Department Note Disclosure
B31: Beginning Balance | D31: Additions | F31: Deductions | H31: Deductions (Mod) | J31: Additions (Mod)
B32: Entry #0 | C32: + | D32: Entry #3 | E32: - | F32: Entry #6 | G32: - | H32: Entry #9 | I32: + | J32: Entry #10 | N32: Sum Principal Payments | P32: Variance
B33: =IF('LS-Fund 0042 Journal Entries'!$F$8="Proprietary - Enterprise Fund",'LS-Fund 0042 Journal Entries'!$K$23,0) -> 0 | C33: + | D33: =IF('LS-Fund 0042 Journal Entries'!$F$8="Proprietary - Enterprise Fund",'LS-Fund 0042 Journal Entries'!$K$48,0) -> 0 | E33: - | F33: =IF('LS-Fund 0042 Journal Entries'!$F$8="Proprietary - Enterprise Fund",'LS-Fund 0042 Journal Entries'!$J$68,0) -> 0 | G33: - | H33: =IF('LS-Fund 0042 Journal Entries'!$F$8="Proprietary - Enterprise Fund",'LS-Fund 0042 Journal Entries'!$J$96,0) -> 0 | I33: + | J33: =IF('LS-Fund 0042 Journal Entries'!$F$8="Proprietary - Enterprise Fund",'LS-Fund 0042 Journal Entries'!$K$113,0) -> 0 | K33: = | L33: =+B33+D33-F33-H33+J33 -> 0 | N33: =SUM('LS-Department Note Disclosure'!B75:B98) -> 0 | P33: =L33-N33 -> 0
D35: =IF(OR(P33>0, (P33<0)), "Please review and correct the variance.","")
A37: 2. To match the journal entry to the principal amount due in the next fiscal year in Note Disclosure.
B38: a) Governmental Funds
B40: Journal Entries | N40: Department Note Disclosure
B41: Entry #7 | C41: Due within one year | N41: =CONCATENATE('LS-Department Note Disclosure'!$A$13," Principal Payments") -> 2023–2024 Principal Payments | P41: Variance
B42: 33463895 | N42: ='LS-Department Note Disclosure'!B13 -> 33463895 | P42: =B42-N42 -> 0
D44: =IF(OR(P42>0, (P42<0)), "Please review and correct the variance.","")
B45: b) Proprietary - Internal Service Funds
B47: Journal Entries | N47: Department Note Disclosure
B48: Entry #7 | C48: Due within one year | N48: =CONCATENATE('LS-Department Note Disclosure'!$A$44," Principal Payments") -> 2023–2024 Principal Payments | P48: Variance
B49: =IF('LS-Fund 0042 Journal Entries'!$F$8="Proprietary - Internal Service Fund",'LS-Fund 0042 Journal Entries'!$K$76,0) -> 0 | N49: ='LS-Department Note Disclosure'!B44 -> 0 | P49: =B49-N49 -> 0
D51: =IF(OR(P49>0, (P49<0)), "Please review and correct the variance.","")
B53: c) Proprietary - Enterprise Funds
B55: Journal Entries | N55: Department Note Disclosure
B56: Entry #7 | C56: Due within one year | N56: =CONCATENATE('LS-Department Note Disclosure'!$A$75," Principal Payments") -> 2023–2024 Principal Payments | P56: Variance
B57: =IF('LS-Fund 0042 Journal Entries'!$F$8="Proprietary - Enterprise Fund",'LS-Fund 0042 Journal Entries'!$K$76,0) -> 0 | N57: ='LS-Department Note Disclosure'!B75 -> 0 | P57: =B57-N57 -> 0
D59: =IF(OR(P57>0, (P57<0)), "Please review and correct the variance.","")
...

Sheet LR-Fund 0042 Journal Entries
A1: Lessor-Type Contracts Fund-by-Fund Journal Entries Form (to be submitted to the SCO annually—one form per fund)
A2: Manually complete every yellow field in this worksheet—there are no automatically calculated data-entry cells in this worksheet.
A3: Fiscal year: | E3: 2022-2023
A4: Organization Name: | E4: Department of Transportation
A5: Organization Code (4-Digit): | E5: 2660
A6: Fund Number (4-Digit): | E6: 42
A7: Fund Classification: | E7: 'Governmental
A8: Fund Type: | E8: 'Governmental Fund
A11: Establish Beginning Balances (existing leases only)
A12: Entry #
A13: 0 | B13: Roll prior year ending balance to record opening balance of lease receivable and deferred inflow of resources. | M13: Combined Lessor Templates | P13: From SCO BB List | S13: Difference
B14: Dr: Acct 0417 - LEASES RECEIVABLE - NONCURRENT | J14: =M14 -> 19915320 | M14: 19915320 | P14: 19915319 | S14: =P14-M14 -> -1
B15: Dr: Acct 0950 - BEGINNING FUND BALANCE | J15: =P15 -> 0 | P15: =IF(SUM($Q$17)>SUM($P$14),SUM($Q$17)-SUM($P$14),0) -> 0 | S15: =P15-M15 -> 0
B16: Dr: Acct 0952 - BEGINNING FUND ADJUSTMENT/PRIOR PERIOD ADJUSTMENT | J16: =IF(SUM($K$17:$K$18)>SUM($J$14:$J$15),SUM($K$17:$K$18)-SUM($J$14:$J$15),0) -> 0 | S16: =P16-M16 -> 0
C17: Cr: Acct 0698 - OTHER DEFERRED INFLOWS OF RESOURCES | K17: =N17 -> 19819534 | N17: 19819534 | Q17: 19819534 | S17: =Q17-N17 -> -0.15954555
C18: Dr: Acct 0950 - BEGINNING FUND BALANCE | K18: =Q18 -> 95785 | N18: 95785.416 | Q18: =IF(SUM($Q$17)<SUM($P$14),-SUM($Q$17)+SUM($P$14),0) -> 95785 | S18: =Q18-N18 -> -0.41626253
C19: Dr: Acct 0952 - BEGINNING FUND ADJUSTMENT/PRIOR PERIOD ADJUSTMENT | K19: =IF(SUM($K$17:$K$18)<SUM($J$14:$J$15),-SUM($K$17:$K$18)+SUM($J$14:$J$15),0) -> 0.84045445 | S19: =Q19-N19 -> 0
J20: =SUM(J14:J19) -> 19915320 | K20: =SUM(K14:K19) -> 19915320 | L20: =IF(J20=K20,"<- Debits and Credits equal each other.","<- Debits and Credits do not equal each other.") -> <- Debits and Credits equal each other.
A22: Record New Leases (new leases only)
A23: 1 | B23: Record receivable and related deferred inflow at inception of lease.
B24: Dr: Acct 0417 - LEASES RECEIVABLE - NONCURRENT | J24: 0
C25: Cr: Acct 0698 - OTHER DEFERRED INFLOWS OF RESOURCES | K25: 0
J26: =J24 -> 0 | K26: =K25 -> 0 | L26: =IF(J26=K26,"<- Debits and Credits equal each other.","<- Debits and Credits do not equal each other.") -> <- Debits and Credits equal each other.
A28: Record Annual Activity (all leases)
A29: 2 | B29: Record receipt of lease payments as reduction of lease receivable and recognize interest revenue.
B30: =IF($E$7="Governmental","Dr: Acct 0775 - OTHER INCOME","Dr: Acct 0755 - SALES & SERVICES") -> Dr: Acct 0755 - SALES & SERVICES | J30: 2785837.1
C31: Cr: Acct 0417 - LEASES RECEIVABLE - NONCURRENT | K31: 2618690
C32: =IF($E$7="Governmental","Cr: Acct 0740 - INTEREST INCOME","Cr: Acct 0765 - INVESTMENT AND INTEREST") -> Cr: Acct 0765 - INVESTMENT AND INTEREST | K32: 167147.07
J33: =J30 -> 2785837.1 | K33: =SUM(K31:K32) -> 2785837.1 | L33: =IF(J33=K33,"<- Debits and Credits equal each other.","<- Debits and Credits do not equal each other.") -> <- Debits and Credits equal each other.
A35: 3 | B35: Record straight-line recognition of revenue.
B36: Dr: Acct 0698 - OTHER DEFERRED INFLOWS OF RESOURCES | C36: Cr: Acct 0698 - OTHER DEFERRED INFLOWS OF RESOURCES | D36: Cr: Acct 0698 - OTHER DEFERRED INFLOWS OF RESOURCES | E36: Cr: Acct 0698 - OTHER DEFERRED INFLOWS OF RESOURCES | J36: 2682353.2
C37: =IF($E$7="Governmental","Cr: Acct 0775 - OTHER INCOME","Cr: Acct 0778 - RENT") -> Cr: Acct 0778 - RENT | K37: 2682353.2
J38: =J36 -> 2682353.2 | K38: =K37 -> 2682353.2 | L38: =IF(J38=K38,"<- Debits and Credits equal each other.","<- Debits and Credits do not equal each other.") -> <- Debits and Credits equal each other.
A40: 4 | B40: Reclassify the current portion of the lease receivable from non-current to current.
B41: Dr: Acct 0036 - LEASES RECEIVABLE - CURRENT | J41: 2641657
C42: Cr: Acct 0417 - LEASES RECEIVABLE - NONCURRENT | D42: Cr: Acct 0416 - LEASES RECEIVABLE - NONCURRENT | E42: Cr: Acct 0416 - LEASES RECEIVABLE - NONCURRENT | K42: 2641657
B43: NOTE: This is the annual year-end reclassification of the non-current liability to current. It is to be reversed at the start of the next fiscal year.SCO combines the current and non current amount in Entry #0 to reestablish the beginning balances. No action required. | J43: =J41 -> 2641657 | K43: =K42 -> 2641657 | L43: =IF(J43=K43,"<- Debits and Credits equal each other.","<- Debits and Credits do not equal each other.") -> <- Debits and Credits equal each other.
A47: Lease Remeasurement and Modifications (only if a significant modification occurred during the fiscal year)
A48: 5 | B48: Record early termination or lease modifications to decrease the lease receivable and other deferred inflows of resources.
B49: Dr: Acct 0698 - OTHER DEFERRED INFLOWS OF RESOURCES
...

Sheet LR-Department Note Disclosure
A1: Submit one form for the department to the SCO annually.
A2: Note: There are three tables of note disclosures on this form —1) governmental funds, 2) proprietary - internal service funds, and 3) proprietary - enterprise funds. Complete all applicable tables before submitting to the SCO.
A3: Manually complete every yellow field in this worksheet—there are no automatically calculated cells in this worksheet.
A4: Complete the fields below using aggregated and summarized information from all of your department's completed contract template forms.
A5: The fields in this worksheet should contain the sums of the department's contracts' corresponding information in their note disclosure worksheets.
A8: I. Governmental funds
A9: Fiscal Year: | B9: 2022–2023
A10: Organization Code: | B10: 2660 | C10: Department of Transportation
A11: Organization Name: | B11: Department of Transportation | C11: 2660
A12: The below information must be entered manually.
B13: Principal Receipts | C13: Interest Receipts | E13: ="All of this worksheet's questions are for Fiscal Year "&$B$9&":" -> All of this worksheet's questions are for Fiscal Year 2022–2023:
A14: =RIGHT(B9,4)&"–"&RIGHT(B9,4)+1 -> 2023–2024 | B14: 2641657 | C14: 144180.09 | E14: 1. Did your leasing arrangements have any variable receipts which ARE NOT included in the measurement of the lease receivable? These include but are not limited to receipts related to residual value guarantees and termination penalties.
A15: =LEFT(A14,4)+1&"–"&RIGHT(A14,4)+1 -> 2024–2025 | B15: 2598335.4 | C15: 121045.73
A16: =LEFT(A15,4)+1&"–"&RIGHT(A15,4)+1 -> 2025–2026 | B16: 2588302.8 | C16: 97850.329
A17: =LEFT(A16,4)+1&"–"&RIGHT(A16,4)+1 -> 2026–2027 | B17: 2611693.8 | C17: 74459.273
A18: =LEFT(A17,4)+1&"–"&RIGHT(A17,4)+1 -> 2027–2028 | B18: 2635296.3 | C18: 50856.827 | E18: No
A19: =LEFT(A18,4)+1&"–"&RIGHT(A18,4)+5 -> 2028–2033 | B19: 4221344.4 | C19: 31731.291 | E19: ="If yes, record the dollar amount of variable receipts below for fiscal year "&$B$9&":" -> If yes, record the dollar amount of variable receipts below for fiscal year 2022–2023:
A20: =LEFT(A19,4)+5&"–"&RIGHT(A19,4)+5 -> 2033–2038 | E20: 0
A21: =LEFT(A20,4)+5&"–"&RIGHT(A20,4)+5 -> 2038–2043 | E21: ="2. Did you grant any lease incentives to the lessee during fiscal year "&$B$9&"? If so, record the amount below:" -> 2. Did you grant any lease incentives to the lessee during fiscal year 2022–2023? If so, record the amount below:
A22: =LEFT(A21,4)+5&"–"&RIGHT(A21,4)+5 -> 2043–2048
A23: =LEFT(A22,4)+5&"–"&RIGHT(A22,4)+5 -> 2048–2053 | E23: 0
A24: =LEFT(A23,4)+5&"–"&RIGHT(A23,4)+5 -> 2053–2058
A25: =LEFT(A24,4)+5&"–"&RIGHT(A24,4)+5 -> 2058–2063
A26: =LEFT(A25,4)+5&"–"&RIGHT(A25,4)+5 -> 2063–2068
A27: =LEFT(A26,4)+5&"–"&RIGHT(A26,4)+5 -> 2068–2073
A28: =LEFT(A27,4)+5&"–"&RIGHT(A27,4)+5 -> 2073–2078
A29: =LEFT(A28,4)+5&"–"&RIGHT(A28,4)+5 -> 2078–2083
A30: =LEFT(A29,4)+5&"–"&RIGHT(A29,4)+5 -> 2083–2088
A31: =LEFT(A30,4)+5&"–"&RIGHT(A30,4)+5 -> 2088–2093
A32: =LEFT(A31,4)+5&"–"&RIGHT(A31,4)+5 -> 2093–2098
A33: =LEFT(A32,4)+5&"–"&RIGHT(A32,4)+5 -> 2098–2103
A34: =LEFT(A33,4)+5&"–"&RIGHT(A33,4)+5 -> 2103–2108
A35: =LEFT(A34,4)+5&"–"&RIGHT(A34,4)+5 -> 2108–2113
... A37: =LEFT(A36,4)+5&"–"&RIGHT(A36,4)+5 -> 2118–2123
A39: II. Proprietary - INTERNAL SERVICE FUNDS
A40: Fiscal Year: | B40: =B9 -> 2022–2023
A41: Organization Code: | B41: =B10 -> 2660
A42: Organization Name: | B42: =B11 -> Department of Transportation
A43: The below information must be entered manually.
B44: Principal Receipts | C44: Interest Receipts | E44: ="All of this worksheet's questions are for Fiscal Year "&$B$9&":" -> All of this worksheet's questions are for Fiscal Year 2022–2023:
...

Sheet LR-Check Figures
A1: GASB Statement No. 87 Lessors
A2: Check Figures
A4: Purpose:
A5: The purpose of this workbook is to check the figures entered in the journal entries reconcile to the future principal receipts disclosed and the changes in the schedule of the lease receivable.
A8: NOTE: If multiple funds are included in this workbook, manually complete every yellow field by consolidating the entries by fund type (Governmental, Proprietary ISF, and Proprietary EF).
A10: 1. To reconcile the journal entries of Lease Receivable with the principal receipts in Note Disclosure.
B11: a) Governmental Funds
B13: Journal Entries | N13: Department Note Disclosure
B14: Beginning Balance | D14: Additions | F14: Deductions | H14: Deductions (Mod) | J14: Additions (Mod)
B15: Entry #0 | C15: + | D15: Entry #1 | E15: - | F15: Entry #2 | G15: - | H15: Entry #5 | I15: + | J15: Entry #6 | N15: Sum Principal Receipts | P15: Variance
B16: 19915320 | C16: + | D16: =IF('LR-Fund 0042 Journal Entries'!$E$8="Governmental Fund",'LR-Fund 0042 Journal Entries'!$J$24,0) -> 0 | E16: - | F16: 2618690 | G16: - | H16: =IF('LR-Fund 0042 Journal Entries'!$E$8="Governmental Fund",'LR-Fund 0042 Journal Entries'!$K$52,0) -> 0 | I16: + | J16: =IF('LR-Fund 0042 Journal Entries'!$E$8="Governmental Fund",'LR-Fund 0042 Journal Entries'!$J$58,0) -> 0 | K16: = | L16: =+B16+D16-F16-H16+J16 -> 17296630 | N16: =SUM('LR-Department Note Disclosure'!B14:B37) -> 17296630 | P16: =L16-N16 -> 0.4241919
D18: =IF(OR(P16>0, (P16<0)), "Please review and correct the variance.","") -> Please review and correct the variance.
B19: b) Proprietary - Internal Service Funds
B21: Journal Entries | N21: Department Note Disclosure
B22: Beginning Balance | D22: Additions | F22: Deductions | H22: Deductions (Mod) | J22: Additions (Mod)
B23: Entry #0 | C23: + | D23: Entry #1 | E23: - | F23: Entry #2 | G23: - | H23: Entry #5 | I23: + | J23: Entry #6 | N23: Sum Principal Receipts | P23: Variance
B24: =IF('LR-Fund 0042 Journal Entries'!$E$8="Proprietary - Internal Service Fund",'LR-Fund 0042 Journal Entries'!$J$14,0) -> 0 | C24: + | D24: =IF('LR-Fund 0042 Journal Entries'!$E$8="Proprietary - Internal Service Fund",'LR-Fund 0042 Journal Entries'!$J$24,0) -> 0 | E24: - | F24: =IF('LR-Fund 0042 Journal Entries'!$E$8="Proprietary - Internal Service Fund",'LR-Fund 0042 Journal Entries'!$K$31,0) -> 0 | G24: - | H24: =IF('LR-Fund 0042 Journal Entries'!$E$8="Proprietary - Internal Service Fund",'LR-Fund 0042 Journal Entries'!$K$52,0) -> 0 | I24: + | J24: =IF('LR-Fund 0042 Journal Entries'!$E$8="Proprietary - Internal Service Fund",'LR-Fund 0042 Journal Entries'!$J$58,0) -> 0 | K24: = | L24: =+B24+D24-F24-H24+J24 -> 0 | N24: =SUM('LR-Department Note Disclosure'!B45:B68) -> 0 | P24: =L24-N24 -> 0
D26: =IF(OR(P24>0, (P24<0)), "Please review and correct the variance.","")
B28: c) Proprietary - Enterprise Funds
B30: Journal Entries | N30: Department Note Disclosure
B31: Beginning Balance | D31: Additions | F31: Deductions | H31: Deductions (Mod) | J31: Additions (Mod)
B32: Entry #0 | C32: + | D32: Entry #1 | E32: - | F32: Entry #2 | G32: - | H32: Entry #5 | I32: + | J32: Entry #6 | N32: Sum Principal Receipts | P32: Variance
B33: =IF('LR-Fund 0042 Journal Entries'!$E$8="Proprietary - Enterprise Fund",'LR-Fund 0042 Journal Entries'!$J$14,0) -> 0 | C33: + | D33: =IF('LR-Fund 0042 Journal Entries'!$E$8="Proprietary - Enterprise Fund",'LR-Fund 0042 Journal Entries'!$J$24,0) -> 0 | E33: - | F33: =IF('LR-Fund 0042 Journal Entries'!$E$8="Proprietary - Enterprise Fund",'LR-Fund 0042 Journal Entries'!$K$31,0) -> 0 | G33: - | H33: =IF('LR-Fund 0042 Journal Entries'!$E$8="Proprietary - Enterprise Fund",'LR-Fund 0042 Journal Entries'!$K$52,0) -> 0 | I33: + | J33: =IF('LR-Fund 0042 Journal Entries'!$E$8="Proprietary - Enterprise Fund",'LR-Fund 0042 Journal Entries'!$J$58,0) -> 0 | K33: = | L33: =+B33+D33-F33-H33+J33 -> 0 | N33: =SUM('LR-Department Note Disclosure'!B76:B99) -> 0 | P33: =L33-N33 -> 0
D35: =IF(OR(P33>0, (P33<0)), "Please review and correct the variance.","")
A37: 2. To match the journal entry to the principal amount due receivable in the next fiscal year in Note Disclosure.
B38: a) Governmental Funds
B40: Journal Entries | N40: Department Note Disclosure
B41: Entry #4 | C41: Due within one year | N41: =CONCATENATE('LS-Department Note Disclosure'!$A$13," Principal Payments") -> 2023–2024 Principal Payments | P41: Variance
B42: 2641657 | N42: ='LR-Department Note Disclosure'!B14 -> 2641657 | P42: =B42-N42 -> 0
D44: =IF(OR(P42>0, (P42<0)), "Please review and correct the variance.","")
B45: b) Proprietary - Internal Service Funds
B47: Journal Entries | N47: Department Note Disclosure
B48: Entry #4 | C48: Due within one year | N48: =CONCATENATE('LS-Department Note Disclosure'!$A$44," Principal Payments") -> 2023–2024 Principal Payments | P48: Variance
B49: =IF('LR-Fund 0042 Journal Entries'!$E$8="Proprietary - Internal Service Fund",'LR-Fund 0042 Journal Entries'!$J$41,0) -> 0 | N49: ='LR-Department Note Disclosure'!B45 -> 0 | P49: =B49-N49 -> 0
D51: =IF(OR(P49>0, (P49<0)), "Please review and correct the variance.","")
B53: c) Proprietary - Enterprise Funds
B55: Journal Entries | N55: Department Note Disclosure
B56: Entry #4 | C56: Due within one year | N56: =CONCATENATE('LS-Department Note Disclosure'!$A$75," Principal Payments") -> 2023–2024 Principal Payments | P56: Variance
B57: =IF('LR-Fund 0042 Journal Entries'!$E$8="Proprietary - Enterprise Fund",'LR-Fund 0042 Journal Entries'!$J$41,0) -> 0 | N57: ='LR-Department Note Disclosure'!B76 -> 0 | P57: =B57-N57 -> 0
