Workbook
Name ActuaryCredentialsGASB: [1]DeveloperInfo!$D$19
Name ActuaryNameGASB: [1]DeveloperInfo!$D$17
Name ActuaryTitleGASB: [1]DeveloperInfo!$D$18
Name AdjCNSDate: [1]DeveloperInfo!$D$33
Name AdjCNSDate1: [1]DeveloperInfo!$E$33
Name AdjCNSDateTempEnable: [1]DeveloperInfo!$F$34
Name AgencyCode: #REF!
Name AgencyCode1: #REF!
Name AnalystGASB: [1]DeveloperInfo!$D$20
Name Annuity: #REF!
Name Annuity1: #REF!
Name AnnuityLY: #REF!
Name ASTABPF: [1]DeveloperInfo!$D$36
Name ASTABPF1: [1]DeveloperInfo!$D$37
Name ASTEBPF: [1]DeveloperInfo!$F$37
Name ClientShortGASB: [1]DeveloperInfo!$D$9
Name CLPOWERDisc: [1]Adjust!$H$199
Name CLPOWERDiscMinus1: [1]Adjust!$L$199
Name CLPOWERDiscPlus1: [1]Adjust!$K$199
Name CLPOWERExp: [1]Adjust!$G$199
Name CNSDateDisc: [1]DeveloperInfo!$D$32
Name CNSDateDisc1: [1]DeveloperInfo!$E$32
Name ColaRate: [1]DeveloperInfo!$D$40
Name ConsultantNameGASB: [1]DeveloperInfo!$D$22
Name ConsultantTitleGASB: [1]DeveloperInfo!$D$23
Name Disc1DELTACENSUS: [1]Adjust!$G$102
Name Disc1INTNDIV12: [1]Adjust!$H$195
Name Disc1SINTADJBOM: [1]Adjust!$I$197
Name Disc1SINTNDIV12: [1]Adjust!$I$195
Name DiscDELTACENSUS: [1]Adjust!$H$102
Name DiscINTADJBOM: [1]Adjust!$J$197
Name DiscINTNDIV12: [1]Adjust!$J$195
Name DiscMinusOneINTADJBOM: [1]Adjust!$L$197
Name DiscMinusOneINTNDIV12: [1]Adjust!$L$195
Name DiscPlusOneINTADJBOM: [1]Adjust!$K$197
Name DiscPlusOneINTNDIV12: [1]Adjust!$K$195
Name EmployerRates: #REF!
Name EmployerRates1: #REF!
Name EmployerRatesLEO: #REF!
Name EmployerRatesLEO1: #REF!
Name ERData: [1]ER_DATA!$B$16:$EN$318
Name ERID: [1]ER_NPLExpense!$L$8
Name ERInfo: [1]ER_Input!$B$16:$Y$318
Name Exp1INTADJBOM: [1]Adjust!$G$197
Name Exp1INTNDIV12: [1]Adjust!$G$195
Name FracYearProj: [1]TPL!$C$43
Name FundOfficeContactGASB: [1]DeveloperInfo!$D$10
Name FYrsGASB: [1]DeveloperInfo!$D$54
Name GainLoss: [1]ER_Allocation!$P$12
Name GASBDiscMinusOneINTADJBOM: [1]Adjust!$L$197
Name GASBDiscMinusOneINTNDIV12: [1]Adjust!$L$195
Name InflRate: [1]DeveloperInfo!$D$38
Name InflRate1: [1]DeveloperInfo!$E$38
Name IntDisc: [1]DeveloperInfo!$F$47
Name IntDisc1: [1]DeveloperInfo!$D$47
Name IntDisc1S: [1]DeveloperInfo!$E$47
Name INTDiscMinusOne: [1]DeveloperInfo!$H$47
Name INTDiscPlusOne: [1]DeveloperInfo!$G$47
Name IntExp1: [1]DeveloperInfo!$I$47
Name MeasureDate: [1]DeveloperInfo!$D$31

Sheet Fund 0001 Journal Entries
A1: GASB 96 - SBITA Contracts Fund-by-Fund Journal Entries Form (to be submitted to the SCO annually—one form per fund)
A2: Manually complete every yellow field in this worksheet—there are no automatically calculated data-entry cells in this worksheet.
A3: Fiscal year: | F3: 2023–2024
A4: Organization Name: | F4: Department of Justice
A5: Organization Code (Business Unit): | F5: 0820
A6: Fund Number: | F6: 1
A7: Fund Type: | F7: Governmental Fund
A8: Fund Classification: | F8: =IF(OR($F$7='Drop Down Menus'!B2,$F$7='Drop Down Menus'!$B$3),'Drop Down Menus'!$D$9,IFERROR(VLOOKUP($F$5,GAAP02Aindex!$A$2:$D$900,4,FALSE),"Unidentified")) -> GENERAL GOVERNMENT
A12: =IF($F$3="2022–2023","Establish Beginning Balances (SBITAs commenced on or before 07/01/2022)","Establish Beginning Balances (existing SBITAs only)") -> Establish Beginning Balances (existing SBITAs only)
A13: Entry #
A14: 0 | B14: =IF($F$3="2022–2023","To establish the beginning balance of SBITAs as of 07/01/2022.","Roll forward prior year right-to-use SBITAs to record opening balances.") -> Roll forward prior year right-to-use SBITAs to record opening balances. | M14: Department Beginning Balances | P14: From SCO BB List | S14: Difference
B15: Dr: Acct 0480 - RIGHT-TO-USE SBITA - AMORTIZABLE | J15: =ROUND(M15,0) -> 3655450 | M15: 3655450 | P15: 3655450 | S15: =M15-P15 -> 0 | T15: Report any "Differences" on the Report 18 Differential.
B16: Dr: Acct 0950 - BEGINNING FUND BALANCE | J16: =ROUND(P16,0) -> 0 | M16: 8892 | P16: =IF(SUM($Q$18:$Q$19)>$P$15,SUM($Q$18:$Q$19)-$P$15,0) -> 0 | S16: =M16-P16 -> 8892 | T16: No action required.
B17: Dr: Acct 0952 - BEG FB ADJ/PRIOR PERIOD ADJUSTMENT | J17: =ROUND(IF(SUM($K$18:$K$20)>SUM($J$15:$J$16),SUM($K$18:$K$20)-SUM($J$15:$J$16),0),0) -> 0 | S17: =M17-P17 -> 0 | T17: No action required.
C18: Cr. Acct 0475 - ACCUMULATED AMORTIZATION - RIGHT-TO-USE SBITA | K18: =ROUND(N18,0) -> 2247186 | N18: 2247186 | Q18: 2247186 | S18: =N18-Q18 -> 0 | T18: No action required.
C19: Cr: Acct 0674 - RIGHT-TO-USE SBITA LIABILITY | K19: =ROUND(N19,0) -> 968958 | N19: 968958 | Q19: 968958 | S19: =N19-Q19 -> 0 | T19: No action required.
C20: Cr: Acct 0950 - BEGINNING FUND BALANCE | K20: =ROUND(Q20,0) -> 439306 | N20: 448198 | Q20: =IF(SUM($Q$18:$Q$19)<$P$15,-SUM($Q$18:$Q$19)+$P$15,0) -> 439306 | S20: =N20-Q20 -> 8892 | T20: No action required.
C21: Cr: Acct 0952 - BEG FB ADJ/PRIOR PERIOD ADJUSTMENT | K21: =ROUND(IF(SUM($K$18:$K$20)<SUM($J$15:$J$16),-SUM($K$18:$K$20)+SUM($J$15:$J$16),0),0) -> 0 | S21: =N21-Q21 -> 0 | T21: No action required.
J22: =ROUND(SUM(J15:J17),0) -> 3655450 | K22: =ROUND(SUM(K18:K21),0) -> 3655450 | L22: =IF(J22=K22,"<- Debits and Credits equal each other.","<- Debits and Credits do not equal each other.") -> <- Debits and Credits equal each other.
B24: SBITA ASSET (Acct 0480) AMOUNT SHOULD BE REPORTED AS BEGINNING BALANCE ON REPORT 18.
A26: =IF($F$3="2022–2023","Record SBITAs Commenced on or after 07/02/2022","Record New SBITAs (new SBITAs only)") -> Record New SBITAs (new SBITAs only)
A27: 1 | B27: Record at inception of SBITA in accordance with Fund-Based accounting (Governmental Funds Only).
B28: Dr: Acct 0842 - CAPITAL OUTLAY | J28: 1083987
C29: Cr: Acct 0789 - LEASE AND OTHER FINANCING PROCEEDS | K29: 1083987
C30: =VLOOKUP($F$8,'Drop Down Menus'!$D$2:$G$10,4,FALSE) -> Cr: Acct 0808 - GENERAL GOV. (GAAP ADJ)
J31: =ROUND(SUM(J28:J30),2) -> 1083987 | K31: =ROUND(SUM(K28:K30),2) -> 1083987 | L31: =IF(J31=K31,"<- Debits and Credits equal each other.","<- Debits and Credits do not equal each other.") -> <- Debits and Credits equal each other.
A33: 2 | B33: Reverse the fund-based entry in #1 above, if any, and record an inception of SBITA in accordance with GAAP Govt Wide.
B34: Dr: Acct 0480 - RIGHT-TO-USE SBITA - AMORTIZABLE | J34: 1083987
B35: Dr: Acct 0789 - LEASE AND OTHER FINANCING PROCEEDS | J35: 1083987
C36: Cr: Acct 0842 - CAPITAL OUTLAY | K36: 1083987
C37: Cr: Acct 0674 - RIGHT-TO-USE SBITA LIABILITY | K37: 1083987
C38: =VLOOKUP($F$8,'Drop Down Menus'!$D$2:$G$10,4,FALSE) -> Cr: Acct 0808 - GENERAL GOV. (GAAP ADJ)
J39: =ROUND(SUM(J34:J35),2) -> 2167974 | K39: =ROUND(SUM(K36:K38),2) -> 2167974 | L39: =IF(J39=K39,"<- Debits and Credits equal each other.","<- Debits and Credits do not equal each other.") -> <- Debits and Credits equal each other.
B41: SBITA ASSET (Acct 0480) AMOUNT SHOULD BE INCLUDED AS "ADDITIONS" ON REPORT 18.
A43: Record Annual Activity (all SBITAs)
A44: 3 | B44: Record amortization of the SBITA asset for the year.
B45: Dr: Acct 0875 - DEPRECIATION/AMORTIZATION | J45: 882518
C46: Cr. Acct 0475 - ACCUMULATED AMORTIZATION - RIGHT-TO-USE SBITA | K46: =J45 -> 882518
J47: =ROUND(SUM(J45:J45),2) -> 882518 | K47: =ROUND(SUM(K46),2) -> 882518 | L47: =IF(J47=K47,"<- Debits and Credits equal each other.","<- Debits and Credits do not equal each other.") -> <- Debits and Credits equal each other.
A49: 4 | B49: Reclassify information technology subscription exp. to debt service principal and interest exp.
...

Sheet Fund 0012 Journal Entries
A1: GASB 96 - SBITA Contracts Fund-by-Fund Journal Entries Form (to be submitted to the SCO annually—one form per fund)
A2: Manually complete every yellow field in this worksheet—there are no automatically calculated data-entry cells in this worksheet.
A3: Fiscal year: | F3: 2023–2024
A4: Organization Name: | F4: Department of Justice
A5: Organization Code (Business Unit): | F5: 0820
A6: Fund Number: | F6: 12
A7: Fund Type: | F7: Governmental Fund
A8: Fund Classification: | F8: =IF(OR($F$7='Drop Down Menus'!B2,$F$7='Drop Down Menus'!$B$3),'Drop Down Menus'!$D$9,IFERROR(VLOOKUP($F$5,GAAP02Aindex!$A$2:$D$900,4,FALSE),"Unidentified")) -> GENERAL GOVERNMENT
A12: =IF($F$3="2022–2023","Establish Beginning Balances (SBITAs commenced on or before 07/01/2022)","Establish Beginning Balances (existing SBITAs only)") -> Establish Beginning Balances (existing SBITAs only)
A13: Entry #
A14: 0 | B14: =IF($F$3="2022–2023","To establish the beginning balance of SBITAs as of 07/01/2022.","Roll forward prior year right-to-use SBITAs to record opening balances.") -> Roll forward prior year right-to-use SBITAs to record opening balances. | M14: Department Beginning Balances | P14: From SCO BB List | S14: Difference
B15: Dr: Acct 0480 - RIGHT-TO-USE SBITA - AMORTIZABLE | J15: =ROUND(M15,0) -> 717 | M15: 717 | P15: 717 | S15: =M15-P15 -> 0 | T15: Report any "Differences" on the Report 18 Differential.
B16: Dr: Acct 0950 - BEGINNING FUND BALANCE | J16: =ROUND(P16,0) -> 0 | M16: 4 | P16: =IF(SUM($Q$18:$Q$19)>$P$15,SUM($Q$18:$Q$19)-$P$15,0) -> 0 | S16: =M16-P16 -> 4 | T16: No action required.
B17: Dr: Acct 0952 - BEG FB ADJ/PRIOR PERIOD ADJUSTMENT | J17: =ROUND(IF(SUM($K$18:$K$20)>SUM($J$15:$J$16),SUM($K$18:$K$20)-SUM($J$15:$J$16),0),0) -> 0 | S17: =M17-P17 -> 0 | T17: No action required.
C18: Cr. Acct 0475 - ACCUMULATED AMORTIZATION - RIGHT-TO-USE SBITA | K18: =ROUND(N18,0) -> 295 | N18: 295 | Q18: 295 | S18: =N18-Q18 -> 0 | T18: No action required.
C19: Cr: Acct 0674 - RIGHT-TO-USE SBITA LIABILITY | K19: =ROUND(N19,0) -> 411 | N19: 411 | Q19: 411 | S19: =N19-Q19 -> 0 | T19: No action required.
C20: Cr: Acct 0950 - BEGINNING FUND BALANCE | K20: =ROUND(Q20,0) -> 11 | N20: 15 | Q20: =IF(SUM($Q$18:$Q$19)<$P$15,-SUM($Q$18:$Q$19)+$P$15,0) -> 11 | S20: =N20-Q20 -> 4 | T20: No action required.
C21: Cr: Acct 0952 - BEG FB ADJ/PRIOR PERIOD ADJUSTMENT | K21: =ROUND(IF(SUM($K$18:$K$20)<SUM($J$15:$J$16),-SUM($K$18:$K$20)+SUM($J$15:$J$16),0),0) -> 0 | S21: =N21-Q21 -> 0 | T21: No action required.
J22: =ROUND(SUM(J15:J17),0) -> 717 | K22: =ROUND(SUM(K18:K21),0) -> 717 | L22: =IF(J22=K22,"<- Debits and Credits equal each other.","<- Debits and Credits do not equal each other.") -> <- Debits and Credits equal each other.
B24: SBITA ASSET (Acct 0480) AMOUNT SHOULD BE REPORTED AS BEGINNING BALANCE ON REPORT 18.
A26: =IF($F$3="2022–2023","Record SBITAs Commenced on or after 07/02/2022","Record New SBITAs (new SBITAs only)") -> Record New SBITAs (new SBITAs only)
A27: 1 | B27: Record at inception of SBITA in accordance with Fund-Based accounting (Governmental Funds Only).
B28: Dr: Acct 0842 - CAPITAL OUTLAY | J28: 557
C29: Cr: Acct 0789 - LEASE AND OTHER FINANCING PROCEEDS | K29: 557
C30: =VLOOKUP($F$8,'Drop Down Menus'!$D$2:$G$10,4,FALSE) -> Cr: Acct 0808 - GENERAL GOV. (GAAP ADJ)
J31: =ROUND(SUM(J28:J30),2) -> 557 | K31: =ROUND(SUM(K28:K30),2) -> 557 | L31: =IF(J31=K31,"<- Debits and Credits equal each other.","<- Debits and Credits do not equal each other.") -> <- Debits and Credits equal each other.
A33: 2 | B33: Reverse the fund-based entry in #1 above, if any, and record an inception of SBITA in accordance with GAAP Govt Wide.
B34: Dr: Acct 0480 - RIGHT-TO-USE SBITA - AMORTIZABLE | J34: 557
B35: Dr: Acct 0789 - LEASE AND OTHER FINANCING PROCEEDS | J35: 557
C36: Cr: Acct 0842 - CAPITAL OUTLAY | K36: 557
C37: Cr: Acct 0674 - RIGHT-TO-USE SBITA LIABILITY | K37: 557
C38: =VLOOKUP($F$8,'Drop Down Menus'!$D$2:$G$10,4,FALSE) -> Cr: Acct 0808 - GENERAL GOV. (GAAP ADJ)
J39: =ROUND(SUM(J34:J35),2) -> 1114 | K39: =ROUND(SUM(K36:K38),2) -> 1114 | L39: =IF(J39=K39,"<- Debits and Credits equal each other.","<- Debits and Credits do not equal each other.") -> <- Debits and Credits equal each other.
B41: SBITA ASSET (Acct 0480) AMOUNT SHOULD BE INCLUDED AS "ADDITIONS" ON REPORT 18.
A43: Record Annual Activity (all SBITAs)
A44: 3 | B44: Record amortization of the SBITA asset for the year.
B45: Dr: Acct 0875 - DEPRECIATION/AMORTIZATION | J45: 161
C46: Cr. Acct 0475 - ACCUMULATED AMORTIZATION - RIGHT-TO-USE SBITA | K46: =J45 -> 161
J47: =ROUND(SUM(J45:J45),2) -> 161 | K47: =ROUND(SUM(K46),2) -> 161 | L47: =IF(J47=K47,"<- Debits and Credits equal each other.","<- Debits and Credits do not equal each other.") -> <- Debits and Credits equal each other.
A49: 4 | B49: Reclassify information technology subscription exp. to debt service principal and interest exp.
...

Sheet Fund 0017 Journal Entries
A1: GASB 96 - SBITA Contracts Fund-by-Fund Journal Entries Form (to be submitted to the SCO annually—one form per fund)
A2: Manually complete every yellow field in this worksheet—there are no automatically calculated data-entry cells in this worksheet.
A3: Fiscal year: | F3: 2023–2024
A4: Organization Name: | F4: Department of Justice
A5: Organization Code (Business Unit): | F5: 0820
A6: Fund Number: | F6: 17
A7: Fund Type: | F7: Governmental Fund
A8: Fund Classification: | F8: =IF(OR($F$7='Drop Down Menus'!B2,$F$7='Drop Down Menus'!$B$3),'Drop Down Menus'!$D$9,IFERROR(VLOOKUP($F$5,GAAP02Aindex!$A$2:$D$900,4,FALSE),"Unidentified")) -> GENERAL GOVERNMENT
A12: =IF($F$3="2022–2023","Establish Beginning Balances (SBITAs commenced on or before 07/01/2022)","Establish Beginning Balances (existing SBITAs only)") -> Establish Beginning Balances (existing SBITAs only)
A13: Entry #
A14: 0 | B14: =IF($F$3="2022–2023","To establish the beginning balance of SBITAs as of 07/01/2022.","Roll forward prior year right-to-use SBITAs to record opening balances.") -> Roll forward prior year right-to-use SBITAs to record opening balances. | M14: Department Beginning Balances | P14: From SCO BB List | S14: Difference
B15: Dr: Acct 0480 - RIGHT-TO-USE SBITA - AMORTIZABLE | J15: =ROUND(M15,0) -> 332868 | M15: 332868 | P15: 332868 | S15: =M15-P15 -> 0 | T15: Report any "Differences" on the Report 18 Differential.
B16: Dr: Acct 0950 - BEGINNING FUND BALANCE | J16: =ROUND(P16,0) -> 0 | M16: 1123 | P16: =IF(SUM($Q$18:$Q$19)>$P$15,SUM($Q$18:$Q$19)-$P$15,0) -> 0 | S16: =M16-P16 -> 1123 | T16: No action required.
B17: Dr: Acct 0952 - BEG FB ADJ/PRIOR PERIOD ADJUSTMENT | J17: =ROUND(IF(SUM($K$18:$K$20)>SUM($J$15:$J$16),SUM($K$18:$K$20)-SUM($J$15:$J$16),0),0) -> 0 | S17: =M17-P17 -> 0 | T17: No action required.
C18: Cr. Acct 0475 - ACCUMULATED AMORTIZATION - RIGHT-TO-USE SBITA | K18: =ROUND(N18,0) -> 186858 | N18: 186858 | Q18: 186858 | S18: =N18-Q18 -> 0 | T18: No action required.
C19: Cr: Acct 0674 - RIGHT-TO-USE SBITA LIABILITY | K19: =ROUND(N19,0) -> 124913 | N19: 124913 | Q19: 124913 | S19: =N19-Q19 -> 0 | T19: No action required.
C20: Cr: Acct 0950 - BEGINNING FUND BALANCE | K20: =ROUND(Q20,0) -> 21097 | N20: 22220 | Q20: =IF(SUM($Q$18:$Q$19)<$P$15,-SUM($Q$18:$Q$19)+$P$15,0) -> 21097 | S20: =N20-Q20 -> 1123 | T20: No action required.
C21: Cr: Acct 0952 - BEG FB ADJ/PRIOR PERIOD ADJUSTMENT | K21: =ROUND(IF(SUM($K$18:$K$20)<SUM($J$15:$J$16),-SUM($K$18:$K$20)+SUM($J$15:$J$16),0),0) -> 0 | S21: =N21-Q21 -> 0 | T21: No action required.
J22: =ROUND(SUM(J15:J17),0) -> 332868 | K22: =ROUND(SUM(K18:K21),0) -> 332868 | L22: =IF(J22=K22,"<- Debits and Credits equal each other.","<- Debits and Credits do not equal each other.") -> <- Debits and Credits equal each other.
B24: SBITA ASSET (Acct 0480) AMOUNT SHOULD BE REPORTED AS BEGINNING BALANCE ON REPORT 18.
A26: =IF($F$3="2022–2023","Record SBITAs Commenced on or after 07/02/2022","Record New SBITAs (new SBITAs only)") -> Record New SBITAs (new SBITAs only)
A27: 1 | B27: Record at inception of SBITA in accordance with Fund-Based accounting (Governmental Funds Only).
B28: Dr: Acct 0842 - CAPITAL OUTLAY | J28: 897953
C29: Cr: Acct 0789 - LEASE AND OTHER FINANCING PROCEEDS | K29: 897953
C30: =VLOOKUP($F$8,'Drop Down Menus'!$D$2:$G$10,4,FALSE) -> Cr: Acct 0808 - GENERAL GOV. (GAAP ADJ)
J31: =ROUND(SUM(J28:J30),2) -> 897953 | K31: =ROUND(SUM(K28:K30),2) -> 897953 | L31: =IF(J31=K31,"<- Debits and Credits equal each other.","<- Debits and Credits do not equal each other.") -> <- Debits and Credits equal each other.
A33: 2 | B33: Reverse the fund-based entry in #1 above, if any, and record an inception of SBITA in accordance with GAAP Govt Wide.
B34: Dr: Acct 0480 - RIGHT-TO-USE SBITA - AMORTIZABLE | J34: 897953
B35: Dr: Acct 0789 - LEASE AND OTHER FINANCING PROCEEDS | J35: 897953
C36: Cr: Acct 0842 - CAPITAL OUTLAY | K36: 897953
C37: Cr: Acct 0674 - RIGHT-TO-USE SBITA LIABILITY | K37: 897953
C38: =VLOOKUP($F$8,'Drop Down Menus'!$D$2:$G$10,4,FALSE) -> Cr: Acct 0808 - GENERAL GOV. (GAAP ADJ)
J39: =ROUND(SUM(J34:J35),2) -> 1795906 | K39: =ROUND(SUM(K36:K38),2) -> 1795906 | L39: =IF(J39=K39,"<- Debits and Credits equal each other.","<- Debits and Credits do not equal each other.") -> <- Debits and Credits equal each other.
B41: SBITA ASSET (Acct 0480) AMOUNT SHOULD BE INCLUDED AS "ADDITIONS" ON REPORT 18.
A43: Record Annual Activity (all SBITAs)
A44: 3 | B44: Record amortization of the SBITA asset for the year.
B45: Dr: Acct 0875 - DEPRECIATION/AMORTIZATION | J45: 234418
C46: Cr. Acct 0475 - ACCUMULATED AMORTIZATION - RIGHT-TO-USE SBITA | K46: =J45 -> 234418
J47: =ROUND(SUM(J45:J45),2) -> 234418 | K47: =ROUND(SUM(K46),2) -> 234418 | L47: =IF(J47=K47,"<- Debits and Credits equal each other.","<- Debits and Credits do not equal each other.") -> <- Debits and Credits equal each other.
A49: 4 | B49: Reclassify information technology subscription exp. to debt service principal and interest exp.
...

Sheet Fund 0044 Journal Entries
A1: GASB 96 - SBITA Contracts Fund-by-Fund Journal Entries Form (to be submitted to the SCO annually—one form per fund)
A2: Manually complete every yellow field in this worksheet—there are no automatically calculated data-entry cells in this worksheet.
A3: Fiscal year: | F3: 2023–2024
A4: Organization Name: | F4: Department of Justice
A5: Organization Code (Business Unit): | F5: 0820
A6: Fund Number: | F6: 44
A7: Fund Type: | F7: Governmental Fund
A8: Fund Classification: | F8: =IF(OR($F$7='Drop Down Menus'!B2,$F$7='Drop Down Menus'!$B$3),'Drop Down Menus'!$D$9,IFERROR(VLOOKUP($F$5,GAAP02Aindex!$A$2:$D$900,4,FALSE),"Unidentified")) -> GENERAL GOVERNMENT
A12: =IF($F$3="2022–2023","Establish Beginning Balances (SBITAs commenced on or before 07/01/2022)","Establish Beginning Balances (existing SBITAs only)") -> Establish Beginning Balances (existing SBITAs only)
A13: Entry #
A14: 0 | B14: =IF($F$3="2022–2023","To establish the beginning balance of SBITAs as of 07/01/2022.","Roll forward prior year right-to-use SBITAs to record opening balances.") -> Roll forward prior year right-to-use SBITAs to record opening balances. | M14: Department Beginning Balances | P14: From SCO BB List | S14: Difference
B15: Dr: Acct 0480 - RIGHT-TO-USE SBITA - AMORTIZABLE | J15: =ROUND(M15,0) -> 436045 | M15: 436045 | P15: 436045 | S15: =M15-P15 -> 0 | T15: Report any "Differences" on the Report 18 Differential.
B16: Dr: Acct 0950 - BEGINNING FUND BALANCE | J16: =ROUND(P16,0) -> 0 | M16: 1472 | P16: =IF(SUM($Q$18:$Q$19)>$P$15,SUM($Q$18:$Q$19)-$P$15,0) -> 0 | S16: =M16-P16 -> 1472 | T16: No action required.
B17: Dr: Acct 0952 - BEG FB ADJ/PRIOR PERIOD ADJUSTMENT | J17: =ROUND(IF(SUM($K$18:$K$20)>SUM($J$15:$J$16),SUM($K$18:$K$20)-SUM($J$15:$J$16),0),0) -> 0 | S17: =M17-P17 -> 0 | T17: No action required.
C18: Cr. Acct 0475 - ACCUMULATED AMORTIZATION - RIGHT-TO-USE SBITA | K18: =ROUND(N18,0) -> 244778 | N18: 244778 | Q18: 244778 | S18: =N18-Q18 -> 0 | T18: No action required.
C19: Cr: Acct 0674 - RIGHT-TO-USE SBITA LIABILITY | K19: =ROUND(N19,0) -> 163631 | N19: 163631 | Q19: 163631 | S19: =N19-Q19 -> 0 | T19: No action required.
C20: Cr: Acct 0950 - BEGINNING FUND BALANCE | K20: =ROUND(Q20,0) -> 27636 | N20: 29108 | Q20: =IF(SUM($Q$18:$Q$19)<$P$15,-SUM($Q$18:$Q$19)+$P$15,0) -> 27636 | S20: =N20-Q20 -> 1472 | T20: No action required.
C21: Cr: Acct 0952 - BEG FB ADJ/PRIOR PERIOD ADJUSTMENT | K21: =ROUND(IF(SUM($K$18:$K$20)<SUM($J$15:$J$16),-SUM($K$18:$K$20)+SUM($J$15:$J$16),0),0) -> 0 | S21: =N21-Q21 -> 0 | T21: No action required.
J22: =ROUND(SUM(J15:J17),0) -> 436045 | K22: =ROUND(SUM(K18:K21),0) -> 436045 | L22: =IF(J22=K22,"<- Debits and Credits equal each other.","<- Debits and Credits do not equal each other.") -> <- Debits and Credits equal each other.
B24: SBITA ASSET (Acct 0480) AMOUNT SHOULD BE REPORTED AS BEGINNING BALANCE ON REPORT 18.
A26: =IF($F$3="2022–2023","Record SBITAs Commenced on or after 07/02/2022","Record New SBITAs (new SBITAs only)") -> Record New SBITAs (new SBITAs only)
A27: 1 | B27: Record at inception of SBITA in accordance with Fund-Based accounting (Governmental Funds Only).
B28: Dr: Acct 0842 - CAPITAL OUTLAY | J28: 1089435
C29: Cr: Acct 0789 - LEASE AND OTHER FINANCING PROCEEDS | K29: 1089435
C30: =VLOOKUP($F$8,'Drop Down Menus'!$D$2:$G$10,4,FALSE) -> Cr: Acct 0808 - GENERAL GOV. (GAAP ADJ)
J31: =ROUND(SUM(J28:J30),2) -> 1089435 | K31: =ROUND(SUM(K28:K30),2) -> 1089435 | L31: =IF(J31=K31,"<- Debits and Credits equal each other.","<- Debits and Credits do not equal each other.") -> <- Debits and Credits equal each other.
A33: 2 | B33: Reverse the fund-based entry in #1 above, if any, and record an inception of SBITA in accordance with GAAP Govt Wide.
B34: Dr: Acct 0480 - RIGHT-TO-USE SBITA - AMORTIZABLE | J34: 1089435
B35: Dr: Acct 0789 - LEASE AND OTHER FINANCING PROCEEDS | J35: 1089435
C36: Cr: Acct 0842 - CAPITAL OUTLAY | K36: 1089435
C37: Cr: Acct 0674 - RIGHT-TO-USE SBITA LIABILITY | K37: 1089435
C38: =VLOOKUP($F$8,'Drop Down Menus'!$D$2:$G$10,4,FALSE) -> Cr: Acct 0808 - GENERAL GOV. (GAAP ADJ)
J39: =ROUND(SUM(J34:J35),2) -> 2178870 | K39: =ROUND(SUM(K36:K38),2) -> 2178870 | L39: =IF(J39=K39,"<- Debits and Credits equal each other.","<- Debits and Credits do not equal each other.") -> <- Debits and Credits equal each other.
B41: SBITA ASSET (Acct 0480) AMOUNT SHOULD BE INCLUDED AS "ADDITIONS" ON REPORT 18.
A43: Record Annual Activity (all SBITAs)
A44: 3 | B44: Record amortization of the SBITA asset for the year.
B45: Dr: Acct 0875 - DEPRECIATION/AMORTIZATION | J45: 288751
C46: Cr. Acct 0475 - ACCUMULATED AMORTIZATION - RIGHT-TO-USE SBITA | K46: =J45 -> 288751
J47: =ROUND(SUM(J45:J45),2) -> 288751 | K47: =ROUND(SUM(K46),2) -> 288751 | L47: =IF(J47=K47,"<- Debits and Credits equal each other.","<- Debits and Credits do not equal each other.") -> <- Debits and Credits equal each other.
A49: 4 | B49: Reclassify information technology subscription exp. to debt service principal and interest exp.
...

Sheet Fund 0158 Journal Entries
A1: GASB 96 - SBITA Contracts Fund-by-Fund Journal Entries Form (to be submitted to the SCO annually—one form per fund)
A2: Manually complete every yellow field in this worksheet—there are no automatically calculated data-entry cells in this worksheet.
A3: Fiscal year: | F3: 2023–2024
A4: Organization Name: | F4: Department of Justice
A5: Organization Code (Business Unit): | F5: 0820
A6: Fund Number: | F6: 158
A7: Fund Type: | F7: Governmental Fund
A8: Fund Classification: | F8: =IF(OR($F$7='Drop Down Menus'!B2,$F$7='Drop Down Menus'!$B$3),'Drop Down Menus'!$D$9,IFERROR(VLOOKUP($F$5,GAAP02Aindex!$A$2:$D$900,4,FALSE),"Unidentified")) -> GENERAL GOVERNMENT
A12: =IF($F$3="2022–2023","Establish Beginning Balances (SBITAs commenced on or before 07/01/2022)","Establish Beginning Balances (existing SBITAs only)") -> Establish Beginning Balances (existing SBITAs only)
A13: Entry #
A14: 0 | B14: =IF($F$3="2022–2023","To establish the beginning balance of SBITAs as of 07/01/2022.","Roll forward prior year right-to-use SBITAs to record opening balances.") -> Roll forward prior year right-to-use SBITAs to record opening balances. | M14: Department Beginning Balances | P14: From SCO BB List | S14: Difference
B15: Dr: Acct 0480 - RIGHT-TO-USE SBITA - AMORTIZABLE | J15: =ROUND(M15,0) -> 211 | M15: 211 | P15: 211 | S15: =M15-P15 -> 0 | T15: Report any "Differences" on the Report 18 Differential.
B16: Dr: Acct 0950 - BEGINNING FUND BALANCE | J16: =ROUND(P16,0) -> 0 | M16: 1 | P16: =IF(SUM($Q$18:$Q$19)>$P$15,SUM($Q$18:$Q$19)-$P$15,0) -> 0 | S16: =M16-P16 -> 1 | T16: No action required.
B17: Dr: Acct 0952 - BEG FB ADJ/PRIOR PERIOD ADJUSTMENT | J17: =ROUND(IF(SUM($K$18:$K$20)>SUM($J$15:$J$16),SUM($K$18:$K$20)-SUM($J$15:$J$16),0),0) -> 0 | S17: =M17-P17 -> 0 | T17: No action required.
C18: Cr. Acct 0475 - ACCUMULATED AMORTIZATION - RIGHT-TO-USE SBITA | K18: =ROUND(N18,0) -> 119 | N18: 119 | Q18: 119 | S18: =N18-Q18 -> 0 | T18: No action required.
C19: Cr: Acct 0674 - RIGHT-TO-USE SBITA LIABILITY | K19: =ROUND(N19,0) -> 79 | N19: 79 | Q19: 79 | S19: =N19-Q19 -> 0 | T19: No action required.
C20: Cr: Acct 0950 - BEGINNING FUND BALANCE | K20: =ROUND(Q20,0) -> 13 | N20: 14 | Q20: =IF(SUM($Q$18:$Q$19)<$P$15,-SUM($Q$18:$Q$19)+$P$15,0) -> 13 | S20: =N20-Q20 -> 1 | T20: No action required.
C21: Cr: Acct 0952 - BEG FB ADJ/PRIOR PERIOD ADJUSTMENT | K21: =ROUND(IF(SUM($K$18:$K$20)<SUM($J$15:$J$16),-SUM($K$18:$K$20)+SUM($J$15:$J$16),0),0) -> 0 | S21: =N21-Q21 -> 0 | T21: No action required.
J22: =ROUND(SUM(J15:J17),0) -> 211 | K22: =ROUND(SUM(K18:K21),0) -> 211 | L22: =IF(J22=K22,"<- Debits and Credits equal each other.","<- Debits and Credits do not equal each other.") -> <- Debits and Credits equal each other.
B24: SBITA ASSET (Acct 0480) AMOUNT SHOULD BE REPORTED AS BEGINNING BALANCE ON REPORT 18.
A26: =IF($F$3="2022–2023","Record SBITAs Commenced on or after 07/02/2022","Record New SBITAs (new SBITAs only)") -> Record New SBITAs (new SBITAs only)
A27: 1 | B27: Record at inception of SBITA in accordance with Fund-Based accounting (Governmental Funds Only).
B28: Dr: Acct 0842 - CAPITAL OUTLAY | J28: 517
C29: Cr: Acct 0789 - LEASE AND OTHER FINANCING PROCEEDS | K29: 517
C30: =VLOOKUP($F$8,'Drop Down Menus'!$D$2:$G$10,4,FALSE) -> Cr: Acct 0808 - GENERAL GOV. (GAAP ADJ)
J31: =ROUND(SUM(J28:J30),2) -> 517 | K31: =ROUND(SUM(K28:K30),2) -> 517 | L31: =IF(J31=K31,"<- Debits and Credits equal each other.","<- Debits and Credits do not equal each other.") -> <- Debits and Credits equal each other.
A33: 2 | B33: Reverse the fund-based entry in #1 above, if any, and record an inception of SBITA in accordance with GAAP Govt Wide.
B34: Dr: Acct 0480 - RIGHT-TO-USE SBITA - AMORTIZABLE | J34: 517
B35: Dr: Acct 0789 - LEASE AND OTHER FINANCING PROCEEDS | J35: 517
C36: Cr: Acct 0842 - CAPITAL OUTLAY | K36: 517
C37: Cr: Acct 0674 - RIGHT-TO-USE SBITA LIABILITY | K37: 517
C38: =VLOOKUP($F$8,'Drop Down Menus'!$D$2:$G$10,4,FALSE) -> Cr: Acct 0808 - GENERAL GOV. (GAAP ADJ)
J39: =ROUND(SUM(J34:J35),2) -> 1034 | K39: =ROUND(SUM(K36:K38),2) -> 1034 | L39: =IF(J39=K39,"<- Debits and Credits equal each other.","<- Debits and Credits do not equal each other.") -> <- Debits and Credits equal each other.
B41: SBITA ASSET (Acct 0480) AMOUNT SHOULD BE INCLUDED AS "ADDITIONS" ON REPORT 18.
A43: Record Annual Activity (all SBITAs)
A44: 3 | B44: Record amortization of the SBITA asset for the year.
B45: Dr: Acct 0875 - DEPRECIATION/AMORTIZATION | J45: 138
C46: Cr. Acct 0475 - ACCUMULATED AMORTIZATION - RIGHT-TO-USE SBITA | K46: =J45 -> 138
J47: =ROUND(SUM(J45:J45),2) -> 138 | K47: =ROUND(SUM(K46),2) -> 138 | L47: =IF(J47=K47,"<- Debits and Credits equal each other.","<- Debits and Credits do not equal each other.") -> <- Debits and Credits equal each other.
A49: 4 | B49: Reclassify information technology subscription exp. to debt service principal and interest exp.
...

Sheet Fund 0367 Journal Entries
A1: GASB 96 - SBITA Contracts Fund-by-Fund Journal Entries Form (to be submitted to the SCO annually—one form per fund)
A2: Manually complete every yellow field in this worksheet—there are no automatically calculated data-entry cells in this worksheet.
A3: Fiscal year: | F3: 2023–2024
A4: Organization Name: | F4: Department of Justice
A5: Organization Code (Business Unit): | F5: 0820
A6: Fund Number: | F6: 367
A7: Fund Type: | F7: Governmental Fund
A8: Fund Classification: | F8: =IF(OR($F$7='Drop Down Menus'!B2,$F$7='Drop Down Menus'!$B$3),'Drop Down Menus'!$D$9,IFERROR(VLOOKUP($F$5,GAAP02Aindex!$A$2:$D$900,4,FALSE),"Unidentified")) -> GENERAL GOVERNMENT
A12: =IF($F$3="2022–2023","Establish Beginning Balances (SBITAs commenced on or before 07/01/2022)","Establish Beginning Balances (existing SBITAs only)") -> Establish Beginning Balances (existing SBITAs only)
A13: Entry #
A14: 0 | B14: =IF($F$3="2022–2023","To establish the beginning balance of SBITAs as of 07/01/2022.","Roll forward prior year right-to-use SBITAs to record opening balances.") -> Roll forward prior year right-to-use SBITAs to record opening balances. | M14: Department Beginning Balances | P14: From SCO BB List | S14: Difference
B15: Dr: Acct 0480 - RIGHT-TO-USE SBITA - AMORTIZABLE | J15: =ROUND(M15,0) -> 287750 | M15: 287750 | P15: 287750 | S15: =M15-P15 -> 0 | T15: Report any "Differences" on the Report 18 Differential.
B16: Dr: Acct 0950 - BEGINNING FUND BALANCE | J16: =ROUND(P16,0) -> 1500 | M16: 1954 | P16: =IF(SUM($Q$18:$Q$19)>$P$15,SUM($Q$18:$Q$19)-$P$15,0) -> 1500 | S16: =M16-P16 -> 454 | T16: No action required.
B17: Dr: Acct 0952 - BEG FB ADJ/PRIOR PERIOD ADJUSTMENT | J17: =ROUND(IF(SUM($K$18:$K$20)>SUM($J$15:$J$16),SUM($K$18:$K$20)-SUM($J$15:$J$16),0),0) -> 0 | S17: =M17-P17 -> 0 | T17: No action required.
C18: Cr. Acct 0475 - ACCUMULATED AMORTIZATION - RIGHT-TO-USE SBITA | K18: =ROUND(N18,0) -> 99336 | N18: 99336 | Q18: 99336 | S18: =N18-Q18 -> 0 | T18: No action required.
C19: Cr: Acct 0674 - RIGHT-TO-USE SBITA LIABILITY | K19: =ROUND(N19,0) -> 189914 | N19: 189914 | Q19: 189914 | S19: =N19-Q19 -> 0 | T19: No action required.
C20: Cr: Acct 0950 - BEGINNING FUND BALANCE | K20: =ROUND(Q20,0) -> 0 | N20: 454 | Q20: =IF(SUM($Q$18:$Q$19)<$P$15,-SUM($Q$18:$Q$19)+$P$15,0) -> 0 | S20: =N20-Q20 -> 454 | T20: No action required.
C21: Cr: Acct 0952 - BEG FB ADJ/PRIOR PERIOD ADJUSTMENT | K21: =ROUND(IF(SUM($K$18:$K$20)<SUM($J$15:$J$16),-SUM($K$18:$K$20)+SUM($J$15:$J$16),0),0) -> 0 | S21: =N21-Q21 -> 0 | T21: No action required.
J22: =ROUND(SUM(J15:J17),0) -> 289250 | K22: =ROUND(SUM(K18:K21),0) -> 289250 | L22: =IF(J22=K22,"<- Debits and Credits equal each other.","<- Debits and Credits do not equal each other.") -> <- Debits and Credits equal each other.
B24: SBITA ASSET (Acct 0480) AMOUNT SHOULD BE REPORTED AS BEGINNING BALANCE ON REPORT 18.
A26: =IF($F$3="2022–2023","Record SBITAs Commenced on or after 07/02/2022","Record New SBITAs (new SBITAs only)") -> Record New SBITAs (new SBITAs only)
A27: 1 | B27: Record at inception of SBITA in accordance with Fund-Based accounting (Governmental Funds Only).
B28: Dr: Acct 0842 - CAPITAL OUTLAY | J28: 72854
C29: Cr: Acct 0789 - LEASE AND OTHER FINANCING PROCEEDS | K29: 72854
C30: =VLOOKUP($F$8,'Drop Down Menus'!$D$2:$G$10,4,FALSE) -> Cr: Acct 0808 - GENERAL GOV. (GAAP ADJ)
J31: =ROUND(SUM(J28:J30),2) -> 72854 | K31: =ROUND(SUM(K28:K30),2) -> 72854 | L31: =IF(J31=K31,"<- Debits and Credits equal each other.","<- Debits and Credits do not equal each other.") -> <- Debits and Credits equal each other.
A33: 2 | B33: Reverse the fund-based entry in #1 above, if any, and record an inception of SBITA in accordance with GAAP Govt Wide.
B34: Dr: Acct 0480 - RIGHT-TO-USE SBITA - AMORTIZABLE | J34: 72854
B35: Dr: Acct 0789 - LEASE AND OTHER FINANCING PROCEEDS | J35: 72854
C36: Cr: Acct 0842 - CAPITAL OUTLAY | K36: 72854
C37: Cr: Acct 0674 - RIGHT-TO-USE SBITA LIABILITY | K37: 72854
C38: =VLOOKUP($F$8,'Drop Down Menus'!$D$2:$G$10,4,FALSE) -> Cr: Acct 0808 - GENERAL GOV. (GAAP ADJ)
J39: =ROUND(SUM(J34:J35),2) -> 145708 | K39: =ROUND(SUM(K36:K38),2) -> 145708 | L39: =IF(J39=K39,"<- Debits and Credits equal each other.","<- Debits and Credits do not equal each other.") -> <- Debits and Credits equal each other.
B41: SBITA ASSET (Acct 0480) AMOUNT SHOULD BE INCLUDED AS "ADDITIONS" ON REPORT 18.
A43: Record Annual Activity (all SBITAs)
A44: 3 | B44: Record amortization of the SBITA asset for the year.
B45: Dr: Acct 0875 - DEPRECIATION/AMORTIZATION | J45: 21905
C46: Cr. Acct 0475 - ACCUMULATED AMORTIZATION - RIGHT-TO-USE SBITA | K46: =J45 -> 21905
J47: =ROUND(SUM(J45:J45),2) -> 21905 | K47: =ROUND(SUM(K46),2) -> 21905 | L47: =IF(J47=K47,"<- Debits and Credits equal each other.","<- Debits and Credits do not equal each other.") -> <- Debits and Credits equal each other.
A49: 4 | B49: Reclassify information technology subscription exp. to debt service principal and interest exp.
...

Sheet Fund 0378 Journal Entries
A1: GASB 96 - SBITA Contracts Fund-by-Fund Journal Entries Form (to be submitted to the SCO annually—one form per fund)
A2: Manually complete every yellow field in this worksheet—there are no automatically calculated data-entry cells in this worksheet.
A3: Fiscal year: | F3: 2023–2024
A4: Organization Name: | F4: Department of Justice
A5: Organization Code (Business Unit): | F5: 0820
A6: Fund Number: | F6: 378
A7: Fund Type: | F7: Governmental Fund
A8: Fund Classification: | F8: =IF(OR($F$7='Drop Down Menus'!B2,$F$7='Drop Down Menus'!$B$3),'Drop Down Menus'!$D$9,IFERROR(VLOOKUP($F$5,GAAP02Aindex!$A$2:$D$900,4,FALSE),"Unidentified")) -> GENERAL GOVERNMENT
A12: =IF($F$3="2022–2023","Establish Beginning Balances (SBITAs commenced on or before 07/01/2022)","Establish Beginning Balances (existing SBITAs only)") -> Establish Beginning Balances (existing SBITAs only)
A13: Entry #
A14: 0 | B14: =IF($F$3="2022–2023","To establish the beginning balance of SBITAs as of 07/01/2022.","Roll forward prior year right-to-use SBITAs to record opening balances.") -> Roll forward prior year right-to-use SBITAs to record opening balances. | M14: Department Beginning Balances | P14: From SCO BB List | S14: Difference
B15: Dr: Acct 0480 - RIGHT-TO-USE SBITA - AMORTIZABLE | J15: =ROUND(M15,0) -> 14455 | M15: 14455 | P15: 14455 | S15: =M15-P15 -> 0 | T15: Report any "Differences" on the Report 18 Differential.
B16: Dr: Acct 0950 - BEGINNING FUND BALANCE | J16: =ROUND(P16,0) -> 0 | M16: 88 | P16: =IF(SUM($Q$18:$Q$19)>$P$15,SUM($Q$18:$Q$19)-$P$15,0) -> 0 | S16: =M16-P16 -> 88 | T16: No action required.
B17: Dr: Acct 0952 - BEG FB ADJ/PRIOR PERIOD ADJUSTMENT | J17: =ROUND(IF(SUM($K$18:$K$20)>SUM($J$15:$J$16),SUM($K$18:$K$20)-SUM($J$15:$J$16),0),0) -> 0 | S17: =M17-P17 -> 0 | T17: No action required.
C18: Cr. Acct 0475 - ACCUMULATED AMORTIZATION - RIGHT-TO-USE SBITA | K18: =ROUND(N18,0) -> 7866 | N18: 7866 | Q18: 7866 | S18: =N18-Q18 -> 0 | T18: No action required.
C19: Cr: Acct 0674 - RIGHT-TO-USE SBITA LIABILITY | K19: =ROUND(N19,0) -> 5983 | N19: 5983 | Q19: 5983 | S19: =N19-Q19 -> 0 | T19: No action required.
C20: Cr: Acct 0950 - BEGINNING FUND BALANCE | K20: =ROUND(Q20,0) -> 606 | N20: 694 | Q20: =IF(SUM($Q$18:$Q$19)<$P$15,-SUM($Q$18:$Q$19)+$P$15,0) -> 606 | S20: =N20-Q20 -> 88 | T20: No action required.
C21: Cr: Acct 0952 - BEG FB ADJ/PRIOR PERIOD ADJUSTMENT | K21: =ROUND(IF(SUM($K$18:$K$20)<SUM($J$15:$J$16),-SUM($K$18:$K$20)+SUM($J$15:$J$16),0),0) -> 0 | S21: =N21-Q21 -> 0 | T21: No action required.
J22: =ROUND(SUM(J15:J17),0) -> 14455 | K22: =ROUND(SUM(K18:K21),0) -> 14455 | L22: =IF(J22=K22,"<- Debits and Credits equal each other.","<- Debits and Credits do not equal each other.") -> <- Debits and Credits equal each other.
B24: SBITA ASSET (Acct 0480) AMOUNT SHOULD BE REPORTED AS BEGINNING BALANCE ON REPORT 18.
A26: =IF($F$3="2022–2023","Record SBITAs Commenced on or after 07/02/2022","Record New SBITAs (new SBITAs only)") -> Record New SBITAs (new SBITAs only)
A27: 1 | B27: Record at inception of SBITA in accordance with Fund-Based accounting (Governmental Funds Only).
B28: Dr: Acct 0842 - CAPITAL OUTLAY | J28: 26207
C29: Cr: Acct 0789 - LEASE AND OTHER FINANCING PROCEEDS | K29: 26207
C30: =VLOOKUP($F$8,'Drop Down Menus'!$D$2:$G$10,4,FALSE) -> Cr: Acct 0808 - GENERAL GOV. (GAAP ADJ)
J31: =ROUND(SUM(J28:J30),2) -> 26207 | K31: =ROUND(SUM(K28:K30),2) -> 26207 | L31: =IF(J31=K31,"<- Debits and Credits equal each other.","<- Debits and Credits do not equal each other.") -> <- Debits and Credits equal each other.
A33: 2 | B33: Reverse the fund-based entry in #1 above, if any, and record an inception of SBITA in accordance with GAAP Govt Wide.
B34: Dr: Acct 0480 - RIGHT-TO-USE SBITA - AMORTIZABLE | J34: 26207
B35: Dr: Acct 0789 - LEASE AND OTHER FINANCING PROCEEDS | J35: 26207
C36: Cr: Acct 0842 - CAPITAL OUTLAY | K36: 26207
C37: Cr: Acct 0674 - RIGHT-TO-USE SBITA LIABILITY | K37: 26207
C38: =VLOOKUP($F$8,'Drop Down Menus'!$D$2:$G$10,4,FALSE) -> Cr: Acct 0808 - GENERAL GOV. (GAAP ADJ)
J39: =ROUND(SUM(J34:J35),2) -> 52414 | K39: =ROUND(SUM(K36:K38),2) -> 52414 | L39: =IF(J39=K39,"<- Debits and Credits equal each other.","<- Debits and Credits do not equal each other.") -> <- Debits and Credits equal each other.
B41: SBITA ASSET (Acct 0480) AMOUNT SHOULD BE INCLUDED AS "ADDITIONS" ON REPORT 18.
A43: Record Annual Activity (all SBITAs)
A44: 3 | B44: Record amortization of the SBITA asset for the year.
B45: Dr: Acct 0875 - DEPRECIATION/AMORTIZATION | J45: 8959
C46: Cr. Acct 0475 - ACCUMULATED AMORTIZATION - RIGHT-TO-USE SBITA | K46: =J45 -> 8959
J47: =ROUND(SUM(J45:J45),2) -> 8959 | K47: =ROUND(SUM(K46),2) -> 8959 | L47: =IF(J47=K47,"<- Debits and Credits equal each other.","<- Debits and Credits do not equal each other.") -> <- Debits and Credits equal each other.
A49: 4 | B49: Reclassify information technology subscription exp. to debt service principal and interest exp.
...

Sheet Fund 0460 Journal Entries
A1: GASB 96 - SBITA Contracts Fund-by-Fund Journal Entries Form (to be submitted to the SCO annually—one form per fund)
A2: Manually complete every yellow field in this worksheet—there are no automatically calculated data-entry cells in this worksheet.
A3: Fiscal year: | F3: 2023–2024
A4: Organization Name: | F4: Department of Justice
A5: Organization Code (Business Unit): | F5: 0820
A6: Fund Number: | F6: 460
A7: Fund Type: | F7: Governmental Fund
A8: Fund Classification: | F8: =IF(OR($F$7='Drop Down Menus'!B2,$F$7='Drop Down Menus'!$B$3),'Drop Down Menus'!$D$9,IFERROR(VLOOKUP($F$5,GAAP02Aindex!$A$2:$D$900,4,FALSE),"Unidentified")) -> GENERAL GOVERNMENT
A12: =IF($F$3="2022–2023","Establish Beginning Balances (SBITAs commenced on or before 07/01/2022)","Establish Beginning Balances (existing SBITAs only)") -> Establish Beginning Balances (existing SBITAs only)
A13: Entry #
A14: 0 | B14: =IF($F$3="2022–2023","To establish the beginning balance of SBITAs as of 07/01/2022.","Roll forward prior year right-to-use SBITAs to record opening balances.") -> Roll forward prior year right-to-use SBITAs to record opening balances. | M14: Department Beginning Balances | P14: From SCO BB List | S14: Difference
B15: Dr: Acct 0480 - RIGHT-TO-USE SBITA - AMORTIZABLE | J15: =ROUND(M15,0) -> 184476 | M15: 184476 | P15: 184476 | S15: =M15-P15 -> 0 | T15: Report any "Differences" on the Report 18 Differential.
B16: Dr: Acct 0950 - BEGINNING FUND BALANCE | J16: =ROUND(P16,0) -> 0 | M16: 627 | P16: =IF(SUM($Q$18:$Q$19)>$P$15,SUM($Q$18:$Q$19)-$P$15,0) -> 0 | S16: =M16-P16 -> 627 | T16: No action required.
B17: Dr: Acct 0952 - BEG FB ADJ/PRIOR PERIOD ADJUSTMENT | J17: =ROUND(IF(SUM($K$18:$K$20)>SUM($J$15:$J$16),SUM($K$18:$K$20)-SUM($J$15:$J$16),0),0) -> 0 | S17: =M17-P17 -> 0 | T17: No action required.
C18: Cr. Acct 0475 - ACCUMULATED AMORTIZATION - RIGHT-TO-USE SBITA | K18: =ROUND(N18,0) -> 103526 | N18: 103526 | Q18: 103526 | S18: =N18-Q18 -> 0 | T18: No action required.
C19: Cr: Acct 0674 - RIGHT-TO-USE SBITA LIABILITY | K19: =ROUND(N19,0) -> 69297 | N19: 69297 | Q19: 69297 | S19: =N19-Q19 -> 0 | T19: No action required.
C20: Cr: Acct 0950 - BEGINNING FUND BALANCE | K20: =ROUND(Q20,0) -> 11653 | N20: 12280 | Q20: =IF(SUM($Q$18:$Q$19)<$P$15,-SUM($Q$18:$Q$19)+$P$15,0) -> 11653 | S20: =N20-Q20 -> 627 | T20: No action required.
C21: Cr: Acct 0952 - BEG FB ADJ/PRIOR PERIOD ADJUSTMENT | K21: =ROUND(IF(SUM($K$18:$K$20)<SUM($J$15:$J$16),-SUM($K$18:$K$20)+SUM($J$15:$J$16),0),0) -> 0 | S21: =N21-Q21 -> 0 | T21: No action required.
J22: =ROUND(SUM(J15:J17),0) -> 184476 | K22: =ROUND(SUM(K18:K21),0) -> 184476 | L22: =IF(J22=K22,"<- Debits and Credits equal each other.","<- Debits and Credits do not equal each other.") -> <- Debits and Credits equal each other.
B24: SBITA ASSET (Acct 0480) AMOUNT SHOULD BE REPORTED AS BEGINNING BALANCE ON REPORT 18.
A26: =IF($F$3="2022–2023","Record SBITAs Commenced on or after 07/02/2022","Record New SBITAs (new SBITAs only)") -> Record New SBITAs (new SBITAs only)
A27: 1 | B27: Record at inception of SBITA in accordance with Fund-Based accounting (Governmental Funds Only).
B28: Dr: Acct 0842 - CAPITAL OUTLAY | J28: 385309
C29: Cr: Acct 0789 - LEASE AND OTHER FINANCING PROCEEDS | K29: 385309
C30: =VLOOKUP($F$8,'Drop Down Menus'!$D$2:$G$10,4,FALSE) -> Cr: Acct 0808 - GENERAL GOV. (GAAP ADJ)
J31: =ROUND(SUM(J28:J30),2) -> 385309 | K31: =ROUND(SUM(K28:K30),2) -> 385309 | L31: =IF(J31=K31,"<- Debits and Credits equal each other.","<- Debits and Credits do not equal each other.") -> <- Debits and Credits equal each other.
A33: 2 | B33: Reverse the fund-based entry in #1 above, if any, and record an inception of SBITA in accordance with GAAP Govt Wide.
B34: Dr: Acct 0480 - RIGHT-TO-USE SBITA - AMORTIZABLE | J34: 385309
B35: Dr: Acct 0789 - LEASE AND OTHER FINANCING PROCEEDS | J35: 385309
C36: Cr: Acct 0842 - CAPITAL OUTLAY | K36: 385309
C37: Cr: Acct 0674 - RIGHT-TO-USE SBITA LIABILITY | K37: 385309
C38: =VLOOKUP($F$8,'Drop Down Menus'!$D$2:$G$10,4,FALSE) -> Cr: Acct 0808 - GENERAL GOV. (GAAP ADJ)
J39: =ROUND(SUM(J34:J35),2) -> 770618 | K39: =ROUND(SUM(K36:K38),2) -> 770618 | L39: =IF(J39=K39,"<- Debits and Credits equal each other.","<- Debits and Credits do not equal each other.") -> <- Debits and Credits equal each other.
B41: SBITA ASSET (Acct 0480) AMOUNT SHOULD BE INCLUDED AS "ADDITIONS" ON REPORT 18.
A43: Record Annual Activity (all SBITAs)
A44: 3 | B44: Record amortization of the SBITA asset for the year.
B45: Dr: Acct 0875 - DEPRECIATION/AMORTIZATION | J45: 106395
C46: Cr. Acct 0475 - ACCUMULATED AMORTIZATION - RIGHT-TO-USE SBITA | K46: =J45 -> 106395
J47: =ROUND(SUM(J45:J45),2) -> 106395 | K47: =ROUND(SUM(K46),2) -> 106395 | L47: =IF(J47=K47,"<- Debits and Credits equal each other.","<- Debits and Credits do not equal each other.") -> <- Debits and Credits equal each other.
A49: 4 | B49: Reclassify information technology subscription exp. to debt service principal and interest exp.
...

Sheet Fund 0567 Journal Entries
A1: GASB 96 - SBITA Contracts Fund-by-Fund Journal Entries Form (to be submitted to the SCO annually—one form per fund)
A2: Manually complete every yellow field in this worksheet—there are no automatically calculated data-entry cells in this worksheet.
A3: Fiscal year: | F3: 2023–2024
A4: Organization Name: | F4: Department of Justice
A5: Organization Code (Business Unit): | F5: 0820
A6: Fund Number: | F6: 567
A7: Fund Type: | F7: Governmental Fund
A8: Fund Classification: | F8: =IF(OR($F$7='Drop Down Menus'!B2,$F$7='Drop Down Menus'!$B$3),'Drop Down Menus'!$D$9,IFERROR(VLOOKUP($F$5,GAAP02Aindex!$A$2:$D$900,4,FALSE),"Unidentified")) -> GENERAL GOVERNMENT
A12: =IF($F$3="2022–2023","Establish Beginning Balances (SBITAs commenced on or before 07/01/2022)","Establish Beginning Balances (existing SBITAs only)") -> Establish Beginning Balances (existing SBITAs only)
A13: Entry #
A14: 0 | B14: =IF($F$3="2022–2023","To establish the beginning balance of SBITAs as of 07/01/2022.","Roll forward prior year right-to-use SBITAs to record opening balances.") -> Roll forward prior year right-to-use SBITAs to record opening balances. | M14: Department Beginning Balances | P14: From SCO BB List | S14: Difference
B15: Dr: Acct 0480 - RIGHT-TO-USE SBITA - AMORTIZABLE | J15: =ROUND(M15,0) -> 145210 | M15: 145210 | P15: 145210 | S15: =M15-P15 -> 0 | T15: Report any "Differences" on the Report 18 Differential.
B16: Dr: Acct 0950 - BEGINNING FUND BALANCE | J16: =ROUND(P16,0) -> 1038 | M16: 1038 | P16: =IF(SUM($Q$18:$Q$19)>$P$15,SUM($Q$18:$Q$19)-$P$15,0) -> 1038 | S16: =M16-P16 -> 0 | T16: No action required.
B17: Dr: Acct 0952 - BEG FB ADJ/PRIOR PERIOD ADJUSTMENT | J17: =ROUND(IF(SUM($K$18:$K$20)>SUM($J$15:$J$16),SUM($K$18:$K$20)-SUM($J$15:$J$16),0),0) -> 0 | S17: =M17-P17 -> 0 | T17: No action required.
C18: Cr. Acct 0475 - ACCUMULATED AMORTIZATION - RIGHT-TO-USE SBITA | K18: =ROUND(N18,0) -> 50401 | N18: 50401 | Q18: 50401 | S18: =N18-Q18 -> 0 | T18: No action required.
C19: Cr: Acct 0674 - RIGHT-TO-USE SBITA LIABILITY | K19: =ROUND(N19,0) -> 95847 | N19: 95847 | Q19: 95847 | S19: =N19-Q19 -> 0 | T19: No action required.
C20: Cr: Acct 0950 - BEGINNING FUND BALANCE | K20: =ROUND(Q20,0) -> 0 | Q20: =IF(SUM($Q$18:$Q$19)<$P$15,-SUM($Q$18:$Q$19)+$P$15,0) -> 0 | S20: =N20-Q20 -> 0 | T20: No action required.
C21: Cr: Acct 0952 - BEG FB ADJ/PRIOR PERIOD ADJUSTMENT | K21: =ROUND(IF(SUM($K$18:$K$20)<SUM($J$15:$J$16),-SUM($K$18:$K$20)+SUM($J$15:$J$16),0),0) -> 0 | S21: =N21-Q21 -> 0 | T21: No action required.
J22: =ROUND(SUM(J15:J17),0) -> 146248 | K22: =ROUND(SUM(K18:K21),0) -> 146248 | L22: =IF(J22=K22,"<- Debits and Credits equal each other.","<- Debits and Credits do not equal each other.") -> <- Debits and Credits equal each other.
B24: SBITA ASSET (Acct 0480) AMOUNT SHOULD BE REPORTED AS BEGINNING BALANCE ON REPORT 18.
A26: =IF($F$3="2022–2023","Record SBITAs Commenced on or after 07/02/2022","Record New SBITAs (new SBITAs only)") -> Record New SBITAs (new SBITAs only)
A27: 1 | B27: Record at inception of SBITA in accordance with Fund-Based accounting (Governmental Funds Only).
B28: Dr: Acct 0842 - CAPITAL OUTLAY
C29: Cr: Acct 0789 - LEASE AND OTHER FINANCING PROCEEDS
C30: =VLOOKUP($F$8,'Drop Down Menus'!$D$2:$G$10,4,FALSE) -> Cr: Acct 0808 - GENERAL GOV. (GAAP ADJ)
J31: =ROUND(SUM(J28:J30),2) -> 0 | K31: =ROUND(SUM(K28:K30),2) -> 0 | L31: =IF(J31=K31,"<- Debits and Credits equal each other.","<- Debits and Credits do not equal each other.") -> <- Debits and Credits equal each other.
A33: 2 | B33: Reverse the fund-based entry in #1 above, if any, and record an inception of SBITA in accordance with GAAP Govt Wide.
B34: Dr: Acct 0480 - RIGHT-TO-USE SBITA - AMORTIZABLE
B35: Dr: Acct 0789 - LEASE AND OTHER FINANCING PROCEEDS
C36: Cr: Acct 0842 - CAPITAL OUTLAY
C37: Cr: Acct 0674 - RIGHT-TO-USE SBITA LIABILITY
C38: =VLOOKUP($F$8,'Drop Down Menus'!$D$2:$G$10,4,FALSE) -> Cr: Acct 0808 - GENERAL GOV. (GAAP ADJ)
J39: =ROUND(SUM(J34:J35),2) -> 0 | K39: =ROUND(SUM(K36:K38),2) -> 0 | L39: =IF(J39=K39,"<- Debits and Credits equal each other.","<- Debits and Credits do not equal each other.") -> <- Debits and Credits equal each other.
B41: SBITA ASSET (Acct 0480) AMOUNT SHOULD BE INCLUDED AS "ADDITIONS" ON REPORT 18.
A43: Record Annual Activity (all SBITAs)
A44: 3 | B44: Record amortization of the SBITA asset for the year.
B45: Dr: Acct 0875 - DEPRECIATION/AMORTIZATION | J45: 5993
C46: Cr. Acct 0475 - ACCUMULATED AMORTIZATION - RIGHT-TO-USE SBITA | K46: =J45 -> 5993
J47: =ROUND(SUM(J45:J45),2) -> 5993 | K47: =ROUND(SUM(K46),2) -> 5993 | L47: =IF(J47=K47,"<- Debits and Credits equal each other.","<- Debits and Credits do not equal each other.") -> <- Debits and Credits equal each other.
A49: 4 | B49: Reclassify information technology subscription exp. to debt service principal and interest exp.
...

Sheet Fund 0569 Journal Entries
A1: GASB 96 - SBITA Contracts Fund-by-Fund Journal Entries Form (to be submitted to the SCO annually—one form per fund)
A2: Manually complete every yellow field in this worksheet—there are no automatically calculated data-entry cells in this worksheet.
A3: Fiscal year: | F3: 2023–2024
A4: Organization Name: | F4: Department of Justice
A5: Organization Code (Business Unit): | F5: 0820
A6: Fund Number: | F6: 569
A7: Fund Type: | F7: Governmental Fund
A8: Fund Classification: | F8: =IF(OR($F$7='Drop Down Menus'!B2,$F$7='Drop Down Menus'!$B$3),'Drop Down Menus'!$D$9,IFERROR(VLOOKUP($F$5,GAAP02Aindex!$A$2:$D$900,4,FALSE),"Unidentified")) -> GENERAL GOVERNMENT
A12: =IF($F$3="2022–2023","Establish Beginning Balances (SBITAs commenced on or before 07/01/2022)","Establish Beginning Balances (existing SBITAs only)") -> Establish Beginning Balances (existing SBITAs only)
A13: Entry #
A14: 0 | B14: =IF($F$3="2022–2023","To establish the beginning balance of SBITAs as of 07/01/2022.","Roll forward prior year right-to-use SBITAs to record opening balances.") -> Roll forward prior year right-to-use SBITAs to record opening balances. | M14: Department Beginning Balances | P14: From SCO BB List | S14: Difference
B15: Dr: Acct 0480 - RIGHT-TO-USE SBITA - AMORTIZABLE | J15: =ROUND(M15,0) -> 18449 | M15: 18449 | P15: 18449 | S15: =M15-P15 -> 0 | T15: Report any "Differences" on the Report 18 Differential.
B16: Dr: Acct 0950 - BEGINNING FUND BALANCE | J16: =ROUND(P16,0) -> 0 | M16: 71 | P16: =IF(SUM($Q$18:$Q$19)>$P$15,SUM($Q$18:$Q$19)-$P$15,0) -> 0 | S16: =M16-P16 -> 71 | T16: No action required.
B17: Dr: Acct 0952 - BEG FB ADJ/PRIOR PERIOD ADJUSTMENT | J17: =ROUND(IF(SUM($K$18:$K$20)>SUM($J$15:$J$16),SUM($K$18:$K$20)-SUM($J$15:$J$16),0),0) -> 0 | S17: =M17-P17 -> 0 | T17: No action required.
C18: Cr. Acct 0475 - ACCUMULATED AMORTIZATION - RIGHT-TO-USE SBITA | K18: =ROUND(N18,0) -> 9871 | N18: 9871 | Q18: 9871 | S18: =N18-Q18 -> 0 | T18: No action required.
C19: Cr: Acct 0674 - RIGHT-TO-USE SBITA LIABILITY | K19: =ROUND(N19,0) -> 7568 | N19: 7568 | Q19: 7568 | S19: =N19-Q19 -> 0 | T19: No action required.
C20: Cr: Acct 0950 - BEGINNING FUND BALANCE | K20: =ROUND(Q20,0) -> 1010 | N20: 1081 | Q20: =IF(SUM($Q$18:$Q$19)<$P$15,-SUM($Q$18:$Q$19)+$P$15,0) -> 1010 | S20: =N20-Q20 -> 71 | T20: No action required.
C21: Cr: Acct 0952 - BEG FB ADJ/PRIOR PERIOD ADJUSTMENT | K21: =ROUND(IF(SUM($K$18:$K$20)<SUM($J$15:$J$16),-SUM($K$18:$K$20)+SUM($J$15:$J$16),0),0) -> 0 | S21: =N21-Q21 -> 0 | T21: No action required.
J22: =ROUND(SUM(J15:J17),0) -> 18449 | K22: =ROUND(SUM(K18:K21),0) -> 18449 | L22: =IF(J22=K22,"<- Debits and Credits equal each other.","<- Debits and Credits do not equal each other.") -> <- Debits and Credits equal each other.
B24: SBITA ASSET (Acct 0480) AMOUNT SHOULD BE REPORTED AS BEGINNING BALANCE ON REPORT 18.
A26: =IF($F$3="2022–2023","Record SBITAs Commenced on or after 07/02/2022","Record New SBITAs (new SBITAs only)") -> Record New SBITAs (new SBITAs only)
A27: 1 | B27: Record at inception of SBITA in accordance with Fund-Based accounting (Governmental Funds Only).
B28: Dr: Acct 0842 - CAPITAL OUTLAY | J28: 64264
C29: Cr: Acct 0789 - LEASE AND OTHER FINANCING PROCEEDS | K29: 64264
C30: =VLOOKUP($F$8,'Drop Down Menus'!$D$2:$G$10,4,FALSE) -> Cr: Acct 0808 - GENERAL GOV. (GAAP ADJ)
J31: =ROUND(SUM(J28:J30),2) -> 64264 | K31: =ROUND(SUM(K28:K30),2) -> 64264 | L31: =IF(J31=K31,"<- Debits and Credits equal each other.","<- Debits and Credits do not equal each other.") -> <- Debits and Credits equal each other.
A33: 2 | B33: Reverse the fund-based entry in #1 above, if any, and record an inception of SBITA in accordance with GAAP Govt Wide.
B34: Dr: Acct 0480 - RIGHT-TO-USE SBITA - AMORTIZABLE | J34: 64264
B35: Dr: Acct 0789 - LEASE AND OTHER FINANCING PROCEEDS | J35: 64264
C36: Cr: Acct 0842 - CAPITAL OUTLAY | K36: 64264
C37: Cr: Acct 0674 - RIGHT-TO-USE SBITA LIABILITY | K37: 64264
C38: =VLOOKUP($F$8,'Drop Down Menus'!$D$2:$G$10,4,FALSE) -> Cr: Acct 0808 - GENERAL GOV. (GAAP ADJ)
J39: =ROUND(SUM(J34:J35),2) -> 128528 | K39: =ROUND(SUM(K36:K38),2) -> 128528 | L39: =IF(J39=K39,"<- Debits and Credits equal each other.","<- Debits and Credits do not equal each other.") -> <- Debits and Credits equal each other.
B41: SBITA ASSET (Acct 0480) AMOUNT SHOULD BE INCLUDED AS "ADDITIONS" ON REPORT 18.
A43: Record Annual Activity (all SBITAs)
A44: 3 | B44: Record amortization of the SBITA asset for the year.
B45: Dr: Acct 0875 - DEPRECIATION/AMORTIZATION | J45: 15837
C46: Cr. Acct 0475 - ACCUMULATED AMORTIZATION - RIGHT-TO-USE SBITA | K46: =J45 -> 15837
J47: =ROUND(SUM(J45:J45),2) -> 15837 | K47: =ROUND(SUM(K46),2) -> 15837 | L47: =IF(J47=K47,"<- Debits and Credits equal each other.","<- Debits and Credits do not equal each other.") -> <- Debits and Credits equal each other.
A49: 4 | B49: Reclassify information technology subscription exp. to debt service principal and interest exp.
...

Sheet Fund 0890 Journal Entries
A1: GASB 96 - SBITA Contracts Fund-by-Fund Journal Entries Form (to be submitted to the SCO annually—one form per fund)
A2: Manually complete every yellow field in this worksheet—there are no automatically calculated data-entry cells in this worksheet.
A3: Fiscal year: | F3: 2023–2024
A4: Organization Name: | F4: Department of Justice
A5: Organization Code (Business Unit): | F5: 0820
A6: Fund Number: | F6: 890
A7: Fund Type: | F7: Governmental Fund
A8: Fund Classification: | F8: =IF(OR($F$7='Drop Down Menus'!B2,$F$7='Drop Down Menus'!$B$3),'Drop Down Menus'!$D$9,IFERROR(VLOOKUP($F$5,GAAP02Aindex!$A$2:$D$900,4,FALSE),"Unidentified")) -> GENERAL GOVERNMENT
A12: =IF($F$3="2022–2023","Establish Beginning Balances (SBITAs commenced on or before 07/01/2022)","Establish Beginning Balances (existing SBITAs only)") -> Establish Beginning Balances (existing SBITAs only)
A13: Entry #
A14: 0 | B14: =IF($F$3="2022–2023","To establish the beginning balance of SBITAs as of 07/01/2022.","Roll forward prior year right-to-use SBITAs to record opening balances.") -> Roll forward prior year right-to-use SBITAs to record opening balances. | M14: Department Beginning Balances | P14: From SCO BB List | S14: Difference
B15: Dr: Acct 0480 - RIGHT-TO-USE SBITA - AMORTIZABLE | J15: =ROUND(M15,0) -> 17865 | M15: 17865 | P15: 17865 | S15: =M15-P15 -> 0 | T15: Report any "Differences" on the Report 18 Differential.
B16: Dr: Acct 0950 - BEGINNING FUND BALANCE | J16: =ROUND(P16,0) -> 234 | M16: 234 | P16: =IF(SUM($Q$18:$Q$19)>$P$15,SUM($Q$18:$Q$19)-$P$15,0) -> 234 | S16: =M16-P16 -> 0 | T16: No action required.
B17: Dr: Acct 0952 - BEG FB ADJ/PRIOR PERIOD ADJUSTMENT | J17: =ROUND(IF(SUM($K$18:$K$20)>SUM($J$15:$J$16),SUM($K$18:$K$20)-SUM($J$15:$J$16),0),0) -> 0 | S17: =M17-P17 -> 0 | T17: No action required.
C18: Cr. Acct 0475 - ACCUMULATED AMORTIZATION - RIGHT-TO-USE SBITA | K18: =ROUND(N18,0) -> 8932 | N18: 8932 | Q18: 8932 | S18: =N18-Q18 -> 0 | T18: No action required.
C19: Cr: Acct 0674 - RIGHT-TO-USE SBITA LIABILITY | K19: =ROUND(N19,0) -> 9167 | N19: 9167 | Q19: 9167 | S19: =N19-Q19 -> 0 | T19: No action required.
C20: Cr: Acct 0950 - BEGINNING FUND BALANCE | K20: =ROUND(Q20,0) -> 0 | Q20: =IF(SUM($Q$18:$Q$19)<$P$15,-SUM($Q$18:$Q$19)+$P$15,0) -> 0 | S20: =N20-Q20 -> 0 | T20: No action required.
C21: Cr: Acct 0952 - BEG FB ADJ/PRIOR PERIOD ADJUSTMENT | K21: =ROUND(IF(SUM($K$18:$K$20)<SUM($J$15:$J$16),-SUM($K$18:$K$20)+SUM($J$15:$J$16),0),0) -> 0 | S21: =N21-Q21 -> 0 | T21: No action required.
J22: =ROUND(SUM(J15:J17),0) -> 18099 | K22: =ROUND(SUM(K18:K21),0) -> 18099 | L22: =IF(J22=K22,"<- Debits and Credits equal each other.","<- Debits and Credits do not equal each other.") -> <- Debits and Credits equal each other.
B24: SBITA ASSET (Acct 0480) AMOUNT SHOULD BE REPORTED AS BEGINNING BALANCE ON REPORT 18.
A26: =IF($F$3="2022–2023","Record SBITAs Commenced on or after 07/02/2022","Record New SBITAs (new SBITAs only)") -> Record New SBITAs (new SBITAs only)
A27: 1 | B27: Record at inception of SBITA in accordance with Fund-Based accounting (Governmental Funds Only).
B28: Dr: Acct 0842 - CAPITAL OUTLAY
C29: Cr: Acct 0789 - LEASE AND OTHER FINANCING PROCEEDS
C30: =VLOOKUP($F$8,'Drop Down Menus'!$D$2:$G$10,4,FALSE) -> Cr: Acct 0808 - GENERAL GOV. (GAAP ADJ)
J31: =ROUND(SUM(J28:J30),2) -> 0 | K31: =ROUND(SUM(K28:K30),2) -> 0 | L31: =IF(J31=K31,"<- Debits and Credits equal each other.","<- Debits and Credits do not equal each other.") -> <- Debits and Credits equal each other.
A33: 2 | B33: Reverse the fund-based entry in #1 above, if any, and record an inception of SBITA in accordance with GAAP Govt Wide.
B34: Dr: Acct 0480 - RIGHT-TO-USE SBITA - AMORTIZABLE
B35: Dr: Acct 0789 - LEASE AND OTHER FINANCING PROCEEDS
C36: Cr: Acct 0842 - CAPITAL OUTLAY
C37: Cr: Acct 0674 - RIGHT-TO-USE SBITA LIABILITY
C38: =VLOOKUP($F$8,'Drop Down Menus'!$D$2:$G$10,4,FALSE) -> Cr: Acct 0808 - GENERAL GOV. (GAAP ADJ)
J39: =ROUND(SUM(J34:J35),2) -> 0 | K39: =ROUND(SUM(K36:K38),2) -> 0 | L39: =IF(J39=K39,"<- Debits and Credits equal each other.","<- Debits and Credits do not equal each other.") -> <- Debits and Credits equal each other.
B41: SBITA ASSET (Acct 0480) AMOUNT SHOULD BE INCLUDED AS "ADDITIONS" ON REPORT 18.
A43: Record Annual Activity (all SBITAs)
A44: 3 | B44: Record amortization of the SBITA asset for the year.
B45: Dr: Acct 0875 - DEPRECIATION/AMORTIZATION | J45: 8933
C46: Cr. Acct 0475 - ACCUMULATED AMORTIZATION - RIGHT-TO-USE SBITA | K46: =J45 -> 8933
J47: =ROUND(SUM(J45:J45),2) -> 8933 | K47: =ROUND(SUM(K46),2) -> 8933 | L47: =IF(J47=K47,"<- Debits and Credits equal each other.","<- Debits and Credits do not equal each other.") -> <- Debits and Credits equal each other.
A49: 4 | B49: Reclassify information technology subscription exp. to debt service principal and interest exp.
...

Sheet Fund 1008 Journal Entries
A1: GASB 96 - SBITA Contracts Fund-by-Fund Journal Entries Form (to be submitted to the SCO annually—one form per fund)
A2: Manually complete every yellow field in this worksheet—there are no automatically calculated data-entry cells in this worksheet.
A3: Fiscal year: | F3: 2023–2024
A4: Organization Name: | F4: Department of Justice
A5: Organization Code (Business Unit): | F5: 0820
A6: Fund Number: | F6: 1008
A7: Fund Type: | F7: Governmental Fund
A8: Fund Classification: | F8: =IF(OR($F$7='Drop Down Menus'!B2,$F$7='Drop Down Menus'!$B$3),'Drop Down Menus'!$D$9,IFERROR(VLOOKUP($F$5,GAAP02Aindex!$A$2:$D$900,4,FALSE),"Unidentified")) -> GENERAL GOVERNMENT
A12: =IF($F$3="2022–2023","Establish Beginning Balances (SBITAs commenced on or before 07/01/2022)","Establish Beginning Balances (existing SBITAs only)") -> Establish Beginning Balances (existing SBITAs only)
A13: Entry #
A14: 0 | B14: =IF($F$3="2022–2023","To establish the beginning balance of SBITAs as of 07/01/2022.","Roll forward prior year right-to-use SBITAs to record opening balances.") -> Roll forward prior year right-to-use SBITAs to record opening balances. | M14: Department Beginning Balances | P14: From SCO BB List | S14: Difference
B15: Dr: Acct 0480 - RIGHT-TO-USE SBITA - AMORTIZABLE | J15: =ROUND(M15,0) -> 30776 | M15: 30776 | P15: 30776 | S15: =M15-P15 -> 0 | T15: Report any "Differences" on the Report 18 Differential.
B16: Dr: Acct 0950 - BEGINNING FUND BALANCE | J16: =ROUND(P16,0) -> 403 | M16: 403 | P16: =IF(SUM($Q$18:$Q$19)>$P$15,SUM($Q$18:$Q$19)-$P$15,0) -> 403 | S16: =M16-P16 -> 0 | T16: No action required.
B17: Dr: Acct 0952 - BEG FB ADJ/PRIOR PERIOD ADJUSTMENT | J17: =ROUND(IF(SUM($K$18:$K$20)>SUM($J$15:$J$16),SUM($K$18:$K$20)-SUM($J$15:$J$16),0),0) -> 0 | S17: =M17-P17 -> 0 | T17: No action required.
C18: Cr. Acct 0475 - ACCUMULATED AMORTIZATION - RIGHT-TO-USE SBITA | K18: =ROUND(N18,0) -> 15388 | N18: 15388 | Q18: 15388 | S18: =N18-Q18 -> 0 | T18: No action required.
C19: Cr: Acct 0674 - RIGHT-TO-USE SBITA LIABILITY | K19: =ROUND(N19,0) -> 15791 | N19: 15791 | Q19: 15791 | S19: =N19-Q19 -> 0 | T19: No action required.
C20: Cr: Acct 0950 - BEGINNING FUND BALANCE | K20: =ROUND(Q20,0) -> 0 | Q20: =IF(SUM($Q$18:$Q$19)<$P$15,-SUM($Q$18:$Q$19)+$P$15,0) -> 0 | S20: =N20-Q20 -> 0 | T20: No action required.
C21: Cr: Acct 0952 - BEG FB ADJ/PRIOR PERIOD ADJUSTMENT | K21: =ROUND(IF(SUM($K$18:$K$20)<SUM($J$15:$J$16),-SUM($K$18:$K$20)+SUM($J$15:$J$16),0),0) -> 0 | S21: =N21-Q21 -> 0 | T21: No action required.
J22: =ROUND(SUM(J15:J17),0) -> 31179 | K22: =ROUND(SUM(K18:K21),0) -> 31179 | L22: =IF(J22=K22,"<- Debits and Credits equal each other.","<- Debits and Credits do not equal each other.") -> <- Debits and Credits equal each other.
B24: SBITA ASSET (Acct 0480) AMOUNT SHOULD BE REPORTED AS BEGINNING BALANCE ON REPORT 18.
