Workbook
Name ActuaryCredentialsGASB: [1]DeveloperInfo!$D$19
Name ActuaryNameGASB: [1]DeveloperInfo!$D$17
Name ActuaryTitleGASB: [1]DeveloperInfo!$D$18
Name AdjCNSDate: [1]DeveloperInfo!$D$33
Name AdjCNSDate1: [1]DeveloperInfo!$E$33
Name AdjCNSDateTempEnable: [1]DeveloperInfo!$F$34
Name AgencyCode: #REF!
Name AgencyCode1: #REF!
Name AnalystGASB: [1]DeveloperInfo!$D$20
Name Annuity: #REF!
Name Annuity1: #REF!
Name AnnuityLY: #REF!
Name ASTABPF: [1]DeveloperInfo!$D$36
Name ASTABPF1: [1]DeveloperInfo!$D$37
Name ASTEBPF: [1]DeveloperInfo!$F$37
Name ClientShortGASB: [1]DeveloperInfo!$D$9
Name CLPOWERDisc: [1]Adjust!$H$199
Name CLPOWERDiscMinus1: [1]Adjust!$L$199
Name CLPOWERDiscPlus1: [1]Adjust!$K$199
Name CLPOWERExp: [1]Adjust!$G$199
Name CNSDateDisc: [1]DeveloperInfo!$D$32
Name CNSDateDisc1: [1]DeveloperInfo!$E$32
Name ColaRate: [1]DeveloperInfo!$D$40
Name ConsultantNameGASB: [1]DeveloperInfo!$D$22
Name ConsultantTitleGASB: [1]DeveloperInfo!$D$23
Name Disc1DELTACENSUS: [1]Adjust!$G$102
Name Disc1INTNDIV12: [1]Adjust!$H$195
Name Disc1SINTADJBOM: [1]Adjust!$I$197
Name Disc1SINTNDIV12: [1]Adjust!$I$195
Name DiscDELTACENSUS: [1]Adjust!$H$102
Name DiscINTADJBOM: [1]Adjust!$J$197
Name DiscINTNDIV12: [1]Adjust!$J$195
Name DiscMinusOneINTADJBOM: [1]Adjust!$L$197
Name DiscMinusOneINTNDIV12: [1]Adjust!$L$195
Name DiscPlusOneINTADJBOM: [1]Adjust!$K$197
Name DiscPlusOneINTNDIV12: [1]Adjust!$K$195
Name EmployerRates: #REF!
Name EmployerRates1: #REF!
Name EmployerRatesLEO: #REF!
Name EmployerRatesLEO1: #REF!
Name ERData: [1]ER_DATA!$B$16:$EN$318
Name ERID: [1]ER_NPLExpense!$L$8
Name ERInfo: [1]ER_Input!$B$16:$Y$318
Name Exp1INTADJBOM: [1]Adjust!$G$197
Name Exp1INTNDIV12: [1]Adjust!$G$195
Name FracYearProj: [1]TPL!$C$43
Name FundOfficeContactGASB: [1]DeveloperInfo!$D$10
Name FYrsGASB: [1]DeveloperInfo!$D$54
Name GainLoss: [1]ER_Allocation!$P$12
Name GASBDiscMinusOneINTADJBOM: [1]Adjust!$L$197
Name GASBDiscMinusOneINTNDIV12: [1]Adjust!$L$195
Name InflRate: [1]DeveloperInfo!$D$38
Name InflRate1: [1]DeveloperInfo!$E$38
Name IntDisc: [1]DeveloperInfo!$F$47
Name IntDisc1: [1]DeveloperInfo!$D$47
Name IntDisc1S: [1]DeveloperInfo!$E$47
Name INTDiscMinusOne: [1]DeveloperInfo!$H$47
Name INTDiscPlusOne: [1]DeveloperInfo!$G$47
Name IntExp1: [1]DeveloperInfo!$I$47
Name MeasureDate: [1]DeveloperInfo!$D$31

Sheet Fund 7100 Journal Entries
A1: GASB 96 - SBITA Contracts Fund-by-Fund Journal Entries Form (to be submitted to the SCO annually—one form per fund)
A2: Manually complete every yellow field in this worksheet—there are no automatically calculated data-entry cells in this worksheet.
A3: Fiscal year: | F3: 2023–2024
A4: Organization Name: | F4: Employment Development Department
A5: Organization Code (Business Unit): | F5: 7100
A6: Fund Number: | F6: 870
A7: Fund Type: | F7: Governmental Fund
A8: Fund Classification: | F8: =IF(OR($F$7='Drop Down Menus'!B2,$F$7='Drop Down Menus'!$B$3),'Drop Down Menus'!$D$9,IFERROR(VLOOKUP($F$5,GAAP02Aindex!$A$2:$D$900,4,FALSE),"Unidentified")) -> HEALTH AND HUMAN SERVICES
A12: =IF($F$3="2022–2023","Establish Beginning Balances (SBITAs commenced on or before 07/01/2022)","Establish Beginning Balances (existing SBITAs only)") -> Establish Beginning Balances (existing SBITAs only)
A13: Entry #
A14: 0 | B14: =IF($F$3="2022–2023","To establish the beginning balance of SBITAs as of 07/01/2022.","Roll forward prior year right-to-use SBITAs to record opening balances.") -> Roll forward prior year right-to-use SBITAs to record opening balances. | M14: Department Beginning Balances | P14: From SCO BB List | S14: Difference
B15: Dr: Acct 0480 - RIGHT-TO-USE SBITA - AMORTIZABLE | J15: =ROUND(M15,0) -> 28310925 | M15: 28310925 | P15: 39257440 | S15: =M15-P15 -> -10946515 | T15: Report any "Differences" on the Report 18 Differential.
B16: Dr: Acct 0950 - BEGINNING FUND BALANCE | J16: =ROUND(P16,0) -> 0 | P16: =IF(SUM($Q$18:$Q$19)>$P$15,SUM($Q$18:$Q$19)-$P$15,0) -> 0 | S16: =M16-P16 -> 0 | T16: No action required.
B17: Dr: Acct 0952 - BEG FB ADJ/PRIOR PERIOD ADJUSTMENT | J17: =ROUND(IF(SUM($K$18:$K$20)>SUM($J$15:$J$16),SUM($K$18:$K$20)-SUM($J$15:$J$16),0),0) -> 18506121 | S17: =M17-P17 -> 0 | T17: No action required.
C18: Cr. Acct 0475 - ACCUMULATED AMORTIZATION - RIGHT-TO-USE SBITA | K18: =ROUND(N18,0) -> 10661692 | N18: 10661692 | Q18: 19388711 | S18: =N18-Q18 -> -8727019 | T18: No action required.
C19: Cr: Acct 0674 - RIGHT-TO-USE SBITA LIABILITY | K19: =ROUND(N19,0) -> 20207041 | N19: 20207041 | Q19: 3920416 | S19: =N19-Q19 -> 16286625 | T19: No action required.
C20: Cr: Acct 0950 - BEGINNING FUND BALANCE | K20: =ROUND(Q20,0) -> 15948313 | Q20: =IF(SUM($Q$18:$Q$19)<$P$15,-SUM($Q$18:$Q$19)+$P$15,0) -> 15948313 | S20: =N20-Q20 -> -15948313 | T20: No action required.
C21: Cr: Acct 0952 - BEG FB ADJ/PRIOR PERIOD ADJUSTMENT | K21: =ROUND(IF(SUM($K$18:$K$20)<SUM($J$15:$J$16),-SUM($K$18:$K$20)+SUM($J$15:$J$16),0),0) -> 0 | S21: =N21-Q21 -> 0 | T21: No action required.
J22: =ROUND(SUM(J15:J17),0) -> 46817046 | K22: =ROUND(SUM(K18:K21),0) -> 46817046 | L22: =IF(J22=K22,"<- Debits and Credits equal each other.","<- Debits and Credits do not equal each other.") -> <- Debits and Credits equal each other.
B24: SBITA ASSET (Acct 0480) AMOUNT SHOULD BE REPORTED AS BEGINNING BALANCE ON REPORT 18.
A26: =IF($F$3="2022–2023","Record SBITAs Commenced on or after 07/02/2022","Record New SBITAs (new SBITAs only)") -> Record New SBITAs (new SBITAs only)
A27: 1 | B27: Record at inception of SBITA in accordance with Fund-Based accounting (Governmental Funds Only).
B28: Dr: Acct 0842 - CAPITAL OUTLAY | J28: 1296759
C29: Cr: Acct 0789 - LEASE AND OTHER FINANCING PROCEEDS | K29: 1296759
C30: =VLOOKUP($F$8,'Drop Down Menus'!$D$2:$G$10,4,FALSE) -> Cr: Acct 0815 - HLTH&HUM SV SV.LAB(GAAP ADJ)
J31: =ROUND(SUM(J28:J30),2) -> 1296759 | K31: =ROUND(SUM(K28:K30),2) -> 1296759 | L31: =IF(J31=K31,"<- Debits and Credits equal each other.","<- Debits and Credits do not equal each other.") -> <- Debits and Credits equal each other.
A33: 2 | B33: Reverse the fund-based entry in #1 above, if any, and record an inception of SBITA in accordance with GAAP Govt Wide.
B34: Dr: Acct 0480 - RIGHT-TO-USE SBITA - AMORTIZABLE | J34: 1296759
B35: Dr: Acct 0789 - LEASE AND OTHER FINANCING PROCEEDS | J35: 1296759
C36: Cr: Acct 0842 - CAPITAL OUTLAY | K36: 1296759
C37: Cr: Acct 0674 - RIGHT-TO-USE SBITA LIABILITY | K37: 1296759
C38: =VLOOKUP($F$8,'Drop Down Menus'!$D$2:$G$10,4,FALSE) -> Cr: Acct 0815 - HLTH&HUM SV SV.LAB(GAAP ADJ)
J39: =ROUND(SUM(J34:J35),2) -> 2593518 | K39: =ROUND(SUM(K36:K38),2) -> 2593518 | L39: =IF(J39=K39,"<- Debits and Credits equal each other.","<- Debits and Credits do not equal each other.") -> <- Debits and Credits equal each other.
B41: SBITA ASSET (Acct 0480) AMOUNT SHOULD BE INCLUDED AS "ADDITIONS" ON REPORT 18.
A43: Record Annual Activity (all SBITAs)
A44: 3 | B44: Record amortization of the SBITA asset for the year.
B45: Dr: Acct 0875 - DEPRECIATION/AMORTIZATION | J45: 12271396
C46: Cr. Acct 0475 - ACCUMULATED AMORTIZATION - RIGHT-TO-USE SBITA | K46: =J45 -> 12271396
J47: =ROUND(SUM(J45:J45),2) -> 12271396 | K47: =ROUND(SUM(K46),2) -> 12271396 | L47: =IF(J47=K47,"<- Debits and Credits equal each other.","<- Debits and Credits do not equal each other.") -> <- Debits and Credits equal each other.
A49: 4 | B49: Reclassify information technology subscription exp. to debt service principal and interest exp.
...

Sheet Department Note Disclosure
A1: GASB 96 - SBITA Note Disclosure Form ( Submit one form for the department to the SCO annually)
A3: Note: There are three tables of note disclosures on this form —1) governmental funds, 2) proprietary - internal service funds, and 3) proprietary - enterprise funds. Complete all applicable tables before submitting to the SCO.
A4: Manually complete every yellow field in this worksheet—there are no automatically calculated cells in this worksheet.
A5: Complete the fields below using aggregated and summarized information from all of your department's completed contract template forms.
A7: The fields in this worksheet should contain the sums of the department's contracts' corresponding information in their note disclosure worksheets.
A10: I. Governmental Funds
A11: Fiscal Year: | B11: 2023–2024
A12: Org Code/Business Unit: | B12: 7100
A13: Reporting Department Name: | B13: Employment Development Department
A14: The below information must be entered manually. DO NOT ENTER DECIMALS. PLEASE ROUND TO THE NEAREST DOLLAR.
B15: Principal Payments | C15: Interest Payments | D15: ="All of the below questions are for Fiscal Year "&$B$11&":" -> All of the below questions are for Fiscal Year 2023–2024:
A16: =RIGHT(B11,4)&"–"&RIGHT(B11,4)+1 -> 2024–2025 | B16: 3472991 | C16: 130907 | D16: 1. Did your SBITAs have any variable payments which ARE NOT included in the measurement of the subscription liability?
A17: =LEFT(A16,4)+1&"–"&RIGHT(A16,4)+1 -> 2025–2026 | B17: 3582738 | C17: 21160
A18: =LEFT(A17,4)+1&"–"&RIGHT(A17,4)+1 -> 2026–2027 | B18: 453320 | C18: 21559 | D18: No
A19: =LEFT(A18,4)+1&"–"&RIGHT(A18,4)+1 -> 2027–2028 | D19: ="If yes, record the dollar amount of variable payments below for fiscal year "&$B$11&":" -> If yes, record the dollar amount of variable payments below for fiscal year 2023–2024:
A20: =LEFT(A19,4)+1&"–"&RIGHT(A19,4)+1 -> 2028–2029 | D20: 0
A21: =LEFT(A20,4)+1&"–"&RIGHT(A20,4)+5 -> 2029–2034 | D21: ="2. Record the dollar amount of any other payments for your SBITAs, such as termination penalties, not previously recorded in the payment schedule for fiscal year "&$B$11&":" -> 2. Record the dollar amount of any other payments for your SBITAs, such as termination penalties, not previously recorded in the payment schedule for fiscal year 2023–2024:
A22: =LEFT(A21,4)+5&"–"&RIGHT(A21,4)+5 -> 2034–2039
A23: =LEFT(A22,4)+5&"–"&RIGHT(A22,4)+5 -> 2039–2044 | D23: 0
A24: =LEFT(A23,4)+5&"–"&RIGHT(A23,4)+5 -> 2044–2049 | D24: ="3. Did you receive any SBITA incentives from the SBITA vendor (not already included in the SBITA measurement) during fiscal year "&$B$11&"? If so, record the amount below:" -> 3. Did you receive any SBITA incentives from the SBITA vendor (not already included in the SBITA measurement) during fiscal year 2023–2024? If so, record the amount below:
A25: =LEFT(A24,4)+5&"–"&RIGHT(A24,4)+5 -> 2049–2054
A26: =LEFT(A25,4)+5&"–"&RIGHT(A25,4)+5 -> 2054–2059 | D26: No
A27: =LEFT(A26,4)+5&"–"&RIGHT(A26,4)+5 -> 2059–2064 | D27: ="4. Are there any SBITA commitments known that have yet to commence as of June 30, "&RIGHT($B$11,4)&"?" -> 4. Are there any SBITA commitments known that have yet to commence as of June 30, 2024?
A28: =LEFT(A27,4)+5&"–"&RIGHT(A27,4)+5 -> 2064–2069
A29: =LEFT(A28,4)+5&"–"&RIGHT(A28,4)+5 -> 2069–2074 | D29: No
A30: =LEFT(A29,4)+5&"–"&RIGHT(A29,4)+5 -> 2074–2079 | D30: ="If yes, record the dollar amount of any SBITA commitments not commenced below for fiscal year "&$A$16&":" -> If yes, record the dollar amount of any SBITA commitments not commenced below for fiscal year 2024–2025:
A31: =LEFT(A30,4)+5&"–"&RIGHT(A30,4)+5 -> 2079–2084
A32: =LEFT(A31,4)+5&"–"&RIGHT(A31,4)+5 -> 2084–2089 | D32: 0
A33: =LEFT(A32,4)+5&"–"&RIGHT(A32,4)+5 -> 2089–2094
A34: =LEFT(A33,4)+5&"–"&RIGHT(A33,4)+5 -> 2094–2099
A35: =LEFT(A34,4)+5&"–"&RIGHT(A34,4)+5 -> 2099–2104
A36: =LEFT(A35,4)+5&"–"&RIGHT(A35,4)+5 -> 2104–2109
A37: =LEFT(A36,4)+5&"–"&RIGHT(A36,4)+5 -> 2109–2114
A38: =LEFT(A37,4)+5&"–"&RIGHT(A37,4)+5 -> 2114–2119
A39: =LEFT(A38,4)+5&"–"&RIGHT(A38,4)+5 -> 2119–2124
A41: II. Proprietary - Internal Service Funds
A42: Fiscal Year: | B42: =B11 -> 2023–2024
A43: Org Code/Business Unit: | B43: =B12 -> 7100
A44: Reporting Department Name: | B44: =B13 -> Employment Development Department
A45: The below information must be entered manually. DO NOT ENTER DECIMALS. PLEASE ROUND TO THE NEAREST DOLLAR.
...

Sheet SBITA Liabilities
C3: Schedule of Changes in SBITA Liabilities
C4: ="FY "&'Department Note Disclosure'!$B$11 -> FY 2023–2024
C5: ="Business Unit " &'Fund 7100 Journal Entries'!$F$5&" "&'Fund 7100 Journal Entries'!$F$4 -> Business Unit 7100 Employment Development Department
F7: ="Balance July 1, "&LEFT('Fund 7100 Journal Entries'!$F$3,4) -> Balance July 1, 2023 | H7: Additions | J7: Deductions | L7: ="Balance June 30, "&RIGHT('Fund 7100 Journal Entries'!$F$3,4) -> Balance June 30, 2024 | N7: Due Within One Year | P7: Noncurrent Liabilities
F8: (Entry #0) | H8: (Entry #2 & 9) | J8: (Entry #5 & 8) | N8: (Entry #6)
C9: Governmental Funds
D10: SBITA Liability | F10: =IF('Fund 7100 Journal Entries'!$F$7="Governmental Fund",'Fund 7100 Journal Entries'!$K$19,0) -> 20207041 | H10: =IF('Fund 7100 Journal Entries'!$F$7="Governmental Fund",SUM('Fund 7100 Journal Entries'!$K$37,'Fund 7100 Journal Entries'!$K$85),0) -> 1296759 | J10: =IF('Fund 7100 Journal Entries'!$F$7="Governmental Fund",SUM('Fund 7100 Journal Entries'!$J$56,'Fund 7100 Journal Entries'!$J$76),0) -> 13994751 | L10: =SUM(F10+H10-J10) -> 7509049 | N10: =IF('Fund 7100 Journal Entries'!$F$7="Governmental Fund",'Fund 7100 Journal Entries'!$J$61,0) -> 3472991 | P10: =L10-N10 -> 4036058
C11: Total Governmental Funds | F11: =SUM(F10:F10) -> 20207041 | H11: =SUM(H10:H10) -> 1296759 | J11: =SUM(J10:J10) -> 13994751 | L11: =SUM(L10:L10) -> 7509049 | N11: =SUM(N10:N10) -> 3472991 | P11: =SUM(P10:P10) -> 4036058
C13: Proprietary - Internal Service Funds
D14: SBITA Liability | F14: =IF('Fund 7100 Journal Entries'!$F$7="Proprietary - Internal Service Fund",'Fund 7100 Journal Entries'!$K$19,0) -> 0 | H14: =IF('Fund 7100 Journal Entries'!$F$7="Proprietary - Internal Service Fund",SUM('Fund 7100 Journal Entries'!$K$37,'Fund 7100 Journal Entries'!$K$85),0) -> 0 | J14: =IF('Fund 7100 Journal Entries'!$F$7="Proprietary - Internal Service Fund",SUM('Fund 7100 Journal Entries'!$J$56,'Fund 7100 Journal Entries'!$J$76),0) -> 0 | L14: =SUM(F14+H14-J14) -> 0 | N14: =IF('Fund 7100 Journal Entries'!$F$7="Proprietary - Internal Service Fund",'Fund 7100 Journal Entries'!$J$61,0) -> 0 | P14: =L14-N14 -> 0
C15: Total Proprietary - Internal Service Funds | F15: =SUM(F14:F14) -> 0 | H15: =SUM(H14:H14) -> 0 | J15: =SUM(J14:J14) -> 0 | L15: =SUM(L14:L14) -> 0 | N15: =SUM(N14:N14) -> 0 | P15: =SUM(P14:P14) -> 0
C17: Proprietary - Enterprise Funds
D18: SBITA Liability | F18: =IF('Fund 7100 Journal Entries'!$F$7="Proprietary - Enterprise Fund",'Fund 7100 Journal Entries'!$K$19,0) -> 0 | H18: =IF('Fund 7100 Journal Entries'!$F$7="Proprietary - Enterprise Fund",SUM('Fund 7100 Journal Entries'!$K$37,'Fund 7100 Journal Entries'!$K$85),0) -> 0 | J18: =IF('Fund 7100 Journal Entries'!$F$7="Proprietary - Enterprise Fund",SUM('Fund 7100 Journal Entries'!$J$56,'Fund 7100 Journal Entries'!$J$76),0) -> 0 | L18: =SUM(F18+H18-J18) -> 0 | N18: =IF('Fund 7100 Journal Entries'!$F$7="Proprietary - Enterprise Fund",'Fund 7100 Journal Entries'!$J$61,0) -> 0 | P18: =L18-N18 -> 0
C19: Total Proprietary - Enterprise Funds | F19: =SUM(F18:F18) -> 0 | H19: =SUM(H18:H18) -> 0 | J19: =SUM(J18:J18) -> 0 | L19: =SUM(L18:L18) -> 0 | N19: =SUM(N18:N18) -> 0 | P19: =SUM(P18:P18) -> 0
B22: THIS SCHEDULE IS FOR THE CHANGE IN SBITA LIABILITY (ACCOUNT 0674) ONLY. THESE AMOUNTS WILL DIFFER FROM THE REPORT 18 (ASSETS).
B23: NOTE: If multiple funds are included in this workbook, manually complete every yellow field by consolidating the entries by fund type (Governmental, Proprietary ISF, and Proprietary EF).

Sheet Check Figures 
A1: GASB Statement No. 96 Subscription-Based Information Technology Arrangements
A2: Check Figures
A4: Purpose:
A5: The purpose of this workbook is to check the figures entered in the journal entries reconcile to the future principal payments disclosed and the changes in the schedule of the SBITA liabilities.
A8: NOTE: The yellow highlighted fields have formulas embedded to generate the amounts automatically based on inputs in the journal entries tab. If multiple funds are included in this Workbook, manually complete every yellow field by consolidating the entries by fund type (Governmental Fund, Proprietary - Internal Service Fund, and Proprietary - Enterprise Fund).
A11: 1. To reconcile the journal entries of RTU SBITA Liability with the principal payments in Note Disclosure.
A12: a) Governmental Funds
B14: Journal Entries (Acct 0674 - RIGHT-TO-USE SBITA LIABILITY) | N14: Department Note Disclosure
B15: Beginning Balance | D15: Additions | F15: Deductions | H15: Deductions (Mod) | J15: Additions (Mod) | L15: Total
B16: Entry #0 | C16: + | D16: Entry #2 | E16: - | F16: Entry #5 | G16: - | H16: Entry #8 | I16: + | J16: Entry #9 | N16: Sum Principal Payments | P16: Variance
B17: =IF('Fund 7100 Journal Entries'!$F$7="Governmental Fund",ROUND('Fund 7100 Journal Entries'!$K$19,0),0) -> 20207041 | C17: + | D17: =IF('Fund 7100 Journal Entries'!$F$7="Governmental Fund",ROUND('Fund 7100 Journal Entries'!$K$37,0),0) -> 1296759 | E17: - | F17: =IF('Fund 7100 Journal Entries'!$F$7="Governmental Fund",ROUND('Fund 7100 Journal Entries'!$J$56,0),0) -> 13994751 | G17: - | H17: =IF('Fund 7100 Journal Entries'!$F$7="Governmental Fund",ROUND('Fund 7100 Journal Entries'!$J$76,0),0) -> 0 | I17: + | J17: =IF('Fund 7100 Journal Entries'!$F$7="Governmental Fund",ROUND('Fund 7100 Journal Entries'!$K$85,0),0) -> 0 | K17: = | L17: =+B17+D17-F17-H17+J17 -> 7509049 | N17: =ROUND(SUM('Department Note Disclosure'!$B$16:$B$39),0) -> 7509049 | P17: =L17-N17 -> 0
D18: =IF(OR(P17>0.99, (P17<(-0.99))), "Please review and correct the variance.","")
A20: b) Proprietary - Internal Service Funds
B22: Journal Entries (Acct 0674 - RIGHT-TO-USE SBITA LIABILITY) | N22: Department Note Disclosure
B23: Beginning Balance | D23: Additions | F23: Deductions | H23: Deductions (Mod) | J23: Additions (Mod) | L23: Total
B24: Entry #0 | C24: + | D24: Entry #2 | E24: - | F24: Entry #5 | G24: - | H24: Entry #8 | I24: + | J24: Entry #9 | N24: Sum Principal Payments | P24: Variance
B25: =IF('Fund 7100 Journal Entries'!$F$7="Proprietary - Internal Service Fund",ROUND('Fund 7100 Journal Entries'!$K$19,0),0) -> 0 | C25: + | D25: =IF('Fund 7100 Journal Entries'!$F$7="Proprietary - Internal Service Fund",ROUND('Fund 7100 Journal Entries'!$K$37,0),0) -> 0 | E25: - | F25: =IF('Fund 7100 Journal Entries'!$F$7="Proprietary - Internal Service Fund",ROUND('Fund 7100 Journal Entries'!$J$56,0),0) -> 0 | G25: - | H25: =IF('Fund 7100 Journal Entries'!$F$7="Proprietary - Internal Service Fund",ROUND('Fund 7100 Journal Entries'!$J$76,0),0) -> 0 | I25: + | J25: =IF('Fund 7100 Journal Entries'!$F$7="Proprietary - Internal Service Fund",ROUND('Fund 7100 Journal Entries'!$K$85,0),0) -> 0 | K25: = | L25: =+B25+D25-F25-H25+J25 -> 0 | N25: =ROUND(SUM('Department Note Disclosure'!$B$47:$B$70),0) -> 0 | P25: =L25-N25 -> 0
D27: =IF(OR(P25>0.99, (P25<(-0.99))), "Please review and correct the variance.","")
A29: c) Proprietary - Enterprise Funds
B31: Journal Entries (Acct 0674 - RIGHT-TO-USE SBITA LIABILITY) | N31: Department Note Disclosure
B32: Beginning Balance | D32: Additions | F32: Deductions | H32: Deductions (Mod) | J32: Additions (Mod) | L32: Total
B33: Entry #0 | C33: + | D33: Entry #2 | E33: - | F33: Entry #5 | G33: - | H33: Entry #8 | I33: + | J33: Entry #9 | N33: Sum Principal Payments | P33: Variance
B34: =IF('Fund 7100 Journal Entries'!$F$7="Proprietary - Enterprise Fund",ROUND('Fund 7100 Journal Entries'!$K$19,0),0) -> 0 | C34: + | D34: =IF('Fund 7100 Journal Entries'!$F$7="Proprietary - Enterprise Fund",ROUND('Fund 7100 Journal Entries'!$K$37,0),0) -> 0 | E34: - | F34: =IF('Fund 7100 Journal Entries'!$F$7="Proprietary - Enterprise Fund",ROUND('Fund 7100 Journal Entries'!$J$56,0),0) -> 0 | G34: - | H34: =IF('Fund 7100 Journal Entries'!$F$7="Proprietary - Enterprise Fund",ROUND('Fund 7100 Journal Entries'!$J$76,0),0) -> 0 | I34: + | J34: =IF('Fund 7100 Journal Entries'!$F$7="Proprietary - Enterprise Fund",ROUND('Fund 7100 Journal Entries'!$K$85,0),0) -> 0 | K34: = | L34: =+B34+D34-F34-H34+J34 -> 0 | N34: =ROUND(SUM('Department Note Disclosure'!$B$78:$B$101),0) -> 0 | P34: =L34-N34 -> 0
D35: =IF(OR(P34>0.99, (P34<(-0.99))), "Please review and correct the variance.","")
A37: 2. To match the journal entry to the principal amount due in the next fiscal year in Note Disclosure.
A38: a) Governmental Funds
B40: Journal Entries (Acct 0674 - RIGHT-TO-USE SBITA LIABILITY) | N40: Department Note Disclosure
B41: Entry #6 | C41: Due within one year | N41: ='Department Note Disclosure'!$A$16&" Principal Payments" -> 2024–2025 Principal Payments | P41: Variance
B42: =IF('Fund 7100 Journal Entries'!$F$7="Governmental Fund",ROUND('Fund 7100 Journal Entries'!$K$62,0),0) -> 3472991 | N42: =ROUND('Department Note Disclosure'!$B$16,0) -> 3472991 | P42: =B42-N42 -> 0
B43: =IF(OR(P42>0.99, (P42<(-0.99))), "Please review and correct the variance.","")
A45: b) Proprietary - Internal Service Funds
B47: Journal Entries (Acct 0674 - RIGHT-TO-USE SBITA LIABILITY) | N47: Department Note Disclosure
B48: Entry #6 | C48: Due within one year
B49: =IF('Fund 7100 Journal Entries'!$F$7="Proprietary - Internal Service Fund",ROUND('Fund 7100 Journal Entries'!$K$62,0),0) -> 0 | N49: ='Department Note Disclosure'!$A$47&" Principal Payments" -> 2024–2025 Principal Payments | P49: Variance
B50: =IF(OR(P50>0.99, (P50<(-0.99))), "Please review and correct the variance.","") | N50: =ROUND('Department Note Disclosure'!$B$47,0) -> 0 | P50: =B49-N50 -> 0
A52: c) Proprietary - Enterprise Funds
B54: Journal Entries (Acct 0674 - RIGHT-TO-USE SBITA LIABILITY) | N54: Department Note Disclosure
B55: Entry #6 | C55: Due within one year
B56: =IF('Fund 7100 Journal Entries'!$F$7="Proprietary - Enterprise Fund",ROUND('Fund 7100 Journal Entries'!$K$62,0),0) -> 0 | N56: ='Department Note Disclosure'!$A$47&" Principal Payments" -> 2024–2025 Principal Payments | P56: Variance
B57: =IF(OR(P57>0.99, (P57<(-0.99))), "Please review and correct the variance.","") | N57: =ROUND('Department Note Disclosure'!$B$78,0) -> 0 | P57: =B56-N57 -> 0
...

Sheet Drop Down Menus
A1: 2022–2023 | B1: Governmental Fund | C1: Yes | E1: Please select fund type above. | F1: Please select fund type above. | G1: Please select fund type above.
A2: 2023–2024 | B2: Proprietary - Internal Service Fund | C2: No | D2: GENERAL GOVERNMENT | E2: Dr: Acct 5808 - GENERAL GOV. (REV & EXP) | F2: Dr: Acct 0808 - GENERAL GOV. (GAAP ADJ) | G2: Cr: Acct 0808 - GENERAL GOV. (GAAP ADJ)
A3: 2024–2025 | B3: Proprietary - Enterprise Fund | D3: EDUCATION | E3: Dr: Acct 5810 - EDUCATION EXP (REV-EXP) | F3: Dr: Acct 0810 - EDUCATION EXP (GAAP ADJ) | G3: Cr: Acct 0810 - EDUCATION EXP (GAAP ADJ)
A4: 2025–2026 | D4: HEALTH AND HUMAN SERVICES | E4: Dr: Acct 5815 - HEALTH HM SRV & LAB (REV-EXP) | F4: Dr: Acct 0815 - HLTH&HUM SV SV.LAB(GAAP ADJ) | G4: Cr: Acct 0815 - HLTH&HUM SV SV.LAB(GAAP ADJ)
A5: 2026–2027 | D5: RESOURCES | E5: Dr: Acct 5820 - NATURL RSRCS & ENVIR (REV-EXP) | F5: Dr: Acct 0820 - NAT RES & ENVIRON (GAAP ADJ) | G5: Cr: Acct 0820 - NAT RES & ENVIRON (GAAP ADJ)
A6: 2027–2028 | D6: BUS, CONSUMER SERV, HOUSING | E6: Dr: Acct 5825 - BUS, CONS SERV, HS (REV-EXP) | F6: Dr: Acct 0825 - BUS, CONSUMER SERV, HOUSING | G6: Cr: Acct 0825 - BUS, CONSUMER SERV, HOUSING
A7: 2028–2029 | D7: TRANSPORTATION | E7: Dr: Acct 5830 - TRANSPORTATION (REV-EXP) | F7: Dr: Acct 0830 - TRANSPORTATION (GAAP ADJ) | G7: Cr: Acct 0830 - TRANSPORTATION (GAAP ADJ)
A8: 2029–2030 | D8: CORRECTIONS AND REHABILITATION | E8: Dr: Acct 5835 - CORRECTIONAL PROG. (REV-EXP) | F8: Dr: Acct 0835 - CORRECTIONS AND REHABILITATION | G8: Cr: Acct 0835 - CORRECTIONS AND REHABILITATION
A9: 2030–2031 | D9: PROPRIETARY FUND | E9: Dr: Acct 0870 - SERVICES & CHARGES (MG ADJ) | F9: Dr: Acct 0875 - DEPRECIATION/AMORTIZATION (MG ADJ) | G9: Cr: Acct 0870 - SERVICES & CHARGES (MG ADJ)
A10: 2031–2032 | D10: UNIDENTIFIED | E10: Dr: Acct 0XXX - FUNCTIONAL EXPENSE | F10: Dr: Acct 0XXX - FUNCTIONAL EXPENSE | G10: Cr: Acct 0XXX - FUNCTIONAL EXPENSE
A11: 2032–2033
A12: 2033–2034
A13: 2034–2035
A14: 2035–2036
A15: 2036–2037
A16: 2037–2038
A17: 2038–2039
A18: 2039–2040
A19: 2040–2041
A20: 2041–2042
A21: 2042–2043
A22: 2043–2044
... A101: 2022–2023

Sheet GAAP02Aindex
A1: Agency | B1: Title | C1: Hier1 | D1: Desc1 | E1: Desc2 | F1: Hier2 | G1: Hier3 | H1: Hier4 | I1: Hier5 | J1: EffectiveDate | K1: CancelDate
A2: 0000 | B2: BOND INTEREST AND REDEMPTION | C2: 9000 | D2: BOND INTEREST AND REDEMPTION | F2: 9030 | G2: 9600 | H2: 0000 | I2: 0000 | J2: 04/04/1984 | K2: 00/00/0000
A3: 0010 | B3: LEGISLATIVE, JUDICIAL AND EXEC | C3: 0808 | D3: GENERAL GOVERNMENT | F3: 0000 | G3: 0000 | H3: 0000 | I3: 0000 | J3: 07/11/2006 | K3: 00/00/0000
A4: 0015 | B4: ADD AGENCY TEST | C4: 0808 | D4: GENERAL GOVERNMENT | F4: 0000 | G4: 0000 | H4: 0000 | I4: 0000 | J4: 99/99/9999 | K4: 00/00/0000
A5: 0020 | B5: LEGISLATIVE | C5: 0808 | D5: GENERAL GOVERNMENT | F5: 0000 | G5: 0000 | H5: 0000 | I5: 0000 | J5: 99/99/9999 | K5: 00/00/0000
A6: 0100 | B6: LEGISLATURE | C6: 0808 | D6: GENERAL GOVERNMENT | F6: 0000 | G6: 0000 | H6: 0000 | I6: 0000 | J6: 99/99/9999 | K6: 00/00/0000
A7: 0110 | B7: SENATE | C7: 0808 | D7: GENERAL GOVERNMENT | F7: 0000 | G7: 0000 | H7: 0000 | I7: 0000 | J7: 06/26/1985 | K7: 00/00/0000
A8: 0120 | B8: ASSEMBLY | C8: 0808 | D8: GENERAL GOVERNMENT | F8: 0000 | G8: 0000 | H8: 0000 | I8: 0000 | J8: 06/26/1985 | K8: 00/00/0000
A9: 0130 | B9: LEGISLATIVE JOINT EXPENSES | C9: 0808 | D9: GENERAL GOVERNMENT | F9: 0000 | G9: 0000 | H9: 0000 | I9: 0000 | J9: 06/26/1985 | K9: 00/00/0000
A10: 0150 | B10: CONTRIB TO LEGIS RETIRE FUND | C10: 0808 | D10: GENERAL GOVERNMENT | F10: 0000 | G10: 0000 | H10: 0000 | I10: 0000 | J10: 07/11/2006 | K10: 00/00/0000
A11: 0155 | B11: AUDITOR GENERAL OFFICE | C11: 0808 | D11: GENERAL GOVERNMENT | F11: 0000 | G11: 0000 | H11: 0000 | I11: 0000 | J11: 99/99/9999 | K11: 00/00/0000
A12: 0160 | B12: LEGISLATIVE COUNSEL BUREAU | C12: 0808 | D12: GENERAL GOVERNMENT | F12: 0000 | G12: 0000 | H12: 0000 | I12: 0000 | J12: 04/04/1984 | K12: 00/00/0000
A13: 0170 | B13: CA LAW REVISION COMMISSION | C13: 0808 | D13: GENERAL GOVERNMENT | F13: 0000 | G13: 0000 | H13: 0000 | I13: 0000 | J13: 99/99/9999 | K13: 07/01/1985
... A190: 2140 | B190: STATE BANKING DEPARTMENT | C190: 0825 | D190: BUS, CONSUMER SERV, HOUSING | F190: 0000 | G190: 0000 | H190: 0000 | I190: 0000 | J190: 12/21/2016 | K190: 00/00/0000
A191: 2150 | B191: FINANCIAL INSTITUTIONS | C191: 0825 | D191: ADD BACK TO POST PY REVERSAL | E191: DELETE 16/17 | F191: 0000 | G191: 0000 | H191: 0000 | I191: 0000 | J191: 08/18/2016 | K191: 00/00/0000
A192: 2180 | B192: DEPART OF CORPORATIONS | C192: 0825 | D192: ADD BACK TO POST PY REVERSAL | E192: DELETE 16/17 | F192: 0000 | G192: 0000 | H192: 0000 | I192: 0000 | J192: 08/24/2016 | K192: 00/00/0000
A193: 2190 | B193: MAJOR MEDICAL INSURANCE BOARD | C193: 0825 | D193: BUS, CONSUMER SERV, HOUSING | F193: 0000 | G193: 0000 | H193: 0000 | I193: 0000 | J193: 12/21/2016 | K193: 00/00/0000
A194: 2200 | B194: DEPARTMENT OF COMMERCE | C194: 0825 | D194: BUS, CONSUMER SERV, HOUSING | F194: 0000 | G194: 0000 | H194: 0000 | I194: 0000 | J194: 12/21/2016 | K194: 00/00/0000
A195: 2220 | B195: OFFICE OF SMALL BUSINESS DEVEL | C195: 0825 | D195: BUS, CONSUMER SERV, HOUSING | F195: 0000 | G195: 0000 | H195: 0000 | I195: 0000 | J195: 12/21/2016 | K195: 00/00/0000
A196: 2222 | B196: ST ASST FD FOR ENTERPRISE | C196: 0825 | D196: BUS, CONSUMER SERV, HOUSING | F196: 0000 | G196: 0000 | H196: 0000 | I196: 0000 | J196: 12/21/2016 | K196: 00/00/0000
A197: 2225 | B197: UNITARY FUND PROGRAMS | C197: 0825 | D197: BUS, CONSUMER SERV, HOUSING | F197: 0000 | G197: 0000 | H197: 0000 | I197: 0000 | J197: 12/21/2016 | K197: 00/00/0000
A198: 2230 | B198: CA INDTRL DEV FINCL ADVRY COMM | C198: 0825 | D198: BUS, CONSUMER SERV, HOUSING | F198: 0000 | G198: 0000 | H198: 0000 | I198: 0000 | J198: 12/21/2016 | K198: 07/01/1985
A199: 2235 | B199: CA HOME LOAN MORTGAGE ASSN | C199: 0825 | D199: BUS, CONSUMER SERV, HOUSING | F199: 0000 | G199: 0000 | H199: 0000 | I199: 0000 | J199: 12/21/2016 | K199: 00/00/0000
A200: 2240 | B200: DEPT-HOUSING/COMMUNITY DEVEL | C200: 0825 | D200: BUS, CONSUMER SERV, HOUSING | F200: 0000 | G200: 0000 | H200: 0000 | I200: 0000 | J200: 12/12/2016 | K200: 00/00/1999
A201: 2245 | B201: CALIFORNIA HOUSING FINANCE AGY | C201: 0825 | D201: BUS, CONSUMER SERV, HOUSING | F201: 0000 | G201: 0000 | H201: 0000 | I201: 0000 | J201: 08/19/2016 | K201: 00/00/0000
A202: 2265 | B202: CALIFORNIA HOUSING INSURANCE | C202: 0825 | D202: BUS, CONSUMER SERV, HOUSING | F202: 0000 | G202: 0000 | H202: 0000 | I202: 0000 | J202: 12/21/2016 | K202: 00/00/0000
A203: 2270 | B203: MORTGAGE BOND ALLOC COMMITTEE | C203: 0825 | D203: BUS, CONSUMER SERV, HOUSING | F203: 0000 | G203: 0000 | H203: 0000 | I203: 0000 | J203: 12/21/2016 | K203: 07/01/1985
A204: 2290 | B204: DEPARTMENT OF INSURANCE | C204: 0825 | D204: BUS, CONSUMER SERV, HOUSING | F204: 0000 | G204: 0000 | H204: 0000 | I204: 0000 | J204: 12/21/2016 | K204: 00/00/1999
... A214: 2670 | B214: BD OF PILOT COMMISSIONERS-SF | C214: 0830 | D214: TRANSPORTATION | F214: 0000 | G214: 0000 | H214: 0000 | I214: 0000 | J214: 08/03/2017 | K214: 00/00/0000
A215: 2700 | B215: OFFICE OF TRAFFIC SAFETY | C215: 0830 | D215: TRANSPORTATION | E215: MERGED W/0521-ADD 4 PY ACCR RV | F215: 0000 | G215: 0000 | H215: 0000 | I215: 0000 | J215: 09/28/2016 | K215: 00/00/0000
A216: 2720 | B216: DEPT OF CAL HIGHWAY PATROL | C216: 0830 | D216: TRANSPORTATION | F216: 0000 | G216: 0000 | H216: 0000 | I216: 0000 | J216: 10/28/2016 | K216: 00/00/1999
A217: 2740 | B217: DEPARTMENT OF MOTOR VEHICLES | C217: 0830 | D217: TRANSPORTATION | F217: 0000 | G217: 0000 | H217: 0000 | I217: 0000 | J217: 10/28/2016 | K217: 00/00/0000
A218: 2780 | B218: STEPHEN P TEALE DATA CENTER | C218: 0825 | D218: BUS, CONSUMER SERV, HOUSING | F218: 0000 | G218: 0000 | H218: 0000 | I218: 0000 | J218: 12/21/2016 | K218: 00/00/0000
A219: 2900 | B219: TRADE AND COMMERCE | C219: 0825 | D219: BUS, CONSUMER SERV, HOUSING | F219: 0000 | G219: 0000 | H219: 0000 | I219: 0000 | J219: 12/21/2016 | K219: 00/00/0000
A220: 2920 | B220: TECHNOLOGY TRADE & COMMERCE AG | C220: 0825 | D220: BUS, CONSUMER SERV, HOUSING | F220: 0000 | G220: 0000 | H220: 0000 | I220: 0000 | J220: 12/21/2016 | K220: 00/00/0000
A221: 3000 | B221: NATURAL RESOURCES | C221: 0820 | D221: RESOURCES | F221: 0000 | G221: 0000 | H221: 0000 | I221: 0000 | J221: 08/25/2010 | K221: 00/00/0000
A222: 3100 | B222: EXPOSITION PARK | C222: 0820 | D222: RESOURCES | F222: 0000 | G222: 0000 | H222: 0000 | I222: 0000 | J222: 10/17/2018 | K222: 00/00/0000
A223: 3105 | B223: CALIFORNIA AFRO-AMERICAN MUSEU | C223: 0820 | D223: RESOURCES | F223: 0000 | G223: 0000 | H223: 0000 | I223: 0000 | J223: 09/05/2014 | K223: 00/00/0000
A224: 3110 | B224: SPECIAL RESOURCES PROGRAMS | C224: 0820 | D224: RESOURCES | F224: 0000 | G224: 0000 | H224: 0000 | I224: 0000 | J224: 07/11/2006 | K224: 00/00/1999
A225: 3125 | B225: CALIF TAHOE CONSERVANCY | C225: 0820 | D225: RESOURCES | F225: 0000 | G225: 0000 | H225: 0000 | I225: 0000 | J225: 04/18/1988 | K225: 00/00/1999
...
