Workbook
Name \Z: #REF!
Name \Z: #REF!
Name \Z: #REF!
Name \Z: #REF!
Name \Z: #REF!
Name Table26: '4. Non Current Liab'!$H$1:$P$11
Name Table26: '5. Gov Wide Entries Fund 9142'!$J$1:$R$6
Name Table26: '1. Summary 2324'!$I$1:$Q$12
Name WC_LiabilityAllocation: '4. Non Current Liab'!$A$1:$E$50
Name WC_LiabilityAllocation: '5. Gov Wide Entries Fund 9142'!$A$1:$F$61
Name WC_LiabilityAllocation: '1. Summary 2324'!$A$1:$G$91

Sheet 1. Summary 2324
A1: Workers' Compensation Liability | C1: ref | E1: ref | K1: Identifies as cell reference in this tab
A2: June 30, 2024 | D2: Prior Yr.% from | F2: Short-term | G2: % of Total
B3: KO717 Total | D3: SCIF letter | F3: Liability | G3: Outstanding
B4: (Total billed) | D4: (related to py) | F4: B5*C5 | G4: S-T %
A5: Total paid | B5: ='8. K0717_2024_Jun '!B332 -> 6.8659103e+08 | C5: tab 8 | D5: 0.0093 | E5: A | F5: =B5*D5 -> 6385296.6 | G5: =+F5/'2. K0215-June 30, 2024'!R11 -> 0.0015716524
A6: Add Claim Pmts from audit | B6: =-L21*1000 -> 1820000 | C6: L21
A7: Subtract the Proprietary Funds | B7: Total O/S | D7: % of Total O/S | J7: Primary Government - Gov. Activities & Enterprise fund (amounts in thousands) | M7: ref | O7: ref
A8: Enterprise Funds (Hier 400) | B8: =+'2. K0215-June 30, 2024'!Q418 -> 9909595.4 | C8: tab 2 | D8: =ROUND($G$5,3) -> 0.002 | F8: =-(B8*D8) -> -19819.191 | K8: 2024 | N8: 2023
A9: Internal Services Funds (Hier 500) | B9: =+'2. K0215-June 30, 2024'!Q455 -> 36058778 | C9: tab 2 | D9: =ROUND($G$5,3) -> 0.002 | F9: =-(B9*D9) -> -72117.555 | J9: Liabilities Beg. Bal. | K9: =N12 -> 0 | O9: G1
A10: Allocated to GF & SR | F10: =SUM(F5:F9) -> 6293359.8 | G10: * | J10: Incurred claims | K10: =+K12-K9-K11 -> 688411.03 | O10: G2
J11: Claim payments | K11: =((B5+B6)/1000*-1) -> -688411.03 | O11: G3
B12: Total | F12: Short-term | J12: Liabilities End. Bal. | K12: =N22 -> 0 | N12: =SUM(N9:N11) -> 0 | O12: G4
B13: Outstanding* | D13: Percentage* | F13: Allocation* | N13: =IF(N12=N19,"OK","ERROR") -> OK
A14: General Fund (Hier 100) | B14: =+'2. K0215-June 30, 2024'!Q293 -> 3.0321371e+09 | C14: B14 must match D30 | D14: =B14/B17 -> 0.75492242 | F14: =D14*$F$10 -> 4750998.4 | N14: Check to ensure cells N19 and N12 match
A15: Special Revenue Funds (Hier 200) | B15: =+'2. K0215-June 30, 2024'!Q414 -> 9.8435126e+08 | C15: B15 must match D67 | D15: =B15/B17 -> 0.24507758 | F15: =D15*$F$10 -> 1542361.4 | G15: GF Total
A16: SUBTOTAL - K0215 (w/o Hiers 400, 500, or 900) | B16: =+B14+B15 -> 4.0164883e+09 | F16: =+F14+F15 -> 6293359.8 | G16: =+F14 -> 4750998.4
B17: =+B16 -> 4.0164883e+09 | D17: =SUM(D14:D16) -> 1 | F17: =+F16 -> 6293359.8 | J17: Breakdown of Primary Government (amounts in thousands) | U17: (PY GAAP system) | V17: (CY-PY)
K18: Gov. Activities | L18: Enterprise | M18: ref | N18: Total Primary Gov. | S18: Fund | T18: CY | U18: PY | V18: Change
A19: Breakdown of Workers' Compensation by Exp Code | J19: Beginning | K19: =N12-L19 -> -14535 | L19: =U21 -> 14535 | M19: U21 | N19: =SUM(K19:L19) -> 0 | S19: F0562 | T19: 8337 | U19: 9791 | V19: =T19-U19 -> -1454 | W19: CY amouts see L attachment
A20: General Fund | B20: Expend. Code | D20: Outstanding | F20: Percentage * | G20: Current WC Allocation* | J20: Addition | K20: =K22-K19-K21 -> 688411.03 | L20: 0 | N20: =SUM(K20:L20) -> 688411.03 | S20: F0917 | T20: 4378 | U20: 4744 | V20: =T20-U20 -> -366 | W20: CY amouts see J attachment
B21: 808 | D21: =+'2. K0215-June 30, 2024'!Q45 -> 77954501 | E21: tab 2 | F21: =D21/$D$30 -> 0.025709425 | G21: =F21*$F$14 -> 122145.44 | J21: Deduction | K21: =K11-L21 -> -686591.03 | L21: =V21 -> -1820 | M21: V21 | N21: =SUM(K21:L21) -> -688411.03 | T21: =SUM(T19:T20) -> 12715 | U21: =SUM(U19:U20) -> 14535 | V21: =SUM(V19:V20) -> -1820
B22: 810 | D22: =+'2. K0215-June 30, 2024'!R62 -> 6511365 | F22: =D22/$D$30 -> 0.0021474507 | G22: =F22*$F$14 -> 10202.535 | J22: Ending Balance | K22: =ROUND(J112-L22,0) -> -12715 | L22: =SUM(L19:L21) -> 12715 | N22: =SUM(K22:L22) -> 0
A23: Fund 1031 | B23: 810 | D23: ='2. K0215-June 30, 2024'!R59 -> 0 | F23: =D23/$D$30 -> 0 | G23: =F23*$F$14 -> 0 | J23: Current | K23: =ROUND((+G30+G67+D84)/1000,0) -> 6293 | L23: =+D74/1000 -> 0 | N23: =SUM(K23:L23) -> 6293 | T23: PY EB, wp - tab "Summary 2021", cell L22 | U23: 14535
B24: 815 | D24: =SUM('2. K0215-June 30, 2024'!Q70:Q110)+SUM('2. K0215-June 30, 2024'!Q64:Q65) -> 3.8494123e+08 | F24: =D24/$D$30 -> 0.12695377 | G24: =F24*$F$14 -> 603157.16 | J24: NonCurrent | K24: =SUM(K22-K23) -> -19008 | L24: =SUM(L22-L23) -> 12715 | N24: =SUM(K24:L24) -> -6293 | T24: PY variance check | U24: =U21-U23 -> 0
A25: Fund 0870 | B25: 815 | D25: =SUM('2. K0215-June 30, 2024'!Q66:Q69) -> 74005124 | F25: =D25/$D$30 -> 0.024406919 | G25: =F25*$F$14 -> 115957.23 | K25: is a round entry needed | L25: =IF((L22=G74/1000),"OK","ERROR") -> OK | N25: =IF((N24=(ROUND(G89,-3))/1000),"OK","ERROR") -> OK
B26: 820 | D26: =+'2. K0215-June 30, 2024'!Q132 -> 2.9721834e+08 | F26: =D26/$D$30 -> 0.098022726 | G26: =F26*$F$14 -> 465705.82 | L26: check to ensure cells L22 and G74 match | N26: Check to ensure cells N24 and G89 match
B27: 825 | D27: =+'2. K0215-June 30, 2024'!Q135 -> 732131.7 | F27: =D27/$D$30 -> 0.00024145732 | G27: =F27*$F$14 -> 1147.1634
B28: 830 | D28: 0 | F28: =D28/$D$30 -> 0 | G28: =F28*$F$14 -> 0
B29: 835 | D29: =+'2. K0215-June 30, 2024'!Q291 -> 2.1907744e+09 | F29: =D29/$D$30 -> 0.72251825 | G29: =F29*$F$14 -> 3432683.1
A30: Total General Fund | C30: =IF(B14=D30,"OK","ERROR") -> OK | D30: =SUM(D21:D29) -> 3.0321371e+09 | F30: =SUM(F21:F29) -> 1 | G30: =SUM(G21:G29) -> 4750998.4
A32: Special Revenue Funds
A33: 200-100 | B33: #808 - fund 0890 | D33: =+'2. K0215-June 30, 2024'!Q296 -> 12606027 | F33: =D33/$D$67 -> 0.012806431 | G33: =F33*$F$15 -> 19752.146
A34: 200-100 | B34: #810 - fund 0890 | D34: =+'2. K0215-June 30, 2024'!Q307 -> 5447668.2 | F34: =D34/$D$67 -> 0.0055342726 | G34: =F34*$F$15 -> 8535.8487
A35: 200-100 | B35: #815 - fund 0890 | D35: =+'2. K0215-June 30, 2024'!Q306 -> 35360538 | F35: =D35/$D$67 -> 0.035922683 | G35: =F35*$F$15 -> 55405.76
A36: 200-100 | B36: #820 - fund 0890 | D36: =+'2. K0215-June 30, 2024'!Q308 -> 3146933.7 | F36: =D36/$D$67 -> 0.0031969622 | G36: =F36*$F$15 -> 4930.8711
A37: 200-100 | B37: #825 - fund 0890 | D37: =+'2. K0215-June 30, 2024'!Q309 -> 74358.362 | F37: =D37/$D$67 -> 7.5540475e-05 | G37: =F37*$F$15 -> 116.51072
A38: 200-100 | B38: #835 - fund 0890 | D38: =+'2. K0215-June 30, 2024'!Q310 -> 410860.28 | F38: =D38/$D$67 -> 0.00041739194 | G38: =F38*$F$15 -> 643.76922
A39: 200-150 | B39: #820 - fund 0044 | D39: ='2. K0215-June 30, 2024'!Q312 -> 3291027.8 | F39: =D39/$D$67 -> 0.0033433469 | G39: =F39*$F$15 -> 5156.6493 | K39: Information for Note 17 Risk Management
A40: 200-150 | B40: #830 - fund 0042 | D40: =SUM('2. K0215-June 30, 2024'!$Q$314:Q341) -> 2.0736529e+08 | F40: =D40/$D$67 -> 0.21066188 | G40: =F40*$F$15 -> 324916.76
A41: 200-150 | B41: #830 - fund 0044 | D41: =SUM('2. K0215-June 30, 2024'!Q344:Q348) -> 5.0800893e+08 | F41: =D41/$D$67 -> 0.51608502 | G41: =F41*$F$15 -> 795989.62 | J41: Current: | K41: =G30 -> 4750998.4 | L41: General Fund
...

Sheet 2. K0215-June 30, 2024
A1: Chap-Agy # | B1: AGENCY | C1: Agency ID | D1: Exp Code | E1: Fund# | F1: Hier1 | G1: Hier2 | H1: O/S COMP | I1: O/S MED | J1: TOTAL | K1: General Fund (in thousands) | L1: Federal Funds (in thousands) | M1: % Reimb by (or to) Fed. Trust Fund [L/(K+L)] | N1: Federal Trust Fund (200-100) Amount (J*M) | O1: General Fund or Applicable Fund Total (J-N) | P1: To Balance | Q1: Total By Fund Hierarchy | R1: ='3. K0215-REFERENCE'!E287 -> 3.9863007e+09 | S1: Total from K0215 Report tab 3
A2: 30-000 | B2: ATTN: ACCOUNTING OFFICER | C2: 0001 | D2: 808 | E2: 0001 | F2: 100 | G2: 100 | J2: =SUM(H2+I2) -> 0 | K2: 0 | L2: 0 | M2: =IFERROR(+L2/(L2+K2),0) -> 0 | N2: =+J2*M2 -> 0 | O2: =+J2-N2 -> 0 | P2: =ROUND(((O2/$R$1)*$R$2),2) -> 0 | Q2: =+O2+P2 -> 0 | R2: =+R11-R1 -> 76491269 | S2: Balance
A3: 99-999 | B3: UNMATCHED RECS | C3: 0001 | D3: 808 | E3: 0001 | F3: 100 | G3: 100 | J3: =SUM(H3+I3) -> 0 | K3: 0 | L3: 0 | M3: =IFERROR(+L3/(L3+K3),0) -> 0 | N3: =+J3*M3 -> 0 | O3: =+J3-N3 -> 0 | P3: =ROUND(((O3/$R$1)*$R$2),2) -> 0 | Q3: =+O3+P3 -> 0
A4: 03-002 | B4: STATE SENATE EMPLOYEE | C4: 0110 | D4: 808 | E4: 0001 | F4: 100 | G4: 100 | H4: =VLOOKUP(A4,'3. K0215-REFERENCE'!A:D,3,FALSE) -> 48431.85 | I4: =VLOOKUP(A4,'3. K0215-REFERENCE'!A:D,4,FALSE) -> 351671.68 | J4: =SUM(H4+I4) -> 400103.53 | K4: 177325 | L4: 0 | M4: =IFERROR(+L4/(L4+K4),0) -> 0 | N4: =+J4*M4 -> 0 | O4: =+J4-N4 -> 400103.53 | P4: =ROUND(((O4/$R$1)*$R$2),2) -> 7677.4 | Q4: =+O4+P4 -> 407780.93
A5: 03-001 | B5: STATE ASSEMBLY ASSEMBLY MEMBERS-ONLY | C5: 0120 | D5: 808 | E5: 0001 | F5: 100 | G5: 100 | J5: =SUM(H5+I5) -> 0 | K5: 233648 | L5: 0 | M5: =IFERROR(+L5/(L5+K5),0) -> 0 | N5: =+J5*M5 -> 0 | O5: =+J5-N5 -> 0 | P5: =ROUND(((O5/$R$1)*$R$2),2) -> 0 | Q5: =+O5+P5 -> 0
A6: 03-004 | B6: STATE ASSEMBLY | C6: 0120 | D6: 808 | E6: 0001 | F6: 100 | G6: 100 | H6: =VLOOKUP(A6,'3. K0215-REFERENCE'!A:D,3,FALSE) -> 145094.09 | I6: =VLOOKUP(A6,'3. K0215-REFERENCE'!A:D,4,FALSE) -> 787574.88 | J6: =SUM(H6+I6) -> 932668.97 | K6: 233648 | L6: 0 | M6: =IFERROR(+L6/(L6+K6),0) -> 0 | N6: =+J6*M6 -> 0 | O6: =+J6-N6 -> 932668.97 | P6: =ROUND(((O6/$R$1)*$R$2),2) -> 17896.55 | Q6: =+O6+P6 -> 950565.52
A7: 03-007 | B7: STATE SENATE EMPLOYEE | C7: 0110 | D7: 808 | E7: 0001 | F7: 100 | G7: 100 | J7: =SUM(H7+I7) -> 0 | K7: 177325 | L7: 0 | M7: =IFERROR(+L7/(L7+K7),0) -> 0 | N7: =+J7*M7 -> 0 | O7: =+J7-N7 -> 0 | P7: =ROUND(((O7/$R$1)*$R$2),2) -> 0 | Q7: =+O7+P7 -> 0
A8: 03-008 | B8: LEGISLATIVE BUDGET COMMITTEE | C8: 0160 | D8: 808 | E8: 0001 | F8: 100 | G8: 100 | J8: =SUM(H8+I8) -> 0 | K8: 177027 | L8: 0 | M8: =IFERROR(+L8/(L8+K8),0) -> 0 | N8: =+J8*M8 -> 0 | O8: =+J8-N8 -> 0 | P8: =ROUND(((O8/$R$1)*$R$2),2) -> 0 | Q8: =+O8+P8 -> 0
A9: 03-430 | B9: LEGISLATIVE COUNSEL BUREAU | C9: 0160 | D9: 808 | E9: 0001 | F9: 100 | G9: 100 | H9: =VLOOKUP(A9,'3. K0215-REFERENCE'!A:D,3,FALSE) -> 56303.53 | I9: =VLOOKUP(A9,'3. K0215-REFERENCE'!A:D,4,FALSE) -> 545184.56 | J9: =SUM(H9+I9) -> 601488.09 | K9: 177027 | L9: 0 | M9: =IFERROR(+L9/(L9+K9),0) -> 0 | N9: =+J9*M9 -> 0 | O9: =+J9-N9 -> 601488.09 | P9: =ROUND(((O9/$R$1)*$R$2),2) -> 11541.68 | Q9: =+O9+P9 -> 613029.77
A10: 03-368 | B10: GOV OFFC PLANNING/RESEARCH | C10: 0500 | D10: 808 | E10: 0001 | F10: 100 | G10: 100 | J10: =SUM(H10+I10) -> 0 | K10: 26617 | L10: 0 | M10: =IFERROR(+L10/(L10+K10),0) -> 0 | N10: =+J10*M10 -> 0 | O10: =+J10-N10 -> 0 | P10: =ROUND(((O10/$R$1)*$R$2),2) -> 0 | Q10: =+O10+P10 -> 0
A11: 03-370 | B11: GOVERNOR'S OFFICE | C11: 0500 | D11: 808 | E11: 0001 | F11: 100 | G11: 100 | J11: =SUM(H11+I11) -> 0 | K11: 26617 | L11: 0 | M11: =IFERROR(+L11/(L11+K11),0) -> 0 | N11: =+J11*M11 -> 0 | O11: =+J11-N11 -> 0 | P11: =ROUND(((O11/$R$1)*$R$2),2) -> 0 | Q11: =+O11+P11 -> 0 | R11: 4.062792e+09 | S11: B
A12: 03-297 | B12: OFFC OF THE INSPECTOR GENERAL | C12: 0552 | D12: 808 | E12: 0001 | F12: 100 | G12: 100 | H12: =VLOOKUP(A12,'3. K0215-REFERENCE'!A:D,3,FALSE) -> 62263.34 | I12: =VLOOKUP(A12,'3. K0215-REFERENCE'!A:D,4,FALSE) -> 142282.46 | J12: =SUM(H12+I12) -> 204545.8 | K12: 39601 | L12: 0 | M12: =IFERROR(+L12/(L12+K12),0) -> 0 | N12: =+J12*M12 -> 0 | O12: =+J12-N12 -> 204545.8 | P12: =ROUND(((O12/$R$1)*$R$2),2) -> 3924.93 | Q12: =+O12+P12 -> 208470.73 | S12: Total from SCIF Letter to SARD
A13: 03-329 | B13: COMMISSION STATUS OF WOMEN | C13: 8820 | D13: 808 | E13: 0001 | F13: 100 | G13: 100 | J13: =SUM(H13+I13) -> 0 | K13: 1471 | L13: 0 | M13: =IFERROR(+L13/(L13+K13),0) -> 0 | N13: =+J13*M13 -> 0 | O13: =+J13-N13 -> 0 | P13: =ROUND(((O13/$R$1)*$R$2),2) -> 0 | Q13: =+O13+P13 -> 0 | S13: Labeled DOF Package
A14: 03-163 | B14: OFFICE EMERGENCY SERVICES | C14: 0690 | D14: 808 | E14: 0001 | F14: 100 | G14: 100 | H14: =VLOOKUP(A14,'3. K0215-REFERENCE'!A:D,3,FALSE) -> 2266882.4 | I14: =VLOOKUP(A14,'3. K0215-REFERENCE'!A:D,4,FALSE) -> 3908668.5 | J14: =SUM(H14+I14) -> 6175550.9 | K14: 215558 | L14: 2607520 | M14: =+L14/(L14+K14) -> 0.92364433 | N14: =+J14*M14 -> 5704012.6 | O14: =+J14-N14 -> 471538.3 | P14: =ROUND(((O14/$R$1)*$R$2),2) -> 9048.13 | Q14: =+O14+P14 -> 480586.43 | S14: Subject: Workers' Compensation Costs
A15: 30-419 | B15: DOJ-LAW ENFORCEMENT | C15: 0820 | D15: 808 | E15: 0001 | F15: 100 | G15: 100 | H15: =VLOOKUP(A15,'3. K0215-REFERENCE'!A:D,3,FALSE) -> 6005897.5 | I15: =VLOOKUP(A15,'3. K0215-REFERENCE'!A:D,4,FALSE) -> 12956128 | J15: =SUM(H15+I15) -> 18962026 | K15: 486805 | L15: 59756 | M15: =+L15/(L15+K15) -> 0.10933089 | N15: =+J15*M15 -> 2073135.2 | O15: =+J15-N15 -> 16888891 | P15: =ROUND(((O15/$R$1)*$R$2),2) -> 324073.07 | Q15: =+O15+P15 -> 17212964
A16: 30-420 | B16: DEPT OF JUSTICE | C16: 0820 | D16: 808 | E16: 0001 | F16: 100 | G16: 100 | H16: =VLOOKUP(A16,'3. K0215-REFERENCE'!A:D,3,FALSE) -> 2366682.8 | I16: =VLOOKUP(A16,'3. K0215-REFERENCE'!A:D,4,FALSE) -> 5838937 | J16: =SUM(H16+I16) -> 8205619.8 | K16: 486805 | L16: 59756 | M16: =+L16/(L16+K16) -> 0.10933089 | N16: =+J16*M16 -> 897127.71 | O16: =+J16-N16 -> 7308492.1 | P16: =ROUND(((O16/$R$1)*$R$2),2) -> 140239.25 | Q16: =+O16+P16 -> 7448731.3
A17: 30-423 | B17: DOJ-FEDERAL GRANTS | C17: 0820 | D17: 808 | E17: 0001 | F17: 100 | G17: 100 | H17: =VLOOKUP(A17,'3. K0215-REFERENCE'!A:D,3,FALSE) -> 462699.35 | I17: =VLOOKUP(A17,'3. K0215-REFERENCE'!A:D,4,FALSE) -> 445177.89 | J17: =SUM(H17+I17) -> 907877.24 | K17: 486805 | L17: 59756 | M17: =+L17/(L17+K17) -> 0.10933089 | N17: =+J17*M17 -> 99259.026 | O17: =+J17-N17 -> 808618.21 | P17: =ROUND(((O17/$R$1)*$R$2),2) -> 15516.2 | Q17: =+O17+P17 -> 824134.41
A18: 11-051 | B18: STATE CONTROLLER'S OFFICE | C18: 0840 | D18: 808 | E18: 0001 | F18: 100 | G18: 100 | H18: =VLOOKUP(A18,'3. K0215-REFERENCE'!A:D,3,FALSE) -> 101038.58 | I18: =VLOOKUP(A18,'3. K0215-REFERENCE'!A:D,4,FALSE) -> 619570.53 | J18: =SUM(H18+I18) -> 720609.11 | K18: 123122 | L18: 1320 | M18: =+L18/(L18+K18) -> 0.010607351 | N18: =+J18*M18 -> 7643.7539 | O18: =+J18-N18 -> 712965.36 | P18: =ROUND(((O18/$R$1)*$R$2),2) -> 13680.76 | Q18: =+O18+P18 -> 726646.12
A19: 33-333 | B19: STATE CONTROLLER'S OFFICE-FI$CAL | C19: 8880 | D19: 808 | E19: 0001 | F19: 100 | G19: 100 | J19: =SUM(H19+I19) -> 0 | K19: 72904 | L19: 0 | M19: =IFERROR(+L19/(L19+K19),0) -> 0 | N19: =+J19*M19 -> 0 | O19: =+J19-N19 -> 0 | P19: =ROUND(((O19/$R$1)*$R$2),2) -> 0 | Q19: =+O19+P19 -> 0
A20: 21-290 | B20: STATE BRD OF EQUALIZATION | C20: 0860 | D20: 808 | E20: 0001 | F20: 100 | G20: 100 | H20: =VLOOKUP(A20,'3. K0215-REFERENCE'!A:D,3,FALSE) -> 18995 | I20: =VLOOKUP(A20,'3. K0215-REFERENCE'!A:D,4,FALSE) -> 15801.57 | J20: =SUM(H20+I20) -> 34796.57 | K20: 26934 | L20: 0 | M20: =IFERROR(+L20/(L20+K20),0) -> 0 | N20: =+J20*M20 -> 0 | O20: =+J20-N20 -> 34796.57 | P20: =ROUND(((O20/$R$1)*$R$2),2) -> 667.7 | Q20: =+O20+P20 -> 35464.27
A21: 21-291 | B21: CA DEPT. OF TAX AND FEE | C21: 7600 | D21: 808 | E21: 0001 | F21: 100 | G21: 100 | H21: =VLOOKUP(A21,'3. K0215-REFERENCE'!A:D,3,FALSE) -> 4903844.1 | I21: =VLOOKUP(A21,'3. K0215-REFERENCE'!A:D,4,FALSE) -> 7984474.2 | J21: =SUM(H21+I21) -> 12888318 | K21: 494836 | L21: 154 | M21: =+L21/(L21+K21) -> 0.0003111174 | N21: =+J21*M21 -> 4009.78 | O21: =+J21-N21 -> 12884308 | P21: =ROUND(((O21/$R$1)*$R$2),2) -> 247231 | Q21: =+O21+P21 -> 13131539
A22: 03-426 | B22: STATE PUBLIC DEFENDER | C22: 8140 | D22: 808 | E22: 0001 | F22: 100 | G22: 100 | J22: =SUM(H22+I22) -> 0 | K22: 21697 | L22: 0 | M22: =IFERROR(+L22/(L22+K22),0) -> 0 | N22: =+J22*M22 -> 0 | O22: =+J22-N22 -> 0 | P22: =ROUND(((O22/$R$1)*$R$2),2) -> 0 | Q22: =+O22+P22 -> 0
A23: 03-352 | B23: CALIFORNIA ARTS COUNCIL | C23: 8260 | D23: 808 | E23: 0001 | F23: 100 | G23: 100 | H23: =VLOOKUP(A23,'3. K0215-REFERENCE'!A:D,3,FALSE) -> 477.9 | I23: =VLOOKUP(A23,'3. K0215-REFERENCE'!A:D,4,FALSE) -> 11712.77 | J23: =SUM(H23+I23) -> 12190.67 | K23: 11525 | L23: 1180 | M23: =IFERROR(+L23/(L23+K23),0) -> 0.09287682 | N23: =+J23*M23 -> 1132.2307 | O23: =+J23-N23 -> 11058.439 | P23: =ROUND(((O23/$R$1)*$R$2),2) -> 212.2 | Q23: =+O23+P23 -> 11270.639
A24: 03-363 | B24: CA DEPT OF HUMAN RESOURCES | C24: 7501 | D24: 808 | E24: 0001 | F24: 100 | G24: 100 | H24: =VLOOKUP(A24,'3. K0215-REFERENCE'!A:D,3,FALSE) -> 456946.58 | I24: =VLOOKUP(A24,'3. K0215-REFERENCE'!A:D,4,FALSE) -> 379220.01 | J24: =SUM(H24+I24) -> 836166.59 | K24: 30450 | L24: 0 | M24: =IFERROR(+L24/(L24+K24),0) -> 0 | N24: =+J24*M24 -> 0 | O24: =+J24-N24 -> 836166.59 | P24: =ROUND(((O24/$R$1)*$R$2),2) -> 16044.81 | Q24: =+O24+P24 -> 852211.4
A25: 03-325 | B25: FAIR POLITICAL PRACT COMM | C25: 8620 | D25: 808 | E25: 0001 | F25: 100 | G25: 100 | H25: =VLOOKUP(A25,'3. K0215-REFERENCE'!A:D,3,FALSE) -> 4500 | I25: =VLOOKUP(A25,'3. K0215-REFERENCE'!A:D,4,FALSE) -> 45411.22 | J25: =SUM(H25+I25) -> 49911.22 | K25: 18308 | L25: 0 | M25: =IFERROR(+L25/(L25+K25),0) -> 0 | N25: =+J25*M25 -> 0 | O25: =+J25-N25 -> 49911.22 | P25: =ROUND(((O25/$R$1)*$R$2),2) -> 957.72 | Q25: =+O25+P25 -> 50868.94
A26: 99-292 | B26: OFFICE OF TAX APPEALS | C26: 0870 | D26: 808 | E26: 0001 | F26: 100 | G26: 100 | J26: =SUM(H26+I26) -> 0 | K26: 24194 | L26: 0 | M26: =IFERROR(+L26/(L26+K26),0) -> 0 | N26: =+J26*M26 -> 0 | O26: =+J26-N26 -> 0 | P26: =ROUND(((O26/$R$1)*$R$2),2) -> 0 | Q26: =+O26+P26 -> 0
A27: 99-356 | B27: COMMISSION ON STATE MANDATES | C27: 8885 | D27: 808 | E27: 0001 | F27: 100 | G27: 100 | H27: =VLOOKUP(A27,'3. K0215-REFERENCE'!A:D,3,FALSE) -> 0 | I27: =VLOOKUP(A27,'3. K0215-REFERENCE'!A:D,4,FALSE) -> 9304.2 | J27: =SUM(H27+I27) -> 9304.2 | K27: 3117 | L27: 0 | M27: =IFERROR(+L27/(L27+K27),0) -> 0 | N27: =+J27*M27 -> 0 | O27: =+J27-N27 -> 9304.2 | P27: =ROUND(((O27/$R$1)*$R$2),2) -> 178.53 | Q27: =+O27+P27 -> 9482.73
A28: 57-573 | B28: DVA-VETERANS' HOME OF CA | C28: 8955 | D28: 808 | E28: 0001 | F28: 100 | G28: 100 | H28: =VLOOKUP(A28,'3. K0215-REFERENCE'!A:D,3,FALSE) -> 3790118 | I28: =VLOOKUP(A28,'3. K0215-REFERENCE'!A:D,4,FALSE) -> 4888208.6 | J28: =SUM(H28+I28) -> 8678326.6 | K28: 537853 | L28: 0 | M28: =+L28/(L28+K28) -> 0 | N28: =+J28*M28 -> 0 | O28: =+J28-N28 -> 8678326.6 | P28: =ROUND(((O28/$R$1)*$R$2),2) -> 166524.37 | Q28: =+O28+P28 -> 8844850.9
A29: 57-574 | B29: DVA-BARSTOW VETERANS HOME | C29: 8955 | D29: 808 | E29: 0001 | F29: 100 | G29: 100 | H29: =VLOOKUP(A29,'3. K0215-REFERENCE'!A:D,3,FALSE) -> 70915.36 | I29: =VLOOKUP(A29,'3. K0215-REFERENCE'!A:D,4,FALSE) -> 894968.77 | J29: =SUM(H29+I29) -> 965884.13 | K29: 537853 | L29: 0 | M29: =+L29/(L29+K29) -> 0 | N29: =+J29*M29 -> 0 | O29: =+J29-N29 -> 965884.13 | P29: =ROUND(((O29/$R$1)*$R$2),2) -> 18533.9 | Q29: =+O29+P29 -> 984418.03
A30: 57-575 | B30: DVA-CHULA VISTA VETERANS | C30: 8955 | D30: 808 | E30: 0001 | F30: 100 | G30: 100 | H30: =VLOOKUP(A30,'3. K0215-REFERENCE'!A:D,3,FALSE) -> 388607.87 | I30: =VLOOKUP(A30,'3. K0215-REFERENCE'!A:D,4,FALSE) -> 2347917.4 | J30: =SUM(H30+I30) -> 2736525.2 | K30: 537853 | L30: 0 | M30: =+L30/(L30+K30) -> 0 | N30: =+J30*M30 -> 0 | O30: =+J30-N30 -> 2736525.2 | P30: =ROUND(((O30/$R$1)*$R$2),2) -> 52509.91 | Q30: =+O30+P30 -> 2789035.1
A31: 57-576 | B31: DVA-GLAVC | C31: 8955 | D31: 808 | E31: 0001 | F31: 100 | G31: 100 | H31: =VLOOKUP(A31,'3. K0215-REFERENCE'!A:D,3,FALSE) -> 1123946.2 | I31: =VLOOKUP(A31,'3. K0215-REFERENCE'!A:D,4,FALSE) -> 4783625.2 | J31: =SUM(H31+I31) -> 5907571.4 | K31: 537853 | L31: 0 | M31: =+L31/(L31+K31) -> 0 | N31: =+J31*M31 -> 0 | O31: =+J31-N31 -> 5907571.4 | P31: =ROUND(((O31/$R$1)*$R$2),2) -> 113357.64 | Q31: =+O31+P31 -> 6020929
A32: 57-577 | B32: DVA-FRESNO VETERANS HOME | C32: 8955 | D32: 808 | E32: 0001 | F32: 100 | G32: 100 | H32: =VLOOKUP(A32,'3. K0215-REFERENCE'!A:D,3,FALSE) -> 262570.98 | I32: =VLOOKUP(A32,'3. K0215-REFERENCE'!A:D,4,FALSE) -> 1881971.2 | J32: =SUM(H32+I32) -> 2144542.2 | K32: 537853 | L32: 0 | M32: =+L32/(L32+K32) -> 0 | N32: =+J32*M32 -> 0 | O32: =+J32-N32 -> 2144542.2 | P32: =ROUND(((O32/$R$1)*$R$2),2) -> 41150.62 | Q32: =+O32+P32 -> 2185692.9
A33: 57-578 | B33: DVA-REDDING VETERANS HOME | C33: 8955 | D33: 808 | E33: 0001 | F33: 100 | G33: 100 | H33: =VLOOKUP(A33,'3. K0215-REFERENCE'!A:D,3,FALSE) -> 272343.99 | I33: =VLOOKUP(A33,'3. K0215-REFERENCE'!A:D,4,FALSE) -> 1666427.5 | J33: =SUM(H33+I33) -> 1938771.5 | K33: 537853 | L33: 0 | M33: =+L33/(L33+K33) -> 0 | N33: =+J33*M33 -> 0 | O33: =+J33-N33 -> 1938771.5 | P33: =ROUND(((O33/$R$1)*$R$2),2) -> 37202.18 | Q33: =+O33+P33 -> 1975973.7
A34: 57-831 | B34: CA DEPT OF VETERAN'S AFFAIRS - HOME AND FARM | C34: 8955 | D34: 808 | E34: 0001 | F34: 100 | G34: 100 | H34: =VLOOKUP(A34,'3. K0215-REFERENCE'!A:D,3,FALSE) -> 0.5 | I34: =VLOOKUP(A34,'3. K0215-REFERENCE'!A:D,4,FALSE) -> 15167.13 | J34: =SUM(H34+I34) -> 15167.63 | K34: 537853 | L34: 0 | M34: =+L34/(L34+K34) -> 0 | N34: =+J34*M34 -> 0 | O34: =+J34-N34 -> 15167.63 | P34: =ROUND(((O34/$R$1)*$R$2),2) -> 291.04 | Q34: =+O34+P34 -> 15458.67
A35: 57-830 | B35: DEPT OF VETERANS AFFAIRS | C35: 8955 | D35: 808 | E35: 0001 | F35: 100 | G35: 100 | H35: =VLOOKUP(A35,'3. K0215-REFERENCE'!A:D,3,FALSE) -> 2420.76 | I35: =VLOOKUP(A35,'3. K0215-REFERENCE'!A:D,4,FALSE) -> 393689.25 | J35: =SUM(H35+I35) -> 396110.01 | K35: 537853 | L35: 0 | M35: =+L35/(L35+K35) -> 0 | N35: =+J35*M35 -> 0 | O35: =+J35-N35 -> 396110.01 | P35: =ROUND(((O35/$R$1)*$R$2),2) -> 7600.77 | Q35: =+O35+P35 -> 403710.78
A36: 42-564 | B36: FRANCHISE TAX BOARD | C36: 7730 | D36: 808 | E36: 0001 | F36: 100 | G36: 100 | H36: =VLOOKUP(A36,'3. K0215-REFERENCE'!A:D,3,FALSE) -> 939583.82 | I36: =VLOOKUP(A36,'3. K0215-REFERENCE'!A:D,4,FALSE) -> 4686414.8 | J36: =SUM(H36+I36) -> 5625998.6 | K36: 722099 | L36: 0 | M36: =+L36/(L36+K36) -> 0 | N36: =+J36*M36 -> 0 | O36: =+J36-N36 -> 5625998.6 | P36: =ROUND(((O36/$R$1)*$R$2),2) -> 107954.67 | Q36: =+O36+P36 -> 5733953.3
A37: 03-040 | B37: VICTIM COMP & GOV CLMS BD | C37: 7870 | D37: 808 | E37: 0001 | F37: 100 | G37: 100 | H37: =VLOOKUP(A37,'3. K0215-REFERENCE'!A:D,3,FALSE) -> 19.52 | I37: =VLOOKUP(A37,'3. K0215-REFERENCE'!A:D,4,FALSE) -> 172597.25 | J37: =SUM(H37+I37) -> 172616.77 | K37: 808 | L37: 657 | M37: =+L37/(L37+K37) -> 0.44846416 | N37: =+J37*M37 -> 77412.435 | O37: =+J37-N37 -> 95204.335 | P37: =ROUND(((O37/$R$1)*$R$2),2) -> 1826.83 | Q37: =+O37+P37 -> 97031.165
A38: 03-333 | B38: FI$CAL | C38: 8880 | D38: 808 | E38: 0001 | F38: 100 | G38: 100 | H38: =VLOOKUP(A38,'3. K0215-REFERENCE'!A:D,3,FALSE) -> 72183.8 | I38: =VLOOKUP(A38,'3. K0215-REFERENCE'!A:D,4,FALSE) -> 71128.05 | J38: =SUM(H38+I38) -> 143311.85 | K38: 72904 | L38: 0 | M38: =+L38/(L38+K38) -> 0 | N38: =+J38*M38 -> 0 | O38: =+J38-N38 -> 143311.85 | P38: =ROUND(((O38/$R$1)*$R$2),2) -> 2749.94 | Q38: =+O38+P38 -> 146061.79
A39: 03-590 | B39: STATE PERSONNEL BOARD | C39: 7503 | D39: 808 | E39: 0001 | F39: 100 | G39: 100 | H39: =VLOOKUP(A39,'3. K0215-REFERENCE'!A:D,3,FALSE) -> 1562466.5 | I39: =VLOOKUP(A39,'3. K0215-REFERENCE'!A:D,4,FALSE) -> 332405.75 | J39: =SUM(H39+I39) -> 1894872.2 | K39: 2519 | L39: 0 | M39: =+L39/(L39+K39) -> 0 | N39: =+J39*M39 -> 0 | O39: =+J39-N39 -> 1894872.2 | P39: =ROUND(((O39/$R$1)*$R$2),2) -> 36359.82 | Q39: =+O39+P39 -> 1931232.1
A40: 99-275 | B40: CALPERS | C40: 7900 | D40: 808 | E40: 0001 | F40: 100 | G40: 100 | H40: =VLOOKUP(A40,'3. K0215-REFERENCE'!A:D,3,FALSE) -> 1872848.1 | I40: =VLOOKUP(A40,'3. K0215-REFERENCE'!A:D,4,FALSE) -> 1347131.5 | J40: =SUM(H40+I40) -> 3219979.6 | K40: 1657000 | L40: 0 | M40: =+L40/(L40+K40) -> 0 | N40: =+J40*M40 -> 0 | O40: =+J40-N40 -> 3219979.6 | P40: =ROUND(((O40/$R$1)*$R$2),2) -> 61786.69 | Q40: =+O40+P40 -> 3281766.3
...

Sheet 3. K0215-REFERENCE
A1: AGENCY # | B1: Agency Name | C1: O/S COMP | D1: O/S MED | E1: TOTAL | G1: C
A2: 03-002 | B2: STATE SENATE EMPLOYEE | C2: 48431.85 | D2: 351671.68 | E2: =SUM(C2:D2) -> 400103.53 | G2: Source | H2: SCIF
A3: 03-004 | B3: STATE ASSEMBLY | C3: 145094.09 | D3: 787574.88 | E3: =SUM(C3:D3) -> 932668.97 | H3: WC Monthly list of State Contract Open Disability Claims Report as of 6/30/24
A4: 03-016 | B4: DEPT COMMUNITY SVCS & DEV | C4: 100 | D4: 55847.14 | E4: =SUM(C4:D4) -> 55947.14
A5: 03-037 | B5: CDCR-BOARD OF PRISON TERMS | C5: 10007.97 | D5: 234868.94 | E5: =SUM(C5:D5) -> 244876.91
A6: 03-040 | B6: VICTIM COMP & GOV CLMS BD | C6: 19.52 | D6: 172597.25 | E6: =SUM(C6:D6) -> 172616.77
A7: 03-163 | B7: OFFICE EMERGENCY SERVICES | C7: 2266882.4 | D7: 3908668.5 | E7: =SUM(C7:D7) -> 6175550.9
A8: 03-270 | B8: CA STUDENT AID COMMISSION | C8: 28178.01 | D8: 150310.88 | E8: =SUM(C8:D8) -> 178488.89
A9: 03-279 | B9: UNEMPLOYMENT INS APPS BD | C9: 677732.25 | D9: 1606791.8 | E9: =SUM(C9:D9) -> 2284524
A10: 03-297 | B10: OFFC OF THE INSPECTOR GENERAL | C10: 62263.34 | D10: 142282.46 | E10: =SUM(C10:D10) -> 204545.8
A11: 03-314 | B11: CALIFORNIA SCIENCE CENTER | C11: 681409.4 | D11: 426354.78 | E11: =SUM(C11:D11) -> 1107764.2
A12: 03-315 | B12: PUBLIC EMPLMT RELATION BD | C12: 0 | D12: 7914.61 | E12: =SUM(C12:D12) -> 7914.61
A13: 03-317 | B13: CA AFRICAN AMERICAN MUSEUM | C13: 6000 | D13: 41269.59 | E13: =SUM(C13:D13) -> 47269.59
A14: 03-325 | B14: FAIR POLITICAL PRACT COMM | C14: 4500 | D14: 45411.22 | E14: =SUM(C14:D14) -> 49911.22
A15: 03-326 | B15: DEPT FAIR EMPLMT & HOUSING | C15: 88752.72 | D15: 702553.34 | E15: =SUM(C15:D15) -> 791306.06
... A284: 99-817 | B284: DEPT CHILD SUPPORT SERVCS | C284: 97290.73 | D284: 138720.86 | E284: =SUM(C284:D284) -> 236011.59
A287: TOTAL | C287: =SUM(C2:C286) -> 1.4994149e+09 | D287: =SUM(D2:D286) -> 2.4868858e+09 | E287: =C287+D287 -> 3.9863007e+09 | F287: to Tab 1
C290: =C287 -> 1.4994149e+09 | D290: =D287 -> 2.4868858e+09 | E290: =E287 -> 3.9863007e+09 | F290: tab 3
C291: ='2. K0215-June 30, 2024'!H465 -> 1.4994149e+09 | D291: ='2. K0215-June 30, 2024'!I465 -> 2.4868858e+09 | E291: ='2. K0215-June 30, 2024'!J465 -> 3.9863007e+09 | F291: tab 2
C292: =C290-C291 -> 0 | D292: =D290-D291 -> 0 | E292: =E290-E291 -> 0

Sheet 4. Non Current Liab
A1: Workers' Compensation Liability
A2: Governmental Non Current Liability
A3: June 30, 2024
A5: FROM TAB 1
D6: Govn
B7: % of Current | C7: Govn | D7: Distributed
A8: Expenditure | B8: Govn WC | C8: Non Current | D8: Wrkrs Comp
A9: Codes | B9: Expense | C9: WC Liability | D9: Expenditure*
A10: 808 | B10: =+('1. Summary 2324'!D21+'1. Summary 2324'!D33+'1. Summary 2324'!D43+'1. Summary 2324'!D44+'1. Summary 2324'!D45+'1. Summary 2324'!D46)/(+'1. Summary 2324'!D$67+'1. Summary 2324'!D$30) -> 0.026308751 | C10: =+('1. Summary 2324'!G$89 -'1. Summary 2324'!F$86) -> -48772847 | D10: =(+B10*C$10) -> -1283152.7
A11: 810 | B11: =+(+'1. Summary 2324'!D22+'1. Summary 2324'!D23+'1. Summary 2324'!D34+'1. Summary 2324'!D47)/(+'1. Summary 2324'!D$67+'1. Summary 2324'!D$30) -> 0.0029774849 | C11: =+('1. Summary 2324'!G$89 -'1. Summary 2324'!F$86) -> -48772847 | D11: =(+B11*C$10) -> -145220.41
A12: 815 | B12: =+(+'1. Summary 2324'!D24+'1. Summary 2324'!D25+'1. Summary 2324'!D35+'1. Summary 2324'!D48+'1. Summary 2324'!D63+'1. Summary 2324'!D64+'1. Summary 2324'!D65)/(+'1. Summary 2324'!D$67+'1. Summary 2324'!D$30) -> 0.13243485 | C12: =+('1. Summary 2324'!G$89 -'1. Summary 2324'!F$86) -> -48772847 | D12: =(+B12*C$10) -> -6459224.7
A13: 820 | B13: =+('1. Summary 2324'!D26+'1. Summary 2324'!D36+'1. Summary 2324'!D39+'1. Summary 2324'!D54+'1. Summary 2324'!D55+'1. Summary 2324'!D56+'1. Summary 2324'!D57+'1. Summary 2324'!D58+'1. Summary 2324'!D59+'1. Summary 2324'!D60+'1. Summary 2324'!D61+'1. Summary 2324'!D66)/(+'1. Summary 2324'!D$67+'1. Summary 2324'!D$30) -> 0.08603593 | C13: =+('1. Summary 2324'!G$89 -'1. Summary 2324'!F$86) -> -48772847 | D13: =(+B13*C$10) -> -4196217.2
A14: 825 | B14: =+(+'1. Summary 2324'!D27+'1. Summary 2324'!D37+'1. Summary 2324'!D49+'1. Summary 2324'!D50+'1. Summary 2324'!D51+'1. Summary 2324'!D52+'1. Summary 2324'!D53+'1. Summary 2324'!D62)/(+'1. Summary 2324'!D$67+'1. Summary 2324'!D$30) -> 0.0035602294 | C14: =+('1. Summary 2324'!G$89 -'1. Summary 2324'!F$86) -> -48772847 | D14: =(+B14*C$10)+0.06 -> -173642.47
A15: 830 | B15: =+(+'1. Summary 2324'!D28+'1. Summary 2324'!D40+'1. Summary 2324'!D41+'1. Summary 2324'!D42)/(+'1. Summary 2324'!D$67+'1. Summary 2324'!D$30) -> 0.20313524 | C15: =+('1. Summary 2324'!G$89 -'1. Summary 2324'!F$86) -> -48772847 | D15: =(+B15*C$10) -> -9907483.8
A16: 835 | B16: =+(+'1. Summary 2324'!D29+'1. Summary 2324'!D38)/(+'1. Summary 2324'!D$67+'1. Summary 2324'!D$30) -> 0.54554752 | C16: =+('1. Summary 2324'!G$89 -'1. Summary 2324'!F$86) -> -48772847 | D16: =(+B16*C$10) -> -26607906
B17: =SUM(B10:B16) -> 1 | D17: =SUM(D10:D16) -> -48772847 | E17: Governmental Non Current WC Liability as of 06/30/22
A20: Note: "% of Current Govn WC Expense" should total to 100%, if it does not, check the formulas in each row and make sure the correct expenditure codes are included. The "% of Current Govn WC Expense" column will need to be updated if there are funds added to each expenditure code. Check the 'Breakdown of Workers' Compensation by Exp Code' section on the Summary tab for new funds. Do not change the decimal places, amounts could be a vey small percentage of the overall total.
A25: *Total may not foot due to rounding.
I59: Workers'
C60: =+C55+C56+C57 -> 0 | I60: Comp
H61: WC Liability | I61: Discounted | J61: %
A62: * State of California's Self-Insured Employee Workers' Compensation Program (SCIF) | H62: Discounts | I62: Liability | J62: Discount
A63: Actuarial Review as of June 30, 2003
A64: PricewaterhouseCoopers in 1,000s | E64: = | G64: 3458981 | H64: =+G64-I64 -> 708325 | I64: 2750656 | J64: =+H64/G64 -> 0.20477852
A65: Basic Financial Statements and Supplementary Information | G65: 89131 | H65: =+G65-I65 -> 11777 | I65: 77354 | J65: =+H65/G65 -> 0.13213136
A66: Total unpaid claims and claims adjustment at June 30, 2003
B67: Total Estimated Outstanding Workers' Compensation Liability | G67: =+G64+G65 -> 3548112 | H67: =+G67-I67 -> 720102 | I67: =+I64+I65 -> 2828010 | J67: =+H67/G67 -> 0.20295357
B68: (amounts in 1,000's)
A70: SCIF Discounted Workers' Compensation Liability (@ 20.5%) | G70: 2750656
A71: CSUS Discounted WC Liability (9%) | G71: 77354
B73: Total Discounted Workers' Compensation Liability (20.2%) | G73: =+G70+G71 -> 2828010
D86: 1844000

Sheet 5. Gov Wide Entries Fund 9142
A1: Workers' Compensation Liability
A2: Gov Wide Entries for Fund 9142
A3: June 30, 2024
A5: GL Account | B5: Current Year Exp Codes* | C5: REF | D5: Prior Year Exp Codes* | F5: What the 9142 2022/23 balances should be
A6: 0655 | F6: =-'1. Summary 2324'!F17 -> -6293359.8
A7: 0678 | F7: =-F6 -> 6293359.8
A8: 0692 | F8: =-'4. Non Current Liab'!D17 -> 48772847 | G8: from tab 4
A9: 0808 | B9: ='4. Non Current Liab'!D10 -> -1283152.7 | C9: tab 4 | F9: =(B9-D9) -> -1283152.7
A10: 0810 | B10: ='4. Non Current Liab'!D11 -> -145220.41 | C10: tab 4 | F10: =(B10-D10) -> -145220.41
A11: 0815 | B11: ='4. Non Current Liab'!D12 -> -6459224.7 | C11: tab 4 | F11: =(B11-D11) -> -6459224.7
A12: 0820 | B12: ='4. Non Current Liab'!D13 -> -4196217.2 | C12: tab 4 | F12: =(B12-D12) -> -4196217.2
A13: 0825 | B13: ='4. Non Current Liab'!D14 -> -173642.47 | C13: tab 4 | F13: =(B13-D13) -> -173642.47
A14: 0830 | B14: ='4. Non Current Liab'!D15 -> -9907483.8 | C14: tab 4 | F14: =(B14-D14) -> -9907483.8
A15: 0835 | B15: ='4. Non Current Liab'!D16 -> -26607906 | C15: tab 4 | F15: =(B15-D15) -> -26607906
A16: 0950 | F16: =D18 -> 0
A17: 0952
B18: =SUM(B9:B16) -> -48772847 | D18: =SUM(D9:D17) -> 0 | F18: =SUM(F6:F17) -> -3.7252903e-09 | G18: Sum
A20: *Totals may not foot due to rounding.
E85: 1844000

Sheet 6. CSU Breakdown
B1: Self-Insurance Claims Liability | I1: For table reference please attachment "D"
B2: CSURMA (California State University Risk Management Authority)
C4: Balance | I4: Balance | K4: Less | M4: Noncurrent
C5: 45108 | E5: Addition | G5: Deduction | I5: 45473 | K5: Current Portions | M5: Portion
B6: University
B7: Workers' Compensation
B8: Other Self-Insurance Claims Liability
B10: Auxiliary
B11: Workers' Compensation
B12: Other Self-Insurance Claims Liability
B14: Total | C14: =SUM(C7:C12) -> 0 | E14: =SUM(E7:E12) -> 0 | G14: =SUM(G7:G12) -> 0 | I14: =SUM(I7:I12) -> 0 | K14: =SUM(K7:K12) -> 0 | M14: =SUM(M7:M12) -> 0
B16: New Workers' Comp above | C16: =C7+C11 -> 0 | E16: =E7+E11 -> 0 | F16: * | G16: =G7+G11 -> 0 | H16: * | I16: =I7+I11 -> 0 | K16: =K7+K11 -> 0 | M16: =M7+M11 -> 0
B18: * Not part of Table 40 in Note 17; provided for Note
I19: To tab 1 - Actuarial Review
B21: Lottery Additions/Deductions | D21: E | I21: to tab 1
B22: Additions and Deductions, Enterprise | E22: =E21+E16 -> 0 | G22: =G21+G16 -> 0

Sheet 7. Recon
A1: RECONCILIATION OF WORKERS' COMPENSATION FROM STATEMENTS & GOVERNMENT WIDE ADJUSTMENT TO GL FINAL BALANCE
B3: 2023/2024 | C3: Workers' Compensation Liability
I4: Acct 655 | K4: Acct 692 | M4: Total
I5: Current Liab | K5: Noncurrent Liab | M5: 6/30/2023 Bal
B6: Internal Service Funds: | C6: Agency | D6: Fund
B7: Service Revolving Fund | C7: 7760 | D7: 0666 | E7: (Agency prepared statement) | I7: ='1. Summary 2324'!D77 -> 0 | K7: ='1. Summary 2324'!F77 -> 28118000 | M7: =K7+I7 -> 28118000 | O7: See Summary tab, 'Current/Non-Current Workers' Comp Liability for Enterprise and Internal Service Funds' section
B8: Technology Services Revolving Fund | C8: 7502 | D8: 9730 | E8: (Agency prepared statement) | I8: ='1. Summary 2324'!D78 -> 0 | K8: ='1. Summary 2324'!F78 -> 136487 | M8: =K8+I8 -> 136487 | O8: See Summary tab, 'Current/Non-Current Workers' Comp Liability for Enterprise and Internal Service Funds' section
B9: Prison Industries Revolving Fund | C9: 5420 | D9: 0678 | E9: (Audited Statement) | I9: ='1. Summary 2324'!D79 -> 0 | K9: ='1. Summary 2324'!F79 -> 0 | M9: =K9+I9 -> 0 | O9: See Summary tab, 'Current/Non-Current Workers' Comp Liability for Enterprise and Internal Service Funds' section
B10: Architecture Revolving Fund | C10: 9865 | D10: 0602 | E10: (Audited Statement) | I10: ='1. Summary 2324'!D80 -> 0 | K10: ='1. Summary 2324'!F80 -> 290000 | M10: =K10+I10 -> 290000 | O10: See Summary tab, 'Current/Non-Current Workers' Comp Liability for Enterprise and Internal Service Funds' section
B11: Public Safety Comm. Revolving Fund | C11: 0690 | D11: 9751 | E11: (Agency prepared statement) | I11: ='1. Summary 2324'!D81 -> 0 | K11: ='1. Summary 2324'!F81 -> 1210000 | M11: =K11+I11 -> 1210000 | O11: See Summary tab, 'Current/Non-Current Workers' Comp Liability for Enterprise and Internal Service Funds' section
B12: Natural Gas Services Program Fund | C12: 7760 | D12: 9746 | E12: (Agency prepared statement) | I12: ='1. Summary 2324'!D82 -> 0 | K12: ='1. Summary 2324'!F82 -> 3000 | M12: =K12+I12 -> 3000 | O12: See Summary tab, 'Current/Non-Current Workers' Comp Liability for Enterprise and Internal Service Funds' section
B13: State Motor Vehicle Insurance Account | C13: 7760 | D13: 0026 | E13: (Agency prepared statement) | I13: ='1. Summary 2324'!D83 -> 0 | K13: ='1. Summary 2324'!F83 -> 7000 | M13: =K13+I13 -> 7000 | O13: See Summary tab, 'Current/Non-Current Workers' Comp Liability for Enterprise and Internal Service Funds' section
B15: Other Government Activities:
B16: Government Wide Adjustment | D16: 9142 | E16: (Summary) | I16: ='1. Summary 2324'!F10 -> 6293359.8 | K16: ='1. Summary 2324'!J73 -> -48772847 | M16: =K16+I16 -> -42479487 | O16: MUST Adjusted Liability Below (cell 82)
O17: =IF((ROUND(M16,-3)/1000)=ROUND(M82,0),"Matches","Does not match") -> Matches
C19: Fund Class 1 Total - Governmental Activities | I19: =SUM(I7:I18) -> 6293359.8 | K19: =SUM(K7:K18) -> -19008360 | M19: =SUM(M7:M18) -> -12715000
B21: Enterprise Funds:
B22: State Lottery Fund | C22: 0850 | D22: 0562 | E22: (Audited Statement) | I22: ='1. Summary 2324'!D72 -> 0 | K22: ='1. Summary 2324'!F72 -> 8337000 | M22: =K22+I22 -> 8337000 | O22: Include in note under table, if not included in Note 9
B23: Inmate Welfare Fund | C23: 5225 | D23: 0917 | E23: (Agency prepared statement) | I23: ='1. Summary 2324'!D73 -> 0 | K23: ='1. Summary 2324'!F73 -> 4378000 | M23: =K23+I23 -> 4378000
C24: Fund Class 2 Total - Enterprise Activities | I24: =SUM(I22:I23) -> 0 | K24: =SUM(K22:K23) -> 12715000 | M24: =SUM(M22:M23) -> 12715000
B26: TOTAL PRIMARY GOVERNMENT WORKERS' COMPENSATION | I26: =I19+I24 -> 6293359.8 | K26: =K19+K24 -> -6293359.8 | M26: =M19+M24 -> 0 | O26: Should match Total Workers' Comp Liability From All State Programs
B27: Discretely Presented Component: | O27: =IF((ROUND(M26,-3)/1000)=ROUND(M68,0),"Matches","Does not match") -> Matches
B29: CA Housing Finance Fund (CPA) | D29: 0501 | M29: =I29+K29 -> 0
B30: CA School Finance Authority (CPA) | D30: 0526 | M30: =I30+K30 -> 0
B31: CA Expo & State Fair (CPA) | D31: 0510 | M31: =I31+K31 -> 0
B32: State Compensation Insurance Fund (CPA) | D32: 0512 | M32: =I32+K32 -> 0
B33: CA Alternative Energy Source Finance Authority | D33: 0528 | M33: =I33+K33 -> 0
B34: Calif Infrastructure & Economic Development Bank (CPA) | D34: 0649 &9328) | M34: =I34+K34 -> 0
B35: Federal Student Loan Reserve Fund | D35: 0783 | M35: =I35+K35 -> 0
B36: Student Loan Operating Fund | D36: 0784 | M36: =I36+K36 -> 0
B37: EDFUND (CPA 9/30/xx year-end)) | D37: 9940 | M37: =I37+K37 -> 0
B38: Del Mar Race Track Authority (CPA) | D38: 0795 | M38: =I38+K38 -> 0
B39: CA Health Facilities Finance Authority - no audit; look into loans | D39: 0904 | M39: =I39+K39 -> 0
B40: Education Facilities Authority Fund (CPA) - INPUT WITH 0954 | D40: 0911 | M40: =I40+K40 -> 0
B41: Student Loan Authority Fund(CPA) - INPUT WITH 0911 | D41: 0954 | M41: =I41+K41 -> 0
B42: CA Pollution Control Finance Authority | D42: 0930 | M42: =I42+K42 -> 0
B43: CA Urban Waterfront Area Restoration Fund | D43: 0982 | M43: =I43+K43 -> 0
B44: Race Track Leasing Commission (CPA) | D44: 0989 | M44: =I44+K44 -> 0
B45: California Health Trust Fund | D45: 3175 | M45: =I45+K45 -> 0
B46: SAFE-BIDCO | D46: 9935 | M46: =I46+K46 -> 0
...

Sheet 8. K0717_2024_Jun 
A1: Column1
A2: K0717 MONTHLY SUMMARY REPORTS OF STATE AGENCY BILLING 06/30/2024 PAGE 1
A3: CHAPTER AGENCY TOTAL TOTAL TOTAL TOTAL TOTAL TOTAL TOTAL TOTAL BILL
A4: CODE CODE TD PAID PD PAID VR PAID SJDB PAID MED PAID PEN PAID MISC. PAID NET BENEFIT TOTAL
A5: 03 001 0.00 0.00 0.00 0.00 3,967.17 0.00 0.00 3,967.17 3,967.17
A6: 002 7,362.60 40,049.00 0.00 0.00 167,251.75 0.00 6,651.66 214,663.35 221,315.01
A7: 004 13,719.87 72,871.16 0.00 0.00 264,354.41 0.00 10,498.88 350,945.44 361,444.32
A8: 008 0.00 0.00 0.00 0.00 5.63- 0.00 0.00 5.63- 5.63-
A9: 009 0.00 0.00 0.00 0.00 606.02 0.00 0.00 606.02 606.02
A10: 016 0.00 0.00 0.00 0.00 21,893.28 0.00 1,398.20 21,893.28 23,291.48
A11: 037 0.00 0.00 0.00 0.00 10,636.48 0.00 0.00 10,636.48 10,636.48
A12: 040 0.00 3,480.00 0.00 0.00 35,646.07 0.00 404.10 39,126.07 39,530.17
... A330: 817 42,452.01 134,656.58 0.00 0.00 43,019.40 0.00 0.00 220,127.99 220,127.99
A331: TOTALS 87239135.37 230953301.68 17653.25 1552661.68 359675755.62 24117.93 7128404.66 679438507.60 686591030.19 | B331: 6.8659103e+08
B332: 6.8659103e+08

Sheet 9. Proprietary Funds
I2: Total Amount less Fund 0948000
I3: =SUM(Table_CY_GAAP[Amount])-SUMIFS(Table_CY_GAAP[[#All],[Amount]],Table_CY_GAAP[[#All],[Fund]],"0948000") -> -42479487
A4: Fund | B4: t2 | C4: T3 | D4: T4 | E4: Title | F4: GenCode | G4: GLAccount | H4: Fund&Glccount | I4: Amount | J4: FundName | K4: FundClass | L4: Hier1 | M4: MajorMinor | N4: Hier2 | O4: Color
A5: 0562000 | B5: LIABILITIES & DEFERRED INFLOW | C5: LIABILITIES | D5: LIABILITY-NON-CUR | E5: WORKERS COMPENSATION BENEFITS PAYABLE | F5: GBBI | G5: 06920000000 | H5: =Table_CY_GAAP[[#This Row],[Fund]]&Table_CY_GAAP[[#This Row],[GLAccount]] -> 056200006920000000 | I5: -8337000 | J5: STATE LOTTERY FUND | K5: 002 | L5: 400 | M5: 001 | N5: 600
A6: 0948000 | B6: LIABILITIES & DEFERRED INFLOW | C6: LIABILITIES | D6: LIABILITY-NON-CUR | E6: WORKERS COMPENSATION BENEFITS PAYABLE | F6: GBBI | G6: 06920000000 | H6: =Table_CY_GAAP[[#This Row],[Fund]]&Table_CY_GAAP[[#This Row],[GLAccount]] -> 094800006920000000 | I6: -67944000 | J6: CAL ST UNIV & COLL TRUST F | K6: 002 | L6: 400 | M6: 001 | N6: 700
A7: 0917000 | B7: LIABILITIES & DEFERRED INFLOW | C7: LIABILITIES | D7: LIABILITY-NON-CUR | E7: WORKERS COMPENSATION BENEFITS PAYABLE | F7: GBBI | G7: 06920000000 | H7: =Table_CY_GAAP[[#This Row],[Fund]]&Table_CY_GAAP[[#This Row],[GLAccount]] -> 091700006920000000 | I7: -4378000 | J7: INMATES' WELFARE FUND | K7: 002 | L7: 400 | M7: 002 | N7: 900
A8: 0666000 | B8: LIABILITIES & DEFERRED INFLOW | C8: LIABILITIES | D8: LIABILITY-NON-CUR | E8: WORKERS COMPENSATION BENEFITS PAYABLE | F8: GBBI | G8: 06920000000 | H8: =Table_CY_GAAP[[#This Row],[Fund]]&Table_CY_GAAP[[#This Row],[GLAccount]] -> 066600006920000000 | I8: -28118000 | J8: SERVICE REVOLVING FUND | K8: 001 | L8: 500 | M8: 002 | N8: 100
A9: 0602000 | B9: LIABILITIES & DEFERRED INFLOW | C9: LIABILITIES | D9: LIABILITY-NON-CUR | E9: WORKERS COMPENSATION BENEFITS PAYABLE | F9: GBBI | G9: 06920000000 | H9: =Table_CY_GAAP[[#This Row],[Fund]]&Table_CY_GAAP[[#This Row],[GLAccount]] -> 060200006920000000 | I9: -290000 | J9: ARCHITECTURE REVOLVING FUN | K9: 001 | L9: 500 | M9: 002 | N9: 500
A10: 9730000 | B10: LIABILITIES & DEFERRED INFLOW | C10: LIABILITIES | D10: LIABILITY-NON-CUR | E10: WORKERS COMPENSATION BENEFITS PAYABLE | F10: GBBI | G10: 06920000000 | H10: =Table_CY_GAAP[[#This Row],[Fund]]&Table_CY_GAAP[[#This Row],[GLAccount]] -> 973000006920000000 | I10: -136487 | J10: TECHNOLOGY SERVICES REVOLV | K10: 001 | L10: 500 | M10: 002 | N10: 600
A11: 0026000 | B11: LIABILITIES & DEFERRED INFLOW | C11: LIABILITIES | D11: LIABILITY-NON-CUR | E11: WORKERS COMPENSATION BENEFITS PAYABLE | F11: GBBI | G11: 06920000000 | H11: =Table_CY_GAAP[[#This Row],[Fund]]&Table_CY_GAAP[[#This Row],[GLAccount]] -> 002600006920000000 | I11: -7000 | J11: MOTOR VEHICLE INSURANCE AC | K11: 001 | L11: 500 | M11: 002 | N11: 900
A12: 9746000 | B12: LIABILITIES & DEFERRED INFLOW | C12: LIABILITIES | D12: LIABILITY-NON-CUR | E12: WORKERS COMPENSATION BENEFITS PAYABLE | F12: GBBI | G12: 06920000000 | H12: =Table_CY_GAAP[[#This Row],[Fund]]&Table_CY_GAAP[[#This Row],[GLAccount]] -> 974600006920000000 | I12: -3000 | J12: NATURAL GAS SERVICES PROG | K12: 001 | L12: 500 | M12: 002 | N12: 900
A13: 9751000 | B13: LIABILITIES & DEFERRED INFLOW | C13: LIABILITIES | D13: LIABILITY-NON-CUR | E13: WORKERS COMPENSATION BENEFITS PAYABLE | F13: GBBI | G13: 06920000000 | H13: =Table_CY_GAAP[[#This Row],[Fund]]&Table_CY_GAAP[[#This Row],[GLAccount]] -> 975100006920000000 | I13: -1210000 | J13: PUB SAFETY COMM REVOLVING | K13: 001 | L13: 500 | M13: 002 | N13: 900

Sheet TC 35
B1: STATE CONTROLLER'S USE ONLY | BM1: STATE CONTROLLER'S USE ONLY
B2: DOCUMENT NO. | L2: DATE | T2: MSG Code | V2: STATE OF CALIFORNIA | BM2: TC Code | BO2: PREPARED BY: | BS2: NCACCAM
V3: OFFICE OF THE STATE CONTROLLER
B4: S | BM4: 35
B5: STATE CONTROLLER'S USE ONLY | BF5: 1 | BH5: of | BI5: 11
BR7: DC | BS7: A | BT7: SCO USE | BW7: SOURCE
C8: FUND | J8: AGY | N8: FY | R8: M | S8: REF/ITEM | Y8: RED CAT | AD8: P/N | AF8: C | AG8: CAT | AI8: PGM | AK8: ELE | AM8: COMP | AP8: TASK | AS8: ACCT | AW8: SCO | AX8: REV/OBJ | BD8: AMOUNT | BT8: T | BU8: O | BV8: B | BW8: FUND
C9: 0001 | AS9: 0808 | BD9: ='1. Summary 2324'!G21 -> 122145.44 | BR9: D | BS9: G
B10: DESCRIPTION
B11: CURRENT WORKERS COMP AMT
C12: 0001 | AS12: 0810 | BD12: ='1. Summary 2324'!G22 -> 10202.535 | BR12: D | BS12: G
B13: DESCRIPTION
B14: CURRENT WORKERS COMP AMT
C15: 0001 | AS15: 0815 | BD15: ='1. Summary 2324'!G24 -> 603157.16 | BR15: D | BS15: G
B16: DESCRIPTION
B17: CURRENT WORKERS COMP AMT
C18: 0001 | AS18: 0820 | BD18: ='1. Summary 2324'!G26 -> 465705.82 | BR18: D | BS18: G
B19: DESCRIPTION
B20: CURRENT WORKERS COMP AMT
C21: 0001 | AS21: 0825 | BD21: ='1. Summary 2324'!G27 -> 1147.1634 | BR21: D | BS21: G
B22: DESCRIPTION
B23: CURRENT WORKERS COMP AMT
C24: 0001 | AS24: 0835 | BD24: ='1. Summary 2324'!G29 -> 3432683.1 | BR24: D | BS24: G
B25: DESCRIPTION
B26: CURRENT WORKERS COMP AMT
C27: 0001 | AS27: 0810 | BD27: 0 | BR27: D | BS27: G
B29: CURRENT WORKERS COMP AMT
C30: 0001 | AS30: 0678 | BD30: ='1. Summary 2324'!G30-'1. Summary 2324'!G25-'1. Summary 2324'!G23+0.02 -> 4635041.2 | BR30: C | BS30: G
B31: DESCRIPTION
B32: CURRENT WORKERS COMP AMT
B34: DESCRIPTION
B36: CA503 PC VERSION (7/99)

Sheet TC 35 (1)
B1: STATE CONTROLLER'S USE ONLY | BM1: STATE CONTROLLER'S USE ONLY
B2: DOCUMENT NO. | L2: DATE | T2: MSG Code | V2: STATE OF CALIFORNIA | BM2: TC Code | BO2: PREPARED BY: | BS2: ='TC 35'!BS2:CC3 -> NCACCAM
V3: OFFICE OF THE STATE CONTROLLER
B4: S | BM4: 35
B5: STATE CONTROLLER'S USE ONLY | BF5: 2 | BH5: of | BI5: 11
BR7: DC | BS7: A | BT7: SCO USE | BW7: SOURCE
C8: FUND | J8: AGY | N8: FY | R8: M | S8: REF/ITEM | Y8: RED CAT | AD8: P/N | AF8: C | AG8: CAT | AI8: PGM | AK8: ELE | AM8: COMP | AP8: TASK | AS8: ACCT | AW8: SCO | AX8: REV/OBJ | BD8: AMOUNT | BT8: T | BU8: O | BV8: B | BW8: FUND
C9: 1031 | AS9: 0810 | BD9: ='1. Summary 2324'!D23 -> 0 | BR9: D | BS9: G
B10: DESCRIPTION
B11: CURRENT WORKERS COMP AMT
C12: 1031 | AS12: 0678 | BD12: =BD9 -> 0 | BR12: C | BS12: G
B13: DESCRIPTION
B14: CURRENT WORKERS COMP AMT
B16: DESCRIPTION
B19: DESCRIPTION
B22: DESCRIPTION
B25: DESCRIPTION
B31: DESCRIPTION
B34: DESCRIPTION
B36: CA503 PC VERSION (7/99)

Sheet TC 35 (2)
B1: STATE CONTROLLER'S USE ONLY | BM1: STATE CONTROLLER'S USE ONLY
B2: DOCUMENT NO. | L2: DATE | T2: MSG Code | V2: STATE OF CALIFORNIA | BM2: TC Code | BO2: PREPARED BY: | BS2: ='TC 35'!BS2:CC3 -> NCACCAM
V3: OFFICE OF THE STATE CONTROLLER
B4: S | BM4: 35
B5: STATE CONTROLLER'S USE ONLY | BF5: 3 | BH5: of | BI5: 10
BR7: DC | BS7: A | BT7: SCO USE | BW7: SOURCE
C8: FUND | J8: AGY | N8: FY | R8: M | S8: REF/ITEM | Y8: RED CAT | AD8: P/N | AF8: C | AG8: CAT | AI8: PGM | AK8: ELE | AM8: COMP | AP8: TASK | AS8: ACCT | AW8: SCO | AX8: REV/OBJ | BD8: AMOUNT | BT8: T | BU8: O | BV8: B | BW8: FUND
C9: 0870 | AS9: 0815 | BD9: ='1. Summary 2324'!G25 -> 115957.23 | BR9: D | BS9: G
B10: DESCRIPTION
B11: CURRENT WORKERS COMP AMT
C12: 0870 | AS12: 0678 | BD12: =BD9 -> 115957.23 | BR12: C | BS12: G
B13: DESCRIPTION
B14: CURRENT WORKERS COMP AMT
B16: DESCRIPTION
B19: DESCRIPTION
B22: DESCRIPTION
B25: DESCRIPTION
B31: DESCRIPTION
B34: DESCRIPTION
B36: CA503 PC VERSION (7/99)

Sheet TC 35 (3)
A1: 14823.52 | B1: STATE CONTROLLER'S USE ONLY | BM1: STATE CONTROLLER'S USE ONLY
B2: DOCUMENT NO. | L2: DATE | T2: MSG Code | V2: STATE OF CALIFORNIA | BM2: TC Code | BO2: PREPARED BY: | BS2: NCACCAM
V3: OFFICE OF THE STATE CONTROLLER
B4: S | BM4: 35
B5: STATE CONTROLLER'S USE ONLY | BF5: 4 | BH5: of | BI5: 10
BR7: DC | BS7: A | BT7: SCO USE | BW7: SOURCE
C8: FUND | J8: AGY | N8: FY | R8: M | S8: REF/ITEM | Y8: RED CAT | AD8: P/N | AF8: C | AG8: CAT | AI8: PGM | AK8: ELE | AM8: COMP | AP8: TASK | AS8: ACCT | AW8: SCO | AX8: REV/OBJ | BD8: AMOUNT | BT8: T | BU8: O | BV8: B | BW8: FUND
C9: 0890 | AS9: 0808 | BD9: ='1. Summary 2324'!G33 -> 19752.146 | BR9: D | BS9: G
B10: DESCRIPTION
B11: CURRENT WORKERS COMP AMT
C12: 0890 | AS12: 0678 | BD12: =BD9 -> 19752.146 | BR12: C | BS12: G
B13: DESCRIPTION
B14: CURRENT WORKERS COMP AMT
C15: 0890 | AS15: 0810 | BD15: ='1. Summary 2324'!G34 -> 8535.8487 | BR15: D | BS15: G
B16: DESCRIPTION
B17: CURRENT WORKERS COMP AMT
C18: 0890 | AS18: 0678 | BD18: =BD15 -> 8535.8487 | BR18: C | BS18: G
B19: DESCRIPTION
B20: CURRENT WORKERS COMP AMT
C21: 0890 | AS21: 0815 | BD21: ='1. Summary 2324'!G35 -> 55405.76 | BR21: D | BS21: G
B22: DESCRIPTION
B23: CURRENT WORKERS COMP AMT
C24: 0890 | AS24: 0678 | BD24: =BD21 -> 55405.76 | BR24: C | BS24: G
B25: DESCRIPTION
B26: CURRENT WORKERS COMP AMT
C27: 0890 | AS27: 0820 | BD27: ='1. Summary 2324'!G36 -> 4930.8711 | BR27: D | BS27: G
B28: DESCRIPTION
B29: CURRENT WORKERS COMP AMT
C30: 0890 | AS30: 0678 | BD30: =BD27 -> 4930.8711 | BR30: C | BS30: G
B31: DESCRIPTION
B32: CURRENT WORKERS COMP AMT
C33: 0890 | AS33: 0825 | BD33: ='1. Summary 2324'!G37 -> 116.51072 | BR33: D | BS33: G
B34: DESCRIPTION
B35: CURRENT WORKERS COMP AMT
B36: CA503 PC VERSION (7/99)

Sheet TC 35 (4)
B1: STATE CONTROLLER'S USE ONLY | BM1: STATE CONTROLLER'S USE ONLY
B2: DOCUMENT NO. | L2: DATE | T2: MSG Code | V2: STATE OF CALIFORNIA | BM2: TC Code | BO2: PREPARED BY: | BS2: NCACCAM
V3: OFFICE OF THE STATE CONTROLLER
B4: S | BM4: 35
B5: STATE CONTROLLER'S USE ONLY | BF5: 5 | BH5: of | BI5: 10
BR7: DC | BS7: A | BT7: SCO USE | BW7: SOURCE
C8: FUND | J8: AGY | N8: FY | R8: M | S8: REF/ITEM | Y8: RED CAT | AD8: P/N | AF8: C | AG8: CAT | AI8: PGM | AK8: ELE | AM8: COMP | AP8: TASK | AS8: ACCT | AW8: SCO | AX8: REV/OBJ | BD8: AMOUNT | BT8: T | BU8: O | BV8: B | BW8: FUND
C9: 0890 | AS9: 0678 | BD9: ='TC 35 (3)'!BD33:BQ33 -> 116.51072 | BR9: C | BS9: G
B10: DESCRIPTION
B11: CURRENT WORKERS COMP AMT
C12: 0890 | AS12: 0835 | BD12: ='1. Summary 2324'!G38 -> 643.76922 | BR12: D | BS12: G
B13: DESCRIPTION
B14: CURRENT WORKERS COMP AMT
C15: 0890 | AS15: 0678 | BD15: =BD12 -> 643.76922 | BR15: C | BS15: G
B16: DESCRIPTION
B17: CURRENT WORKERS COMP AMT
C18: 0044 | AS18: 0820 | BD18: ='1. Summary 2324'!G39 -> 5156.6493 | BR18: D | BS18: G
B19: DESCRIPTION
B20: CURRENT WORKERS COMP AMT
C21: 0044 | AS21: 0678 | BD21: =BD18 -> 5156.6493 | BR21: C | BS21: G
B22: DESCRIPTION
B23: CURRENT WORKERS COMP AMT
C24: 0042 | AS24: 0830 | BD24: ='1. Summary 2324'!G40 -> 324916.76 | BR24: D | BS24: G
B25: DESCRIPTION
B26: CURRENT WORKERS COMP AMT
C27: 0042 | AS27: 0678 | BD27: =BD24 -> 324916.76 | BR27: C | BS27: G
B28: DESCRIPTION
B29: CURRENT WORKERS COMP AMT
C30: 0044 | AS30: 0830 | BD30: ='1. Summary 2324'!G41 -> 795989.62 | BR30: D | BS30: G
B31: DESCRIPTION
B32: CURRENT WORKERS COMP AMT
C33: 0044 | AS33: 0678 | BD33: =BD30 -> 795989.62 | BR33: C | BS33: G
B34: DESCRIPTION
B35: CURRENT WORKERS COMP AMT
B36: CA503 PC VERSION (7/99)

Sheet TC 35 (5)
B1: STATE CONTROLLER'S USE ONLY | BM1: STATE CONTROLLER'S USE ONLY
B2: DOCUMENT NO. | L2: DATE | T2: MSG Code | V2: STATE OF CALIFORNIA | BM2: TC Code | BO2: PREPARED BY: | BS2: NCACCAM
V3: OFFICE OF THE STATE CONTROLLER
B4: S | BM4: 35
B5: STATE CONTROLLER'S USE ONLY | BF5: 6 | BH5: of | BI5: 10
BR7: DC | BS7: A | BT7: SCO USE | BW7: SOURCE
C8: FUND | J8: AGY | N8: FY | R8: M | S8: REF/ITEM | Y8: RED CAT | AD8: P/N | AF8: C | AG8: CAT | AI8: PGM | AK8: ELE | AM8: COMP | AP8: TASK | AS8: ACCT | AW8: SCO | AX8: REV/OBJ | BD8: AMOUNT | BT8: T | BU8: O | BV8: B | BW8: FUND
B10: DESCRIPTION
B13: DESCRIPTION
C15: 0111 | AS15: 0808 | BD15: ='1. Summary 2324'!G43 -> 10445.355 | BR15: D | BS15: G
B16: DESCRIPTION
B17: CURRENT WORKERS COMP AMT
C18: 0111 | AS18: 0678 | BD18: =BD15 -> 10445.355 | BR18: C | BS18: G
B19: DESCRIPTION
B20: CURRENT WORKERS COMP AMT
C21: 0217 | AS21: 0808 | BD21: ='1. Summary 2324'!G44 -> 10723.658 | BR21: D | BS21: G
B22: DESCRIPTION
B23: CURRENT WORKERS COMP AMT
C24: 0217 | AS24: 0678 | BD24: =BD21 -> 10723.658 | BR24: C | BS24: G
B25: DESCRIPTION
B26: CURRENT WORKERS COMP AMT
C27: 0567 | AS27: 0808 | BD27: ='1. Summary 2324'!G45 -> 0 | BR27: D | BS27: G
B28: DESCRIPTION
B29: CURRENT WORKERS COMP AMT
C30: 0567 | AS30: 0678 | BD30: =BD27 -> 0 | BR30: C | BS30: G
B31: DESCRIPTION
B32: CURRENT WORKERS COMP AMT
C33: 0462 | AS33: 0808 | BD33: ='1. Summary 2324'!G46 -> 2503.8384 | BR33: D | BS33: G
B34: DESCRIPTION
B35: CURRENT WORKERS COMP AMT
B36: CA503 PC VERSION (7/99)

Sheet TC 35 (6)
B1: STATE CONTROLLER'S USE ONLY | BM1: STATE CONTROLLER'S USE ONLY
B2: DOCUMENT NO. | L2: DATE | T2: MSG Code | V2: STATE OF CALIFORNIA | BM2: TC Code | BO2: PREPARED BY: | BS2: NCACCAM
V3: OFFICE OF THE STATE CONTROLLER
B4: S | BM4: 35
B5: STATE CONTROLLER'S USE ONLY | BF5: 7 | BH5: of | BI5: 10
BR7: DC | BS7: A | BT7: SCO USE | BW7: SOURCE
C8: FUND | J8: AGY | N8: FY | R8: M | S8: REF/ITEM | Y8: RED CAT | AD8: P/N | AF8: C | AG8: CAT | AI8: PGM | AK8: ELE | AM8: COMP | AP8: TASK | AS8: ACCT | AW8: SCO | AX8: REV/OBJ | BD8: AMOUNT | BT8: T | BU8: O | BV8: B | BW8: FUND
C9: 0462 | AS9: 0678 | BD9: ='TC 35 (5)'!BD33:BQ33 -> 2503.8384 | BR9: C | BS9: G
B10: DESCRIPTION
B11: CURRENT WORKERS COMP AMT
C12: 0407 | AS12: 0810 | BD12: ='1. Summary 2324'!G47 -> 0 | BR12: D | BS12: G
B13: DESCRIPTION
B14: CURRENT WORKERS COMP AMT
C15: =C12 -> 0407 | AS15: 0678 | BD15: =BD12 -> 0 | BR15: C | BS15: G
B16: DESCRIPTION
B17: CURRENT WORKERS COMP AMT
C18: 0933 | AS18: 0815 | BD18: ='1. Summary 2324'!G48 -> 405.25443 | BR18: D | BS18: G
B19: DESCRIPTION
B20: CURRENT WORKERS COMP AMT
C21: =C18 -> 0933 | AS21: 0678 | BD21: =BD18 -> 405.25443 | BR21: C | BS21: G
B22: DESCRIPTION
B23: CURRENT WORKERS COMP AMT
C24: 0067 | AS24: 0825 | BD24: ='1. Summary 2324'!G49 -> 2519.7332 | BR24: D | BS24: G
B25: DESCRIPTION
B26: CURRENT WORKERS COMP AMT
C27: =C24 -> 0067 | AS27: 0678 | BD27: =BD24 -> 2519.7332 | BR27: C | BS27: G
B28: DESCRIPTION
B29: CURRENT WORKERS COMP AMT
C30: 0317 | AS30: 0825 | BD30: ='1. Summary 2324'!G50 -> 484.99205 | BR30: D | BS30: G
B31: DESCRIPTION
B32: CURRENT WORKERS COMP AMT
C33: =C30 -> 0317 | AS33: 0678 | BD33: =BD30 -> 484.99205 | BR33: C | BS33: G
B34: DESCRIPTION
B35: CURRENT WORKERS COMP AMT
B36: CA503 PC VERSION (7/99)

Sheet TC 35 (7)
B1: STATE CONTROLLER'S USE ONLY | BM1: STATE CONTROLLER'S USE ONLY
B2: DOCUMENT NO. | L2: DATE | T2: MSG Code | V2: STATE OF CALIFORNIA | BM2: TC Code | BO2: PREPARED BY: | BS2: NCACCAM
V3: OFFICE OF THE STATE CONTROLLER
B4: S | BM4: 35
B5: STATE CONTROLLER'S USE ONLY | BF5: 8 | BH5: of | BI5: 10
BR7: DC | BS7: A | BT7: SCO USE | BW7: SOURCE
C8: FUND | J8: AGY | N8: FY | R8: M | S8: REF/ITEM | Y8: RED CAT | AD8: P/N | AF8: C | AG8: CAT | AI8: PGM | AK8: ELE | AM8: COMP | AP8: TASK | AS8: ACCT | AW8: SCO | AX8: REV/OBJ | BD8: AMOUNT | BT8: T | BU8: O | BV8: B | BW8: FUND
C9: 3153 | AS9: 0825 | BD9: ='1. Summary 2324'!G51 -> 80.941962 | BR9: D | BS9: G
B10: DESCRIPTION
B11: CURRENT WORKERS COMP AMT
C12: =C9 -> 3153 | AS12: 0678 | BD12: =BD9 -> 80.941962 | BR12: C | BS12: G
B13: DESCRIPTION
B14: CURRENT WORKERS COMP AMT
C15: 0702 | AS15: 0825 | BD15: ='1. Summary 2324'!G52 -> 12644.035 | BR15: D | BS15: G
B16: DESCRIPTION
B17: CURRENT WORKERS COMP AMT
C18: =C15 -> 0702 | AS18: 0678 | BD18: =BD15 -> 12644.035 | BR18: C | BS18: G
B19: DESCRIPTION
B20: CURRENT WORKERS COMP AMT
C21: 3036 | AS21: 0825 | BD21: ='1. Summary 2324'!G53 -> 4116.8069 | BR21: D | BS21: G
B22: DESCRIPTION
B23: CURRENT WORKERS COMP AMT
C24: =C21 -> 3036 | AS24: 0678 | BD24: =BD21 -> 4116.8069 | BR24: C | BS24: G
B25: DESCRIPTION
B26: CURRENT WORKERS COMP AMT
C27: 0014 | AS27: 0820 | BD27: ='1. Summary 2324'!G54 -> 5582.616 | BR27: D | BS27: G
B28: DESCRIPTION
B29: CURRENT WORKERS COMP AMT
C30: =C27 -> 0014 | AS30: 0678 | BD30: =BD27 -> 5582.616 | BR30: C | BS30: G
B31: DESCRIPTION
B32: CURRENT WORKERS COMP AMT
C33: 3046 | AS33: 0820 | BD33: ='1. Summary 2324'!G55 -> 932.81427 | BR33: D | BS33: G
B34: DESCRIPTION
B35: CURRENT WORKERS COMP AMT
B36: CA503 PC VERSION (7/99)

Sheet TC 35 (8)
B1: STATE CONTROLLER'S USE ONLY | BM1: STATE CONTROLLER'S USE ONLY
B2: DOCUMENT NO. | L2: DATE | T2: MSG Code | V2: STATE OF CALIFORNIA | BM2: TC Code | BO2: PREPARED BY: | BS2: NCACCAM
V3: OFFICE OF THE STATE CONTROLLER
B4: S | BM4: 35 | BQ4: D
B5: STATE CONTROLLER'S USE ONLY | BF5: 9 | BH5: of | BI5: 10
BR7: DC | BS7: A | BT7: SCO USE | BW7: SOURCE
C8: FUND | J8: AGY | N8: FY | R8: M | S8: REF/ITEM | Y8: RED CAT | AD8: P/N | AF8: C | AG8: CAT | AI8: PGM | AK8: ELE | AM8: COMP | AP8: TASK | AS8: ACCT | AW8: SCO | AX8: REV/OBJ | BD8: AMOUNT | BT8: T | BU8: O | BV8: B | BW8: FUND
C9: 3046 | AS9: 0678 | BD9: ='TC 35 (7)'!BD33:BQ33 -> 932.81427 | BR9: C | BS9: G
B10: DESCRIPTION
B11: CURRENT WORKERS COMP AMT
C12: 0140 | AS12: 0820 | BD12: ='1. Summary 2324'!G56 -> 111.67591 | BR12: D | BS12: G
B13: DESCRIPTION
B14: CURRENT WORKERS COMP AMT
C15: =C12 -> 0140 | AS15: 0678 | BD15: =BD12 -> 111.67591 | BR15: C | BS15: G
B16: DESCRIPTION
B17: CURRENT WORKERS COMP AMT
C18: 0200 | AS18: 0820 | BD18: ='1. Summary 2324'!G57 -> 25907.333 | BR18: D | BS18: G
B19: DESCRIPTION
B20: CURRENT WORKERS COMP AMT
C21: =C18 -> 0200 | AS21: 0678 | BD21: =BD18 -> 25907.333 | BR21: C | BS21: G
B22: DESCRIPTION
B23: CURRENT WORKERS COMP AMT
C24: 3211 | AS24: 0820 | BD24: ='1. Summary 2324'!G58 -> 458.60612 | BR24: D | BS24: G
B25: DESCRIPTION
B26: CURRENT WORKERS COMP AMT
C27: =C24 -> 3211 | AS27: 0678 | BD27: =BD24 -> 458.60612 | BR27: C | BS27: G
B28: DESCRIPTION
B29: CURRENT WORKERS COMP AMT
C30: 0387 | AS30: 0820 | BD30: ='1. Summary 2324'!G59 -> 2869.7036 | BR30: D | BS30: G
B31: DESCRIPTION
B32: CURRENT WORKERS COMP AMT
C33: =C30 -> 0387 | AS33: 0678 | BD33: =BD30 -> 2869.7036 | BR33: C | BS33: G
B34: DESCRIPTION
B35: CURRENT WORKERS COMP AMT
B36: CA503 PC VERSION (7/99)

Sheet TC 35 (9)
B1: STATE CONTROLLER'S USE ONLY | BM1: STATE CONTROLLER'S USE ONLY
B2: DOCUMENT NO. | L2: DATE | T2: MSG Code | V2: STATE OF CALIFORNIA | BM2: TC Code | BO2: PREPARED BY: | BS2: NCACCAM
V3: OFFICE OF THE STATE CONTROLLER
B4: S | BM4: 35
B5: STATE CONTROLLER'S USE ONLY | BF5: 10 | BH5: of | BI5: 10
BR7: DC | BS7: A | BT7: SCO USE | BW7: SOURCE
C8: FUND | J8: AGY | N8: FY | R8: M | S8: REF/ITEM | Y8: RED CAT | AD8: P/N | AF8: C | AG8: CAT | AI8: PGM | AK8: ELE | AM8: COMP | AP8: TASK | AS8: ACCT | AW8: SCO | AX8: REV/OBJ | BD8: AMOUNT | BT8: T | BU8: O | BV8: B | BW8: FUND
C9: 0439 | AS9: 0820 | BD9: ='1. Summary 2324'!G60 -> 4171.5344 | BR9: D | BS9: G
B10: DESCRIPTION
B11: CURRENT WORKERS COMP AMT
C12: =C9 -> 0439 | AS12: 0678 | BD12: =BD9 -> 4171.5344 | BR12: C | BS12: G
B13: DESCRIPTION
B14: CURRENT WORKERS COMP AMT
C15: 0565001 | AS15: 0820 | BD15: ='1. Summary 2324'!G61 -> 0 | BR15: D | BS15: G
B16: DESCRIPTION
B17: CURRENT WORKERS COMP AMT
C18: 0565001 | AS18: 0678 | BD18: =BD15 -> 0 | BR18: C | BS18: G
B19: DESCRIPTION
B20: CURRENT WORKERS COMP AMT
C21: 0929 | AS21: 0825 | BD21: ='1. Summary 2324'!G62 -> 1295.622 | BR21: D | BS21: G
B22: DESCRIPTION
B23: CURRENT WORKERS COMP AMT
C24: 0929 | AS24: 0678 | BD24: =BD21 -> 1295.622 | BR24: C | BS24: G
B25: DESCRIPTION
B26: CURRENT WORKERS COMP AMT
C27: 0639 | AS27: 0815 | BD27: ='1. Summary 2324'!G63 -> 0 | BR27: D | BS27: G
B28: DESCRIPTION
B29: CURRENT WORKERS COMP AMT
C30: 0639 | AS30: 0678 | BD30: =BD27 -> 0 | BR30: C | BS30: G
B31: DESCRIPTION
B32: CURRENT WORKERS COMP AMT
C33: 0121 | AS33: 0815 | BD33: ='1. Summary 2324'!G64 -> 777.81924 | BR33: D | BS33: G
B34: DESCRIPTION
B35: CURRENT WORKERS COMP AMT
B36: CA503 PC VERSION (7/99)

Sheet TC 35 (10)
B1: STATE CONTROLLER'S USE ONLY | BM1: STATE CONTROLLER'S USE ONLY
B2: DOCUMENT NO. | L2: DATE | T2: MSG Code | V2: STATE OF CALIFORNIA | BM2: TC Code | BO2: PREPARED BY: | BS2: NCACCAM
V3: OFFICE OF THE STATE CONTROLLER
B4: S | BM4: 35
B5: STATE CONTROLLER'S USE ONLY | BF5: 11 | BH5: of | BI5: 11
BR7: DC | BS7: A | BT7: SCO USE | BW7: SOURCE
C8: FUND | J8: AGY | N8: FY | R8: M | S8: REF/ITEM | Y8: RED CAT | AD8: P/N | AF8: C | AG8: CAT | AI8: PGM | AK8: ELE | AM8: COMP | AP8: TASK | AS8: ACCT | AW8: SCO | AX8: REV/OBJ | BD8: AMOUNT | BT8: T | BU8: O | BV8: B | BW8: FUND
C9: 0121 | AS9: 0678 | BD9: ='TC 35 (9)'!BD33:BQ33 -> 777.81924 | BR9: C | BS9: G
B10: DESCRIPTION
B11: CURRENT WORKERS COMP AMT
C12: 0223 | AS12: 0815 | BD12: ='1. Summary 2324'!G65 -> 57756.943 | BR12: D | BS12: G
B13: DESCRIPTION
B14: CURRENT WORKERS COMP AMT
C15: =C12 -> 0223 | AS15: 0678 | BD15: =BD12 -> 57756.943 | BR15: C | BS15: G
B16: DESCRIPTION
B17: CURRENT WORKERS COMP AMT
C18: 0318 | AS18: 0820 | BD18: ='1. Summary 2324'!G66 -> 25627.447 | BR18: D | BS18: G
B19: DESCRIPTION
B20: CURRENT WORKERS COMP AMT
C21: =C18 -> 0318 | AS21: 0678 | BD21: =BD18 -> 25627.447 | BR21: C | BS21: G
B22: DESCRIPTION
B23: CURRENT WORKERS COMP AMT
C24: 0064 | AS24: 0830 | BD24: ='1. Summary 2324'!G42 -> 157496.76 | BR24: D | BS24: G
B26: CURRENT WORKERS COMP AMT
C27: 0064 | AS27: 0678 | BD27: =BD24 -> 157496.76 | BR27: C | BS27: G
B29: CURRENT WORKERS COMP AMT
B36: CA503 PC VERSION (7/99)

Sheet TC 35 0890 Entry
B1: STATE CONTROLLER'S USE ONLY | BM1: STATE CONTROLLER'S USE ONLY
B2: DOCUMENT NO. | L2: DATE | T2: MSG Code | V2: STATE OF CALIFORNIA | BM2: TC Code | BO2: PREPARED BY: | BS2: NCACCAM
V3: OFFICE OF THE STATE CONTROLLER
B4: S | BM4: 35
