Workbook
Name ActuaryCredentialsGASB: [1]DeveloperInfo!$D$19
Name ActuaryNameGASB: [1]DeveloperInfo!$D$17
Name ActuaryTitleGASB: [1]DeveloperInfo!$D$18
Name AdjCNSDate: [1]DeveloperInfo!$D$33
Name AdjCNSDate1: [1]DeveloperInfo!$E$33
Name AdjCNSDateTempEnable: [1]DeveloperInfo!$F$34
Name AgencyCode: #REF!
Name AgencyCode: #REF!
Name AgencyCode: #REF!
Name AgencyCode: #REF!
Name AgencyCode1: #REF!
Name AgencyCode1: #REF!
Name AgencyCode1: #REF!
Name AgencyCode1: #REF!
Name AnalystGASB: [1]DeveloperInfo!$D$20
Name Annuity: #REF!
Name Annuity: #REF!
Name Annuity: #REF!
Name Annuity: #REF!
Name Annuity1: #REF!
Name Annuity1: #REF!
Name Annuity1: #REF!
Name Annuity1: #REF!
Name AnnuityLY: #REF!
Name AnnuityLY: #REF!
Name AnnuityLY: #REF!
Name AnnuityLY: #REF!
Name ASTABPF: [1]DeveloperInfo!$D$36
Name ASTABPF1: [1]DeveloperInfo!$D$37
Name ASTEBPF: [1]DeveloperInfo!$F$37
Name ClientShortGASB: [1]DeveloperInfo!$D$9
Name CLPOWERDisc: [1]Adjust!$H$199
Name CLPOWERDiscMinus1: [1]Adjust!$L$199
Name CLPOWERDiscPlus1: [1]Adjust!$K$199
Name CLPOWERExp: [1]Adjust!$G$199
Name CNSDateDisc: [1]DeveloperInfo!$D$32
Name CNSDateDisc1: [1]DeveloperInfo!$E$32
Name ColaRate: [1]DeveloperInfo!$D$40
Name ConsultantNameGASB: [1]DeveloperInfo!$D$22
Name ConsultantTitleGASB: [1]DeveloperInfo!$D$23
Name Disc1DELTACENSUS: [1]Adjust!$G$102
Name Disc1INTNDIV12: [1]Adjust!$H$195
Name Disc1SINTADJBOM: [1]Adjust!$I$197
Name Disc1SINTNDIV12: [1]Adjust!$I$195
Name DiscDELTACENSUS: [1]Adjust!$H$102
Name DiscINTADJBOM: [1]Adjust!$J$197
Name DiscINTNDIV12: [1]Adjust!$J$195
Name DiscMinusOneINTADJBOM: [1]Adjust!$L$197
Name DiscMinusOneINTNDIV12: [1]Adjust!$L$195
Name DiscPlusOneINTADJBOM: [1]Adjust!$K$197
Name DiscPlusOneINTNDIV12: [1]Adjust!$K$195
Name EmployerRates: #REF!
Name EmployerRates: #REF!
Name EmployerRates: #REF!
Name EmployerRates: #REF!
Name EmployerRates1: #REF!
Name EmployerRates1: #REF!
Name EmployerRates1: #REF!
Name EmployerRates1: #REF!
Name EmployerRatesLEO: #REF!

Sheet Drop Down Menus
A1: 2021–2022 | B1: Governmental | C1: FI$Cal | D1: Yes | E1: Governmental Fund | G1: Please select fund type above.
A2: 2022–2023 | B2: Proprietary | C2: Non-FI$Cal | D2: No | E2: Proprietary - Internal Service Fund | F2: General government | G2: Cr: Acct 0808 - GENERAL GOV. (GAAP ADJ) | H2: Dr: Acct 0808 - GENERAL GOV. (GAAP ADJ)
A3: 2023–2024 | E3: Proprietary - Enterprise Fund | F3: Education | G3: Cr: Acct 0810 - EDUCATION EXP (GAAP ADJ) | H3: Dr: Acct 0810 - EDUCATION EXP (GAAP ADJ)
A4: 2024–2025 | F4: Health and human services | G4: Cr: Acct 0815 - HLTH&HUM SV SV.LAB(GAAP ADJ) | H4: Dr: Acct 0815 - HLTH&HUM SV SV.LAB(GAAP ADJ)
A5: 2025–2026 | F5: Resources | G5: Cr: Acct 0820 - NAT RES & ENVIRON (GAAP ADJ) | H5: Dr: Acct 0820 - NAT RES & ENVIRON (GAAP ADJ)
A6: 2026–2027 | F6: BUS, CONSUMER SERV, HOUSING | G6: Cr: Acct 0825 - BUS, CONSUMER SERV, HOUSING | H6: Dr: Acct 0825 - BUS, CONSUMER SERV, HOUSING
A7: 2027–2028 | F7: Transportation | G7: Cr: Acct 0830 - TRANSPORTATION (GAAP ADJ) | H7: Dr: Acct 0830 - TRANSPORTATION (GAAP ADJ)
A8: 2028–2029 | F8: CORRECTIONS AND REHABILITATION | G8: Cr: Acct 0835 - CORRECTIONS AND REHABILITATION | H8: Dr: Acct 0835 - CORRECTIONS AND REHABILITATION
A9: 2029–2030 | F9: Proprietary fund | G9: Cr: Acct 0870 - SERVICES & CHARGES (MG ADJ) | H9: Dr: Acct 0870 - SERVICES & CHARGES (MG ADJ)
A10: 2030–2031 | F10: Unidentified | G10: Cr: Acct 0XXX - FUNCTIONAL EXPENSE | H10: Dr: Acct 0XXX - FUNCTIONAL EXPENSE
A11: 2031–2032
A12: 2032–2033
A13: 2033–2034
A14: 2034–2035
A15: 2035–2036
A16: 2036–2037
A17: 2037–2038
A18: 2038–2039
A19: 2039–2040
A20: 2040–2041
A21: 2041–2042
A22: 2042–2043
... A101: 2121–2122

Sheet qryIndex02a
A1: Agency | B1: Title | C1: Hier1 | D1: Desc1 | E1: Desc2 | F1: Hier2 | G1: Hier3 | H1: Hier4 | I1: Hier5 | J1: EffectiveDate | K1: CancelDate
A2: 0000 | B2: BOND INTEREST AND REDEMPTION | C2: 9000 | D2: BOND INTEREST AND REDEMPTION | F2: 9030 | G2: 9600 | H2: 0000 | I2: 0000 | J2: 04/04/1984 | K2: 00/00/0000
A3: 0010 | B3: LEGISLATIVE, JUDICIAL AND EXEC | C3: 0808 | D3: GENERAL GOVERNMENT | F3: 0000 | G3: 0000 | H3: 0000 | I3: 0000 | J3: 07/11/2006 | K3: 00/00/0000
A4: 0015 | B4: ADD AGENCY TEST | C4: 0808 | D4: GENERAL GOVERNMENT | F4: 0000 | G4: 0000 | H4: 0000 | I4: 0000 | J4: 99/99/9999 | K4: 00/00/0000
A5: 0020 | B5: LEGISLATIVE | C5: 0808 | D5: GENERAL GOVERNMENT | F5: 0000 | G5: 0000 | H5: 0000 | I5: 0000 | J5: 99/99/9999 | K5: 00/00/0000
A6: 0100 | B6: LEGISLATURE | C6: 0808 | D6: GENERAL GOVERNMENT | F6: 0000 | G6: 0000 | H6: 0000 | I6: 0000 | J6: 99/99/9999 | K6: 00/00/0000
A7: 0110 | B7: SENATE | C7: 0808 | D7: GENERAL GOVERNMENT | F7: 0000 | G7: 0000 | H7: 0000 | I7: 0000 | J7: 06/26/1985 | K7: 00/00/0000
A8: 0120 | B8: ASSEMBLY | C8: 0808 | D8: GENERAL GOVERNMENT | F8: 0000 | G8: 0000 | H8: 0000 | I8: 0000 | J8: 06/26/1985 | K8: 00/00/0000
A9: 0130 | B9: LEGISLATIVE JOINT EXPENSES | C9: 0808 | D9: GENERAL GOVERNMENT | F9: 0000 | G9: 0000 | H9: 0000 | I9: 0000 | J9: 06/26/1985 | K9: 00/00/0000
A10: 0150 | B10: CONTRIB TO LEGIS RETIRE FUND | C10: 0808 | D10: GENERAL GOVERNMENT | F10: 0000 | G10: 0000 | H10: 0000 | I10: 0000 | J10: 07/11/2006 | K10: 00/00/0000
A11: 0155 | B11: AUDITOR GENERAL OFFICE | C11: 0808 | D11: GENERAL GOVERNMENT | F11: 0000 | G11: 0000 | H11: 0000 | I11: 0000 | J11: 99/99/9999 | K11: 00/00/0000
A12: 0160 | B12: LEGISLATIVE COUNSEL BUREAU | C12: 0808 | D12: GENERAL GOVERNMENT | F12: 0000 | G12: 0000 | H12: 0000 | I12: 0000 | J12: 04/04/1984 | K12: 00/00/0000
A13: 0170 | B13: CA LAW REVISION COMMISSION | C13: 0808 | D13: GENERAL GOVERNMENT | F13: 0000 | G13: 0000 | H13: 0000 | I13: 0000 | J13: 99/99/9999 | K13: 07/01/1985
... A190: 2140 | B190: STATE BANKING DEPARTMENT | C190: 0825 | D190: BUS, CONSUMER SERV, HOUSING | F190: 0000 | G190: 0000 | H190: 0000 | I190: 0000 | J190: 12/21/2016 | K190: 00/00/0000
A191: 2150 | B191: FINANCIAL INSTITUTIONS | C191: 0825 | D191: ADD BACK TO POST PY REVERSAL | E191: DELETE 16/17 | F191: 0000 | G191: 0000 | H191: 0000 | I191: 0000 | J191: 08/18/2016 | K191: 00/00/0000
A192: 2180 | B192: DEPART OF CORPORATIONS | C192: 0825 | D192: ADD BACK TO POST PY REVERSAL | E192: DELETE 16/17 | F192: 0000 | G192: 0000 | H192: 0000 | I192: 0000 | J192: 08/24/2016 | K192: 00/00/0000
A193: 2190 | B193: MAJOR MEDICAL INSURANCE BOARD | C193: 0825 | D193: BUS, CONSUMER SERV, HOUSING | F193: 0000 | G193: 0000 | H193: 0000 | I193: 0000 | J193: 12/21/2016 | K193: 00/00/0000
A194: 2200 | B194: DEPARTMENT OF COMMERCE | C194: 0825 | D194: BUS, CONSUMER SERV, HOUSING | F194: 0000 | G194: 0000 | H194: 0000 | I194: 0000 | J194: 12/21/2016 | K194: 00/00/0000
A195: 2220 | B195: OFFICE OF SMALL BUSINESS DEVEL | C195: 0825 | D195: BUS, CONSUMER SERV, HOUSING | F195: 0000 | G195: 0000 | H195: 0000 | I195: 0000 | J195: 12/21/2016 | K195: 00/00/0000
A196: 2222 | B196: ST ASST FD FOR ENTERPRISE | C196: 0825 | D196: BUS, CONSUMER SERV, HOUSING | F196: 0000 | G196: 0000 | H196: 0000 | I196: 0000 | J196: 12/21/2016 | K196: 00/00/0000
A197: 2225 | B197: UNITARY FUND PROGRAMS | C197: 0825 | D197: BUS, CONSUMER SERV, HOUSING | F197: 0000 | G197: 0000 | H197: 0000 | I197: 0000 | J197: 12/21/2016 | K197: 00/00/0000
A198: 2230 | B198: CA INDTRL DEV FINCL ADVRY COMM | C198: 0825 | D198: BUS, CONSUMER SERV, HOUSING | F198: 0000 | G198: 0000 | H198: 0000 | I198: 0000 | J198: 12/21/2016 | K198: 07/01/1985
A199: 2235 | B199: CA HOME LOAN MORTGAGE ASSN | C199: 0825 | D199: BUS, CONSUMER SERV, HOUSING | F199: 0000 | G199: 0000 | H199: 0000 | I199: 0000 | J199: 12/21/2016 | K199: 00/00/0000
A200: 2240 | B200: DEPT-HOUSING/COMMUNITY DEVEL | C200: 0825 | D200: BUS, CONSUMER SERV, HOUSING | F200: 0000 | G200: 0000 | H200: 0000 | I200: 0000 | J200: 12/12/2016 | K200: 00/00/1999
A201: 2245 | B201: CALIFORNIA HOUSING FINANCE AGY | C201: 0825 | D201: BUS, CONSUMER SERV, HOUSING | F201: 0000 | G201: 0000 | H201: 0000 | I201: 0000 | J201: 08/19/2016 | K201: 00/00/0000
A202: 2265 | B202: CALIFORNIA HOUSING INSURANCE | C202: 0825 | D202: BUS, CONSUMER SERV, HOUSING | F202: 0000 | G202: 0000 | H202: 0000 | I202: 0000 | J202: 12/21/2016 | K202: 00/00/0000
A203: 2270 | B203: MORTGAGE BOND ALLOC COMMITTEE | C203: 0825 | D203: BUS, CONSUMER SERV, HOUSING | F203: 0000 | G203: 0000 | H203: 0000 | I203: 0000 | J203: 12/21/2016 | K203: 07/01/1985
A204: 2290 | B204: DEPARTMENT OF INSURANCE | C204: 0825 | D204: BUS, CONSUMER SERV, HOUSING | F204: 0000 | G204: 0000 | H204: 0000 | I204: 0000 | J204: 12/21/2016 | K204: 00/00/1999
... A214: 2670 | B214: BD OF PILOT COMMISSIONERS-SF | C214: 0830 | D214: TRANSPORTATION | F214: 0000 | G214: 0000 | H214: 0000 | I214: 0000 | J214: 08/03/2017 | K214: 00/00/0000
A215: 2700 | B215: OFFICE OF TRAFFIC SAFETY | C215: 0830 | D215: TRANSPORTATION | E215: MERGED W/0521-ADD 4 PY ACCR RV | F215: 0000 | G215: 0000 | H215: 0000 | I215: 0000 | J215: 09/28/2016 | K215: 00/00/0000
A216: 2720 | B216: DEPT OF CAL HIGHWAY PATROL | C216: 0830 | D216: TRANSPORTATION | F216: 0000 | G216: 0000 | H216: 0000 | I216: 0000 | J216: 10/28/2016 | K216: 00/00/1999
A217: 2740 | B217: DEPARTMENT OF MOTOR VEHICLES | C217: 0830 | D217: TRANSPORTATION | F217: 0000 | G217: 0000 | H217: 0000 | I217: 0000 | J217: 10/28/2016 | K217: 00/00/0000
A218: 2780 | B218: STEPHEN P TEALE DATA CENTER | C218: 0825 | D218: BUS, CONSUMER SERV, HOUSING | F218: 0000 | G218: 0000 | H218: 0000 | I218: 0000 | J218: 12/21/2016 | K218: 00/00/0000
A219: 2900 | B219: TRADE AND COMMERCE | C219: 0825 | D219: BUS, CONSUMER SERV, HOUSING | F219: 0000 | G219: 0000 | H219: 0000 | I219: 0000 | J219: 12/21/2016 | K219: 00/00/0000
A220: 2920 | B220: TECHNOLOGY TRADE & COMMERCE AG | C220: 0825 | D220: BUS, CONSUMER SERV, HOUSING | F220: 0000 | G220: 0000 | H220: 0000 | I220: 0000 | J220: 12/21/2016 | K220: 00/00/0000
A221: 3000 | B221: NATURAL RESOURCES | C221: 0820 | D221: RESOURCES | F221: 0000 | G221: 0000 | H221: 0000 | I221: 0000 | J221: 08/25/2010 | K221: 00/00/0000
A222: 3100 | B222: EXPOSITION PARK | C222: 0820 | D222: RESOURCES | F222: 0000 | G222: 0000 | H222: 0000 | I222: 0000 | J222: 10/17/2018 | K222: 00/00/0000
A223: 3105 | B223: CALIFORNIA AFRO-AMERICAN MUSEU | C223: 0820 | D223: RESOURCES | F223: 0000 | G223: 0000 | H223: 0000 | I223: 0000 | J223: 09/05/2014 | K223: 00/00/0000
A224: 3110 | B224: SPECIAL RESOURCES PROGRAMS | C224: 0820 | D224: RESOURCES | F224: 0000 | G224: 0000 | H224: 0000 | I224: 0000 | J224: 07/11/2006 | K224: 00/00/1999
A225: 3125 | B225: CALIF TAHOE CONSERVANCY | C225: 0820 | D225: RESOURCES | F225: 0000 | G225: 0000 | H225: 0000 | I225: 0000 | J225: 04/18/1988 | K225: 00/00/1999
...

Sheet LS-Version Changes
A1: This sheet details the changes made between version 2 and version 3 of the GASB 87 Lessee Annual Reporting Submission Workbook. Familiarize yourself with the changes in the table below and follow the instructions for updating data from template version 2 to version 3.
A4: Version 2 | B4: Published on SCO website in March 2024 for use for reporting periods 2022-2023 and afterwards.
A5: Version 3 | B5: Published on SCO website in October 2024 for use for reporting periods 2023-2024 and afterwards.
A7: The GASB 87 Annual Reporting Submission Workbook is required to be updated and submitted every year. See below for the summary of changes between versions.
A9: Summary of Changes
A10: Sheet | B10: Feature | C10: Location V2 | D10: Location V3 | E10: Description | F10: Required Action
A11: LS-Fund #### Journal Entries | B11: "Difference" Guidance | C11: N/A | D11: T15-T25 | E11: Wording was added in column T to describe what type of action needs to be taken for the "Differences" in Entry #0. | F11: Clarification only. Follow the guidance in column T.
A12: LS-Fund #### Journal Entries | B12: Highlighted Errors | C12: Multiple | D12: Multiple | E12: Errors such as "Debits and Credits do not equal each other" and "Accts 0848 must agree" will populate in bold and be highlighted to assist with the identification of errors. | F12: Clarification only. Resolve all errors before submitting.
A13: LS-Department Note Disclosure | B13: Reminder - No Decimals. | C13: A11, A42, A73 | D13: A11, A42, A73 | E13: Added additional wording to remind users not to enter decimals into the payment and interest table. | F13: Clarification only. Do not enter decimals.
A14: LS-Department Note Disclosure | B14: Question 4 | C14: D29, D60, D91 | D14: D29, D60, D91 | E14: Removed dropdown menu to allow amounts to be entered in the cells in response to Question 4. | F14: Clarification only.
A15: LS-Lease Liabilities | B15: Reminder - Acct 0691 Only | C15: N/A | D15: B22 | E15: Added additional wording to remind users that the Schedule of Changes in Lease Liabilities is for Account 0691 only, and therefore will differ from the Report 18. | F15: Clarification only.
A16: LS-Lease Liabilities | B16: Linked Values | C16: Multiple | D16: Multiple | E16: Linked values to the LS-Fund #### Journal Entries worksheet. Per line 23, if multiple funds are present in the workbook, the department will need to override the formulas in yellow to capture the activity in all funds. | F16: No action required if the workbook only contains one fund. If the workbook contains multiple funds, override the formulas in yellow.

Sheet LS-Fund #### Journal Entries
A1: Lessee-Type Contracts Fund-by-Fund Journal Entries Form (to be submitted to the SCO annually—one form per fund)
A2: Manually complete every yellow field in this worksheet—there are no automatically calculated data-entry cells in this worksheet.
A3: Fiscal Year: | F3: 2023–2024
A4: Organization Name:
A5: Organization Code (4-Digits):
A6: Fund Number (4-Digits):
A7: Fund Classification:
A8: Fund Type:
A9: Functional Expense: | F9: =IFERROR(IF(F7="Proprietary","Proprietary Fund",VLOOKUP(F5,qryIndex02a!$A$2:$K$654,4,FALSE)),"Unidentified") -> Unidentified
A12: Establish Beginning Balances (existing leases only)
A13: Entry #
A14: 0 | B14: Roll forward prior year right-to-use leases to record opening balances. | M14: Combined Lessee Templates | P14: From SCO BB List | S14: Difference
A15: *Rpt 18 | B15: Dr: Acct 0476 - RIGHT-TO-USE LEASED LAND - AMORTIZABLE | J15: =M15 -> 0 | S15: =P15-M15 -> 0 | T15: Report any "Differences" on the Report 18 Differential.
A16: *Rpt 18 | B16: Dr: Acct 0478 - RIGHT-TO-USE LEASED EQUIPMENT - AMORTIZABLE | J16: =M16 -> 0 | S16: =P16-M16 -> 0 | T16: Report any "Differences" on the Report 18 Differential.
A17: *Rpt 18 | B17: Dr: Acct 0477 - RIGHT-TO-USE LEASED BUILDINGS - AMORTIZABLE | J17: =M17 -> 0 | S17: =P17-M17 -> 0 | T17: Report any "Differences" on the Report 18 Differential.
B18: Dr: Acct 0950 - BEGINNING FUND BALANCE | J18: =P18 -> 0 | P18: =IF(SUM($Q$20:$Q$23)>SUM($P$15:$P$17),SUM($Q$20:$Q$23)-SUM($P$15:$P$17),0) -> 0 | S18: =P18-M18 -> 0 | T18: No action required.
B19: Dr: Acct 0952 - BEGINNING FUND ADJUSTMENT/PRIOR PERIOD ADJUSTMENT | J19: =IF(SUM($K$20:$K$24)>SUM($J$15:$J$18),SUM($K$20:$K$24)-SUM($J$15:$J$18),0) -> 0 | S19: =P19-M19 -> 0 | T19: No action required.
C20: Cr: Acct 0485 - ACCUMULATED AMORTIZATION - RIGHT-TO-USE LEASED LAND | K20: =N20 -> 0 | S20: =Q20-N20 -> 0 | T20: No action required.
C21: Cr: Acct 0479 - ACCUMULATED AMORTIZATION - RIGHT-TO-USE LEASED EQUIPMENT | K21: =N21 -> 0 | S21: =Q21-N21 -> 0 | T21: No action required.
C22: Cr: Acct 0486 - ACCUMULATED AMORTIZATION - RIGHT-TO-USE LEASED BUILDINGS | K22: =N22 -> 0 | S22: =Q22-N22 -> 0 | T22: No action required.
A23: **LS LL/CF | C23: Cr: Acct 0691 - RIGHT-TO-USE LEASE LIABILITY | K23: =N23 -> 0 | S23: =Q23-N23 -> 0 | T23: No action required.
C24: Cr: Acct 0950 - BEGINNING FUND BALANCE | K24: =Q24 -> 0 | Q24: =IF(SUM($Q$20:$Q$23)<SUM($P$15:$P$17),-SUM($Q$20:$Q$23)+SUM($P$15:$P$17),0) -> 0 | S24: =Q24-N24 -> 0 | T24: No action required.
C25: Cr: Acct 0952 - BEGINNING FUND ADJUSTMENT/PRIOR PERIOD ADJUSTMENT | K25: =IF(SUM($K$20:$K$24)<SUM($J$15:$J$18),-SUM($K$20:$K$24)+SUM($J$15:$J$18),0) -> 0 | S25: =Q25-N25 -> 0 | T25: No action required.
J26: =SUM(J15:J25) -> 0 | K26: =SUM(K15:K25) -> 0 | L26: =IF(J26=K26,"<- Debits and Credits equal each other.","<- Debits and Credits do not equal each other.") -> <- Debits and Credits equal each other.
B27: * THESE ASSET AMOUNTS SHOULD BE REPORTED AS BEGINNING BALANCES ON REPORT 18.
B28: ** This amount should be included in the beginning balance column on the LS-Lease Liability and LS-Check Figures Tabs.
A31: Record New Leases (new leases only)
A32: 1 | B32: Record lease contract commencement (fund-based entries only)
B33: Dr: Acct 0842 - CAPITAL OUTLAY
C34: Cr: Acct 0789 - LEASE AND OTHER FINANCING PROCEEDS
C35: =IF($F$7="Proprietary","Cr: Acct 0870 - SERVICES & CHARGES (MG ADJ)",VLOOKUP($F$9,'Drop Down Menus'!$F$2:$G$10,2,FALSE)) -> Cr: Acct 0XXX - FUNCTIONAL EXPENSE
J36: =SUM(J33:J35) -> 0 | K36: =SUM(K33:K35) -> 0 | L36: =IF(J36=K36,"<- Debits and Credits equal each other.","<- Debits and Credits do not equal each other.") -> <- Debits and Credits equal each other.
A38: 2 | B38: Record leased assets.
A39: *Rpt 18 | B39: Dr: Acct 0476 - RIGHT-TO-USE LEASED LAND - AMORTIZABLE
A40: *Rpt 18 | B40: Dr: Acct 0478 - RIGHT-TO-USE LEASED EQUIPMENT - AMORTIZABLE
A41: *Rpt 18 | B41: Dr: Acct 0477 - RIGHT-TO-USE LEASED BUILDINGS - AMORTIZABLE
C42: Cr: Acct 0842 - CAPITAL OUTLAY
B43: * THESE AMOUNTS SHOULD BE INCLUDED AS "ADDITIONS" ON REPORT 18. | J43: =SUM(J39:J42) -> 0 | K43: =SUM(K39:K42) -> 0 | L43: =IF(J43=K43,"<- Debits and Credits equal each other.","<- Debits and Credits do not equal each other.") -> <- Debits and Credits equal each other.
A46: 3 | B46: Replace proceeds from leases with right-to-use lease liability.
B47: Dr: Acct 0789 - LEASE AND OTHER FINANCING PROCEEDS
...

Sheet LS-Department Note Disclosure
A1: Submit one form for the department to the SCO annually.
A2: Note: There are three tables of note disclosures on this form —1) governmental funds, 2) proprietary - internal service funds, and 3) proprietary - enterprise funds. Complete all applicable tables before submitting to the SCO.
A3: Manually complete every yellow field in this worksheet—there are no automatically calculated cells in this worksheet.
A4: Complete the fields below using aggregated and summarized information from all of your department's completed contract template forms.
A5: The fields in this worksheet should contain the sums of the department's contracts' corresponding information in their note disclosure worksheets.
A7: I. Governmental funds
A8: Fiscal Year: | B8: 2023–2024
A9: Organization Code:
A10: Organization Name:
A11: The below information must be entered manually. DO NOT ENTER DECIMALS. PLEASE ROUND TO THE NEAREST DOLLAR.
B12: Principal Payments | C12: Interest Payments | D12: ="All of the below questions are for Fiscal Year "&$B$8&":" -> All of the below questions are for Fiscal Year 2023–2024:
A13: =RIGHT(B8,4)&"–"&RIGHT(B8,4)+1 -> 2024–2025 | D13: 1. Did your leasing arrangements have any variable payments which ARE NOT included in the measurement of the lease liability?
A14: =LEFT(A13,4)+1&"–"&RIGHT(A13,4)+1 -> 2025–2026
A15: =LEFT(A14,4)+1&"–"&RIGHT(A14,4)+1 -> 2026–2027
A16: =LEFT(A15,4)+1&"–"&RIGHT(A15,4)+1 -> 2027–2028 | D16: ="If yes, record the dollar amount of variable payments below for fiscal year "&$B$8&":" -> If yes, record the dollar amount of variable payments below for fiscal year 2023–2024:
A17: =LEFT(A16,4)+1&"–"&RIGHT(A16,4)+1 -> 2028–2029
A18: =LEFT(A17,4)+1&"–"&RIGHT(A17,4)+5 -> 2029–2034 | D18: 2. Do your leasing arrangements have any residual value guarantees provided by YOU which ARE NOT included in the measurement of the lease liability?
A19: =LEFT(A18,4)+5&"–"&RIGHT(A18,4)+5 -> 2034–2039
A20: =LEFT(A19,4)+5&"–"&RIGHT(A19,4)+5 -> 2039–2044
A21: =LEFT(A20,4)+5&"–"&RIGHT(A20,4)+5 -> 2044–2049 | D21: ="If yes, record the dollar amount of any payments made for residual value guarantees below for fiscal year "&$B$8&":" -> If yes, record the dollar amount of any payments made for residual value guarantees below for fiscal year 2023–2024:
A22: =LEFT(A21,4)+5&"–"&RIGHT(A21,4)+5 -> 2049–2054
A23: =LEFT(A22,4)+5&"–"&RIGHT(A22,4)+5 -> 2054–2059
A24: =LEFT(A23,4)+5&"–"&RIGHT(A23,4)+5 -> 2059–2064 | D24: ="3. Record the dollar amount of any other payments for this lease, such as termination penalties, not previously recorded in the payment schedule for fiscal year "&$B$8&":" -> 3. Record the dollar amount of any other payments for this lease, such as termination penalties, not previously recorded in the payment schedule for fiscal year 2023–2024:
A25: =LEFT(A24,4)+5&"–"&RIGHT(A24,4)+5 -> 2064–2069
A26: =LEFT(A25,4)+5&"–"&RIGHT(A25,4)+5 -> 2069–2074
A27: =LEFT(A26,4)+5&"–"&RIGHT(A26,4)+5 -> 2074–2079 | D27: ="4. Did you receive any lease incentives from the lessor (not already included in the lease measurment) during fiscal year "&$B$8&"? If so, record the amount below:" -> 4. Did you receive any lease incentives from the lessor (not already included in the lease measurment) during fiscal year 2023–2024? If so, record the amount below:
A28: =LEFT(A27,4)+5&"–"&RIGHT(A27,4)+5 -> 2079–2084
A29: =LEFT(A28,4)+5&"–"&RIGHT(A28,4)+5 -> 2084–2089
A30: =LEFT(A29,4)+5&"–"&RIGHT(A29,4)+5 -> 2089–2094 | D30: =CONCATENATE("5. Are there any lease commitments known that have yet to commence as of June 30, ",RIGHT(B8,4),"?") -> 5. Are there any lease commitments known that have yet to commence as of June 30, 2024?
A31: =LEFT(A30,4)+5&"–"&RIGHT(A30,4)+5 -> 2094–2099
A32: =LEFT(A31,4)+5&"–"&RIGHT(A31,4)+5 -> 2099–2104 | D32: ="If yes, record the dollar amount of any lease commitments not commenced below for fiscal year "&A13&"." -> If yes, record the dollar amount of any lease commitments not commenced below for fiscal year 2024–2025.
A33: =LEFT(A32,4)+5&"–"&RIGHT(A32,4)+5 -> 2104–2109
A34: =LEFT(A33,4)+5&"–"&RIGHT(A33,4)+5 -> 2109–2114
A35: =LEFT(A34,4)+5&"–"&RIGHT(A34,4)+5 -> 2114–2119
A36: =LEFT(A35,4)+5&"–"&RIGHT(A35,4)+5 -> 2119–2124
A38: II. Proprietary - INTERNAL SERVICE FUNDS
A39: Fiscal Year: | B39: =B8 -> 2023–2024
A40: Organization Code: | B40: =B9 -> 0
A41: Organization Name: | B41: =B10 -> 0
A42: The below information must be entered manually. DO NOT ENTER DECIMALS. PLEASE ROUND TO THE NEAREST DOLLAR.
...

Sheet LS-Lease Liabilities
J3: Schedule of Changes in Lease Liabilities
J4: =CONCATENATE("FY ",'LS-Fund #### Journal Entries'!F3) -> FY 2023–2024
J5: =CONCATENATE("Business Unit ",'LS-Department Note Disclosure'!B9," - ",'LS-Department Note Disclosure'!B10) -> Business Unit -
F7: =CONCATENATE("Balance July 1, ",MID(J4,4,4)) -> Balance July 1, 2023 | H7: Additions | J7: Deductions | L7: =CONCATENATE("Balance June 30, ",RIGHT(J4,4)) -> Balance June 30, 2024 | N7: Due Within One Year | P7: Noncurrent Liabilities
F8: (Entry #0) | H8: (Entry #3 & 10) | J8: (Entry #6 & 9) | N8: (Entry #7)
C9: Governmental Funds
D10: Lease Liability | F10: =IF('LS-Fund #### Journal Entries'!$F$8="Governmental Fund",'LS-Fund #### Journal Entries'!$K$23,0) -> 0 | H10: =IF('LS-Fund #### Journal Entries'!$F$8="Governmental Fund",SUM('LS-Fund #### Journal Entries'!$K$48,'LS-Fund #### Journal Entries'!K113),0) -> 0 | J10: =IF('LS-Fund #### Journal Entries'!$F$8="Governmental Fund",SUM('LS-Fund #### Journal Entries'!$J$68,'LS-Fund #### Journal Entries'!J96),0) -> 0 | L10: =SUM(F10+H10-J10) -> 0 | N10: =IF('LS-Fund #### Journal Entries'!$F$8="Governmental Fund",'LS-Fund #### Journal Entries'!$K$76,0) -> 0 | P10: =L10-N10 -> 0
C11: Total Governmental Funds | F11: =SUM(F10:F10) -> 0 | H11: =SUM(H10:H10) -> 0 | J11: =SUM(J10:J10) -> 0 | L11: =SUM(L10:L10) -> 0 | N11: =SUM(N10:N10) -> 0 | P11: =SUM(P10:P10) -> 0
C13: Proprietary - Internal Service Funds
D14: Lease Liability | F14: =IF('LS-Fund #### Journal Entries'!$F$8="Proprietary - Internal Service Fund",'LS-Fund #### Journal Entries'!$K$23,0) -> 0 | H14: =IF('LS-Fund #### Journal Entries'!$F$8="Proprietary - Internal Service Fund",SUM('LS-Fund #### Journal Entries'!$K$48,'LS-Fund #### Journal Entries'!K113),0) -> 0 | J14: =IF('LS-Fund #### Journal Entries'!$F$8="Proprietary - Internal Service Fund",SUM('LS-Fund #### Journal Entries'!$J$68,'LS-Fund #### Journal Entries'!J96),0) -> 0 | L14: =SUM(F14+H14-J14) -> 0 | N14: =IF('LS-Fund #### Journal Entries'!$F$8="Proprietary - Internal Service Fund",'LS-Fund #### Journal Entries'!$K$76,0) -> 0 | P14: =L14-N14 -> 0
C15: Total Proprietary - Internal Service Funds | F15: =SUM(F14:F14) -> 0 | H15: =SUM(H14:H14) -> 0 | J15: =SUM(J14:J14) -> 0 | L15: =SUM(L14:L14) -> 0 | N15: =SUM(N14:N14) -> 0 | P15: =SUM(P14:P14) -> 0
C17: Proprietary - Enterprise Funds
D18: Lease Liability | F18: =IF('LS-Fund #### Journal Entries'!$F$8="Proprietary - Enterprise Fund",'LS-Fund #### Journal Entries'!$K$23,0) -> 0 | H18: =IF('LS-Fund #### Journal Entries'!$F$8="Proprietary - Enterprise Fund",SUM('LS-Fund #### Journal Entries'!$K$48,'LS-Fund #### Journal Entries'!K113),0) -> 0 | J18: =IF('LS-Fund #### Journal Entries'!$F$8="Proprietary - Enterprise Fund",SUM('LS-Fund #### Journal Entries'!$J$68,'LS-Fund #### Journal Entries'!J96),0) -> 0 | L18: =SUM(F18+H18-J18) -> 0 | N18: =IF('LS-Fund #### Journal Entries'!$F$8="Proprietary - Enterprise Fund",'LS-Fund #### Journal Entries'!$K$76,0) -> 0 | P18: =L18-N18 -> 0
C19: Total Proprietary - Enterprise Funds | F19: =SUM(F18:F18) -> 0 | H19: =SUM(H18:H18) -> 0 | J19: =SUM(J18:J18) -> 0 | L19: =SUM(L18:L18) -> 0 | N19: =SUM(N18:N18) -> 0 | P19: =SUM(P18:P18) -> 0
B22: THIS SCHEDULE IS FOR THE CHANGE IN LEASE LIABILITY (ACCOUNT 0691) ONLY. THESE AMOUNTS WILL DIFFER FROM THE REPORT 18 (ASSETS).
B23: NOTE: If multiple funds are included in this workbook, manually complete every yellow field by consolidating the entries by fund type (Governmental, Proprietary ISF, and Proprietary EF).

Sheet LS-Check Figures  
A1: GASB Statement No. 87 Leases
A2: Check Figures
A4: Purpose:
A5: The purpose of this workbook is to check the figures entered in the journal entries reconcile to the future principal payments disclosed and the changes in the schedule of the lease liabilities.
A8: NOTE: If multiple funds are included in this workbook, manually complete every yellow field by consolidating the entries by fund type (Governmental, Proprietary ISF, and Proprietary EF).
A10: 1. To reconcile the journal entries of RTU Lease Liability with the principal payments in Note Disclosure.
B11: a) Governmental Funds
B13: Journal Entries | N13: Department Note Disclosure
B14: Beginning Balance | D14: Additions | F14: Deductions | H14: Deductions (Mod) | J14: Additions (Mod)
B15: Entry #0 | C15: + | D15: Entry #3 | E15: - | F15: Entry #6 | G15: - | H15: Entry #9 | I15: + | J15: Entry #10 | N15: Sum Principal Payments | P15: Variance
B16: =IF('LS-Fund #### Journal Entries'!$F$8="Governmental Fund",'LS-Fund #### Journal Entries'!$K$23,0) -> 0 | C16: + | D16: =IF('LS-Fund #### Journal Entries'!$F$8="Governmental Fund",'LS-Fund #### Journal Entries'!$K$48,0) -> 0 | E16: - | F16: =IF('LS-Fund #### Journal Entries'!$F$8="Governmental Fund",'LS-Fund #### Journal Entries'!$J$68,0) -> 0 | G16: - | H16: =IF('LS-Fund #### Journal Entries'!$F$8="Governmental Fund",'LS-Fund #### Journal Entries'!$J$96,0) -> 0 | I16: + | J16: =IF('LS-Fund #### Journal Entries'!$F$8="Governmental Fund",'LS-Fund #### Journal Entries'!$K$113,0) -> 0 | K16: = | L16: =+B16+D16-F16-H16+J16 -> 0 | N16: =SUM('LS-Department Note Disclosure'!B13:B36) -> 0 | P16: =L16-N16 -> 0
D18: =IF(OR(P16>0, (P16<0)), "Please review and correct the variance.","")
B19: b) Proprietary - Internal Service Funds
B21: Journal Entries | N21: Department Note Disclosure
B22: Beginning Balance | D22: Additions | F22: Deductions | H22: Deductions (Mod) | J22: Additions (Mod)
B23: Entry #0 | C23: + | D23: Entry #3 | E23: - | F23: Entry #6 | G23: - | H23: Entry #9 | I23: + | J23: Entry #10 | N23: Sum Principal Payments | P23: Variance
B24: =IF('LS-Fund #### Journal Entries'!$F$8="Proprietary - Internal Service Fund",'LS-Fund #### Journal Entries'!$K$23,0) -> 0 | C24: + | D24: =IF('LS-Fund #### Journal Entries'!$F$8="Proprietary - Internal Service Fund",'LS-Fund #### Journal Entries'!$K$48,0) -> 0 | E24: - | F24: =IF('LS-Fund #### Journal Entries'!$F$8="Proprietary - Internal Service Fund",'LS-Fund #### Journal Entries'!$J$68,0) -> 0 | G24: - | H24: =IF('LS-Fund #### Journal Entries'!$F$8="Proprietary - Internal Service Fund",'LS-Fund #### Journal Entries'!$J$96,0) -> 0 | I24: + | J24: =IF('LS-Fund #### Journal Entries'!$F$8="Proprietary - Internal Service Fund",'LS-Fund #### Journal Entries'!$K$113,0) -> 0 | K24: = | L24: =+B24+D24-F24-H24+J24 -> 0 | N24: =SUM('LS-Department Note Disclosure'!B44:B67) -> 0 | P24: =L24-N24 -> 0
D26: =IF(OR(P24>0, (P24<0)), "Please review and correct the variance.","")
B28: c) Proprietary - Enterprise Funds
B30: Journal Entries | N30: Department Note Disclosure
B31: Beginning Balance | D31: Additions | F31: Deductions | H31: Deductions (Mod) | J31: Additions (Mod)
B32: Entry #0 | C32: + | D32: Entry #3 | E32: - | F32: Entry #6 | G32: - | H32: Entry #9 | I32: + | J32: Entry #10 | N32: Sum Principal Payments | P32: Variance
B33: =IF('LS-Fund #### Journal Entries'!$F$8="Proprietary - Enterprise Fund",'LS-Fund #### Journal Entries'!$K$23,0) -> 0 | C33: + | D33: =IF('LS-Fund #### Journal Entries'!$F$8="Proprietary - Enterprise Fund",'LS-Fund #### Journal Entries'!$K$48,0) -> 0 | E33: - | F33: =IF('LS-Fund #### Journal Entries'!$F$8="Proprietary - Enterprise Fund",'LS-Fund #### Journal Entries'!$J$68,0) -> 0 | G33: - | H33: =IF('LS-Fund #### Journal Entries'!$F$8="Proprietary - Enterprise Fund",'LS-Fund #### Journal Entries'!$J$96,0) -> 0 | I33: + | J33: =IF('LS-Fund #### Journal Entries'!$F$8="Proprietary - Enterprise Fund",'LS-Fund #### Journal Entries'!$K$113,0) -> 0 | K33: = | L33: =+B33+D33-F33-H33+J33 -> 0 | N33: =SUM('LS-Department Note Disclosure'!B75:B98) -> 0 | P33: =L33-N33 -> 0
D35: =IF(OR(P33>0, (P33<0)), "Please review and correct the variance.","")
A37: 2. To match the journal entry to the principal amount due in the next fiscal year in Note Disclosure.
B38: a) Governmental Funds
B40: Journal Entries | N40: Department Note Disclosure
B41: Entry #7 | C41: Due within one year | N41: =CONCATENATE('LS-Department Note Disclosure'!$A$13," Principal Payments") -> 2024–2025 Principal Payments | P41: Variance
B42: =IF('LS-Fund #### Journal Entries'!$F$8="Governmental Fund",'LS-Fund #### Journal Entries'!$K$76,0) -> 0 | N42: ='LS-Department Note Disclosure'!B13 -> 0 | P42: =B42-N42 -> 0
D44: =IF(OR(P42>0, (P42<0)), "Please review and correct the variance.","")
B45: b) Proprietary - Internal Service Funds
B47: Journal Entries | N47: Department Note Disclosure
B48: Entry #7 | C48: Due within one year | N48: =CONCATENATE('LS-Department Note Disclosure'!$A$44," Principal Payments") -> 2024–2025 Principal Payments | P48: Variance
B49: =IF('LS-Fund #### Journal Entries'!$F$8="Proprietary - Internal Service Fund",'LS-Fund #### Journal Entries'!$K$76,0) -> 0 | N49: ='LS-Department Note Disclosure'!B44 -> 0 | P49: =B49-N49 -> 0
D51: =IF(OR(P49>0, (P49<0)), "Please review and correct the variance.","")
B53: c) Proprietary - Enterprise Funds
B55: Journal Entries | N55: Department Note Disclosure
B56: Entry #7 | C56: Due within one year | N56: =CONCATENATE('LS-Department Note Disclosure'!$A$75," Principal Payments") -> 2024–2025 Principal Payments | P56: Variance
B57: =IF('LS-Fund #### Journal Entries'!$F$8="Proprietary - Enterprise Fund",'LS-Fund #### Journal Entries'!$K$76,0) -> 0 | N57: ='LS-Department Note Disclosure'!B75 -> 0 | P57: =B57-N57 -> 0
D59: =IF(OR(P57>0, (P57<0)), "Please review and correct the variance.","")
...

Sheet LR-Version Changes
A1: This sheet details the changes made between version 2 and version 3 of the GASB 87 Lessor Annual Reporting Submission Workbook. Familiarize yourself with the changes in the table below and follow the instructions for updating data from template version 2 to version 3.
A4: Version 2 | B4: Published on SCO website in March 2024 for use for reporting periods 2022-2023 and afterwards.
A5: Version 3 | B5: Published on SCO website in October 2024 for use for reporting periods 2023-2024 and afterwards.
A7: The GASB 87 Annual Reporting Submission Workbook is required to be updated and submitted every year. See below for the summary of changes between versions.
A9: Summary of Changes
A10: Sheet | B10: Feature | C10: Location V2 | D10: Location V3 | E10: Description | F10: Required Action
A11: LR-Fund #### Journal Entries | B11: "Difference" Guidance | C11: N/A | D11: T14-T19 | E11: Wording was added in column T to describe what type of action needs to be taken for the "Differences" in Entry #0. | F11: Clarification only. Follow the guidance in column T.
A12: LR-Fund #### Journal Entries | B12: Highlighted Errors | C12: Multiple | D12: Multiple | E12: Errors such as "Debits and Credits do not equal each other" will populate in bold and be highlighted to assist with the identification of errors. | F12: Clarification only. Resolve all errors before submitting.
A13: LR-Fund #### Journal Entries | B13: Fixed Entry Description | C13: C18, C19 | D13: C18, C19 | E13: Fixed wording of account description to properly note the entry as a credit, instead of a debit. | F13: Clarification only. No action required.
A14: LR-Fund #### Journal Entries | B14: Account Number | C14: C32 | D14: C32 | E14: Changed account 0765-Investment and interest to account 0777-Investment and interest income. | F14: Clarification only. No action required.
A15: LS-Department Note Disclosure | B15: Reminder - No Decimals. | C15: A12, A43, A74 | D15: A12, A43, A74 | E15: Added additional wording to remind users not to enter decimals into the payment and interest table. | F15: Clarification only. Do not enter decimals.

Sheet LR-Fund 0001 Journal Entries
A1: Lessor-Type Contracts Fund-by-Fund Journal Entries Form (to be submitted to the SCO annually—one form per fund)
A2: Manually complete every yellow field in this worksheet—there are no automatically calculated data-entry cells in this worksheet.
A3: Fiscal year: | E3: 2023–2024
A4: Organization Name: | E4: Veterans Affairs
A5: Organization Code (4-Digit): | E5: 8955
A6: Fund Number (4-Digit): | E6: 1
A7: Fund Classification: | E7: Governmental
A8: Fund Type: | E8: Governmental Fund
A11: Establish Beginning Balances (existing leases only)
A12: Entry #
A13: 0 | B13: Roll prior year ending balance to record opening balance of lease receivable and deferred inflow of resources. | M13: Combined Lessor Templates | P13: From SCO BB List | S13: Difference
B14: Dr: Acct 0417 - LEASES RECEIVABLE - NONCURRENT | J14: =M14 -> 1325339 | M14: 1325339 | P14: 1325339 | S14: =P14-M14 -> 0 | T14: No action required.
B15: Dr: Acct 0950 - BEGINNING FUND BALANCE | J15: =P15 -> 27140 | M15: 27140 | P15: =IF(SUM($Q$17)>SUM($P$14),SUM($Q$17)-SUM($P$14),0) -> 27140 | S15: =P15-M15 -> 0 | T15: No action required.
B16: Dr: Acct 0952 - BEGINNING FUND ADJUSTMENT/PRIOR PERIOD ADJUSTMENT | J16: =IF(SUM($K$17:$K$18)>SUM($J$14:$J$15),SUM($K$17:$K$18)-SUM($J$14:$J$15),0) -> 0 | S16: =P16-M16 -> 0 | T16: No action required.
C17: Cr: Acct 0698 - OTHER DEFERRED INFLOWS OF RESOURCES | K17: =N17 -> 1352479 | N17: 1352479 | Q17: 1352479 | S17: =Q17-N17 -> 0 | T17: No action required.
C18: Cr: Acct 0950 - BEGINNING FUND BALANCE | K18: =Q18 -> 0 | Q18: =IF(SUM($Q$17)<SUM($P$14),-SUM($Q$17)+SUM($P$14),0) -> 0 | S18: =Q18-N18 -> 0 | T18: No action required.
C19: Cr: Acct 0952 - BEGINNING FUND ADJUSTMENT/PRIOR PERIOD ADJUSTMENT | K19: =IF(SUM($K$17:$K$18)<SUM($J$14:$J$15),-SUM($K$17:$K$18)+SUM($J$14:$J$15),0) -> 0 | S19: =Q19-N19 -> 0 | T19: No action required.
J20: =SUM(J14:J19) -> 1352479 | K20: =SUM(K14:K19) -> 1352479 | L20: =IF(J20=K20,"<- Debits and Credits equal each other.","<- Debits and Credits do not equal each other.") -> <- Debits and Credits equal each other.
A22: Record New Leases (new leases only)
A23: 1 | B23: Record receivable and related deferred inflow at inception of lease.
B24: Dr: Acct 0417 - LEASES RECEIVABLE - NONCURRENT
C25: Cr: Acct 0698 - OTHER DEFERRED INFLOWS OF RESOURCES
J26: =J24 -> 0 | K26: =K25 -> 0 | L26: =IF(J26=K26,"<- Debits and Credits equal each other.","<- Debits and Credits do not equal each other.") -> <- Debits and Credits equal each other.
A28: Record Annual Activity (all leases)
A29: 2 | B29: Record receipt of lease payments as reduction of lease receivable and recognize interest revenue.
B30: =IF($E$7="Governmental","Dr: Acct 0775 - OTHER INCOME","Dr: Acct 0755 - SALES & SERVICES") -> Dr: Acct 0775 - OTHER INCOME | J30: 153747
C31: Cr: Acct 0417 - LEASES RECEIVABLE - NONCURRENT | K31: 137710
C32: =IF($E$7="Governmental","Cr: Acct 0740 - INTEREST INCOME","Cr: Acct 0777 - INVESTMENT AND INTEREST INCOME") -> Cr: Acct 0740 - INTEREST INCOME | K32: 16037
J33: =J30 -> 153747 | K33: =SUM(K31:K32) -> 153747 | L33: =IF(J33=K33,"<- Debits and Credits equal each other.","<- Debits and Credits do not equal each other.") -> <- Debits and Credits equal each other.
A35: 3 | B35: Record straight-line recognition of revenue.
B36: Dr: Acct 0698 - OTHER DEFERRED INFLOWS OF RESOURCES | C36: Cr: Acct 0698 - OTHER DEFERRED INFLOWS OF RESOURCES | D36: Cr: Acct 0698 - OTHER DEFERRED INFLOWS OF RESOURCES | E36: Cr: Acct 0698 - OTHER DEFERRED INFLOWS OF RESOURCES | J36: 153747
C37: =IF($E$7="Governmental","Cr: Acct 0775 - OTHER INCOME","Cr: Acct 0778 - RENT") -> Cr: Acct 0775 - OTHER INCOME | K37: 153747
J38: =J36 -> 153747 | K38: =K37 -> 153747 | L38: =IF(J38=K38,"<- Debits and Credits equal each other.","<- Debits and Credits do not equal each other.") -> <- Debits and Credits equal each other.
A40: 4 | B40: Reclassify the current portion of the lease receivable from non-current to current.
B41: Dr: Acct 0036 - LEASES RECEIVABLE - CURRENT | J41: 143062
C42: Cr: Acct 0417 - LEASES RECEIVABLE - NONCURRENT | D42: Cr: Acct 0416 - LEASES RECEIVABLE - NONCURRENT | E42: Cr: Acct 0416 - LEASES RECEIVABLE - NONCURRENT | K42: 143062
B43: NOTE: This is the annual year-end reclassification of the non-current liability to current. It is to be reversed at the start of the next fiscal year.SCO combines the current and non current amount in Entry #0 to reestablish the beginning balances. No action required. | J43: =J41 -> 143062 | K43: =K42 -> 143062 | L43: =IF(J43=K43,"<- Debits and Credits equal each other.","<- Debits and Credits do not equal each other.") -> <- Debits and Credits equal each other.
A47: Lease Remeasurement and Modifications (only if a significant modification occurred during the fiscal year)
A48: 5 | B48: Record early termination or lease modifications to decrease the lease receivable and other deferred inflows of resources.
B49: Dr: Acct 0698 - OTHER DEFERRED INFLOWS OF RESOURCES
...

Sheet LR-Department Note Disclosure
A1: Submit one form for the department to the SCO annually.
A2: Note: There are three tables of note disclosures on this form —1) governmental funds, 2) proprietary - internal service funds, and 3) proprietary - enterprise funds. Complete all applicable tables before submitting to the SCO.
A3: Manually complete every yellow field in this worksheet—there are no automatically calculated cells in this worksheet.
A4: Complete the fields below using aggregated and summarized information from all of your department's completed contract template forms.
A5: The fields in this worksheet should contain the sums of the department's contracts' corresponding information in their note disclosure worksheets.
A8: I. Governmental funds
A9: Fiscal Year: | B9: 2023–2024
A10: Organization Code: | B10: 8955
A11: Organization Name: | B11: Veterans Affairs
A12: The below information must be entered manually. DO NOT ENTER DECIMALS. PLEASE ROUND TO THE NEAREST DOLLAR.
B13: Principal Receipts | C13: Interest Receipts | E13: ="All of this worksheet's questions are for Fiscal Year "&$B$9&":" -> All of this worksheet's questions are for Fiscal Year 2023–2024:
A14: =RIGHT(B9,4)&"–"&RIGHT(B9,4)+1 -> 2024–2025 | B14: 143061.58 | C14: 14371.266 | E14: 1. Did your leasing arrangements have any variable receipts which ARE NOT included in the measurement of the lease receivable? These include but are not limited to receipts related to residual value guarantees and termination penalties.
A15: =LEFT(A14,4)+1&"–"&RIGHT(A14,4)+1 -> 2025–2026 | B15: 148678.35 | C15: 12626.88
A16: =LEFT(A15,4)+1&"–"&RIGHT(A15,4)+1 -> 2026–2027 | B16: 154571.14 | C16: 10799.348
A17: =LEFT(A16,4)+1&"–"&RIGHT(A16,4)+1 -> 2027–2028 | B17: 160754.62 | C17: 8884.4
A18: =LEFT(A17,4)+1&"–"&RIGHT(A17,4)+1 -> 2028–2029 | B18: 140546.76 | C18: 6907.57 | E18: No
A19: =LEFT(A18,4)+1&"–"&RIGHT(A18,4)+5 -> 2029–2034 | B19: 328787.92 | C19: 15217.06 | E19: ="If yes, record the dollar amount of variable receipts below for fiscal year "&$B$9&":" -> If yes, record the dollar amount of variable receipts below for fiscal year 2023–2024:
A20: =LEFT(A19,4)+5&"–"&RIGHT(A19,4)+5 -> 2034–2039 | B20: 89522.44 | C20: 5044.88
A21: =LEFT(A20,4)+5&"–"&RIGHT(A20,4)+5 -> 2039–2044 | B21: 21706.66 | C21: 136.01 | E21: ="2. Did you grant any lease incentives to the lessee during fiscal year "&$B$9&"? If so, record the amount below:" -> 2. Did you grant any lease incentives to the lessee during fiscal year 2023–2024? If so, record the amount below:
A22: =LEFT(A21,4)+5&"–"&RIGHT(A21,4)+5 -> 2044–2049
A23: =LEFT(A22,4)+5&"–"&RIGHT(A22,4)+5 -> 2049–2054 | E23: No
A24: =LEFT(A23,4)+5&"–"&RIGHT(A23,4)+5 -> 2054–2059
A25: =LEFT(A24,4)+5&"–"&RIGHT(A24,4)+5 -> 2059–2064
A26: =LEFT(A25,4)+5&"–"&RIGHT(A25,4)+5 -> 2064–2069
A27: =LEFT(A26,4)+5&"–"&RIGHT(A26,4)+5 -> 2069–2074
A28: =LEFT(A27,4)+5&"–"&RIGHT(A27,4)+5 -> 2074–2079
A29: =LEFT(A28,4)+5&"–"&RIGHT(A28,4)+5 -> 2079–2084
A30: =LEFT(A29,4)+5&"–"&RIGHT(A29,4)+5 -> 2084–2089
A31: =LEFT(A30,4)+5&"–"&RIGHT(A30,4)+5 -> 2089–2094
A32: =LEFT(A31,4)+5&"–"&RIGHT(A31,4)+5 -> 2094–2099
A33: =LEFT(A32,4)+5&"–"&RIGHT(A32,4)+5 -> 2099–2104
A34: =LEFT(A33,4)+5&"–"&RIGHT(A33,4)+5 -> 2104–2109
A35: =LEFT(A34,4)+5&"–"&RIGHT(A34,4)+5 -> 2109–2114
... A37: =LEFT(A36,4)+5&"–"&RIGHT(A36,4)+5 -> 2119–2124
A39: II. Proprietary - INTERNAL SERVICE FUNDS
A40: Fiscal Year: | B40: =B9 -> 2023–2024
A41: Organization Code: | B41: =B10 -> 8955
A42: Organization Name: | B42: =B11 -> Veterans Affairs
A43: The below information must be entered manually. DO NOT ENTER DECIMALS. PLEASE ROUND TO THE NEAREST DOLLAR.
B44: Principal Receipts | C44: Interest Receipts | E44: ="All of this worksheet's questions are for Fiscal Year "&$B$9&":" -> All of this worksheet's questions are for Fiscal Year 2023–2024:
...

Sheet LR-Check Figures
A1: GASB Statement No. 87 Lessors
A2: Check Figures
A4: Purpose:
A5: The purpose of this workbook is to check the figures entered in the journal entries reconcile to the future principal receipts disclosed and the changes in the schedule of the lease receivable.
A8: NOTE: If multiple funds are included in this workbook, manually complete every yellow field by consolidating the entries by fund type (Governmental, Proprietary ISF, and Proprietary EF).
A10: 1. To reconcile the journal entries of Lease Receivable with the principal receipts in Note Disclosure.
B11: a) Governmental Funds
B13: Journal Entries | N13: Department Note Disclosure
B14: Beginning Balance | D14: Additions | F14: Deductions | H14: Deductions (Mod) | J14: Additions (Mod)
B15: Entry #0 | C15: + | D15: Entry #1 | E15: - | F15: Entry #2 | G15: - | H15: Entry #5 | I15: + | J15: Entry #6 | N15: Sum Principal Receipts | P15: Variance
B16: =IF('LR-Fund 0001 Journal Entries'!$E$8="Governmental Fund",'LR-Fund 0001 Journal Entries'!$J$14,0) -> 1325339 | C16: + | D16: =IF('LR-Fund 0001 Journal Entries'!$E$8="Governmental Fund",'LR-Fund 0001 Journal Entries'!$J$24,0) -> 0 | E16: - | F16: =IF('LR-Fund 0001 Journal Entries'!$E$8="Governmental Fund",'LR-Fund 0001 Journal Entries'!$K$31,0) -> 137710 | G16: - | H16: =IF('LR-Fund 0001 Journal Entries'!$E$8="Governmental Fund",'LR-Fund 0001 Journal Entries'!$K$52,0) -> 0 | I16: + | J16: =IF('LR-Fund 0001 Journal Entries'!$E$8="Governmental Fund",'LR-Fund 0001 Journal Entries'!$J$58,0) -> 0 | K16: = | L16: =+B16+D16-F16-H16+J16 -> 1187629 | N16: =SUM('LR-Department Note Disclosure'!B14:B37) -> 1187629.5 | P16: =L16-N16 -> -0.47676368
D18: =IF(OR(P16>0, (P16<0)), "Please review and correct the variance.","") -> Please review and correct the variance.
B19: b) Proprietary - Internal Service Funds
B21: Journal Entries | N21: Department Note Disclosure
B22: Beginning Balance | D22: Additions | F22: Deductions | H22: Deductions (Mod) | J22: Additions (Mod)
B23: Entry #0 | C23: + | D23: Entry #1 | E23: - | F23: Entry #2 | G23: - | H23: Entry #5 | I23: + | J23: Entry #6 | N23: Sum Principal Receipts | P23: Variance
B24: =IF('LR-Fund 0001 Journal Entries'!$E$8="Proprietary - Internal Service Fund",'LR-Fund 0001 Journal Entries'!$J$14,0) -> 0 | C24: + | D24: =IF('LR-Fund 0001 Journal Entries'!$E$8="Proprietary - Internal Service Fund",'LR-Fund 0001 Journal Entries'!$J$24,0) -> 0 | E24: - | F24: =IF('LR-Fund 0001 Journal Entries'!$E$8="Proprietary - Internal Service Fund",'LR-Fund 0001 Journal Entries'!$K$31,0) -> 0 | G24: - | H24: =IF('LR-Fund 0001 Journal Entries'!$E$8="Proprietary - Internal Service Fund",'LR-Fund 0001 Journal Entries'!$K$52,0) -> 0 | I24: + | J24: =IF('LR-Fund 0001 Journal Entries'!$E$8="Proprietary - Internal Service Fund",'LR-Fund 0001 Journal Entries'!$J$58,0) -> 0 | K24: = | L24: =+B24+D24-F24-H24+J24 -> 0 | N24: =SUM('LR-Department Note Disclosure'!B45:B68) -> 0 | P24: =L24-N24 -> 0
D26: =IF(OR(P24>0, (P24<0)), "Please review and correct the variance.","")
B28: c) Proprietary - Enterprise Funds
B30: Journal Entries | N30: Department Note Disclosure
B31: Beginning Balance | D31: Additions | F31: Deductions | H31: Deductions (Mod) | J31: Additions (Mod)
B32: Entry #0 | C32: + | D32: Entry #1 | E32: - | F32: Entry #2 | G32: - | H32: Entry #5 | I32: + | J32: Entry #6 | N32: Sum Principal Receipts | P32: Variance
B33: =IF('LR-Fund 0001 Journal Entries'!$E$8="Proprietary - Enterprise Fund",'LR-Fund 0001 Journal Entries'!$J$14,0) -> 0 | C33: + | D33: =IF('LR-Fund 0001 Journal Entries'!$E$8="Proprietary - Enterprise Fund",'LR-Fund 0001 Journal Entries'!$J$24,0) -> 0 | E33: - | F33: =IF('LR-Fund 0001 Journal Entries'!$E$8="Proprietary - Enterprise Fund",'LR-Fund 0001 Journal Entries'!$K$31,0) -> 0 | G33: - | H33: =IF('LR-Fund 0001 Journal Entries'!$E$8="Proprietary - Enterprise Fund",'LR-Fund 0001 Journal Entries'!$K$52,0) -> 0 | I33: + | J33: =IF('LR-Fund 0001 Journal Entries'!$E$8="Proprietary - Enterprise Fund",'LR-Fund 0001 Journal Entries'!$J$58,0) -> 0 | K33: = | L33: =+B33+D33-F33-H33+J33 -> 0 | N33: =SUM('LR-Department Note Disclosure'!B76:B99) -> 0 | P33: =L33-N33 -> 0
D35: =IF(OR(P33>0, (P33<0)), "Please review and correct the variance.","")
A37: 2. To match the journal entry to the principal amount due receivable in the next fiscal year in Note Disclosure.
B38: a) Governmental Funds
B40: Journal Entries | N40: Department Note Disclosure
B41: Entry #4 | C41: Due within one year | N41: =CONCATENATE('LS-Department Note Disclosure'!$A$13," Principal Payments") -> 2024–2025 Principal Payments | P41: Variance
B42: =IF('LR-Fund 0001 Journal Entries'!$E$8="Governmental Fund",'LR-Fund 0001 Journal Entries'!$J$41,0) -> 143062 | N42: ='LR-Department Note Disclosure'!B14 -> 143061.58 | P42: =B42-N42 -> 0.41552909
D44: =IF(OR(P42>0, (P42<0)), "Please review and correct the variance.","") -> Please review and correct the variance.
B45: b) Proprietary - Internal Service Funds
B47: Journal Entries | N47: Department Note Disclosure
B48: Entry #4 | C48: Due within one year | N48: =CONCATENATE('LS-Department Note Disclosure'!$A$44," Principal Payments") -> 2024–2025 Principal Payments | P48: Variance
B49: =IF('LR-Fund 0001 Journal Entries'!$E$8="Proprietary - Internal Service Fund",'LR-Fund 0001 Journal Entries'!$J$41,0) -> 0 | N49: ='LR-Department Note Disclosure'!B45 -> 0 | P49: =B49-N49 -> 0
D51: =IF(OR(P49>0, (P49<0)), "Please review and correct the variance.","")
B53: c) Proprietary - Enterprise Funds
B55: Journal Entries | N55: Department Note Disclosure
B56: Entry #4 | C56: Due within one year | N56: =CONCATENATE('LS-Department Note Disclosure'!$A$75," Principal Payments") -> 2024–2025 Principal Payments | P56: Variance
B57: =IF('LR-Fund 0001 Journal Entries'!$E$8="Proprietary - Enterprise Fund",'LR-Fund 0001 Journal Entries'!$J$41,0) -> 0 | N57: ='LR-Department Note Disclosure'!B76 -> 0 | P57: =B57-N57 -> 0

Sheet FP-Version Changes
A1: This sheet details the changes made between version 2 and version 3 of the GASB 87 Lessee Financed Purchase Annual Reporting Submission Workbook. Familiarize yourself with the changes in the table below and follow the instructions for updating data from template version 2 to version 3.
A4: Version 2 | B4: Published on SCO website in March 2024 for use for reporting periods 2022-2023 and afterwards.
A5: Version 3 | B5: Published on SCO website in October 2024 for use for reporting periods 2023-2024 and afterwards.
A7: The GASB 87 Annual Reporting Submission Workbook is required to be updated and submitted every year. See below for the summary of changes between versions.
A9: Summary of Changes
A10: Sheet | B10: Feature | C10: Location V2 | D10: Location V3 | E10: Description | F10: Required Action
A11: FP-Fund #### Journal Entries | B11: "Difference" Guidance | C11: N/A | D11: T15-T25 | E11: Wording was added in column T to describe what type of action needs to be taken for the "Differences" in Entry #0. | F11: Clarification only. Follow the guidance in column T.
A12: FP-Fund #### Journal Entries | B12: Highlighted Errors | C12: Multiple | D12: Multiple | E12: Errors such as "Debits and Credits do not equal each other" and "Accts 0848 must agree" will populate in bold and be highlighted to assist with the identification of errors. | F12: Clarification only. Resolve all errors before submitting.
A13: FP-Lease Liabilities | B13: Reminder - Acct 0695 Only | C13: N/A | D13: B22 | E13: Added additional wording to remind users that the Schedule of Changes in Lease Liabilities is for Account 0695 only, and therefore will differ from the Report 18. | F13: Clarification only.

Sheet FP-Fund #### Journal Entries
A1: Financed Purchase-Type Contracts Fund-by-Fund Journal Entries Form (to be submitted to the SCO annually—one form per fund)
A2: Manually complete every yellow field in this worksheet—there are no automatically calculated data-entry cells in this worksheet.
A3: Fiscal Year: | F3: 2023–2024
A4: Organization Name:
A5: Organization Code (4-Digits):
A6: Fund Number:
A7: Fund Classification:
A8: Fund Type:
A9: Functional Expense: | F9: =IFERROR(IF(F7="Proprietary","Proprietary Fund",VLOOKUP(F5,qryIndex02a!$A$2:$K$654,4,FALSE)),"Unidentified") -> Unidentified
A12: Establish Beginning Balances (existing financed purchases only)
A13: Entry #
A14: 0 | B14: Roll prior year to record opening balances of financed purchase assets and liabilities. | M14: Combined FP Templates | P14: From SCO BB List | S14: Difference
B15: Dr: Acct 0446 - LAND AND LAND IMPROVEMENTS | J15: =M15 -> 0 | S15: =P15-M15 -> 0 | T15: Report any "Differences" on the Report 18 Differential.
B16: Dr: Acct 0448 - BUILDINGS AND BUILDING IMPROVEMENTS | J16: =M16 -> 0 | S16: =P16-M16 -> 0 | T16: Report any "Differences" on the Report 18 Differential.
B17: Dr: Acct 0450 - EQUIPMENT | J17: =M17 -> 0 | S17: =P17-M17 -> 0 | T17: Report any "Differences" on the Report 18 Differential.
B18: Dr: Acct 0950 - BEGINNING FUND BALANCE | J18: =P18 -> 0 | P18: =IF(SUM($Q$21:$Q$23)>SUM($P$15:$P$17),SUM($Q$21:$Q$23)-SUM($P$15:$P$17),0) -> 0 | S18: =P18-M18 -> 0 | T18: No action required.
B19: Dr: Acct 0952 - BEGINNING FUND ADJUSTMENT/PRIOR PERIOD ADJUSTMENT | J19: =IF(SUM($K$21:$K$24)>SUM($J$15:$J$18),SUM($K$21:$K$24)-SUM($J$15:$J$18),0) -> 0 | S19: =P19-M19 -> 0 | T19: No action required.
C20: Land is not depreciable
C21: Cr: Acct 0462 - ACCUMULATED DEPRECIATION - EQUIPMENT | K21: =N21 -> 0 | S21: =Q21-N21 -> 0 | T21: No action required.
C22: Cr: Acct 0458 - ACCUMULATED DEPRECIATION - BUILDINGS AND BUILDING IMPROVEMENTS | K22: =N22 -> 0 | S22: =Q22-N22 -> 0 | T22: No action required.
C23: Cr: Acct 0695 - OTHER NONCURRENT LIABILITIES | K23: =N23 -> 0 | S23: =Q23-N23 -> 0 | T23: No action required.
C24: Cr: Acct 0950 - BEGINNING FUND BALANCE | K24: =Q24 -> 0 | Q24: =IF(SUM($Q$21:$Q$23)<SUM($P$15:$P$17),-SUM($Q$21:$Q$23)+SUM($P$15:$P$17),0) -> 0 | S24: =Q24-N24 -> 0 | T24: No action required.
C25: Cr: Acct 0952 - BEGINNING FUND ADJUSTMENT/PRIOR PERIOD ADJUSTMENT | K25: =IF(SUM($K$21:$K$24)<SUM($J$15:$J$18),-SUM($K$21:$K$24)+SUM($J$15:$J$18),0) -> 0 | S25: =Q25-N25 -> 0 | T25: No action required.
J26: =SUM(J15:J25) -> 0 | K26: =SUM(K15:K25) -> 0 | L26: =IF(J26=K26,"<- Debits and Credits equal each other.","<- Debits and Credits do not equal each other.") -> <- Debits and Credits equal each other.
A29: Record New Financed Purchases (new financed purchases only)
A30: 1 | B30: Record financed purchase contract commencement (fund-based entries only)
B31: Dr: Acct 0842 - CAPITAL OUTLAY
C32: Cr: Acct 0789 - LEASE AND OTHER FINANCING PROCEEDS
C33: =IF($F$7="Proprietary","Cr: Acct 0870 - SERVICES & CHARGES (MG ADJ)",VLOOKUP($F$9,'Drop Down Menus'!$F$2:$G$10,2,FALSE)) -> Cr: Acct 0XXX - FUNCTIONAL EXPENSE
J34: =SUM(J31:J33) -> 0 | K34: =SUM(K31:K33) -> 0 | L34: =IF(J34=K34,"<- Debits and Credits equal each other.","<- Debits and Credits do not equal each other.") -> <- Debits and Credits equal each other.
A36: 2 | B36: Record financed purchase assets. These amounts should be included in the Report 18.
B37: Dr: Acct 0446 - LAND AND LAND IMPROVEMENTS
B38: Dr: Acct 0448 - BUILDINGS AND BUILDING IMPROVEMENTS
B39: Dr: Acct 0450 - EQUIPMENT
C40: Cr: Acct 0842 - CAPITAL OUTLAY
J41: =SUM(J37:J40) -> 0 | K41: =SUM(K37:K40) -> 0 | L41: =IF(J41=K41,"<- Debits and Credits equal each other.","<- Debits and Credits do not equal each other.") -> <- Debits and Credits equal each other.
A43: 3 | B43: Replace proceeds from leases with other noncurrent liabilities.
B44: Dr: Acct 0789 - LEASE AND OTHER FINANCING PROCEEDS
C45: Cr: Acct 0695 - OTHER NONCURRENT LIABILITIES
J46: =SUM(J44:J45) -> 0 | K46: =SUM(K44:K45) -> 0 | L46: =IF(J46=K46,"<- Debits and Credits equal each other.","<- Debits and Credits do not equal each other.") -> <- Debits and Credits equal each other.
...

Sheet FP-Lease Liabilities
J3: Schedule of Changes in Lease Liabilities
J4: =CONCATENATE("FY ",'FP-Fund #### Journal Entries'!F3) -> FY 2023–2024
J5: =CONCATENATE("Business Unit ",'FP-Fund #### Journal Entries'!F5," - ",'FP-Fund #### Journal Entries'!F4) -> Business Unit -
F7: =CONCATENATE("Balance July 1, ",MID(J4,4,4)) -> Balance July 1, 2023 | H7: Additions | J7: Deductions | L7: =CONCATENATE("Balance June 30, ",RIGHT(J4,4)) -> Balance June 30, 2024 | N7: Due Within One Year | P7: Noncurrent Liabilities
F8: (Entry #0) | H8: (Entry #3) | J8: (Entry #6) | N8: (Entry #7)
C9: Governmental Funds
D10: Installment Contracts Payable (Financed Purchase) | L10: =SUM(F10+H10-J10) -> 0 | P10: =L10-N10 -> 0
C11: Total Governmental Funds | F11: =SUM(F10:F10) -> 0 | H11: =SUM(H10:H10) -> 0 | J11: =SUM(J10:J10) -> 0 | L11: =SUM(L10:L10) -> 0 | N11: =SUM(N10:N10) -> 0 | P11: =SUM(P10:P10) -> 0
C13: Proprietary - Internal Service Funds
D14: Installment Contracts Payable (Financed Purchase) | L14: =SUM(F14+H14-J14) -> 0 | P14: =L14-N14 -> 0
C15: Total Proprietary - Internal Service Funds | F15: =SUM(F14:F14) -> 0 | H15: =SUM(H14:H14) -> 0 | J15: =SUM(J14:J14) -> 0 | L15: =SUM(L14:L14) -> 0 | N15: =SUM(N14:N14) -> 0 | P15: =SUM(P14:P14) -> 0
C17: Proprietary - Enterprise Funds
D18: Installment Contracts Payable (Financed Purchase) | L18: =SUM(F18+H18-J18) -> 0 | P18: =L18-N18 -> 0
C19: Total Proprietary - Enterprise Funds | F19: =SUM(F18:F18) -> 0 | H19: =SUM(H18:H18) -> 0 | J19: =SUM(J18:J18) -> 0 | L19: =SUM(L18:L18) -> 0 | N19: =SUM(N18:N18) -> 0 | P19: =SUM(P18:P18) -> 0
B22: THIS SCHEDULE IS FOR THE CHANGE IN OTHER NONCURRENT LIABILITIES (ACCOUNT 0695) ONLY. THESE AMOUNTS WILL DIFFER FROM THE REPORT 18 (ASSETS).
