Workbook
Name ITEM_CAPCOST: #REF!
Name ITEM_CAPCOST: #REF!
Name ITEM_CAPCOST: #REF!
Name page\x2dtotal: #REF!
Name page\x2dtotal: #REF!
Name page\x2dtotal: #REF!
Name page\x2dtotal: #REF!
Name page\x2dtotal: #REF!
Name page\x2dtotal: #REF!
Name page\x2dtotal: #REF!
Name page\x2dtotal: #REF!
Name page\x2dtotal: #REF!
Name page\x2dtotal\x2dmaster0: #REF!
Name page\x2dtotal\x2dmaster0: #REF!
Name page\x2dtotal\x2dmaster0: #REF!
Name page\x2dtotal\x2dmaster0: #REF!
Name page\x2dtotal\x2dmaster0: #REF!
Name page\x2dtotal\x2dmaster0: #REF!
Name page\x2dtotal\x2dmaster0: #REF!
Name page\x2dtotal\x2dmaster0: #REF!
Name page\x2dtotal\x2dmaster0: #REF!
Name page\x2dtotal\x2dmaster0_1_1: #REF!
Name page\x2dtotal\x2dmaster0_2_1: '0001'!#REF!
Name page\x2dtotal\x2dmaster0_2_1: '0041'!#REF!
Name page\x2dtotal\x2dmaster0_2_1: '0042'!#REF!
Name page\x2dtotal\x2dmaster0_2_1: '0042 Revised'!#REF!
Name page\x2dtotal\x2dmaster0_2_1: '0046'!#REF!
Name page\x2dtotal\x2dmaster0_2_1: '0183'!#REF!
Name page\x2dtotal\x2dmaster0_2_1: '0523'!#REF!
Name page\x2dtotal\x2dmaster0_2_1: '0541'!#REF!
Name page\x2dtotal\x2dmaster0_2_1: '0653'!#REF!
Name page\x2dtotal\x2dmaster0_2_1: '0673'!#REF!
Name page\x2dtotal\x2dmaster0_2_1: '0703'!#REF!
Name page\x2dtotal\x2dmaster0_2_1: '0756'!#REF!
Name page\x2dtotal\x2dmaster0_2_1: '0942'!#REF!
Name page\x2dtotal\x2dmaster0_2_1: '2504'!#REF!
Name page\x2dtotal\x2dmaster0_2_1: '3007'!#REF!
Name page\x2dtotal\x2dmaster0_2_1: '3290'!#REF!
Name page\x2dtotal\x2dmaster0_2_1: '3291'!#REF!
Name page\x2dtotal\x2dmaster0_2_1: '6055'!#REF!
Name page\x2dtotal\x2dmaster0_2_1: '6056'!#REF!
Name page\x2dtotal\x2dmaster0_2_1: '6058'!#REF!
Name page\x2dtotal\x2dmaster0_2_1: '6059'!#REF!
Name page\x2dtotal\x2dmaster0_2_1: '6060'!#REF!
Name page\x2dtotal\x2dmaster0_2_1: '6062'!#REF!
Name page\x2dtotal\x2dmaster0_2_1: '6063'!#REF!
Name page\x2dtotal\x2dmaster0_2_1: '6064'!#REF!
Name page\x2dtotal\x2dmaster0_2_1: '6072'!#REF!
Name page\x2dtotal\x2dmaster0_2_1: '6801'!#REF!
Name page\x2dtotal\x2dmaster0_2_1: #REF!
Name page\x2dtotal\x2dmaster0_2_1: #REF!
Name page\x2dtotal\x2dmaster0_2_1: #REF!
Name page\x2dtotal\x2dmaster0_2_1: #REF!
Name page\x2dtotal\x2dmaster0_2_1: #REF!
Name page\x2dtotal\x2dmaster0_2_1: #REF!
Name page\x2dtotal\x2dmaster0_2_1: #REF!
Name page\x2dtotal\x2dmaster0_2_1: #REF!
Name page\x2dtotal\x2dmaster0_3_1: #REF!
Name page\x2dtotal\x2dmaster0_3_1: #REF!
Name page\x2dtotal\x2dmaster0_3_1: #REF!

Sheet 0001
I1: Page No : 1
A2: REPORT 18 – STATEMENT OF CHANGES IN CAPITAL ASSETS
A3: Department Name (2660)
A4: GENERAL FUND (0001)
A5: Fiscal Year 2023-24
A6: As of 06/30/2024
A7: Business Unit: | C7: 2660 - DEPARTMENT OF TRANSPORTATION | I7: Report ID: RPTGL075 | J7: RPTGL075
A8: Fund: | C8: 0001 - GENERAL FUND | I8: Run Date: | J8: =TODAY() -> 45723
I9: Run Time: | J9: =NOW() -> 45723.508
A14: Account – Description | F14: Beginning Balance | G14: Additions | H14: Deductions | J14: Ending Balance
A15: Tangible Assets
A16: 2310 Land a | F16: =F42 -> 886023.84 | G16: =G42 -> 69487.68 | J16: =F16+G16-H16 -> 955511.52
A17: 2321 Buildings | F17: 105422.6 | J17: =F17+G17-H17 -> 105422.6
A18: 2331 Improvements Other Than Buildings | J18: =F18+G18-H18 -> 0
A19: 2341 Equipment | F19: 934059.34 | G19: 76269.42 | H19: 368175.54 | J19: =F19+G19-H19 -> 642153.22
A20: 2350 Construction Work in Progress b | F20: 64122817 | G20: 72150164 | H20: 19313010 | J20: =F20+G20-H20 -> 1.1695997e+08
A21: 2361 Infrastructure - Non Depreciable b | F21: 5886148 | G21: 50235158 | J21: =F21+G21-H21 -> 56121306
A23: Intangible Assets
A24: 2411 Computer Software - Amortizable | J24: =F24+G24-H24 -> 0
A25: 2412 Land Use Rights - Amortizable | J25: =F25+G25-H25 -> 0
A26: 2413 Patents, Copyrights, and Trademarks - Amortizable | J26: =F26+G26-H26 -> 0
A27: 2414 Other Intangible Assets - Amortizable | J27: =F27+G27-H27 -> 0
A28: 2415 Right-to-Use Leased Land - Amortizable | J28: =F28+G28-H28 -> 0
A29: 2416 Right-to-Use Leased Buildings - Amortizable | J29: =F29+G29-H29 -> 0
A30: 2417 Right-to-Use Leased Equipment - Amortizable | J30: =F30+G30-H30 -> 0
A31: 2418 Right-to-Use Subscription-Based Information Technology Arrangements (SBITA) - Amortizable | J31: =F31+G31-H31 -> 0
A32: 2422 Land Use Rights - Non-Amortizable | J32: =F32+G32-H32 -> 0
A35: Fund: | B35: 0001 | F35: =SUM(F16:F34) -> 71934471 | G35: =SUM(G16:G34) -> 1.2253108e+08 | H35: =SUM(H16:H34) -> 19681185 | J35: =SUM(J16:J34) -> 1.7478436e+08
A37: Note:
F38: Total | G38: Additions | H38: Deductions | J38: Total
A39: Land - Operational Dept (2310-5000) | F39: 622702.5 | J39: =F39+G39-H39 -> 622702.5
A40: Land - Infrastructure Dept (2310-5900) b | F40: 263321.34 | G40: 69487.68 | H40: 0 | J40: =F40+G40-H40 -> 332809.02
A42: a - Total Land | F42: =SUM(F39:F41) -> 886023.84 | G42: =SUM(G39:G40) -> 69487.68 | H42: =SUM(H39:H40) -> 0 | J42: =SUM(J39:J41) -> 955511.52
A44: b - Infrastructure only.
A46: c - The $19,313,009.55 in Construction Work in Progress' Deductions which represents FY 2023/2024's Transfer from CWIP to Non-Depreciable Infrastructure (Completed).
A49: I certify (or declare) under penalty of perjury that the attached reports are true, accurate and complete, and were prepared following the applicable laws, regulations, policies, procedures, and instructions. I have not violated any of the provisions of Article 4, Chapter 1, Division 4, Title 1, Government Code (commencing with Section 1090) and Article 2, Chapter 1, Part 3, Division 3, Title 2, Government Code (commencing with Section 13030).
A54: Subscribed and executed this 30th day of August, 2024 at Sacramento, California.
I60: KIM PHAN, Chief
I61: Service Transactions & Asset
I62: Reconciliation Section

Sheet 0041
I1: Page No : 2
A2: REPORT 18 – STATEMENT OF CHANGES IN CAPITAL ASSETS
A3: Department Name (2660)
A4: AERONAUTICS FUND (0041)
A5: Fiscal Year 2023-24
A6: As of 06/30/2024
A7: Business Unit: | C7: 2660 - DEPARTMENT OF TRANSPORTATION | I7: Report ID: RPTGL075 | J7: RPTGL075
A8: Fund: | C8: 0041 AERONAUTICS FUND | I8: Run Date: | J8: =TODAY() -> 45723
I9: Run Time: | J9: =NOW() -> 45723.508
A14: Account – Description | F14: Beginning Balance | G14: Additions | H14: Deductions | J14: Ending Balance
A15: Tangible Assets
A16: 2310 Land a | J16: =F16+G16-H16 -> 0
A17: 2321 Buildings | J17: =F17+G17-H17 -> 0
A18: 2331 Improvements Other Than Buildings | J18: =F18+G18-H18 -> 0
A19: 2341 Equipment | F19: 1161084.4 | J19: =F19+G19-H19 -> 1161084.4
A20: 2350 Construction Work in Progress a | J20: =F20+G20-H20 -> 0
A21: 2361 Infrastructure - Non Depreciable a | J21: =F21+G21-H21 -> 0
A23: Intangible Assets
A24: 2411 Computer Software - Amortizable | F24: 46612.91 | G24: 244.97 | J24: =F24+G24-H24 -> 46857.88
A25: 2412 Land Use Rights - Amortizable | J25: =F25+G25-H25 -> 0
A26: 2413 Patents, Copyrights, and Trademarks - Amortizable | J26: =F26+G26-H26 -> 0
A27: 2414 Other Intangible Assets - Amortizable | J27: =F27+G27-H27 -> 0
A28: 2415 Right-to-Use Leased Land - Amortizable | J28: =F28+G28-H28 -> 0
A29: 2416 Right-to-Use Leased Buildings - Amortizable | J29: =F29+G29-H29 -> 0
A30: 2417 Right-to-Use Leased Equipment - Amortizable | J30: =F30+G30-H30 -> 0
A31: 2418 Right-to-Use Subscription-Based Information Technology Arrangements (SBITA) - Amortizable | F31: 2917.18 | G31: 586.15401 | H31: 1031.4191 | J31: =F31+G31-H31 -> 2471.9149
A32: 2422 Land Use Rights - Non-Amortizable | J32: =F32+G32-H32 -> 0
A35: Fund: | B35: 0041 | F35: =SUM(F16:F34) -> 1210614.5 | G35: =SUM(G16:G34) -> 831.12401 | H35: =SUM(H16:H34) -> 1031.4191 | J35: =SUM(J16:J34) -> 1210414.2
A37: Note:
A38: a - Infrastructure only.
A40: I certify (or declare) under penalty of perjury that the attached reports are true, accurate and complete, and were prepared following the applicable laws, regulations, policies, procedures, and instructions. I have not violated any of the provisions of Article 4, Chapter 1, Division 4, Title 1, Government Code (commencing with Section 1090) and Article 2, Chapter 1, Part 3, Division 3, Title 2, Government Code (commencing with Section 13030).
A46: Subscribed and executed this 30th day of August, 2024 at Sacramento, California.
I52: KIM PHAN, Chief
I53: Service Transactions & Asset
I54: Reconciliation Section

Sheet 0042
I1: Page No : 3
A2: REPORT 18 – STATEMENT OF CHANGES IN CAPITAL ASSETS
A3: Department Name (2660)
A4: STATE HIGHWAY ACCOUNT FUND (0042)
A5: Fiscal Year 2023-24
A6: As of 06/30/2024
A7: Business Unit: | C7: 2660 - DEPARTMENT OF TRANSPORTATION | I7: Report ID: | J7: RPTGL075
A8: Fund: | C8: 0042 - STATE HIGHWAY ACCOUNT FUND | I8: Run Date: | J8: =TODAY() -> 45723
I9: Run Time: | J9: =NOW() -> 45723.508
A14: Account – Description | F14: Beginning Balance | G14: Additions | H14: Deductions | J14: Ending Balance
A15: Tangible Assets
A16: 2310 Land a | F16: =F46 -> 1.564042e+10 | G16: =G46 -> 81451063 | H16: =H46 -> 9765407.8 | J16: =F16+G16-H16 -> 1.5712106e+10
A17: 2321 Buildings | F17: 1.4156632e+09 | G17: 42601673 | J17: =F17+G17-H17 -> 1.4582649e+09
A18: 2331 Improvements Other Than Buildings | J18: =F18+G18-H18 -> 0
A19: 2341 Equipment | F19: 1.4379425e+09 | G19: 1.8596728e+08 | H19: 496553.53 | J19: =F19+G19-H19 -> 1.6234132e+09 | K19: Use CT11 and CT12 for CY Additions and Deductions (Absolute Values)
A20: 2350 Construction Work in Progress a | F20: 7.8459633e+09 | G20: 1.4755909e+09 | H20: 8.4688869e+08 | J20: =F20+G20-H20 -> 8.4746656e+09
A21: 2361 Infrastructure - Non Depreciable b | F21: 7.6082172e+10 | G21: 9.4013799e+08 | H21: 34997799 | J21: =F21+G21-H21 -> 7.6987312e+10
A23: Intangible Assets
A24: 2411 Computer Software - Amortizable | F24: 2.0057783e+08 | G24: 9250221.4 | J24: =F24+G24-H24 -> 2.0982805e+08
A25: 2412 Land Use Rights - Amortizable | J25: =F25+G25-H25 -> 0
A26: 2413 Patents, Copyrights, and Trademarks - Amortizable | F26: 374638.98 | J26: =F26+G26-H26 -> 374638.98
A27: 2414 Other Intangible Assets - Amortizable | J27: =F27+G27-H27 -> 0
A28: 2415 Right-to-Use Leased Land - Amortizable | J28: =F28+G28-H28 -> 0
A29: 2416 Right-to-Use Leased Buildings - Amortizable | F29: 91516505 | G29: 22460939 | H29: 7311305 | J29: =F29+G29-H29 -> 1.0666614e+08
A30: 2417 Right-to-Use Leased Equipment - Amortizable | J30: =F30+G30-H30 -> 0
A31: 2418 Right-to-Use Subscription-Based Information Technology Arrangements (SBITA) - Amortizable | F31: 8479526.8 | G31: 1696224.9 | H31: 2870666.8 | J31: =F31+G31-H31 -> 7305084.9
A32: 2422 Land Use Rights - Non-Amortizable | J32: =F32+G32-H32 -> 0
A35: Fund: | B35: 0042 | F35: =SUM(F16:F34) -> 1.0272311e+11 | G35: =SUM(G16:G34) -> 2.7591563e+09 | H35: =SUM(H16:H34) -> 9.0233042e+08 | J35: =SUM(J16:J34) -> 1.0457994e+11
A37: Note:
F38: Total | G38: Additions | H38: Deductions | J38: Total
A39: Land - Excess Land (2310-1000) | F39: 117804433 | G39: 2590694 | H39: 2963759 | J39: =F39+G39-H39 -> 117431368
A40: Land - Park Lease (2310-4001) | F40: 45936 | J40: =F40+G40-H40 -> 45936
A41: Land - Operational Dept (2310-5000) | F41: 62974266 | G41: 716392.57 | J41: =F41+G41-H41 -> 63690658
A42: Land - Operational Federal (2310-5001) | F42: 1991250 | J42: =F42+G42-H42 -> 1991250
A43: Land - Infrastructure Dept (2310-5900) | F43: 1.3467719e+10 | G43: 58321705 | H43: 6801648.8 | J43: =F43+G43-H43 -> 1.3519239e+10
A44: Land - Infrastructure Federal (2310-5901) | F44: 1.9898852e+09 | G44: 19822272 | J44: =F44+G44-H44 -> 2.0097075e+09
A46: a - Total Land | F46: =SUM(F39:F45) -> 1.564042e+10 | G46: =SUM(G39:G45) -> 81451063 | H46: =SUM(H39:I44) -> 9765407.8 | J46: =SUM(J39:J45) -> 1.5712106e+10
A48: b - Infrastructure only.
A50: c1 - The $2,963,759 in Excess Land (0042) Deductions amount is the result of the following:
D52: 1. Deduction amount is the result of routine disposal/sales transactions. | J52: 1805530
...

Sheet F0042 Diff
A1: Department of Transportation (2660)
A2: Statement of Changes in Capital Assets Group of Accounts - Report 18
A3: Beginning Balance Differential Report
A4: State Highway Account Fund (0042)
A5: As of June 30, 2024
K7: Breakdown of Difference:
E8: (1) | G8: (2) | I8: (3) | K8: (4) | M8: (5) | O8: (6) | Q8: (7) | S8: (8) | T8: (9) | V8: (10)
E9: Prior Year Ending Balance | G9: Current Year Beginning Balance | I9: Difference | K9: Assets unreported in the prior year | M9: Non-capitalizable assets reported as capital assets in the prior year | O9: Availability Payment Arrangements (GASB 94) | Q9: Other amounts that make up the difference (provide description): Per SCO guidance, applying % to District Project Survey % adjustment for Prior Year Expenditures. | S9: Other amounts that make up the difference (provide description): incorrect entry was made in current year balance | T9: Other amounts that make up the difference (provide description): Prior Year Fund to Fund Adjustment. | V9: Restatement Amount (should agree to the difference calculated)
A11: Tangible Assets
B12: Land (2310) | E12: 1.5634135e+10 | G12: 1.564042e+10 | I12: =G12-E12 -> 6285322.6 | Q12: 6285322.6 | V12: =SUM(K12:T12) -> 6285322.6
B13: Buildings (2321) | E13: 1.4156632e+09 | G13: 1.4156632e+09 | I13: =G13-E13 -> 0 | V13: =SUM(K13:T13) -> 0
B14: Improvements Other Than Buildings (2331) | I14: =G14-E14 -> 0 | V14: =SUM(K14:T14) -> 0
B15: Equipment (2341) | E15: 1.4379425e+09 | G15: 1.4379425e+09 | I15: =G15-E15 -> 0 | V15: =SUM(K15:T15) -> 0
B16: Construction Work in Progress (2350) | E16: 7.859028e+09 | G16: 7.8459633e+09 | I16: =G16-E16 -> -13064680 | Q16: 3027102.2 | T16: -16091782 | V16: =SUM(K16:T16) -> -13064680
B17: Infrastructure - Non Depreciable (2361) | E17: 7.5953678e+10 | G17: 7.6082172e+10 | I17: =G17-E17 -> 1.2849325e+08 | Q17: 1.2047809e+08 | T17: 8015163.2 | V17: =SUM(K17:T17) -> 1.2849325e+08
A18: Intangible Assets | V18: =SUM(K18:T18) -> 0
B19: Computer Software - Amortizable (2411) | E19: 2.0057783e+08 | G19: 2.0057783e+08 | I19: =G19-E19 -> 0 | V19: =SUM(K19:T19) -> 0
B20: Land Use Rights - Amortizable (2412) | V20: =SUM(K20:T20) -> 0
B21: Patents, Copyrights, and Trademarks - Amortizable (2413) | E21: 374638.98 | G21: 374638.98 | I21: =G21-E21 -> 0 | V21: =SUM(K21:T21) -> 0
B22: Other Intangible Assets - Amortizable (2414) | V22: =SUM(K22:T22) -> 0
B23: Right-to-Use Leased Land - Amortizable () | V23: =SUM(K23:T23) -> 0
B24: Right-to-Use Leased Buildings - Amortizable (2416) | E24: 91516505 | G24: 91516505 | I24: =G24-E24 -> 0 | V24: =SUM(K24:T24) -> 0
B25: Right-to-Use Leased Equipment - Amortizable | V25: =SUM(K25:T25) -> 0
B26: Right-to-Use Subscription-Based Information Technology Arrangements (SBITA) - Amortizable (2418) | E26: 8479526.8 | G26: 8479526.8 | I26: =G26-E26 -> 0 | S26: 0 | V26: =SUM(K26:T26) -> 0
B27: Land Use Rights - Non-Amortizable (2422) | V27: =SUM(K27:T27) -> 0
B28: Patents, Copyrights, and Trademarks - Non-Amortizable | I28: =G28-E28 -> 0 | V28: =SUM(K28:T28) -> 0
A29: Total | E29: =SUM(E12:E28) -> 1.026014e+11 | G29: =SUM(G12:G28) -> 1.0272311e+11 | I29: =SUM(I12:I28) -> 1.2171389e+08 | K29: =SUM(K12:K28) -> 0 | M29: =SUM(M12:M28) -> 0 | O29: =SUM(O12:O28) -> 0 | Q29: =SUM(Q12:Q28) -> 1.2979051e+08 | S29: =SUM(S12:S28) -> 0 | T29: =SUM(T12:T28) -> -8076618.6 | V29: =SUM(V12:V28) -> 1.2171389e+08
A32: Report Instructions:
A33: Col. 1 - | C33: Enter Ending Balance from Prior Year Report 18.
A34: Col. 2 - | C34: Enter Beginning Balance from Current Year Report 18.
A35: Col. 3 - | C35: Compute difference between current year beginning balance and prior year ending balance.
C36: Research posting and source documents to identify and explain the difference.
A37: Col. 4 - 9 | C37: Breakdown and categorize the differences in columns 4 to 9.
A38: Col. 10 - | C38: Compute the sum of columns 4 to 8. The amount should agree with the computed difference in column 3.

Sheet 0042 Revised
I1: Page No : 3
A2: REPORT 18 – STATEMENT OF CHANGES IN CAPITAL ASSETS
A3: Department Name (2660)
A4: STATE HIGHWAY ACCOUNT FUND (0042)
A5: Fiscal Year 2023-24 Revised 2/6/2025
A6: =[1]Date!A2 -> As of 06/30/2024
A7: Business Unit: | C7: 2660 - DEPARTMENT OF TRANSPORTATION | I7: Report ID: | J7: RPTGL075
A8: Fund: | C8: 0042 - STATE HIGHWAY ACCOUNT FUND | I8: Run Date: | J8: =TODAY() -> 45723
I9: Run Time: | J9: =NOW() -> 45723.508
A14: Account – Description | F14: Beginning Balance | G14: Additions | H14: Deductions | J14: Ending Balance
A15: Tangible Assets
A16: 2310 Land a | F16: 1.4969009e+10 | G16: 81451063 | H16: 9765407.8 | J16: =F16+G16-H16 -> 1.5040695e+10
A17: 2321 Buildings | F17: 1.4156632e+09 | G17: 42601673 | J17: =F17+G17-H17 -> 1.4582649e+09
A18: 2331 Improvements Other Than Buildings | J18: =F18+G18-H18 -> 0
A19: 2341 Equipment | F19: 1.4379425e+09 | G19: 1.8596728e+08 | H19: 496553.53 | J19: =F19+G19-H19 -> 1.6234132e+09
A20: 2350 Construction Work in Progress a | F20: 7.8459633e+09 | G20: 1.4755909e+09 | H20: 8.4688869e+08 | J20: =F20+G20-H20 -> 8.4746656e+09
A21: 2361 Infrastructure - Non Depreciable b | F21: 7.6753583e+10 | G21: 9.4013799e+08 | H21: 34997799 | J21: =F21+G21-H21 -> 7.7658723e+10
A23: Intangible Assets
A24: 2411 Computer Software - Amortizable | F24: 2.0057783e+08 | G24: 9250221.4 | J24: =F24+G24-H24 -> 2.0982805e+08
A25: 2412 Land Use Rights - Amortizable | J25: =F25+G25-H25 -> 0
A26: 2413 Patents, Copyrights, and Trademarks - Amortizable | F26: 374638.98 | J26: =F26+G26-H26 -> 374638.98
A27: 2414 Other Intangible Assets - Amortizable | J27: =F27+G27-H27 -> 0
A28: 2415 Right-to-Use Leased Land - Amortizable | J28: =F28+G28-H28 -> 0
A29: 2416 Right-to-Use Leased Buildings - Amortizable | F29: 91516505 | G29: 22460939 | H29: 7311305 | J29: =F29+G29-H29 -> 1.0666614e+08
A30: 2417 Right-to-Use Leased Equipment - Amortizable | J30: =F30+G30-H30 -> 0
A31: 2418 Right-to-Use Subscription-Based Information Technology Arrangements (SBITA) - Amortizable | F31: 8479526.8 | G31: 1696224.9 | H31: 2870666.8 | J31: =F31+G31-H31 -> 7305084.9
A32: 2422 Land Use Rights - Non-Amortizable | J32: =F32+G32-H32 -> 0
A35: Fund: | B35: 0042 | F35: =SUM(F16:F34) -> 1.0272311e+11 | G35: =SUM(G16:G34) -> 2.7591563e+09 | H35: =SUM(H16:H34) -> 9.0233042e+08 | J35: =SUM(J16:J34) -> 1.0457994e+11
A37: Note:
F38: Total | G38: Additions | H38: Deductions | J38: Total
A39: Land - Excess Land (2310-1000) | F39: 117804433 | G39: 2590694 | H39: 2963759 | J39: =F39+G39-H39 -> 117431368
A40: Land - Park Lease (2310-4001) | F40: 45936 | J40: =F40+G40-H40 -> 45936
A41: Land - Operational Dept (2310-5000) | F41: 62974266 | G41: 716392.57 | J41: =F41+G41-H41 -> 63690658
A42: Land - Operational Federal (2310-5001) | F42: 1991250 | J42: =F42+G42-H42 -> 1991250
A43: Land - Infrastructure Dept (2310-5900) | F43: 1.3266296e+10 | G43: 58321705 | H43: 6801648.8 | J43: =F43+G43-H43 -> 1.3317816e+10
A44: Land - Infrastructure Federal (2310-5901) | F44: 1.5198974e+09 | G44: 19822272 | J44: =F44+G44-H44 -> 1.5397197e+09
A46: a - Total Land | F46: =SUM(F39:F45) -> 1.4969009e+10 | G46: =SUM(G39:G45) -> 81451063 | H46: =SUM(H39:I44) -> 9765407.8 | J46: =SUM(J39:J45) -> 1.5040695e+10
A48: b - Infrastructure only.
A50: c1 - The $2,963,759 in Excess Land (0042) Deductions amount is the result of the following:
D52: 1. Deduction amount is the result of routine disposal/sales transactions. | J52: 1805530
...

Sheet F0042 Diff Revised
A1: Department of Transportation (2660)
A2: Statement of Changes in Capital Assets Group of Accounts - Report 18
A3: Beginning Balance Differential Report
A4: State Highway Account Fund (0042)
A5: As of June 30, 2024 Revised 2/6/2025
K7: Breakdown of Difference:
E8: (1) | G8: (2) | I8: (3) | K8: (4) | M8: (5) | O8: (6) | Q8: (7) | S8: (8) | T8: (9) | V8: (10)
E9: Prior Year Ending Balance | G9: Current Year Beginning Balance | I9: Difference | K9: Assets unreported in the prior year | M9: Non-capitalizable assets reported as capital assets in the prior year | O9: Availability Payment Arrangements (GASB 94) | Q9: Other amounts that make up the difference (provide description): Per SCO guidance, applying % to District Project Survey % adjustment for Prior Year Expenditures. | S9: Other amounts that make up the difference (provide description): incorrect entry was made in current year balance | T9: Other amounts that make up the difference (provide description): Prior Year Fund to Fund Adjustment. | V9: Restatement Amount (should agree to the difference calculated)
A11: Tangible Assets
B12: Land (2310) | E12: 1.4962724e+10 | G12: 1.4969009e+10 | I12: =G12-E12 -> 6285322.6 | Q12: 6285322.6 | V12: =SUM(K12:T12) -> 6285322.6
B13: Buildings (2321) | E13: 1.4156632e+09 | G13: 1.4156632e+09 | I13: =G13-E13 -> 0 | V13: =SUM(K13:T13) -> 0
B14: Improvements Other Than Buildings (2331) | I14: =G14-E14 -> 0 | V14: =SUM(K14:T14) -> 0
B15: Equipment (2341) | E15: 1.4379425e+09 | G15: 1.4379425e+09 | I15: =G15-E15 -> 0 | V15: =SUM(K15:T15) -> 0
B16: Construction Work in Progress (2350) | E16: 7.859028e+09 | G16: 7.8459633e+09 | I16: =G16-E16 -> -13064680 | Q16: 3027102.2 | T16: -16091782 | V16: =SUM(K16:T16) -> -13064680
B17: Infrastructure - Non Depreciable (2361) | E17: 7.6625089e+10 | G17: 7.6753583e+10 | I17: =G17-E17 -> 1.2849325e+08 | Q17: 1.2047809e+08 | T17: 8015163.2 | V17: =SUM(K17:T17) -> 1.2849325e+08
A18: Intangible Assets | V18: =SUM(K18:T18) -> 0
B19: Computer Software - Amortizable (2411) | E19: 2.0057783e+08 | G19: 2.0057783e+08 | I19: =G19-E19 -> 0 | V19: =SUM(K19:T19) -> 0
B20: Land Use Rights - Amortizable (2412) | V20: =SUM(K20:T20) -> 0
B21: Patents, Copyrights, and Trademarks - Amortizable (2413) | E21: 374638.98 | G21: 374638.98 | I21: =G21-E21 -> 0 | V21: =SUM(K21:T21) -> 0
B22: Other Intangible Assets - Amortizable (2414) | V22: =SUM(K22:T22) -> 0
B23: Right-to-Use Leased Land - Amortizable () | V23: =SUM(K23:T23) -> 0
B24: Right-to-Use Leased Buildings - Amortizable (2416) | E24: 91516505 | G24: 91516505 | I24: =G24-E24 -> 0 | V24: =SUM(K24:T24) -> 0
B25: Right-to-Use Leased Equipment - Amortizable | V25: =SUM(K25:T25) -> 0
B26: Right-to-Use Subscription-Based Information Technology Arrangements (SBITA) - Amortizable (2418) | E26: 8479526.8 | G26: 8479526.8 | I26: =G26-E26 -> 0 | S26: 0 | V26: =SUM(K26:T26) -> 0
B27: Land Use Rights - Non-Amortizable (2422) | V27: =SUM(K27:T27) -> 0
B28: Patents, Copyrights, and Trademarks - Non-Amortizable | I28: =G28-E28 -> 0 | V28: =SUM(K28:T28) -> 0
A29: Total | E29: =SUM(E12:E28) -> 1.026014e+11 | G29: =SUM(G12:G28) -> 1.0272311e+11 | I29: =SUM(I12:I28) -> 1.2171389e+08 | K29: =SUM(K12:K28) -> 0 | M29: =SUM(M12:M28) -> 0 | O29: =SUM(O12:O28) -> 0 | Q29: =SUM(Q12:Q28) -> 1.2979051e+08 | S29: =SUM(S12:S28) -> 0 | T29: =SUM(T12:T28) -> -8076618.6 | V29: =SUM(V12:V28) -> 1.2171389e+08
A32: Report Instructions:
A33: Col. 1 - | C33: Enter Ending Balance from Prior Year Report 18.
A34: Col. 2 - | C34: Enter Beginning Balance from Current Year Report 18.
A35: Col. 3 - | C35: Compute difference between current year beginning balance and prior year ending balance.
C36: Research posting and source documents to identify and explain the difference.
A37: Col. 4 - 9 | C37: Breakdown and categorize the differences in columns 4 to 9.
A38: Col. 10 - | C38: Compute the sum of columns 4 to 8. The amount should agree with the computed difference in column 3.

Sheet 0046
I1: Page No : 4
A2: REPORT 18 – STATEMENT OF CHANGES IN CAPITAL ASSETS
A3: Department Name (2660)
A4: PUBLIC TRANSPORTATION ACCOUNT (0046)
A5: Fiscal Year 2023-24
A6: As of 06/30/2024
A7: Business Unit: | C7: 2660 - DEPARTMENT OF TRANSPORTATION | I7: Report ID: | J7: RPTGL075
A8: Fund: | C8: 0046 - PUBLIC TRANSPORTATION ACCOUNT | I8: Run Date: | J8: =TODAY() -> 45723
I9: Run Time: | J9: =NOW() -> 45723.508
A14: Account – Description | F14: Beginning Balance | G14: Additions | H14: Deductions | J14: Ending Balance
A15: Tangible Assets
A16: 2310 Land a | J16: =F16+G16-H16 -> 0
A17: 2321 Buildings | J17: =F17+G17-H17 -> 0
A18: 2331 Improvements Other Than Buildings | J18: =F18+G18-H18 -> 0
A19: 2341 Equipment | F19: 40064932 | G19: 1267363.2 | J19: =F19+G19-H19 -> 41332295
A20: 2350 Construction Work in Progress a | J20: =F20+G20-H20 -> 0
A21: 2361 Infrastructure - Non Depreciable a | F21: 7120136.5 | J21: =F21+G21-H21 -> 7120136.5
A23: Intangible Assets
A24: 2411 Computer Software - Amortizable | F24: 2193840.4 | G24: 432271.5 | J24: =F24+G24-H24 -> 2626111.9
A25: 2412 Land Use Rights - Amortizable | J25: =F25+G25-H25 -> 0
A26: 2413 Patents, Copyrights, and Trademarks - Amortizable | J26: =F26+G26-H26 -> 0
A27: 2414 Other Intangible Assets - Amortizable | J27: =F27+G27-H27 -> 0
A28: 2415 Right-to-Use Leased Land - Amortizable | J28: =F28+G28-H28 -> 0
A29: 2416 Right-to-Use Leased Buildings - Amortizable | J29: =F29+G29-H29 -> 0
A30: 2417 Right-to-Use Leased Equipment - Amortizable | F30: 17089708 | J30: =F30+G30-H30 -> 17089708
A31: 2418 Right-to-Use Subscription-Based Information Technology Arrangements (SBITA) - Amortizable | F31: 135390.6 | G31: 27869.276 | H31: 45732.922 | J31: =F31+G31-H31 -> 117526.95
A32: 2422 Land Use Rights - Non-Amortizable | J32: =F32+G32-H32 -> 0
A35: Fund: | B35: 0046 | F35: =SUM(F16:F34) -> 66604007 | G35: =SUM(G16:G33) -> 1727503.9 | H35: =SUM(H16:H33) -> 45732.922 | J35: =SUM(J16:J33) -> 68285778
A37: Note:
A38: a - Infrastructure only.
A41: I certify (or declare) under penalty of perjury that the attached reports are true, accurate and complete, and were prepared following the applicable laws, regulations, policies, procedures, and instructions. I have not violated any of the provisions of Article 4, Chapter 1, Division 4, Title 1, Government Code (commencing with Section 1090) and Article 2, Chapter 1, Part 3, Division 3, Title 2, Government Code (commencing with Section 13030).
A46: Subscribed and executed this 30th day of August, 2024 at Sacramento, California.
I52: KIM PHAN, Chief
I53: Service Transactions & Asset
I54: Reconciliation Section

Sheet 0183
I1: Page No : 5
A2: REPORT 18 – STATEMENT OF CHANGES IN CAPITAL ASSETS
A3: Department Name (2660)
A4: ENVIRONMENTAL ENHANCEMENT AND MITIGATION (0183)
A5: Fiscal Year 2023-24
A6: As of 06/30/2024
A7: Business Unit: | C7: 2660 - DEPARTMENT OF TRANSPORTATION | I7: Report ID: | J7: RPTGL075
A8: Fund: | C8: 0183 - ENVIRONMENTAL ENHANCEMENT AND MITIGATION | I8: Run Date: | J8: =TODAY() -> 45723
I9: Run Time: | J9: =NOW() -> 45723.508
A14: Account – Description | F14: Beginning Balance | G14: Additions | H14: Deductions | J14: Ending Balance
A15: Tangible Assets
A16: 2310 Land a | J16: =F16+G16-H16 -> 0
A17: 2321 Buildings | J17: =F17+G17-H17 -> 0
A18: 2331 Improvements Other Than Buildings | J18: =F18+G18-H18 -> 0
A19: 2341 Equipment | J19: =F19+G19-H19 -> 0
A20: 2350 Construction Work in Progress a | F20: 61012094 | J20: =F20+G20-H20 -> 61012094
A21: 2361 Infrastructure - Non Depreciable a | F21: 1657162.1 | J21: =F21+G21-H21 -> 1657162.1
A23: Intangible Assets
A24: 2411 Computer Software - Amortizable | J24: =F24+G24-H24 -> 0
A25: 2412 Land Use Rights - Amortizable | J25: =F25+G25-H25 -> 0
A26: 2413 Patents, Copyrights, and Trademarks - Amortizable | J26: =F26+G26-H26 -> 0
A27: 2414 Other Intangible Assets - Amortizable | J27: =F27+G27-H27 -> 0
A28: 2415 Right-to-Use Leased Land - Amortizable | J28: =F28+G28-H28 -> 0
A29: 2416 Right-to-Use Leased Buildings - Amortizable | J29: =F29+G29-H29 -> 0
A30: 2417 Right-to-Use Leased Equipment - Amortizable | J30: =F30+G30-H30 -> 0
A31: 2418 Right-to-Use Subscription-Based Information Technology Arrangements (SBITA) - Amortizable | J31: =F31+G31-H31 -> 0
A32: 2422 Land Use Rights - Non-Amortizable | J32: =F32+G32-H32 -> 0
A35: Fund: | B35: 0183 | F35: =SUM(F16:F34) -> 62669256 | G35: =SUM(G16:G34) -> 0 | H35: =SUM(H16:H34) -> 0 | J35: =SUM(J16:J34) -> 62669256
A37: Note:
A38: a - Infrastructure only.
A40: I certify (or declare) under penalty of perjury that the attached reports are true, accurate and complete, and were prepared following the applicable laws, regulations, policies, procedures, and instructions. I have not violated any of the provisions of Article 4, Chapter 1, Division 4, Title 1, Government Code (commencing with Section 1090) and Article 2, Chapter 1, Part 3, Division 3, Title 2, Government Code (commencing with Section 13030).
A46: Subscribed and executed this 30th day of August, 2024 at Sacramento, California.
I55: KIM PHAN, Chief
I56: Service Transactions & Asset
I57: Reconciliation Section

Sheet 0523
I1: Page No : 6
A2: REPORT 18 – STATEMENT OF CHANGES IN CAPITAL ASSETS
A3: Department Name (2660)
A4: EAST BAY STATE BUILDING AUTHORITY FUND (0523)
A5: Fiscal Year 2023-24
A6: As of 06/30/2024
A7: Business Unit: | C7: 2660 - DEPARTMENT OF TRANSPORTATION | I7: Report ID: | J7: RPTGL075
A8: Fund: | C8: 0523 EAST BAY STATE BUILDING AUTHORITY FUND | I8: Run Date: | J8: =TODAY() -> 45723
I9: Run Time: | J9: =NOW() -> 45723.508
A14: Account – Description | F14: Beginning Balance | G14: Additions | H14: Deductions | J14: Ending Balance
A15: Tangible Assets
A16: 2310 Land a | F16: 8000000 | J16: =F16+G16-H16 -> 8000000
A17: 2321 Buildings | F17: 2.8527591e+08 | J17: =F17+G17-H17 -> 2.8527591e+08
A18: 2331 Improvements Other Than Buildings | J18: =F18+G18-H18 -> 0
A19: 2341 Equipment | J19: =F19+G19-H19 -> 0
A20: 2350 Construction Work in Progress a | J20: =F20+G20-H20 -> 0
A21: 2361 Infrastructure - Non Depreciable a | J21: =F21+G21-H21 -> 0
A23: Intangible Assets
A24: 2411 Computer Software - Amortizable | J24: =F24+G24-H24 -> 0
A25: 2412 Land Use Rights - Amortizable | J25: =F25+G25-H25 -> 0
A26: 2413 Patents, Copyrights, and Trademarks - Amortizable | J26: =F26+G26-H26 -> 0
A27: 2414 Other Intangible Assets - Amortizable | J27: =F27+G27-H27 -> 0
A28: 2415 Right-to-Use Leased Land - Amortizable | J28: =F28+G28-H28 -> 0
A29: 2416 Right-to-Use Leased Buildings - Amortizable | J29: =F29+G29-H29 -> 0
A30: 2417 Right-to-Use Leased Equipment - Amortizable | J30: =F30+G30-H30 -> 0
A31: 2418 Right-to-Use Subscription-Based Information Technology Arrangements (SBITA) - Amortizable | J31: =F31+G31-H31 -> 0
A32: 2422 Land Use Rights - Non-Amortizable | J32: =F32+G32-H32 -> 0
A35: Fund: | B35: 0523 | F35: =SUM(F16:F34) -> 2.9327591e+08 | G35: =SUM(G16:G34) -> 0 | H35: =SUM(H16:H34) -> 0 | J35: =SUM(J16:J34) -> 2.9327591e+08
A37: Note:
A38: a - Infrastructure only.
A40: I certify (or declare) under penalty of perjury that the attached reports are true, accurate and complete, and were prepared following the applicable laws, regulations, policies, procedures, and instructions. I have not violated any of the provisions of Article 4, Chapter 1, Division 4, Title 1, Government Code (commencing with Section 1090) and Article 2, Chapter 1, Part 3, Division 3, Title 2, Government Code (commencing with Section 13030).
A46: Subscribed and executed this 30th day of August, 2024 at Sacramento, California.
I52: KIM PHAN, Chief
I53: Service Transactions & Asset
I54: Reconciliation Section

Sheet 0541
I1: Page No : 7
A2: REPORT 18 – STATEMENT OF CHANGES IN CAPITAL ASSETS
A3: Department Name (2660)
A4: SAN BERNARDINO STATE BUILDING AUTHORITY (0541)
A5: Fiscal Year 2023-24
A6: As of 06/30/2024
A7: Business Unit: | C7: 2660 - DEPARTMENT OF TRANSPORTATION | I7: Report ID: | J7: RPTGL075
A8: Fund: | C8: 0541 SAN BERNARDINO STATE BUILDING AUTHORITY | I8: Run Date: | J8: =TODAY() -> 45723
I9: Run Time: | J9: =NOW() -> 45723.508
A14: Account – Description | F14: Beginning Balance | G14: Additions | H14: Deductions | J14: Ending Balance
A15: Tangible Assets
A16: 2310 Land a | J16: =F16+G16-H16 -> 0
A17: 2321 Buildings | F17: 56772761 | J17: =F17+G17-H17 -> 56772761
A18: 2331 Improvements Other Than Buildings | J18: =F18+G18-H18 -> 0
A19: 2341 Equipment | J19: =F19+G19-H19 -> 0
A20: 2350 Construction Work in Progress a | J20: =F20+G20-H20 -> 0
A21: 2361 Infrastructure - Non Depreciable a | J21: =F21+G21-H21 -> 0
A23: Intangible Assets
A24: 2411 Computer Software - Amortizable | J24: =F24+G24-H24 -> 0
A25: 2412 Land Use Rights - Amortizable | J25: =F25+G25-H25 -> 0
A26: 2413 Patents, Copyrights, and Trademarks - Amortizable | J26: =F26+G26-H26 -> 0
A27: 2414 Other Intangible Assets - Amortizable | J27: =F27+G27-H27 -> 0
A28: 2415 Right-to-Use Leased Land - Amortizable | J28: =F28+G28-H28 -> 0
A29: 2416 Right-to-Use Leased Buildings - Amortizable | J29: =F29+G29-H29 -> 0
A30: 2417 Right-to-Use Leased Equipment - Amortizable | J30: =F30+G30-H30 -> 0
A31: 2418 Right-to-Use Subscription-Based Information Technology Arrangements (SBITA) - Amortizable | J31: =F31+G31-H31 -> 0
A32: 2422 Land Use Rights - Non-Amortizable | J32: =F32+G32-H32 -> 0
A35: Fund: | B35: 0541 | F35: =SUM(F16:F34) -> 56772761 | G35: =SUM(G16:G34) -> 0 | H35: =SUM(H16:H34) -> 0 | J35: =SUM(J16:J34) -> 56772761
A37: Note:
A38: a - Infrastructure only.
A40: I certify (or declare) under penalty of perjury that the attached reports are true, accurate and complete, and were prepared following the applicable laws, regulations, policies, procedures, and instructions. I have not violated any of the provisions of Article 4, Chapter 1, Division 4, Title 1, Government Code (commencing with Section 1090) and Article 2, Chapter 1, Part 3, Division 3, Title 2, Government Code (commencing with Section 13030).
A46: Subscribed and executed this 30th day of August, 2024 at Sacramento, California.
I52: KIM PHAN, Chief
I53: Service Transactions & Asset
I54: Reconciliation Section

Sheet 0653
I1: Page No : 8
A2: REPORT 18 – STATEMENT OF CHANGES IN CAPITAL ASSETS
A3: Department Name (2660)
A4: SEISMIC RETROFIT BOND FUND OF 1996 (0653)
A5: Fiscal Year 2023-24
A6: As of 06/30/2024
A7: Business Unit: | C7: 2660 - DEPARTMENT OF TRANSPORTATION | I7: Report ID: | J7: RPTGL075
A8: Fund: | C8: 0653 SEISMIC RETROFIT BOND FUND OF 1996 | I8: Run Date: | J8: =TODAY() -> 45723
I9: Run Time: | J9: =NOW() -> 45723.508
A14: Account – Description | F14: Beginning Balance | G14: Additions | H14: Deductions | J14: Ending Balance
A15: Tangible Assets
A16: 2310 Land a | F16: 300093.59 | J16: =F16+G16-H16 -> 300093.59
A17: 2321 Buildings | F17: 13055910 | J17: =F17+G17-H17 -> 13055910
A18: 2331 Improvements Other Than Buildings | J18: =F18+G18-H18 -> 0
A19: 2341 Equipment | F19: 267582.18 | J19: =F19+G19-H19 -> 267582.18
A20: 2350 Construction Work in Progress a | F20: 1743959.2 | J20: =F20+G20-H20 -> 1743959.2
A21: 2361 Infrastructure - Non Depreciable a | F21: 61523709 | J21: =F21+G21-H21 -> 61523709
A23: Intangible Assets
A24: 2411 Computer Software - Amortizable | J24: =F24+G24-H24 -> 0
A25: 2412 Land Use Rights - Amortizable | J25: =F25+G25-H25 -> 0
A26: 2413 Patents, Copyrights, and Trademarks - Amortizable | J26: =F26+G26-H26 -> 0
A27: 2414 Other Intangible Assets - Amortizable | J27: =F27+G27-H27 -> 0
A28: 2415 Right-to-Use Leased Land - Amortizable | J28: =F28+G28-H28 -> 0
A29: 2416 Right-to-Use Leased Buildings - Amortizable | J29: =F29+G29-H29 -> 0
A30: 2417 Right-to-Use Leased Equipment - Amortizable | J30: =F30+G30-H30 -> 0
A31: 2418 Right-to-Use Subscription-Based Information Technology Arrangements (SBITA) - Amortizable | J31: =F31+G31-H31 -> 0
A32: 2422 Land Use Rights - Non-Amortizable | J32: =F32+G32-H32 -> 0
A35: Fund: | B35: 0653 | F35: =SUM(F16:F34) -> 76891254 | G35: =SUM(G16:G34) -> 0 | H35: =SUM(H16:H34) -> 0 | J35: =SUM(J16:J34) -> 76891254
A37: Note:
A38: a - Infrastructure only.
A40: I certify (or declare) under penalty of perjury that the attached reports are true, accurate and complete, and were prepared following the applicable laws, regulations, policies, procedures, and instructions. I have not violated any of the provisions of Article 4, Chapter 1, Division 4, Title 1, Government Code (commencing with Section 1090) and Article 2, Chapter 1, Part 3, Division 3, Title 2, Government Code (commencing with Section 13030).
A46: Subscribed and executed this 30th day of August, 2024 at Sacramento, California.
I52: KIM PHAN, Chief
I53: Service Transactions & Asset
I54: Reconciliation Section

Sheet 0673
I1: Page No : 9
A2: REPORT 18 – STATEMENT OF CHANGES IN CAPITAL ASSETS
A3: Department Name (2660)
A4: PASSENGER EQUIPMENT ACQUISITION FUND (0673)
A5: Fiscal Year 2023-24
A6: As of 06/30/2024
A7: Business Unit: | C7: 2660 - DEPARTMENT OF TRANSPORTATION | I7: Report ID: | J7: RPTGL075
A8: Fund: | C8: 0673 PASSENGER EQUIPMENT ACQUISITION FUND | I8: Run Date: | J8: =TODAY() -> 45723
I9: Run Time: | J9: =NOW() -> 45723.508
A14: Account – Description | F14: Beginning Balance | G14: Additions | H14: Deductions | J14: Ending Balance
A15: Tangible Assets
A16: 2310 Land a | J16: =F16+G16-H16 -> 0
A17: 2321 Buildings | J17: =F17+G17-H17 -> 0
A18: 2331 Improvements Other Than Buildings | J18: =F18+G18-H18 -> 0
A19: 2341 Equipment | F19: 6674000 | J19: =F19+G19-H19 -> 6674000
A20: 2350 Construction Work in Progress a | J20: =F20+G20-H20 -> 0
A21: 2361 Infrastructure - Non Depreciable a | J21: =F21+G21-H21 -> 0
A23: Intangible Assets
A24: 2411 Computer Software - Amortizable | J24: =F24+G24-H24 -> 0
A25: 2412 Land Use Rights - Amortizable | J25: =F25+G25-H25 -> 0
A26: 2413 Patents, Copyrights, and Trademarks - Amortizable | J26: =F26+G26-H26 -> 0
A27: 2414 Other Intangible Assets - Amortizable | J27: =F27+G27-H27 -> 0
A28: 2415 Right-to-Use Leased Land - Amortizable | J28: =F28+G28-H28 -> 0
A29: 2416 Right-to-Use Leased Buildings - Amortizable | J29: =F29+G29-H29 -> 0
A30: 2417 Right-to-Use Leased Equipment - Amortizable | J30: =F30+G30-H30 -> 0
A31: 2418 Right-to-Use Subscription-Based Information Technology Arrangements (SBITA) - Amortizable | J31: =F31+G31-H31 -> 0
A32: 2422 Land Use Rights - Non-Amortizable | J32: =F32+G32-H32 -> 0
A35: Fund: | B35: 0673 | F35: =SUM(F16:F34) -> 6674000 | G35: =SUM(G16:G34) -> 0 | H35: =SUM(H16:H34) -> 0 | J35: =SUM(J16:J34) -> 6674000
A37: Note:
A38: a - Infrastructure only.
A40: I certify (or declare) under penalty of perjury that the attached reports are true, accurate and complete, and were prepared following the applicable laws, regulations, policies, procedures, and instructions. I have not violated any of the provisions of Article 4, Chapter 1, Division 4, Title 1, Government Code (commencing with Section 1090) and Article 2, Chapter 1, Part 3, Division 3, Title 2, Government Code (commencing with Section 13030).
A46: Subscribed and executed this 30th day of August, 2024 at Sacramento, California.
I52: KIM PHAN, Chief
I53: Service Transactions & Asset
I54: Reconciliation Section

Sheet 0703
I1: Page No : 10
A2: REPORT 18 – STATEMENT OF CHANGES IN CAPITAL ASSETS
A3: Department Name (2660)
A4: PROPOSITION 116 RAIL BONDS (0703)
A5: Fiscal Year 2023-24
A6: As of 06/30/2024
A7: Business Unit: | C7: 2660 - DEPARTMENT OF TRANSPORTATION | I7: Report ID: | J7: RPTGL075
A8: Fund: | C8: 0703 PROPOSITION 116 RAIL BONDS | I8: Run Date: | J8: =TODAY() -> 45723
I9: Run Time: | J9: =NOW() -> 45723.508
A14: Account – Description | F14: Beginning Balance | G14: Additions | H14: Deductions | J14: Ending Balance
A15: Tangible Assets
A16: 2310 Land a | J16: =F16+G16-H16 -> 0
A17: 2321 Buildings | J17: =F17+G17-H17 -> 0
A18: 2331 Improvements Other Than Buildings | J18: =F18+G18-H18 -> 0
A19: 2341 Equipment | F19: 70479745 | J19: =F19+G19-H19 -> 70479745
A20: 2350 Construction Work in Progress a | J20: =F20+G20-H20 -> 0
A21: 2361 Infrastructure - Non Depreciable a | J21: =F21+G21-H21 -> 0
A23: Intangible Assets
A24: 2411 Computer Software - Amortizable | J24: =F24+G24-H24 -> 0
A25: 2412 Land Use Rights - Amortizable | J25: =F25+G25-H25 -> 0
A26: 2413 Patents, Copyrights, and Trademarks - Amortizable | J26: =F26+G26-H26 -> 0
A27: 2414 Other Intangible Assets - Amortizable | J27: =F27+G27-H27 -> 0
A28: 2415 Right-to-Use Leased Land - Amortizable | J28: =F28+G28-H28 -> 0
A29: 2416 Right-to-Use Leased Buildings - Amortizable | J29: =F29+G29-H29 -> 0
A30: 2417 Right-to-Use Leased Equipment - Amortizable | J30: =F30+G30-H30 -> 0
A31: 2418 Right-to-Use Subscription-Based Information Technology Arrangements (SBITA) - Amortizable | J31: =F31+G31-H31 -> 0
A32: 2422 Land Use Rights - Non-Amortizable | J32: =F32+G32-H32 -> 0
A35: Fund: | B35: 0703 | F35: =SUM(F16:F34) -> 70479745 | G35: =SUM(G16:G34) -> 0 | H35: =SUM(H16:H34) -> 0 | J35: =SUM(J16:J34) -> 70479745
A37: Note:
A38: a - Infrastructure only.
A40: I certify (or declare) under penalty of perjury that the attached reports are true, accurate and complete, and were prepared following the applicable laws, regulations, policies, procedures, and instructions. I have not violated any of the provisions of Article 4, Chapter 1, Division 4, Title 1, Government Code (commencing with Section 1090) and Article 2, Chapter 1, Part 3, Division 3, Title 2, Government Code (commencing with Section 13030).
A46: Subscribed and executed this 30th day of August, 2024 at Sacramento, California.
I52: KIM PHAN, Chief
I53: Service Transactions & Asset
I54: Reconciliation Section

Sheet 0756
I1: Page No : 11
A2: REPORT 18 – STATEMENT OF CHANGES IN CAPITAL ASSETS
A3: Department Name (2660)
A4: PASSENGER RAIL BOND FUND - PROPOSITION 108 (0756)
A5: Fiscal Year 2023-24
A6: As of 06/30/2024
A7: Business Unit: | C7: 2660 - DEPARTMENT OF TRANSPORTATION | I7: Report ID: | J7: RPTGL075
A8: Fund: | C8: 0756 PASSENGER RAIL BOND FUND - PROPOSITION 108 | I8: Run Date: | J8: =TODAY() -> 45723
I9: Run Time: | J9: =NOW() -> 45723.508
A14: Account – Description | F14: Beginning Balance | G14: Additions | H14: Deductions | J14: Ending Balance
A15: Tangible Assets
A16: 2310 Land a | J16: =F16+G16-H16 -> 0
A17: 2321 Buildings | J17: =F17+G17-H17 -> 0
A18: 2331 Improvements Other Than Buildings | J18: =F18+G18-H18 -> 0
A19: 2341 Equipment | F19: 1.0175604e+08 | J19: =F19+G19-H19 -> 1.0175604e+08
A20: 2350 Construction Work in Progress a | J20: =F20+G20-H20 -> 0
A21: 2361 Infrastructure - Non Depreciable a | J21: =F21+G21-H21 -> 0
A23: Intangible Assets
A24: 2411 Computer Software - Amortizable | J24: =F24+G24-H24 -> 0
A25: 2412 Land Use Rights - Amortizable | J25: =F25+G25-H25 -> 0
A26: 2413 Patents, Copyrights, and Trademarks - Amortizable | J26: =F26+G26-H26 -> 0
A27: 2414 Other Intangible Assets - Amortizable | J27: =F27+G27-H27 -> 0
A28: 2415 Right-to-Use Leased Land - Amortizable | J28: =F28+G28-H28 -> 0
A29: 2416 Right-to-Use Leased Buildings - Amortizable | J29: =F29+G29-H29 -> 0
A30: 2417 Right-to-Use Leased Equipment - Amortizable | J30: =F30+G30-H30 -> 0
A31: 2418 Right-to-Use Subscription-Based Information Technology Arrangements (SBITA) - Amortizable | J31: =F31+G31-H31 -> 0
A32: 2422 Land Use Rights - Non-Amortizable | J32: =F32+G32-H32 -> 0
A35: Fund: | B35: 0756 | F35: =SUM(F16:F34) -> 1.0175604e+08 | G35: =SUM(G16:G34) -> 0 | H35: =SUM(H16:H34) -> 0 | J35: =SUM(J16:J34) -> 1.0175604e+08
A37: Note:
A38: a - Infrastructure only.
A40: I certify (or declare) under penalty of perjury that the attached reports are true, accurate and complete, and were prepared following the applicable laws, regulations, policies, procedures, and instructions. I have not violated any of the provisions of Article 4, Chapter 1, Division 4, Title 1, Government Code (commencing with Section 1090) and Article 2, Chapter 1, Part 3, Division 3, Title 2, Government Code (commencing with Section 13030).
A46: Subscribed and executed this 30th day of August, 2024 at Sacramento, California.
I52: KIM PHAN, Chief
I53: Service Transactions & Asset
I54: Reconciliation Section

Sheet 0942
I1: Page No : 12
A2: REPORT 18 – STATEMENT OF CHANGES IN CAPITAL ASSETS
A3: Department Name (2660)
A4: SPECIAL DEPOSITS FUND (0942)
A5: Fiscal Year 2023-24
A6: As of 06/30/2024
A7: Business Unit: | C7: 2660 - DEPARTMENT OF TRANSPORTATION | I7: Report ID: | J7: RPTGL075
A8: Fund: | C8: 0942 SPECIAL DEPOSITS FUND | I8: Run Date: | J8: =TODAY() -> 45723
I9: Run Time: | J9: =NOW() -> 45723.508
A14: Account – Description | F14: Beginning Balance | G14: Additions | H14: Deductions | J14: Ending Balance
A15: Tangible Assets
A16: 2310 Land a | J16: =F16+G16-H16 -> 0
A17: 2321 Buildings | J17: =F17+G17-H17 -> 0
A18: 2331 Improvements Other Than Buildings | J18: =F18+G18-H18 -> 0
A19: 2341 Equipment | J19: =F19+G19-H19 -> 0
A20: 2350 Construction Work in Progress a | F20: 56384988 | G20: 30051.7 | H20: 0 | J20: =F20+G20-H20 -> 56415040
A21: 2361 Infrastructure - Non Depreciable a | J21: =F21+G21-H21 -> 0
A23: Intangible Assets
A24: 2411 Computer Software - Amortizable | J24: =F24+G24-H24 -> 0
A25: 2412 Land Use Rights - Amortizable | J25: =F25+G25-H25 -> 0
A26: 2413 Patents, Copyrights, and Trademarks - Amortizable | J26: =F26+G26-H26 -> 0
A27: 2414 Other Intangible Assets - Amortizable | J27: =F27+G27-H27 -> 0
A28: 2415 Right-to-Use Leased Land - Amortizable | J28: =F28+G28-H28 -> 0
A29: 2416 Right-to-Use Leased Buildings - Amortizable | J29: =F29+G29-H29 -> 0
A30: 2417 Right-to-Use Leased Equipment - Amortizable | J30: =F30+G30-H30 -> 0
A31: 2418 Right-to-Use Subscription-Based Information Technology Arrangements (SBITA) - Amortizable | J31: =F31+G31-H31 -> 0
A32: 2422 Land Use Rights - Non-Amortizable | J32: =F32+G32-H32 -> 0
A35: Fund: | B35: 0942 | F35: =SUM(F16:F34) -> 56384988 | G35: =SUM(G16:G34) -> 30051.7 | H35: =SUM(H16:H34) -> 0 | J35: =SUM(J16:J34) -> 56415040
A37: Note:
A38: a - Infrastructure only.
A40: I certify (or declare) under penalty of perjury that the attached reports are true, accurate and complete, and were prepared following the applicable laws, regulations, policies, procedures, and instructions. I have not violated any of the provisions of Article 4, Chapter 1, Division 4, Title 1, Government Code (commencing with Section 1090) and Article 2, Chapter 1, Part 3, Division 3, Title 2, Government Code (commencing with Section 13030).
A46: Subscribed and executed this 30th day of August, 2024 at Sacramento, California.
I52: KIM PHAN, Chief
I53: Service Transactions & Asset
I54: Reconciliation Section

Sheet 2504
I1: Page No : 13
A2: REPORT 18 – STATEMENT OF CHANGES IN CAPITAL ASSETS
A3: Department Name (2660)
A4: Advance Mitigation Account, State Transportation Fund (2504)
A5: Fiscal Year 2023-24
A6: As of 06/30/2024
A7: Business Unit: | C7: 2660 - DEPARTMENT OF TRANSPORTATION | I7: Report ID: RPTGL075 | J7: RPTGL075
A8: Fund: | C8: 2504 ADVANCE MITIGATION ACCOUNT, State Transportation Fund | I8: Run Date: | J8: =TODAY() -> 45723
I9: Run Time: | J9: =NOW() -> 45723.508
A14: Account – Description | F14: Beginning Balance | G14: Additions | H14: Deductions | J14: Ending Balance
A15: Tangible Assets
A16: 2310 Land a | J16: =F16+G16-H16 -> 0
A17: 2321 Buildings | J17: =F17+G17-H17 -> 0
A18: 2331 Improvements Other Than Buildings | J18: =F18+G18-H18 -> 0
A19: 2341 Equipment | J19: =F19+G19-H19 -> 0
A20: 2350 Construction Work in Progress a | J20: =F20+G20-H20 -> 0
A21: 2361 Infrastructure - Non Depreciable a | J21: =F21+G21-H21 -> 0
A23: Intangible Assets
A24: 2411 Computer Software - Amortizable | J24: =F24+G24-H24 -> 0
A25: 2412 Land Use Rights - Amortizable | F25: 0 | H25: 0 | J25: =F25+G25-H25 -> 0
A26: 2413 Patents, Copyrights, and Trademarks - Amortizable | G26: 3187845 | J26: =F26+G26-H26 -> 3187845
A27: 2414 Other Intangible Assets - Amortizable | J27: =F27+G27-H27 -> 0
A28: 2415 Right-to-Use Leased Land - Amortizable | J28: =F28+G28-H28 -> 0
A29: 2416 Right-to-Use Leased Buildings - Amortizable | J29: =F29+G29-H29 -> 0
A30: 2417 Right-to-Use Leased Equipment - Amortizable | J30: =F30+G30-H30 -> 0
A31: 2418 Right-to-Use Subscription-Based Information Technology Arrangements (SBITA) - Amortizable | J31: =F31+G31-H31 -> 0
A32: 2422 Land Use Rights - Non-Amortizable | J32: =F32+G32-H32 -> 0
A35: Fund: | B35: 2504 | F35: =SUM(F23:F34) -> 0 | G35: =SUM(G23:G34) -> 3187845 | H35: =SUM(H23:H34) -> 0 | J35: =SUM(J23:J34) -> 3187845
A37: Note:
A38: a - Infrastructure only.
A40: I certify (or declare) under penalty of perjury that the attached reports are true, accurate and complete, and were prepared following the applicable laws, regulations, policies, procedures, and instructions. I have not violated any of the provisions of Article 4, Chapter 1, Division 4, Title 1, Government Code (commencing with Section 1090) and Article 2, Chapter 1, Part 3, Division 3, Title 2, Government Code (commencing with Section 13030).
A46: Subscribed and executed this 30th day of August, 2024 at Sacramento, California.
I52: KIM PHAN, Chief
I53: Service Transactions & Asset
I54: Reconciliation Section

Sheet 3007
I1: Page No : 14
A2: REPORT 18 – STATEMENT OF CHANGES IN CAPITAL ASSETS
A3: Department Name (2660)
A4: TRAFFIC CONGESTION RELIEF FUND (3007)
A5: Fiscal Year 2023-24
A6: As of 06/30/2024
A7: Business Unit: | C7: 2660 - DEPARTMENT OF TRANSPORTATION | I7: Report ID: | J7: RPTGL075
A8: Fund: | C8: 3007 TRAFFIC CONGESTION RELIEF FUND | I8: Run Date: | J8: =TODAY() -> 45723
I9: Run Time: | J9: =NOW() -> 45723.508
A14: Account – Description | F14: Beginning Balance | G14: Additions | H14: Deductions | J14: Ending Balance
A15: Tangible Assets
A16: 2310 Land a | F16: 3.2481782e+08 | G16: 2630.83 | H16: 0 | J16: =F16+G16-H16 -> 3.2482045e+08
A17: 2321 Buildings | J17: =F17+G17-H17 -> 0
A18: 2331 Improvements Other Than Buildings | J18: =F18+G18-H18 -> 0
A19: 2341 Equipment | F19: 122733.78 | J19: =F19+G19-H19 -> 122733.78
A20: 2350 Construction Work in Progress a | F20: 3.0664624e+08 | G20: 0 | H20: 0 | J20: =F20+G20-H20 -> 3.0664624e+08
A21: 2361 Infrastructure - Non Depreciable a | F21: 5.5697738e+08 | G21: 46709.76 | H21: 0 | J21: =F21+G21-H21 -> 5.5702409e+08
J22: =F22+G22-H22 -> 0
A23: Intangible Assets | J23: =F23+G23-H23 -> 0
A24: 2411 Computer Software - Amortizable | J24: =F24+G24-H24 -> 0
A25: 2412 Land Use Rights - Amortizable | J25: =F25+G25-H25 -> 0
A26: 2413 Patents, Copyrights, and Trademarks - Amortizable | J26: =F26+G26-H26 -> 0
A27: 2414 Other Intangible Assets - Amortizable | J27: =F27+G27-H27 -> 0
A28: 2415 Right-to-Use Leased Land - Amortizable | J28: =F28+G28-H28 -> 0
A29: 2416 Right-to-Use Leased Buildings - Amortizable | J29: =F29+G29-H29 -> 0
A30: 2417 Right-to-Use Leased Equipment - Amortizable | J30: =F30+G30-H30 -> 0
A31: 2418 Right-to-Use Subscription-Based Information Technology Arrangements (SBITA) - Amortizable | J31: =F31+G31-H31 -> 0
A32: 2422 Land Use Rights - Non-Amortizable | J32: =F32+G32-H32 -> 0
A35: Fund: | B35: 3007 | F35: =SUM(F16:F34) -> 1.1885642e+09 | G35: =SUM(G16:G34) -> 49340.59 | H35: =SUM(H16:H34) -> 0 | J35: =SUM(J16:J34) -> 1.1886135e+09
A37: Note:
A38: a - Infrastructure only.
A40: b - The $2,630.83 in Land Additions is part of a larger project, over $5K, that is multi-funded.
A42: c - See "Beginning Balance Differential Report".
A44: I certify (or declare) under penalty of perjury that the attached reports are true, accurate and complete, and were prepared following the applicable laws, regulations, policies, procedures, and instructions. I have not violated any of the provisions of Article 4, Chapter 1, Division 4, Title 1, Government Code (commencing with Section 1090) and Article 2, Chapter 1, Part 3, Division 3, Title 2, Government Code (commencing with Section 13030).
A50: Subscribed and executed this 30th day of August, 2024 at Sacramento, California.
I56: KIM PHAN, Chief
I57: Service Transactions & Asset
I58: Reconciliation Section

Sheet F3007 Diff
A1: Department of Transportation (2660)
A2: Statement of Changes in Capital Assets Group of Accounts - Report 18
A3: Beginning Balance Differential Report
A4: State Highway Account Fund (3007)
A5: As of June 30, 2024
K7: Breakdown of Difference:
E8: (1) | G8: (2) | I8: (3) | K8: (4) | M8: (5) | O8: (6) | Q8: (7) | S8: (8) | T8: (9) | V8: (10)
E9: Prior Year Ending Balance | G9: Current Year Beginning Balance | I9: Difference | K9: Assets unreported in the prior year | M9: Non-capitalizable assets reported as capital assets in the prior year | O9: Availability Payment Arrangements (GASB 94) | Q9: Other amounts that make up the difference (provide description): Per SCO guidance, applying % to District Project Survey % adjustment for Prior Year Expenditures. | S9: Other amounts that make up the difference (provide description): incorrect entry was made in current year balance | T9: Other amounts that make up the difference (provide description): GASB 87 FY 2021-2022 implementation beginning balance adjustment. | V9: Restatement Amount (should agree to the difference calculated)
A11: Tangible Assets
B12: Land (2310) | E12: 3.2481782e+08 | G12: 3.2481782e+08 | I12: =G12-E12 -> 0 | V12: =SUM(K12:T12) -> 0
B13: Buildings (2321) | E13: 0 | G13: 0 | I13: =G13-E13 -> 0 | V13: =SUM(K13:T13) -> 0
B14: Improvements Other Than Buildings (2331) | I14: =G14-E14 -> 0 | V14: =SUM(K14:T14) -> 0
B15: Equipment (2341) | E15: 122733.78 | G15: 122733.78 | I15: =G15-E15 -> 0 | V15: =SUM(K15:T15) -> 0
B16: Construction Work in Progress (2350) | E16: 3.0762842e+08 | G16: 3.0664624e+08 | I16: =G16-E16 -> -982176.8 | Q16: -982176.8 | V16: =SUM(K16:T16) -> -982176.8
B17: Infrastructure - Non Depreciable (2361) | E17: 5.5519998e+08 | G17: 5.5697738e+08 | I17: =G17-E17 -> 1777400 | Q17: 1777400 | V17: =SUM(K17:T17) -> 1777400
A18: Intangible Assets | V18: =SUM(K18:T18) -> 0
B19: Computer Software - Amortizable (2411) | E19: 0 | G19: 0 | I19: =G19-E19 -> 0 | V19: =SUM(K19:T19) -> 0
B20: Land Use Rights - Amortizable (2412) | V20: =SUM(K20:T20) -> 0
B21: Patents, Copyrights, and Trademarks - Amortizable (2413) | E21: 0 | G21: 0 | I21: =G21-E21 -> 0 | V21: =SUM(K21:T21) -> 0
B22: Other Intangible Assets - Amortizable (2414) | V22: =SUM(K22:T22) -> 0
B23: Right-to-Use Leased Land - Amortizable () | V23: =SUM(K23:T23) -> 0
B24: Right-to-Use Leased Buildings - Amortizable (2416) | E24: 0 | G24: 0 | I24: =G24-E24 -> 0 | V24: =SUM(K24:T24) -> 0
B25: Right-to-Use Leased Equipment - Amortizable | V25: =SUM(K25:T25) -> 0
B26: Right-to-Use Subscription-Based Information Technology Arrangements (SBITA) - Amortizable (2418) | E26: 0 | G26: 0 | I26: =G26-E26 -> 0 | S26: 0 | V26: =SUM(K26:T26) -> 0
B27: Land Use Rights - Non-Amortizable (2422) | V27: =SUM(K27:T27) -> 0
B28: Patents, Copyrights, and Trademarks - Non-Amortizable | I28: =G28-E28 -> 0 | V28: =SUM(K28:T28) -> 0
A29: Total | E29: =SUM(E12:E28) -> 1.1877689e+09 | G29: =SUM(G12:G28) -> 1.1885642e+09 | I29: =SUM(I12:I28) -> 795223.2 | K29: =SUM(K12:K28) -> 0 | M29: =SUM(M12:M28) -> 0 | O29: =SUM(O12:O28) -> 0 | Q29: =SUM(Q12:Q28) -> 795223.2 | S29: =SUM(S12:S28) -> 0 | T29: =SUM(T12:T28) -> 0 | V29: =SUM(V12:V28) -> 795223.2
A32: Report Instructions:
A33: Col. 1 - | C33: Enter Ending Balance from Prior Year Report 18.
A34: Col. 2 - | C34: Enter Beginning Balance from Current Year Report 18.
A35: Col. 3 - | C35: Compute difference between current year beginning balance and prior year ending balance.
C36: Research posting and source documents to identify and explain the difference.
A37: Col. 4 - 9 | C37: Breakdown and categorize the differences in columns 4 to 9.
A38: Col. 10 - | C38: Compute the sum of columns 4 to 8. The amount should agree with the computed difference in column 3.

Sheet 3290
I1: Page No : 15
A2: REPORT 18 – STATEMENT OF CHANGES IN CAPITAL ASSETS
A3: Department Name (2660)
A4: ROAD MAINTENANCE AND REHABILITATION ACCOUNT (3290)
A5: Fiscal Year 2023-24
A6: As of 06/30/2024
A7: Business Unit: | C7: 2660 - DEPARTMENT OF TRANSPORTATION | I7: Report ID: | J7: RPTGL075
A8: Fund: | C8: 3290 ROAD MAINTENANCE AND REHABILITATION ACCOUNT | I8: Run Date: | J8: =TODAY() -> 45723
I9: Run Time: | J9: =NOW() -> 45723.508
A14: Account – Description | F14: Beginning Balance | G14: Additions | H14: Deductions | J14: Ending Balance
A15: Tangible Assets
A16: 2310 Land a | F16: 18682476 | G16: 3384432.5 | J16: =F16+G16-H16 -> 22066908
A17: 2321 Buildings | F17: 0 | G17: 9485.68 | J17: =F17+G17-H17 -> 9485.68
A18: 2331 Improvements Other Than Buildings | J18: =F18+G18-H18 -> 0
A19: 2341 Equipment | F19: 1608024.9 | G19: 267420.37 | H19: 358620.74 | J19: =F19+G19-H19 -> 1516824.6
A20: 2350 Construction Work in Progress a | F20: 5.1405771e+08 | G20: 1.4160137e+08 | H20: 2.4375495e+08 | J20: =F20+G20-H20 -> 4.1190413e+08
A21: 2361 Infrastructure - Non Depreciable b | F21: 2.0764281e+08 | G21: 2.6748512e+08 | H21: 0 | J21: =F21+G21-H21 -> 4.7512793e+08
A23: Intangible Assets
A24: 2411 Computer Software - Amortizable | F24: 1140915.6 | G24: 7891.3 | J24: =F24+G24-H24 -> 1148806.9
A25: 2412 Land Use Rights - Amortizable | J25: =F25+G25-H25 -> 0
A26: 2413 Patents, Copyrights, and Trademarks - Amortizable | J26: =F26+G26-H26 -> 0
A27: 2414 Other Intangible Assets - Amortizable | J27: =F27+G27-H27 -> 0
A28: 2415 Right-to-Use Leased Land - Amortizable | J28: =F28+G28-H28 -> 0
A29: 2416 Right-to-Use Leased Buildings - Amortizable | F29: 9654616 | G29: 3564523.1 | H29: 1104181.1 | J29: =F29+G29-H29 -> 12114958
A30: 2417 Right-to-Use Leased Equipment - Amortizable | J30: =F30+G30-H30 -> 0
A31: 2418 Right-to-Use Subscription-Based Information Technology Arrangements (SBITA) - Amortizable | F31: 41712.96 | G31: 8849.98 | H31: 14112.76 | J31: =F31+G31-H31 -> 36450.18
A32: 2422 Land Use Rights - Non-Amortizable | J32: =F32+G32-H32 -> 0
A35: Fund: | B35: 3290 | F35: =SUM(F16:F34) -> 7.5282826e+08 | G35: =SUM(G16:G34) -> 4.163291e+08 | H35: =SUM(H16:H34) -> 2.4523187e+08 | J35: =SUM(J16:J34) -> 9.2392549e+08
A37: Note:
A38: a - Infrastructure only.
A40: b - Infrastructure only.
A42: c - The $243,754,951.19 in Construction Work in Progress' Deductions which represents FY 2023/2024's Transfer from CWIP to Non-Depreciable Infrastructure (Completed).
A45: d - The $1,104,181.11 in deductions for Right-to-Use Leased Buildings - Amortizable represents FY2023/2024 removal of lease asset at the end of the lease term.
A48: e - See "Beginning Balance Differential Report".
A50: I certify (or declare) under penalty of perjury that the attached reports are true, accurate and complete, and were prepared following the applicable laws, regulations, policies, procedures, and instructions. I have not violated any of the provisions of Article 4, Chapter 1, Division 4, Title 1, Government Code (commencing with Section 1090) and Article 2, Chapter 1, Part 3, Division 3, Title 2, Government Code (commencing with Section 13030).
A56: Subscribed and executed this 30th day of August, 2024 at Sacramento, California.
I62: KIM PHAN, Chief
I63: Service Transactions & Asset
I64: Reconciliation Section

Sheet F3290 Diff 
A1: Department of Transportation (2660)
A2: Statement of Changes in Capital Assets Group of Accounts - Report 18
A3: Beginning Balance Differential Report
A4: State Highway Account Fund (3290)
A5: As of June 30, 2024
K7: Breakdown of Difference:
E8: (1) | G8: (2) | I8: (3) | K8: (4) | M8: (5) | O8: (6) | Q8: (7) | S8: (8) | T8: (9) | V8: (10)
E9: Prior Year Ending Balance | G9: Current Year Beginning Balance | I9: Difference | K9: Assets unreported in the prior year | M9: Non-capitalizable assets reported as capital assets in the prior year | O9: Availability Payment Arrangements (GASB 94) | Q9: Other amounts that make up the difference (provide description): Per SCO guidance, applying % to District Project Survey % adjustment for Prior Year Expenditures. | S9: Other amounts that make up the difference (provide description): GASB 87 FY2021-2022 Implementation beginning balance adjustment | T9: Other amounts that make up the difference (provide description): Prior Year Fund to Fund Adjustment. | V9: Restatement Amount (should agree to the difference calculated)
A11: Tangible Assets
B12: Land (2310) | E12: 18207982 | G12: 18682476 | I12: =G12-E12 -> 474494.04 | Q12: 474494.04 | V12: =SUM(K12:T12) -> 474494.04
B13: Buildings (2321) | E13: 0 | G13: 0 | I13: =G13-E13 -> 0 | V13: =SUM(K13:T13) -> 0
B14: Improvements Other Than Buildings (2331) | I14: =G14-E14 -> 0 | V14: =SUM(K14:T14) -> 0
B15: Equipment (2341) | E15: 1608024.9 | G15: 1608024.9 | I15: =G15-E15 -> 0 | V15: =SUM(K15:T15) -> 0
B16: Construction Work in Progress (2350) | E16: 5.7001773e+08 | G16: 5.1405771e+08 | I16: =G16-E16 -> -55960018 | Q16: -55960018 | V16: =SUM(K16:T16) -> -55960018
